Workbook

Sheet 처음
B1: K-건설맵 공사서류 원클릭
B2: 한 번 입력하면 착공부터 준공·하자까지 서류 34가지가 채워집니다. 매크로 없이 수식만 써서 엑셀·한셀·구글 시트 어디서나 열립니다. 모든 공사 현장(관급·민간)에 쓸 수 있습니다.
B4: ① | C4: 「입력」 시트의 노란 칸을 채웁니다. | G4: 입력 하러 가기 →
B5: ② | C5: 아래 목록에서 서류 이름을 누르면 그 서류로 갑니다. 서류 칸은 입력에서 저절로 채워집니다.
B6: ③ | C6: 인쇄하거나 PDF로 저장합니다 (한 서류가 A4 한 장).
B8: =IF(('입력'!$C$6="")+('입력'!$C$7="")+('입력'!$C$11="")+('입력'!$C$12="")+('입력'!$C$13="")+('입력'!$C$14="")+('입력'!$C$17="")+('입력'!$C$18="")+('입력'!$C$27="")+('입력'!$C$28="")+('입력'!$C$30="")+('입력'!$C$38="")=0,"✔ 꼭 필요한 칸은 다 채웠습니다.","⚠ 꼭 필요한 칸 중 "&(('입력'!$C$6="")+('입력'!$C$7="")+('입력'!$C$11="")+('입력'!$C$12="")+('입력'!$C$13="")+('입력'!$C$14="")+('입력'!$C$17="")+('입력'!$C$18="")+('입력'!$C$27="")+('입력'!$C$28="")+('입력'!$C$30="")+('입력'!$C$38=""))&"개가 비어 있습니다 — 입력 시트를 확인하세요.")
B10: 번호 | C10: 서 류 | D10: 누가 내나 | E10: 언 제 | F10: 관급 | G10: 무엇인가
B11: 1 | C11: 사용인감계 | D11: 업체 | E11: 계약 | G11: 법인 인감 대신 쓸 도장을 신고하는 서류.
B12: 2 | C12: 계약보증금 납부서 | D12: 업체 | E12: 계약 | F12: 관급 | G12: 계약보증금(보증서·현금)을 내는 서류. 금액은 요율로 자동 계산.
B13: 3 | C13: 계약보증금 지급각서 | D13: 업체 | E13: 계약 | F13: 관급 | G13: 계약보증금 대신 내는 지급각서 (면제 대상일 때).
B14: 4 | C14: 청렴계약 이행서약서 | D14: 업체 | E14: 계약 | F14: 관급 | G14: 금품·담합을 하지 않겠다는 서약서.
B15: 5 | C15: 수의계약 각서 | D15: 업체 | E15: 계약 | F15: 관급 | G15: 수의계약일 때 내는 각서.
B16: 6 | C16: 선금 신청서 | D16: 업체 | E16: 계약 | F16: 관급 | G16: 선금을 달라는 신청서. 신청률을 넣으면 금액·한글 금액 자동.
B17: 7 | C17: 선금 사용계획서 | D17: 업체 | E17: 계약 | F17: 관급 | G17: 선금을 어디에 쓸지 적는 계획서. 표는 빈 줄 — 합계만 자동.
B18: 8 | C18: 착공신고서 | D18: 업체 | E18: 착공 | G18: 공사를 시작했다고 알리는 서류. 공사명·계약금액·공사기간이 입력에서 채워집니다.
B19: 9 | C19: 현장대리인계 | D19: 업체 | E19: 착공 | G19: 현장대리인의 자격·연락처를 알리는 서류.
B20: 10 | C20: 예정공정표 | D20: 업체 | E20: 착공 | G20: 공종별 공사 일정을 달 단위로 적는 표.
B21: 11 | C21: 인력·장비 투입계획서 | D21: 업체 | E21: 착공 | G21: 착공신고서 붙임 «공정별 인력 및 장비투입계획서». 달은 착공일부터 저절로.
B22: 12 | C22: 직접시공계획서 | D22: 업체 | E22: 착공 | G22: 우리 회사가 직접 시공할 공종·금액을 알리는 계획서.
B23: 13 | C23: 산안비 사용계획서 | D23: 업체 | E23: 착공 | G23: 산안비를 항목별로 언제·얼마 쓸지 적는 계획서. 항목 9가지는 고시 서식 그대로.
B24: 14 | C24: 수도전기료 납부각서 | D24: 업체 | E24: 착공 | G24: 기존 시설 안에서 공사할 때 — 수도·전기 요금 정산 각서.
B25: 15 | C25: 월간 공정보고서 | D25: 업체 | E25: 공사 중 | G25: 달마다 내는 공정 보고. 계획·실적 공정률을 넣으면 앞섬·늦음 자동.
B26: 16 | C26: 노무비 청구내역서 | D26: 업체 | E26: 공사 중 | F26: 관급 | G26: 달마다 노무비를 청구할 때 직종별로 모은 표. 누계 자동 · 표는 빈 줄.
B27: 17 | C27: 산안비 사용내역서 | D27: 업체 | E27: 공사 중 | G27: 고시 별지 제1호서식 첫 쪽(총괄) 칸 그대로. 항목별 사용내역 9쪽은 🦺 산안비 도구에서.
B28: 18 | C28: 하도급계약 통보서 | D28: 업체 | E28: 공사 중 | G28: 법정 서식(건설산업기본법 시행규칙 별지 제23호서식) 앞·뒤쪽 칸 그대로 — 2장. 하도급률 자동.
B29: 19 | C29: 하도급계약 통보서 뒤쪽 | D29: 업체 | E29: 공사 중 | G29: 별지 제23호서식 뒤쪽(첨부서류 · 유의사항 · 처리절차) 그대로. 앞쪽과 같이 인쇄하세요.
B30: 20 | C30: 기성검사 요청서 | D30: 업체 | E30: 공사 중 | G30: 기성 부분 검사를 요청하는 서류. 누계·기성률 자동.
B31: 21 | C31: 기성대가 청구서 | D31: 업체 | E31: 공사 중 | G31: 기성금을 청구하는 서류. 선금 정산을 빼고 계산.
B32: 22 | C32: 하도급대금 지급확인서 | D32: 업체 | E32: 공사 중 | F32: 관급 | G32: 하도급·자재·장비 대금을 준 것을 확인하는 서류(기성 청구 때). 기성 회차·기간 자동.
B33: 23 | C33: 공기연장 신청서 | D33: 업체 | E33: 공사 중 | G33: 준공기한을 늘려 달라는 신청서. 연장 일수 자동.
B34: 24 | C34: 계약금액 조정 신청서 | D34: 업체 | E34: 공사 중 | F34: 관급 | G34: 설계변경·물가변동으로 계약금액을 고쳐 달라는 신청서. 조정 후 금액·한글 금액 자동.
B35: 25 | C35: 준공신고서 | D35: 업체 | E35: 준공 | G35: 공사를 마쳤다고 알리는 서류(준공계).
B36: 26 | C36: 준공검사 요청서 | D36: 업체 | E36: 준공 | G36: 준공검사를 해 달라는 요청서(준공검사원).
B37: 27 | C37: 준공대가 청구서 | D37: 업체 | E37: 준공 | G37: 준공금을 청구하는 서류. 기성·선금·지체상금 공제 자동.
B38: 28 | C38: 준공정산 동의서 | D38: 업체 | E38: 준공 | G38: 정산된 최종 금액에 동의하는 서류.
B39: 29 | C39: 하자보수보증금 납부서 | D39: 업체 | E39: 준공 | G39: 하자보수보증금을 내는 서류. 금액·기간 자동.
B40: 30 | C40: 하자보수보증금 지급각서 | D40: 업체 | E40: 준공 | F40: 관급 | G40: 하자보수보증금 대신 내는 지급각서.
B41: 31 | C41: 공사감독조서 | D41: 발주기관 | E41: 준공 | G41: 감독자가 쓰는 감독 결과 조서.
B42: 32 | C42: 준공검사조서 | D42: 발주기관 | E42: 준공 | G42: 검사자가 쓰는 준공검사 조서.
B43: 33 | C43: 공사대장 | D43: 발주기관 | E43: 관리 | G43: 공사 하나를 한 장으로 정리한 관리 카드.
...

Sheet 입력
B1: 공사서류 원클릭 — 입력
B2: 노란 칸만 채우면 서류 34가지에 저절로 들어갑니다. 모르는 칸은 비워 두세요 — 서류에서 그 자리만 빈칸으로 나옵니다.
B3: ← 처음(목록)으로
B5: 1. 공사
B6: 공 사 명 | D6: 계약서에 적힌 이름 그대로
B7: 현장 위치 | D7: 공사 현장 주소
B8: 공사 개요 | D8: 주요 공사 내용 한 줄 (공사대장에 들어갑니다)
B9: 계약 번호 | D9: 없으면 비워 두세요
B10: 계약 방법 | D10: 고르세요
B11: 계 약 일 | D11: 예: 2026-03-02
B12: 착 공 일
B13: 준공 기한 (계약상) | D13: 계약서의 준공 예정일
B14: 계약 금액 (원, 부가세 포함) | D14: 숫자만 — 예: 123456000
B16: 2. 발주기관 (발주자)
B17: 발주기관 이름 | D17: 민간 공사면 건축주·회사 이름
B18: 서류 받는 사람 (귀하 앞) | D18: 서류 끝 「○○○ 귀하」 에 들어갈 이름·직함
B19: 발주기관 주소
B20: 공사 감독자 (직·성명) | D20: 예: 시설팀장 ○○○
B21: 준공 검사자 (직·성명)
B22: 검사 입회자 (직·성명)
B23: 설계자 | D23: 설계사무소 (공사대장용, 없으면 비움)
B24: 감리자 | D24: 감리단 (없으면 비움)
B26: 3. 계약상대자 (우리 회사)
B27: 상 호
B28: 대 표 자
B29: 사업자등록번호 | D29: 000-00-00000
B30: 주 소
B31: 전화번호
B32: 업종 (면허) | D32: 예: 실내건축공사업
B33: 은 행 명 | D33: 대금 받을 계좌 (계약 때 등록한 계좌)
B34: 예 금 주
B35: 계좌번호
B37: 4. 현장대리인
B38: 성 명
B39: 생년월일 | D39: 예: 1980. 1. 1.
B40: 자격 종목·등급 | D40: 예: 건축기사 / 건설기술인 중급
B41: 자격(등록) 번호
B42: 연 락 처
B44: 5. 보증·요율 — 계약서에 적힌 값을 넣으세요
B45: 계약보증금률 (%) | D45: 예: 10 → 10% (공고서·계약서 확인)
...

Sheet 01 사용인감계
B2: 사 용 인 감 계 | O2: ← 처음(목록)으로
O3: ✎ 입력 고치기
B4: 상 호 | E4: ='입력'!$C$27&""
B5: 대 표 자 | E5: ='입력'!$C$28&"" | O5: 칸은 「입력」 시트에서 저절로 채워집니다. 여기서 직접 고쳐 써도 됩니다 (그 칸만 수식이 바뀜).
B6: 사업자등록번호 | E6: ='입력'!$C$29&""
B7: 주 소 | E7: ='입력'!$C$30&""
B9: 대상 계약 | E9: ='입력'!$C$6&""
B10: 사용 기간 | E10: 이 계약의 체결부터 하자담보책임기간이 끝날 때까지
B12: 구 분 | E12: 인 감 | J12: 비 고
B13: 법인(개인) 인감 | J13: 인감증명서 붙임
B14: 사용 인감
B16: 위 사용 인감을 이 계약과 관련된 모든 서류에 법인(개인) 인감을 대신하여 사용하고자 신고하며, 이 인감을 사용하여 생기는 모든 책임은 우리 회사가 집니다.
B18: =IF('입력'!$C$11=""," 년 월 일",YEAR('입력'!$C$11)&"년 "&MONTH('입력'!$C$11)&"월 "&DAY('입력'!$C$11)&"일")
B20: 계약상대자 | G20: 상 호 | I20: : | J20: ='입력'!$C$27&""
G21: 주 소 | I21: : | J21: ='입력'!$C$30&""
G22: 대 표 자 | I22: : | J22: ='입력'!$C$28&" (인)"
B25: =IF('입력'!$C$18=""," 귀하",'입력'!$C$18&" 귀하")

Sheet 02 계약보증금 납부서
B2: 계 약 보 증 금 납 부 서 | O2: ← 처음(목록)으로
O3: ✎ 입력 고치기
B4: 공 사 명 | E4: ='입력'!$C$6&""
B5: 계약 번호 | E5: ='입력'!$C$9&"" | O5: 칸은 「입력」 시트에서 저절로 채워집니다. 여기서 직접 고쳐 써도 됩니다 (그 칸만 수식이 바뀜).
B6: 계약 금액 | E6: =IF('입력'!$C$14="","",'계산'!$J$3&"원정 (₩"&FIXED('입력'!$C$14,0)&")")
B7: 보증금률 | E7: =IF('입력'!$C$45="","",'입력'!$C$45&"%")
B8: 계약보증금 | E8: =IF('입력'!$C$124="","",'계산'!$J$5&"원정 (₩"&FIXED('입력'!$C$124,0)&")")
B9: 납부 방법 | E9: ='입력'!$C$46&""
B10: 보증 기간 | E10: =IF(OR('입력'!$C$11="",'입력'!$C$13=""),"",IF('입력'!$C$11="","",YEAR('입력'!$C$11)&". "&MONTH('입력'!$C$11)&". "&DAY('입력'!$C$11)&".")&" ~ "&IF('입력'!$C$13="","",YEAR('입력'!$C$13)&". "&MONTH('입력'!$C$13)&". "&DAY('입력'!$C$13)&"."))
B12: 위 계약의 계약보증금을 위와 같이 납부합니다.
B13: 붙임 서류 | I13: 부수 | K13: 비고
B14: 계약보증서(보증증권) — 현금이면 납부 영수증 | I14: 1부
B16: ※ 보증 기간은 보증서에 적힌 기간을 확인하세요.
B18: =IF('입력'!$C$11=""," 년 월 일",YEAR('입력'!$C$11)&"년 "&MONTH('입력'!$C$11)&"월 "&DAY('입력'!$C$11)&"일")
B20: 계약상대자 | G20: 상 호 | I20: : | J20: ='입력'!$C$27&""
G21: 주 소 | I21: : | J21: ='입력'!$C$30&""
G22: 대 표 자 | I22: : | J22: ='입력'!$C$28&" (인)"
B25: =IF('입력'!$C$18=""," 귀하",'입력'!$C$18&" 귀하")

Sheet 03 계약보증금 지급각서
B2: 계 약 보 증 금 지 급 각 서 | O2: ← 처음(목록)으로
O3: ✎ 입력 고치기
B4: 공 사 명 | E4: ='입력'!$C$6&""
B5: 계약 번호 | E5: ='입력'!$C$9&"" | O5: 칸은 「입력」 시트에서 저절로 채워집니다. 여기서 직접 고쳐 써도 됩니다 (그 칸만 수식이 바뀜).
B6: 계약 금액 | E6: =IF('입력'!$C$14="","",'계산'!$J$3&"원정 (₩"&FIXED('입력'!$C$14,0)&")")
B7: 계약보증금 | E7: =IF('입력'!$C$124="","",'계산'!$J$5&"원정 (₩"&FIXED('입력'!$C$124,0)&")")
B9: 우리 회사는 위 계약의 계약보증금 납부를 면제받는 대신, 계약상의 의무를 이행하지 아니하여 계약보증금이 발주기관에 귀속되는 사유가 생긴 때에는 위 계약보증금에 해당하는 금액을 발주기관의 청구에 따라 즉시 현금으로 납부할 것을 각서합니다.
B11: =IF('입력'!$C$11=""," 년 월 일",YEAR('입력'!$C$11)&"년 "&MONTH('입력'!$C$11)&"월 "&DAY('입력'!$C$11)&"일")
B13: 계약상대자 | G13: 상 호 | I13: : | J13: ='입력'!$C$27&""
G14: 주 소 | I14: : | J14: ='입력'!$C$30&""
G15: 대 표 자 | I15: : | J15: ='입력'!$C$28&" (인)"
B18: =IF('입력'!$C$18=""," 귀하",'입력'!$C$18&" 귀하")

Sheet 04 청렴계약 이행서약서
B2: 청 렴 계 약 이 행 서 약 서 | O2: ← 처음(목록)으로
O3: ✎ 입력 고치기
B4: 공 사 명 | E4: ='입력'!$C$6&""
B5: 계약 번호 | E5: ='입력'!$C$9&"" | O5: 칸은 「입력」 시트에서 저절로 채워집니다. 여기서 직접 고쳐 써도 됩니다 (그 칸만 수식이 바뀜).
B6: 상 호 | E6: ='입력'!$C$27&""
B7: 대 표 자 | E7: ='입력'!$C$28&""
B9: 우리 회사는 위 공사의 입찰·계약 체결과 이행에 관련하여 다음 사항을 지킬 것을 서약합니다.
B10: 1. 관계 공무원(임직원)에게 직접 또는 간접으로 금품·향응 등을 주거나 받지 않겠습니다.
B11: 2. 담합 등 공정한 경쟁을 방해하는 행위를 하지 않겠습니다.
B12: 3. 하도급·자재·장비 업체와의 거래에서도 부당한 요구를 하거나 금품을 주고받지 않겠습니다.
B13: 4. 위 사항을 어긴 때에는 계약 해제·해지, 입찰참가자격 제한 등 관계 법령과 계약 조건에 따른 조치를 받아들이겠습니다.
B15: =IF('입력'!$C$11=""," 년 월 일",YEAR('입력'!$C$11)&"년 "&MONTH('입력'!$C$11)&"월 "&DAY('입력'!$C$11)&"일")
B17: 계약상대자 | G17: 상 호 | I17: : | J17: ='입력'!$C$27&""
G18: 주 소 | I18: : | J18: ='입력'!$C$30&""
G19: 대 표 자 | I19: : | J19: ='입력'!$C$28&" (인)"
B22: =IF('입력'!$C$18=""," 귀하",'입력'!$C$18&" 귀하")

Sheet 05 수의계약 각서
B2: 수 의 계 약 각 서 | O2: ← 처음(목록)으로
O3: ✎ 입력 고치기
B4: 공 사 명 | E4: ='입력'!$C$6&""
B5: 계약 금액 | E5: =IF('입력'!$C$14="","",'계산'!$J$3&"원정 (₩"&FIXED('입력'!$C$14,0)&")") | O5: 칸은 「입력」 시트에서 저절로 채워집니다. 여기서 직접 고쳐 써도 됩니다 (그 칸만 수식이 바뀜).
B6: 계약 방법 | E6: ='입력'!$C$10&""
B8: 우리 회사는 위 공사를 수의계약으로 체결하면서 다음 사항을 지킬 것을 각서합니다.
B9: 1. 견적서 제출과 계약 체결 과정에서 다른 업체와 짜거나 부정한 방법을 쓰지 않았습니다.
B10: 2. 수의계약 상대자가 되는 데 결격 사유가 없으며, 제출한 서류는 사실과 다르지 않습니다.
B11: 3. 계약을 이행하면서 관계 법령과 계약 조건을 성실히 지키겠습니다.
B12: 4. 위 사항이 사실과 다르거나 이를 어긴 때에는 계약 해제·해지 등 관계 법령에 따른 조치를 받아들이겠습니다.
B14: =IF('입력'!$C$11=""," 년 월 일",YEAR('입력'!$C$11)&"년 "&MONTH('입력'!$C$11)&"월 "&DAY('입력'!$C$11)&"일")
B16: 계약상대자 | G16: 상 호 | I16: : | J16: ='입력'!$C$27&""
G17: 주 소 | I17: : | J17: ='입력'!$C$30&""
G18: 대 표 자 | I18: : | J18: ='입력'!$C$28&" (인)"
B21: =IF('입력'!$C$18=""," 귀하",'입력'!$C$18&" 귀하")

Sheet 06 선금 신청서
B2: 선 금 신 청 서 | O2: ← 처음(목록)으로
O3: ✎ 입력 고치기
B4: 공 사 명 | E4: ='입력'!$C$6&""
B5: 계약 번호 | E5: ='입력'!$C$9&"" | O5: 칸은 「입력」 시트에서 저절로 채워집니다. 여기서 직접 고쳐 써도 됩니다 (그 칸만 수식이 바뀜).
B6: 계약 금액 | E6: =IF('입력'!$C$14="","",'계산'!$J$3&"원정 (₩"&FIXED('입력'!$C$14,0)&")")
B7: 선금 신청률 | E7: =IF('입력'!$C$86="","",'입력'!$C$86&"%")
B8: 선금 신청 금액 | E8: =IF('입력'!$C$142="","",'계산'!$J$12&"원정 (₩"&FIXED('입력'!$C$142,0)&")")
B9: 보증기관 · 보증번호 | E9: ='입력'!$C$88&""
B11: 은 행 명 | E11: ='입력'!$C$33&""
B12: 예 금 주 | E12: ='입력'!$C$34&""
B13: 계좌 번호 | E13: ='입력'!$C$35&""
B15: 위와 같이 선금을 신청합니다.
B16: 붙임 서류 | I16: 부수 | K16: 비고
B17: 선금 보증서(보증증권) | I17: 1부
B18: 선금 사용계획서 | I18: 1부
B21: =IF('입력'!$C$85=""," 년 월 일",YEAR('입력'!$C$85)&"년 "&MONTH('입력'!$C$85)&"월 "&DAY('입력'!$C$85)&"일")
B23: 계약상대자 | G23: 상 호 | I23: : | J23: ='입력'!$C$27&""
G24: 주 소 | I24: : | J24: ='입력'!$C$30&""
G25: 대 표 자 | I25: : | J25: ='입력'!$C$28&" (인)"
B28: =IF('입력'!$C$18=""," 귀하",'입력'!$C$18&" 귀하")

Sheet 07 선금 사용계획서
B2: 선 금 사 용 계 획 서 | O2: ← 처음(목록)으로
O3: ✎ 입력 고치기
B4: 공 사 명 | E4: ='입력'!$C$6&""
B5: 선금 수령액 | E5: =IF('입력'!$C$142="","",'계산'!$J$12&"원정 (₩"&FIXED('입력'!$C$142,0)&")") | O5: 칸은 「입력」 시트에서 저절로 채워집니다. 여기서 직접 고쳐 써도 됩니다 (그 칸만 수식이 바뀜).
B6: 사용 기간
B8: 사용 항목 | E8: 세부 내용 | I8: 금액 (원) | K8: 사용 시기 | M8: 비 고
B19: 합 계 | I19: =IF(SUM(I9:I18)=0,"",SUM(I9:I18))
B21: 위와 같이 선금을 사용할 것을 계획하며, 계약 목적 외에는 사용하지 않겠습니다.
B23: =IF('입력'!$C$85=""," 년 월 일",YEAR('입력'!$C$85)&"년 "&MONTH('입력'!$C$85)&"월 "&DAY('입력'!$C$85)&"일")
B25: 계약상대자 | G25: 상 호 | I25: : | J25: ='입력'!$C$27&""
G26: 주 소 | I26: : | J26: ='입력'!$C$30&""
G27: 대 표 자 | I27: : | J27: ='입력'!$C$28&" (인)"
B30: =IF('입력'!$C$18=""," 귀하",'입력'!$C$18&" 귀하")

Sheet 08 착공신고서
B2: 착 공 신 고 서 | O2: ← 처음(목록)으로
O3: ✎ 입력 고치기
B4: 공 사 명 | E4: ='입력'!$C$6&""
B5: 계약 번호 | E5: ='입력'!$C$9&"" | O5: 칸은 「입력」 시트에서 저절로 채워집니다. 여기서 직접 고쳐 써도 됩니다 (그 칸만 수식이 바뀜).
B6: 계 약 일 | E6: =IF('입력'!$C$11="","",YEAR('입력'!$C$11)&". "&MONTH('입력'!$C$11)&". "&DAY('입력'!$C$11)&".")
B7: 계약 금액 | E7: =IF('입력'!$C$14="","",'계산'!$J$3&"원정 (₩"&FIXED('입력'!$C$14,0)&")")
B8: 공사 기간 | E8: =IF(OR('입력'!$C$12="",'입력'!$C$13=""),"",IF('입력'!$C$12="","",YEAR('입력'!$C$12)&". "&MONTH('입력'!$C$12)&". "&DAY('입력'!$C$12)&".")&" ~ "&IF('입력'!$C$13="","",YEAR('입력'!$C$13)&". "&MONTH('입력'!$C$13)&". "&DAY('입력'!$C$13)&".")&" ("&('입력'!$C$13-'입력'!$C$12+1)&"일)")
B9: 착 공 일 | E9: =IF('입력'!$C$12="","",YEAR('입력'!$C$12)&". "&MONTH('입력'!$C$12)&". "&DAY('입력'!$C$12)&".")
B10: 준공 기한 | E10: =IF('입력'!$C$13="","",YEAR('입력'!$C$13)&". "&MONTH('입력'!$C$13)&". "&DAY('입력'!$C$13)&".")
B11: 현장 위치 | E11: ='입력'!$C$7&""
B12: 현장대리인 | E12: ='입력'!$C$38&IF('입력'!$C$40="",""," ("&'입력'!$C$40&")")
B14: 위 공사를 계약 조건에 따라 착공하였기에 관계 서류를 붙여 신고합니다.
B15: 붙임 서류 | I15: 부수 | K15: 비고
B16: 현장기술자 지정신고서 (현장대리인) | I16: 1부
B17: 공사공정예정표 | I17: 1부
B18: 안전·환경 및 품질관리계획서 | I18: 1부
B19: 공정별 인력 및 장비투입계획서 | I19: 1부
B20: 착공 전 현장사진 | I20: 1부
B21: 그 밖에 발주기관이 정한 서류 (직접시공계획서 등) | I21: 1부
B23: ※ 붙임은 공사계약일반조건 제17조①(착공신고서) 그대로입니다. 공사기간 30일 미만 등은 발주기관이 내지 않게 할 수 있습니다.
B25: =IF('입력'!$C$12=""," 년 월 일",YEAR('입력'!$C$12)&"년 "&MONTH('입력'!$C$12)&"월 "&DAY('입력'!$C$12)&"일")
B27: 계약상대자 | G27: 상 호 | I27: : | J27: ='입력'!$C$27&""
G28: 주 소 | I28: : | J28: ='입력'!$C$30&""
G29: 대 표 자 | I29: : | J29: ='입력'!$C$28&" (인)"
B32: =IF('입력'!$C$18=""," 귀하",'입력'!$C$18&" 귀하")

Sheet 09 현장대리인계
B2: 현 장 대 리 인 지 정 신 고 서 | O2: ← 처음(목록)으로
O3: ✎ 입력 고치기
B4: 공 사 명 | E4: ='입력'!$C$6&""
B5: 계약 번호 | E5: ='입력'!$C$9&"" | O5: 칸은 「입력」 시트에서 저절로 채워집니다. 여기서 직접 고쳐 써도 됩니다 (그 칸만 수식이 바뀜).
B6: 공사 기간 | E6: =IF(OR('입력'!$C$12="",'입력'!$C$13=""),"",IF('입력'!$C$12="","",YEAR('입력'!$C$12)&". "&MONTH('입력'!$C$12)&". "&DAY('입력'!$C$12)&".")&" ~ "&IF('입력'!$C$13="","",YEAR('입력'!$C$13)&". "&MONTH('입력'!$C$13)&". "&DAY('입력'!$C$13)&".")&" ("&('입력'!$C$13-'입력'!$C$12+1)&"일)")
B7: 현장 위치 | E7: ='입력'!$C$7&""
B9: 성 명 | D9: 생년월일 | F9: 자격 종목·등급 | I9: 자격(등록) 번호 | L9: 연 락 처
B10: ='입력'!$C$38&"" | D10: ='입력'!$C$39&"" | F10: ='입력'!$C$40&"" | I10: ='입력'!$C$41&"" | L10: ='입력'!$C$42&""
B12: 배치 기간 | E12: =IF(OR('입력'!$C$12="",'입력'!$C$13=""),"",IF('입력'!$C$12="","",YEAR('입력'!$C$12)&". "&MONTH('입력'!$C$12)&". "&DAY('입력'!$C$12)&".")&" ~ "&IF('입력'!$C$13="","",YEAR('입력'!$C$13)&". "&MONTH('입력'!$C$13)&". "&DAY('입력'!$C$13)&"."))
B14: 위 사람을 이 공사의 현장대리인으로 지정하여 배치하였기에 신고합니다. 현장대리인은 계약 조건과 관계 법령에 따라 이 공사의 현장 관리 업무를 맡습니다.
B15: 붙임 서류 | I15: 부수 | K15: 비고
B16: 자격증(경력수첩) 사본 | I16: 1부
B17: 경력증명서 | I17: 1부
B18: 재직 증명 (4대 보험 가입 증명 등) | I18: 1부
B21: =IF('입력'!$C$12=""," 년 월 일",YEAR('입력'!$C$12)&"년 "&MONTH('입력'!$C$12)&"월 "&DAY('입력'!$C$12)&"일")
B23: 현장대리인 | G23: 성 명 | I23: : | J23: ='입력'!$C$38&" (인)"
B25: 계약상대자 | G25: 상 호 | I25: : | J25: ='입력'!$C$27&""
G26: 주 소 | I26: : | J26: ='입력'!$C$30&""
G27: 대 표 자 | I27: : | J27: ='입력'!$C$28&" (인)"
B30: =IF('입력'!$C$18=""," 귀하",'입력'!$C$18&" 귀하")

Sheet 10 예정공정표
B2: 공 사 예 정 공 정 표 | O2: ← 처음(목록)으로
O3: ✎ 입력 고치기
B4: 공 사 명 | E4: ='입력'!$C$6&""
B5: 공사 기간 | E5: =IF(OR('입력'!$C$12="",'입력'!$C$13=""),"",IF('입력'!$C$12="","",YEAR('입력'!$C$12)&". "&MONTH('입력'!$C$12)&". "&DAY('입력'!$C$12)&".")&" ~ "&IF('입력'!$C$13="","",YEAR('입력'!$C$13)&". "&MONTH('입력'!$C$13)&". "&DAY('입력'!$C$13)&".")&" ("&('입력'!$C$13-'입력'!$C$12+1)&"일)") | O5: 칸은 「입력」 시트에서 저절로 채워집니다. 여기서 직접 고쳐 써도 됩니다 (그 칸만 수식이 바뀜).
B7: 공 종 | E7: 비중(%) | F7: =IF('입력'!$C$12="","",MONTH(EDATE(DATE(YEAR('입력'!$C$12),MONTH('입력'!$C$12),1),0))&"월") | G7: =IF('입력'!$C$12="","",MONTH(EDATE(DATE(YEAR('입력'!$C$12),MONTH('입력'!$C$12),1),1))&"월") | H7: =IF('입력'!$C$12="","",MONTH(EDATE(DATE(YEAR('입력'!$C$12),MONTH('입력'!$C$12),1),2))&"월") | I7: =IF('입력'!$C$12="","",MONTH(EDATE(DATE(YEAR('입력'!$C$12),MONTH('입력'!$C$12),1),3))&"월") | J7: =IF('입력'!$C$12="","",MONTH(EDATE(DATE(YEAR('입력'!$C$12),MONTH('입력'!$C$12),1),4))&"월") | K7: =IF('입력'!$C$12="","",MONTH(EDATE(DATE(YEAR('입력'!$C$12),MONTH('입력'!$C$12),1),5))&"월") | L7: =IF('입력'!$C$12="","",MONTH(EDATE(DATE(YEAR('입력'!$C$12),MONTH('입력'!$C$12),1),6))&"월") | M7: =IF('입력'!$C$12="","",MONTH(EDATE(DATE(YEAR('입력'!$C$12),MONTH('입력'!$C$12),1),7))&"월")
B20: 월별 예정공정률(%)
B21: 누계 예정공정률(%)
B23: ※ 공종마다 시작하는 달부터 끝나는 달까지 칸을 칠하거나 선(━)을 긋습니다. 달 이름은 착공일에 맞춰 저절로 바뀝니다.
B25: =IF('입력'!$C$12=""," 년 월 일",YEAR('입력'!$C$12)&"년 "&MONTH('입력'!$C$12)&"월 "&DAY('입력'!$C$12)&"일")
B27: 계약상대자 | G27: 상 호 | I27: : | J27: ='입력'!$C$27&""
G28: 주 소 | I28: : | J28: ='입력'!$C$30&""
G29: 대 표 자 | I29: : | J29: ='입력'!$C$28&" (인)"
B32: =IF('입력'!$C$18=""," 귀하",'입력'!$C$18&" 귀하")

Sheet 11 인력·장비 투입계획서
B2: 공정별 인력 및 장비 투입계획서 | O2: ← 처음(목록)으로
O3: ✎ 입력 고치기
B4: 공 사 명 | E4: ='입력'!$C$6&""
B5: 공사 기간 | E5: =IF(OR('입력'!$C$12="",'입력'!$C$13=""),"",IF('입력'!$C$12="","",YEAR('입력'!$C$12)&". "&MONTH('입력'!$C$12)&". "&DAY('입력'!$C$12)&".")&" ~ "&IF('입력'!$C$13="","",YEAR('입력'!$C$13)&". "&MONTH('입력'!$C$13)&". "&DAY('입력'!$C$13)&".")&" ("&('입력'!$C$13-'입력'!$C$12+1)&"일)") | O5: 칸은 「입력」 시트에서 저절로 채워집니다. 여기서 직접 고쳐 써도 됩니다 (그 칸만 수식이 바뀜).
B6: 현장 위치 | E6: ='입력'!$C$7&""
B8: ■ 인력 (명)
B9: 공 종 | D9: 직 종 | F9: =IF('입력'!$C$12="","",MONTH(EDATE(DATE(YEAR('입력'!$C$12),MONTH('입력'!$C$12),1),0))&"월") | G9: =IF('입력'!$C$12="","",MONTH(EDATE(DATE(YEAR('입력'!$C$12),MONTH('입력'!$C$12),1),1))&"월") | H9: =IF('입력'!$C$12="","",MONTH(EDATE(DATE(YEAR('입력'!$C$12),MONTH('입력'!$C$12),1),2))&"월") | I9: =IF('입력'!$C$12="","",MONTH(EDATE(DATE(YEAR('입력'!$C$12),MONTH('입력'!$C$12),1),3))&"월") | J9: =IF('입력'!$C$12="","",MONTH(EDATE(DATE(YEAR('입력'!$C$12),MONTH('입력'!$C$12),1),4))&"월") | K9: =IF('입력'!$C$12="","",MONTH(EDATE(DATE(YEAR('입력'!$C$12),MONTH('입력'!$C$12),1),5))&"월") | L9: =IF('입력'!$C$12="","",MONTH(EDATE(DATE(YEAR('입력'!$C$12),MONTH('입력'!$C$12),1),6))&"월") | M9: =IF('입력'!$C$12="","",MONTH(EDATE(DATE(YEAR('입력'!$C$12),MONTH('입력'!$C$12),1),7))&"월")
B17: 합 계 | F17: =IF(SUM(F10:F16)=0,"",SUM(F10:F16)) | G17: =IF(SUM(G10:G16)=0,"",SUM(G10:G16)) | H17: =IF(SUM(H10:H16)=0,"",SUM(H10:H16)) | I17: =IF(SUM(I10:I16)=0,"",SUM(I10:I16)) | J17: =IF(SUM(J10:J16)=0,"",SUM(J10:J16)) | K17: =IF(SUM(K10:K16)=0,"",SUM(K10:K16)) | L17: =IF(SUM(L10:L16)=0,"",SUM(L10:L16)) | M17: =IF(SUM(M10:M16)=0,"",SUM(M10:M16))
B19: ■ 장비 (대)
B20: 공 종 | D20: 장비 · 규격 | F20: =IF('입력'!$C$12="","",MONTH(EDATE(DATE(YEAR('입력'!$C$12),MONTH('입력'!$C$12),1),0))&"월") | G20: =IF('입력'!$C$12="","",MONTH(EDATE(DATE(YEAR('입력'!$C$12),MONTH('입력'!$C$12),1),1))&"월") | H20: =IF('입력'!$C$12="","",MONTH(EDATE(DATE(YEAR('입력'!$C$12),MONTH('입력'!$C$12),1),2))&"월") | I20: =IF('입력'!$C$12="","",MONTH(EDATE(DATE(YEAR('입력'!$C$12),MONTH('입력'!$C$12),1),3))&"월") | J20: =IF('입력'!$C$12="","",MONTH(EDATE(DATE(YEAR('입력'!$C$12),MONTH('입력'!$C$12),1),4))&"월") | K20: =IF('입력'!$C$12="","",MONTH(EDATE(DATE(YEAR('입력'!$C$12),MONTH('입력'!$C$12),1),5))&"월") | L20: =IF('입력'!$C$12="","",MONTH(EDATE(DATE(YEAR('입력'!$C$12),MONTH('입력'!$C$12),1),6))&"월") | M20: =IF('입력'!$C$12="","",MONTH(EDATE(DATE(YEAR('입력'!$C$12),MONTH('입력'!$C$12),1),7))&"월")
B27: 합 계 | F27: =IF(SUM(F21:F26)=0,"",SUM(F21:F26)) | G27: =IF(SUM(G21:G26)=0,"",SUM(G21:G26)) | H27: =IF(SUM(H21:H26)=0,"",SUM(H21:H26)) | I27: =IF(SUM(I21:I26)=0,"",SUM(I21:I26)) | J27: =IF(SUM(J21:J26)=0,"",SUM(J21:J26)) | K27: =IF(SUM(K21:K26)=0,"",SUM(K21:K26)) | L27: =IF(SUM(L21:L26)=0,"",SUM(L21:L26)) | M27: =IF(SUM(M21:M26)=0,"",SUM(M21:M26))
B29: ※ 공종마다 달별 투입 인원(명)·장비(대)를 적습니다. 달 이름은 착공일에 맞춰 저절로 바뀝니다.
B31: =IF('입력'!$C$12=""," 년 월 일",YEAR('입력'!$C$12)&"년 "&MONTH('입력'!$C$12)&"월 "&DAY('입력'!$C$12)&"일")
B33: 계약상대자 | G33: 상 호 | I33: : | J33: ='입력'!$C$27&""
G34: 주 소 | I34: : | J34: ='입력'!$C$30&""
G35: 대 표 자 | I35: : | J35: ='입력'!$C$28&" (인)"
B38: =IF('입력'!$C$18=""," 귀하",'입력'!$C$18&" 귀하")

Sheet 12 직접시공계획서
B2: 직 접 시 공 계 획 서 | O2: ← 처음(목록)으로
O3: ✎ 입력 고치기
B4: 공 사 명 | E4: ='입력'!$C$6&""
B5: 계약 금액 | E5: =IF('입력'!$C$14="","",'계산'!$J$3&"원정 (₩"&FIXED('입력'!$C$14,0)&")") | O5: 칸은 「입력」 시트에서 저절로 채워집니다. 여기서 직접 고쳐 써도 됩니다 (그 칸만 수식이 바뀜).
B6: 공사 기간 | E6: =IF(OR('입력'!$C$12="",'입력'!$C$13=""),"",IF('입력'!$C$12="","",YEAR('입력'!$C$12)&". "&MONTH('입력'!$C$12)&". "&DAY('입력'!$C$12)&".")&" ~ "&IF('입력'!$C$13="","",YEAR('입력'!$C$13)&". "&MONTH('입력'!$C$13)&". "&DAY('입력'!$C$13)&".")&" ("&('입력'!$C$13-'입력'!$C$12+1)&"일)")
B7: 현장 위치 | E7: ='입력'!$C$7&""
B9: 공 종 | D9: 직접 시공할 내용 | H9: 금액 (원) | K9: 비율(%) | L9: 비고
B18: 합 계 | H18: =IF(SUM(H10:H17)=0,"",SUM(H10:H17)) | K18: =IF(OR(H18="",N('입력'!$C$14)=0),"",H18/'입력'!$C$14)
B20: 위와 같이 이 공사를 직접 시공할 계획을 알려 드립니다.
B21: ※ 직접 시공 대상과 비율은 건설산업기본법(직접 시공 조항)과 계약 조건을 확인하세요.
B23: =IF('입력'!$C$12=""," 년 월 일",YEAR('입력'!$C$12)&"년 "&MONTH('입력'!$C$12)&"월 "&DAY('입력'!$C$12)&"일")
B25: 계약상대자 | G25: 상 호 | I25: : | J25: ='입력'!$C$27&""
G26: 주 소 | I26: : | J26: ='입력'!$C$30&""
G27: 대 표 자 | I27: : | J27: ='입력'!$C$28&" (인)"
B30: =IF('입력'!$C$18=""," 귀하",'입력'!$C$18&" 귀하")

Sheet 13 산안비 사용계획서
B2: 산업안전보건관리비 사용계획서 | O2: ← 처음(목록)으로
O3: ✎ 입력 고치기
B4: 공 사 명 | E4: ='입력'!$C$6&""
B5: 계약 금액 | E5: =IF('입력'!$C$14="","",'계산'!$J$3&"원정 (₩"&FIXED('입력'!$C$14,0)&")") | O5: 칸은 「입력」 시트에서 저절로 채워집니다. 여기서 직접 고쳐 써도 됩니다 (그 칸만 수식이 바뀜).
B6: 계상된 산업안전보건관리비 | E6: =IF('입력'!$C$97="","",FIXED('입력'!$C$97,0)&"원")
B7: 공사 기간 | E7: =IF(OR('입력'!$C$12="",'입력'!$C$13=""),"",IF('입력'!$C$12="","",YEAR('입력'!$C$12)&". "&MONTH('입력'!$C$12)&". "&DAY('입력'!$C$12)&".")&" ~ "&IF('입력'!$C$13="","",YEAR('입력'!$C$13)&". "&MONTH('입력'!$C$13)&". "&DAY('입력'!$C$13)&".")&" ("&('입력'!$C$13-'입력'!$C$12+1)&"일)")
B9: 사 용 항 목 | F9: 세부 내용 | I9: 예정 금액 (원) | K9: 사용 시기 | M9: 비 고
B10: 1. 안전·보건관리자 임금 등
B11: 2. 안전시설비 등
B12: 3. 보호구 등
B13: 4. 안전보건진단비 등
B14: 5. 안전보건교육비 등
B15: 6. 근로자 건강장해예방비 등
B16: 7. 건설재해예방전문지도기관 기술지도비
B17: 8. 본사 전담조직 근로자 임금 등
B18: 9. 위험성평가 등에 따른 소요비용
B19: 합 계 | I19: =IF(SUM(I10:I18)=0,"",SUM(I10:I18))
B21: ※ 항목은 「건설업 산업안전보건관리비 계상 및 사용기준」(고용노동부고시) 별지 제1호서식의 9가지입니다. 계상액은 🦺 산안비 계상기(k-conmap.com/tools/sanan)로 셀 수 있습니다.
B23: =IF('입력'!$C$12=""," 년 월 일",YEAR('입력'!$C$12)&"년 "&MONTH('입력'!$C$12)&"월 "&DAY('입력'!$C$12)&"일")
B25: 계약상대자 | G25: 상 호 | I25: : | J25: ='입력'!$C$27&""
G26: 주 소 | I26: : | J26: ='입력'!$C$30&""
G27: 대 표 자 | I27: : | J27: ='입력'!$C$28&" (인)"
B30: =IF('입력'!$C$18=""," 귀하",'입력'!$C$18&" 귀하")

Sheet 14 수도전기료 납부각서
B2: 수 도 · 전 기 료 납 부 각 서 | O2: ← 처음(목록)으로
O3: ✎ 입력 고치기
B4: 공 사 명 | E4: ='입력'!$C$6&""
B5: 공사 기간 | E5: =IF(OR('입력'!$C$12="",'입력'!$C$13=""),"",IF('입력'!$C$12="","",YEAR('입력'!$C$12)&". "&MONTH('입력'!$C$12)&". "&DAY('입력'!$C$12)&".")&" ~ "&IF('입력'!$C$13="","",YEAR('입력'!$C$13)&". "&MONTH('입력'!$C$13)&". "&DAY('입력'!$C$13)&".")&" ("&('입력'!$C$13-'입력'!$C$12+1)&"일)") | O5: 칸은 「입력」 시트에서 저절로 채워집니다. 여기서 직접 고쳐 써도 됩니다 (그 칸만 수식이 바뀜).
B6: 현장 위치 | E6: ='입력'!$C$7&""
B8: 우리 회사는 위 공사 기간 동안 발주기관(시설)의 수도·전기 등을 공사에 쓰는 경우, 사용량을 계량하거나 발주기관과 협의한 방법으로 산정한 요금을 발주기관이 정한 기한까지 납부할 것을 각서합니다.
B9: 구 분 | D9: 계량 방법 | G9: 시작 지침 | I9: 끝 지침 | K9: 비 고
B10: 수 도
B11: 전 기
B12: 기 타
B15: =IF('입력'!$C$12=""," 년 월 일",YEAR('입력'!$C$12)&"년 "&MONTH('입력'!$C$12)&"월 "&DAY('입력'!$C$12)&"일")
B17: 계약상대자 | G17: 상 호 | I17: : | J17: ='입력'!$C$27&""
G18: 주 소 | I18: : | J18: ='입력'!$C$30&""
G19: 대 표 자 | I19: : | J19: ='입력'!$C$28&" (인)"
B22: =IF('입력'!$C$18=""," 귀하",'입력'!$C$18&" 귀하")

Sheet 15 월간 공정보고서
B2: 월 간 공 정 보 고 서 | O2: ← 처음(목록)으로
O3: ✎ 입력 고치기
B4: 공 사 명 | E4: ='입력'!$C$6&""
B5: 대상 달 | E5: =IF('입력'!$C$91="","",YEAR('입력'!$C$91)&"년 "&MONTH('입력'!$C$91)&"월") | O5: 칸은 「입력」 시트에서 저절로 채워집니다. 여기서 직접 고쳐 써도 됩니다 (그 칸만 수식이 바뀜).
B6: 공사 기간 | E6: =IF(OR('입력'!$C$12="",'입력'!$C$130=""),"",IF('입력'!$C$12="","",YEAR('입력'!$C$12)&". "&MONTH('입력'!$C$12)&". "&DAY('입력'!$C$12)&".")&" ~ "&IF('입력'!$C$130="","",YEAR('입력'!$C$130)&". "&MONTH('입력'!$C$130)&". "&DAY('입력'!$C$130)&".")&" ("&('입력'!$C$130-'입력'!$C$12+1)&"일)")
B7: 계획 공정률 (누계) | E7: =IF('입력'!$C$93="","",'입력'!$C$93&"%")
B8: 실적 공정률 (누계) | E8: =IF('입력'!$C$94="","",'입력'!$C$94&"%")
B9: 계획 대비 | E9: =IF(OR('입력'!$C$93="",'입력'!$C$94=""),"",IF('입력'!$C$94='입력'!$C$93,"계획대로",IF('입력'!$C$94>'입력'!$C$93,"계획보다 "&FIXED('입력'!$C$94-'입력'!$C$93,2)&"%p 앞섬","계획보다 "&FIXED('입력'!$C$93-'입력'!$C$94,2)&"%p 늦음")))
B11: 공 종 | D11: 이번 달 한 일 | H11: 다음 달 할 일 | L11: 비 고
B21: 특기 사항 (문제점 · 대책)
B23: ※ 붙임: 공정 사진, 예정·실적 공정표(S커브 — 📈 예정공정표 도구).
B25: =IF('입력'!$C$92=""," 년 월 일",YEAR('입력'!$C$92)&"년 "&MONTH('입력'!$C$92)&"월 "&DAY('입력'!$C$92)&"일")
B27: 계약상대자 | G27: 상 호 | I27: : | J27: ='입력'!$C$27&""
G28: 주 소 | I28: : | J28: ='입력'!$C$30&""
G29: 대 표 자 | I29: : | J29: ='입력'!$C$28&" (인)"
B32: =IF('입력'!$C$18=""," 귀하",'입력'!$C$18&" 귀하")

Sheet 16 노무비 청구내역서
B2: 노 무 비 청 구 내 역 서 | O2: ← 처음(목록)으로
O3: ✎ 입력 고치기
B4: 공 사 명 | E4: ='입력'!$C$6&""
B5: 계약 번호 | E5: ='입력'!$C$9&"" | O5: 칸은 「입력」 시트에서 저절로 채워집니다. 여기서 직접 고쳐 써도 됩니다 (그 칸만 수식이 바뀜).
B6: 대상 달 | E6: =IF('입력'!$C$91="","",YEAR('입력'!$C$91)&"년 "&MONTH('입력'!$C$91)&"월")
B7: 이번 달 청구 금액 | E7: =IF('입력'!$C$95="","",FIXED('입력'!$C$95,0)&"원")
B8: 전월까지 누계 | E8: =IF('입력'!$C$96="","",FIXED('입력'!$C$96,0)&"원")
B9: 누 계 | E9: =IF('입력'!$C$143="","",FIXED('입력'!$C$143,0)&"원")
B11: ■ 직종별 집계
B12: 직 종 | D12: 인원 (명) | F12: 연인원 (공수) | H12: 단가 (원) | J12: 금액 (원) | L12: 비 고
B25: 합 계 | D25: =IF(SUM(D13:D24)=0,"",SUM(D13:D24)) | F25: =IF(SUM(F13:F24)=0,"",SUM(F13:F24)) | J25: =IF(SUM(J13:J24)=0,"",SUM(J13:J24))
B27: ※ 표의 금액 합계가 «이번 달 청구 금액» 과 같은지 확인하세요. 붙임: 임금대장 · 노무비 지급확인서 · 출역일보 · 근로자 명부.
B29: =IF('입력'!$C$92=""," 년 월 일",YEAR('입력'!$C$92)&"년 "&MONTH('입력'!$C$92)&"월 "&DAY('입력'!$C$92)&"일")
B31: 계약상대자 | G31: 상 호 | I31: : | J31: ='입력'!$C$27&""
G32: 주 소 | I32: : | J32: ='입력'!$C$30&""
G33: 대 표 자 | I33: : | J33: ='입력'!$C$28&" (인)"
B36: =IF('입력'!$C$18=""," 귀하",'입력'!$C$18&" 귀하")

Sheet 17 산안비 사용내역서
B1: 【별지 제1호 서식】
B2: 산업안전보건관리비 사용내역서 | O2: ← 처음(목록)으로
O3: ✎ 입력 고치기
B4: 건설업체명 | D4: ='입력'!$C$27&"" | H4: 공 사 명 | J4: ='입력'!$C$6&""
B5: 소 재 지 | D5: ='입력'!$C$30&"" | H5: 대 표 자 | J5: ='입력'!$C$28&"" | O5: 칸은 「입력」 시트에서 저절로 채워집니다. 여기서 직접 고쳐 써도 됩니다 (그 칸만 수식이 바뀜).
B6: 공 사 금 액 | D6: =IF('입력'!$C$14="","원",FIXED('입력'!$C$14,0)&" 원") | H6: 공 사 기 간 | J6: =IF(OR('입력'!$C$12="",'입력'!$C$130=""),"~",IF('입력'!$C$12="","",YEAR('입력'!$C$12)&". "&MONTH('입력'!$C$12)&". "&DAY('입력'!$C$12)&".")&" ~ "&IF('입력'!$C$130="","",YEAR('입력'!$C$130)&". "&MONTH('입력'!$C$130)&". "&DAY('입력'!$C$130)&"."))
B7: 발 주 자 | D7: ='입력'!$C$17&"" | H7: 누계공정률 | J7: =IF('입력'!$C$94="","%",'입력'!$C$94&" %")
B8: 계 상 된 산업안전보건관리비 | D8: =IF('입력'!$C$97="","원",FIXED('입력'!$C$97,0)&" 원")
B9: 사 용 금 액
B10: 항 목 | H10: =IF('입력'!$C$91="","( )월 사용금액","( "&MONTH('입력'!$C$91)&" )월 사용금액") | K10: 누계 사용금액
B11: 계 | H11: =IF(SUM(H12:H20)=0,"",SUM(H12:H20)) | K11: =IF(SUM(K12:K20)=0,"",SUM(K12:K20))
B12: 1. 안전·보건관리자 임금 등
B13: 2. 안전시설비 등
B14: 3. 보호구 등
B15: 4. 안전보건진단비 등
B16: 5. 안전보건교육비 등
B17: 6. 근로자 건강장해예방비 등
B18: 7. 건설재해예방전문지도기관 기술지도비
B19: 8. 본사 전담조직 근로자 임금 등
B20: 9. 위험성평가 등에 따른 소요비용
B22: 「건설업 산업안전보건관리비 계상 및 사용기준」 제10조제1항에 따라 위와 같이 사용내역서를 작성하였습니다.
B24: =IF('입력'!$C$92=""," 년 월 일",YEAR('입력'!$C$92)&"년 "&MONTH('입력'!$C$92)&"월 "&DAY('입력'!$C$92)&"일")
B26: 작 성 자 | D26: 직책 | G26: 성명 | K26: (서명 또는 인)
B27: 확 인 자 | D27: 직책 | G27: 성명 | K27: (서명 또는 인)

Sheet 18 하도급계약 통보서
B1: ■ 건설산업기본법 시행규칙 [별지 제23호서식] <개정 2021. 8. 27.> | L1: (앞쪽)
B2: 건설공사의 하도급계약 통보서 | O2: ← 처음(목록)으로
O3: ✎ 입력 고치기
B4: 공사명 | G4: ='입력'!$C$6&""
B5: 수급인 | D5: 상호 및 대표자 | G5: ='입력'!$C$27&IF('입력'!$C$28="",""," / "&'입력'!$C$28) | O5: 칸은 「입력」 시트에서 저절로 채워집니다. 여기서 직접 고쳐 써도 됩니다 (그 칸만 수식이 바뀜).
D6: 영업소 소재지 | G6: ='입력'!$C$30&""
D7: 하도급 사유 | G7: ='입력'!$C$105&""
B8: 하수급인 | D8: 상호 및 대표자 | G8: ='입력'!$C$100&IF('입력'!$C$101="",""," / "&'입력'!$C$101)
D9: 업종 및 등록번호 | G9: ='입력'!$C$102&""
D10: 영업소 소재지 | G10: ='입력'!$C$103&""
D11: 수급인에게 협력업자로 등록된 연월일 | G11: =IF('입력'!$C$104="","",YEAR('입력'!$C$104)&". "&MONTH('입력'!$C$104)&". "&DAY('입력'!$C$104)&".")
B12: 하도급 내용 | D12: 공사의 종류 | G12: ='입력'!$C$106&""
D13: 하도급내용(율) | G13: ="도급액(① 하도급 부분): "&IF('입력'!$C$107="","",FIXED('입력'!$C$107,0)&"원")
G14: ="하도급(예정)금액: "&IF('입력'!$C$108="","",FIXED('입력'!$C$108,0)&"원")
G15: ="② 하도급률: "&IF('입력'!$C$144="","",FIXED('입력'!$C$144*100,2)&"%")
D16: 하도급내용 (예정·변경)일 | G16: =IF('입력'!$C$109="","",YEAR('입력'!$C$109)&". "&MONTH('입력'!$C$109)&". "&DAY('입력'!$C$109)&".") | I16: 하도급 공사기간 | K16: ="착공(예정): "&IF('입력'!$C$110="","",YEAR('입력'!$C$110)&". "&MONTH('입력'!$C$110)&". "&DAY('입력'!$C$110)&".")
K17: ="준공(예정): "&IF('입력'!$C$111="","",YEAR('입력'!$C$111)&". "&MONTH('입력'!$C$111)&". "&DAY('입력'!$C$111)&".")
D18: 사회보험료 | G18: 직접노무비 또는 노무비 | I18: 반영 요율 | J18: 반영금액 | L18: 부담방법
D19: ③ 고용보험 | L19: [ ] 일괄 [ ] 개별
D20: ④ 산재해보상보험 | L20: [ ] 일괄 [ ] 개별
D21: ⑤ 국민연금보험
D22: ⑥ 국민건강보험
D23: ⑦ 노인장기요양보험
D24: ⑧ 퇴직공제부금 | L24: [ ] 일괄 [ ] 개별
D25: *③~⑧에서 보험료를 일괄 부담할 경우에는 부담방법 중 일괄란에만 표시합니다.
B27: 「건설산업기본법」 제29조제6항 및 같은 법 시행령 제32조제1항에 따라 위와 같이 건설공사의 하도급계약내용을 통보합니다.
B29: =IF('입력'!$C$112=""," 년 월 일",YEAR('입력'!$C$112)&"년 "&MONTH('입력'!$C$112)&"월 "&DAY('입력'!$C$112)&"일")
F31: 수급인 | H31: ='입력'!$C$27&IF('입력'!$C$28="",""," / "&'입력'!$C$28) | L31: (서명 또는 인)
B34: =IF('입력'!$C$18=""," 귀하",'입력'!$C$18&" 귀하")
B35: 첨부서류 | D35: 뒤쪽 참조

Sheet 19 하도급계약 통보서 뒤쪽
L1: (뒤쪽)
O2: ← 처음(목록)으로
O3: ✎ 입력 고치기
B4: 첨부서류 | D4: 1. 하도급계약서(변경계약서를 포함하고, 특수조건이 있는 경우 특수조건을 포함합니다) 사본
D5: 2. 공사량(규모)·공사단가 및 공사금액 등이 분명하게 적힌 공사내역서 | O5: 칸은 「입력」 시트에서 저절로 채워집니다. 여기서 직접 고쳐 써도 됩니다 (그 칸만 수식이 바뀜).
D6: 3. 예정공정표
D7: 4. 하도급대금지급보증서 교부의무가 면제되는 경우에는 그 증빙서류
D8: 5. 현장설명서(현장설명을 실시한 경우만 해당합니다)
D9: 6. 공동도급인 경우 공동수급체 구성원 간에 체결한 협정서 사본. 다만, 별지 제17호서식의 건설공사대장에 해당 협정서의 내용을 첨부한 경우는 제외합니다.
B10: 유의사항
B11: ① 하도급 부분 금액은 하도급하려는 공사 부분에 대하여 수급인의 계약단가(직접·간접 노무비, 재료비 및 경비를 포함합니다)를 기준으로 산출한 금액에 일반관리비, 이윤 및 부가가치세를 포함한 금액을 말하며, 수급인이 하수급인에게 직접 지급하는 자재의 비용과 「건설산업기본법」 제34조제3항에 따른 하도급대금 지급보증서 발급에 드는 금액 등 관계 법령에 따라 수급인이 부담하는 금액은 제외합니다.
B12: ② 하도급률은 하도급 계약금액을 하도급 부분 금액으로 나눈 비율을 말합니다.
B13: 처리절차
B14: 이 통보서는 아래와 같이 처리됩니다.
B15: 건설사업자 | H15: 발주자(담당부서)
B16: 통보서 작성·제출 ──▶ | H16: 접수
H17: ▼
H18: 통보내용 확인 (적정성)
H19: ▼
H20: 결재

Sheet 20 기성검사 요청서
B2: 기 성 부 분 검 사 요 청 서 | O2: ← 처음(목록)으로
O3: ✎ 입력 고치기
B4: 공 사 명 | E4: ='입력'!$C$6&""
B5: 계약 번호 | E5: ='입력'!$C$9&"" | O5: 칸은 「입력」 시트에서 저절로 채워집니다. 여기서 직접 고쳐 써도 됩니다 (그 칸만 수식이 바뀜).
B6: 계약 금액 | E6: =IF('입력'!$C$14="","",'계산'!$J$3&"원정 (₩"&FIXED('입력'!$C$14,0)&")")
B7: 공사 기간 | E7: =IF(OR('입력'!$C$12="",'입력'!$C$130=""),"",IF('입력'!$C$12="","",YEAR('입력'!$C$12)&". "&MONTH('입력'!$C$12)&". "&DAY('입력'!$C$12)&".")&" ~ "&IF('입력'!$C$130="","",YEAR('입력'!$C$130)&". "&MONTH('입력'!$C$130)&". "&DAY('입력'!$C$130)&".")&" ("&('입력'!$C$130-'입력'!$C$12+1)&"일)")
B8: 기성 회차 | E8: =IF('입력'!$C$53="","","제 "&'입력'!$C$53&" 회")
B9: 기성 대상기간 | E9: =IF(OR('입력'!$C$54="",'입력'!$C$55=""),"",IF('입력'!$C$54="","",YEAR('입력'!$C$54)&". "&MONTH('입력'!$C$54)&". "&DAY('입력'!$C$54)&".")&" ~ "&IF('입력'!$C$55="","",YEAR('입력'!$C$55)&". "&MONTH('입력'!$C$55)&". "&DAY('입력'!$C$55)&"."))
B11: 구 분 | F11: 금 액 (원) | K11: 계약 금액 대비
B12: 계약 금액 | F12: =IF('입력'!$C$14="","",FIXED('입력'!$C$14,0)&"원")
B13: 전회까지 기성 누계 | F13: =IF('입력'!$C$58="","",FIXED('입력'!$C$58,0)&"원") | K13: =IF(OR('입력'!$C$58="",N('입력'!$C$14)=0),"",TEXT('입력'!$C$58/'입력'!$C$14,"0.00%"))
B14: 이번 회 기성 | F14: =IF('입력'!$C$59="","",FIXED('입력'!$C$59,0)&"원") | K14: =IF(OR('입력'!$C$59="",N('입력'!$C$14)=0),"",TEXT('입력'!$C$59/'입력'!$C$14,"0.00%"))
B15: 이번 회까지 누계 | F15: =IF('입력'!$C$134="","",FIXED('입력'!$C$134,0)&"원") | K15: =IF('입력'!$C$135="","",TEXT('입력'!$C$135,"0.00%"))
B17: 위 공사의 기성 부분에 대하여 검사를 요청합니다.
B18: 붙임 서류 | I18: 부수 | K18: 비고
B19: 기성 내역서 | I19: 1부
B20: 기성 부분 사진 | I20: 1부
B21: 품질시험 성과 (해당 시) | I21: 1부
B24: =IF('입력'!$C$56=""," 년 월 일",YEAR('입력'!$C$56)&"년 "&MONTH('입력'!$C$56)&"월 "&DAY('입력'!$C$56)&"일")
B26: 계약상대자 | G26: 상 호 | I26: : | J26: ='입력'!$C$27&""
G27: 주 소 | I27: : | J27: ='입력'!$C$30&""
G28: 대 표 자 | I28: : | J28: ='입력'!$C$28&" (인)"
B31: =IF('입력'!$C$18=""," 귀하",'입력'!$C$18&" 귀하")

Sheet 21 기성대가 청구서
B2: 기 성 대 가 청 구 서 | O2: ← 처음(목록)으로
O3: ✎ 입력 고치기
B4: 공 사 명 | E4: ='입력'!$C$6&""
B5: 계약 번호 | E5: ='입력'!$C$9&"" | O5: 칸은 「입력」 시트에서 저절로 채워집니다. 여기서 직접 고쳐 써도 됩니다 (그 칸만 수식이 바뀜).
B6: 기성 회차 | E6: =IF('입력'!$C$53="","","제 "&'입력'!$C$53&" 회")
B8: 이번 회 기성금액 | E8: =IF('입력'!$C$59="","",FIXED('입력'!$C$59,0)&"원")
B9: 선금 정산액 (공제) | E9: =IF('입력'!$C$60="","",FIXED('입력'!$C$60,0)&"원")
B10: 청구 금액 | E10: =IF('입력'!$C$136="","",'계산'!$J$7&"원정 (₩"&FIXED('입력'!$C$136,0)&")")
B11: 공급가액 / 부가세 | E11: =IF('입력'!$C$136="","",FIXED(ROUND('입력'!$C$136/1.1,0),0)&"원 / "&FIXED('입력'!$C$136-ROUND('입력'!$C$136/1.1,0),0)&"원")
B13: 은 행 명 | E13: ='입력'!$C$33&""
B14: 예 금 주 | E14: ='입력'!$C$34&""
B15: 계좌 번호 | E15: ='입력'!$C$35&""
B17: 위 공사의 기성 대가를 위와 같이 청구합니다.
B18: ※ 공급가액·부가세는 청구 금액을 1.1로 나눠 계산한 값입니다. 세금계산서 금액과 맞는지 확인하세요.
B20: =IF('입력'!$C$137=""," 년 월 일",YEAR('입력'!$C$137)&"년 "&MONTH('입력'!$C$137)&"월 "&DAY('입력'!$C$137)&"일")
B22: 계약상대자 | G22: 상 호 | I22: : | J22: ='입력'!$C$27&""
G23: 주 소 | I23: : | J23: ='입력'!$C$30&""
G24: 대 표 자 | I24: : | J24: ='입력'!$C$28&" (인)"
B27: =IF('입력'!$C$18=""," 귀하",'입력'!$C$18&" 귀하")

Sheet 22 하도급대금 지급확인서
B2: 하 도 급 대 금 지 급 확 인 서 | O2: ← 처음(목록)으로
O3: ✎ 입력 고치기
B4: 공 사 명 | E4: ='입력'!$C$6&""
B5: 계약 번호 | E5: ='입력'!$C$9&"" | O5: 칸은 「입력」 시트에서 저절로 채워집니다. 여기서 직접 고쳐 써도 됩니다 (그 칸만 수식이 바뀜).
B6: 기성 회차 | E6: =IF('입력'!$C$53="","","제 "&'입력'!$C$53&" 회")
B7: 대상 기간 | E7: =IF(OR('입력'!$C$54="",'입력'!$C$55=""),"",IF('입력'!$C$54="","",YEAR('입력'!$C$54)&". "&MONTH('입력'!$C$54)&". "&DAY('입력'!$C$54)&".")&" ~ "&IF('입력'!$C$55="","",YEAR('입력'!$C$55)&". "&MONTH('입력'!$C$55)&". "&DAY('입력'!$C$55)&"."))
B9: 구 분 | C9: 상 호 | E9: 계약 금액 (원) | G9: 금회 지급액 (원) | I9: 누계 지급액 (원) | K9: 지 급 일 | M9: 지급 방법
B10: =IF('입력'!$C$100="","","하도급") | C10: ='입력'!$C$100&"" | E10: =IF('입력'!$C$108="","",'입력'!$C$108)
B18: 합 계 | E18: =IF(SUM(E10:E17)=0,"",SUM(E10:E17)) | G18: =IF(SUM(G10:G17)=0,"",SUM(G10:G17)) | I18: =IF(SUM(I10:I17)=0,"",SUM(I10:I17))
B20: ※ 구분: 하도급 / 자재 / 장비. 첫 줄은 «12. 하도급» 입력에서 채워집니다.
B21: 위와 같이 지급하였음을 확인합니다.
B23: =IF('입력'!$C$137=""," 년 월 일",YEAR('입력'!$C$137)&"년 "&MONTH('입력'!$C$137)&"월 "&DAY('입력'!$C$137)&"일")
B25: 계약상대자 | G25: 상 호 | I25: : | J25: ='입력'!$C$27&""
G26: 주 소 | I26: : | J26: ='입력'!$C$30&""
G27: 대 표 자 | I27: : | J27: ='입력'!$C$28&" (인)"
B30: =IF('입력'!$C$18=""," 귀하",'입력'!$C$18&" 귀하")

Sheet 23 공기연장 신청서
B2: 공 기 연 장 신 청 서 | O2: ← 처음(목록)으로
O3: ✎ 입력 고치기
B4: 공 사 명 | E4: ='입력'!$C$6&""
B5: 계약 번호 | E5: ='입력'!$C$9&"" | O5: 칸은 「입력」 시트에서 저절로 채워집니다. 여기서 직접 고쳐 써도 됩니다 (그 칸만 수식이 바뀜).
B6: 계약 금액 | E6: =IF('입력'!$C$14="","",'계산'!$J$3&"원정 (₩"&FIXED('입력'!$C$14,0)&")")
B7: 당초 공사기간 | E7: =IF(OR('입력'!$C$12="",'입력'!$C$13=""),"",IF('입력'!$C$12="","",YEAR('입력'!$C$12)&". "&MONTH('입력'!$C$12)&". "&DAY('입력'!$C$12)&".")&" ~ "&IF('입력'!$C$13="","",YEAR('입력'!$C$13)&". "&MONTH('입력'!$C$13)&". "&DAY('입력'!$C$13)&".")&" ("&('입력'!$C$13-'입력'!$C$12+1)&"일)")
B8: 연장 요청 기한 | E8: =IF('입력'!$C$64="","",YEAR('입력'!$C$64)&". "&MONTH('입력'!$C$64)&". "&DAY('입력'!$C$64)&".")
B9: 연장 일수 | E9: =IF('입력'!$C$140="","",'입력'!$C$140&"일")
B10: 연장 사유 | E10: ='입력'!$C$65&""
B12: 위와 같은 사유로 계약 기간 안에 공사를 마칠 수 없어 계약 기간의 연장을 신청합니다.
B13: 붙임 서류 | I13: 부수 | K13: 비고
B14: 연장 사유 증빙 자료 | I14: 1부
B15: 변경 예정공정표 | I15: 1부
B18: =IF('입력'!$C$63=""," 년 월 일",YEAR('입력'!$C$63)&"년 "&MONTH('입력'!$C$63)&"월 "&DAY('입력'!$C$63)&"일")
B20: 계약상대자 | G20: 상 호 | I20: : | J20: ='입력'!$C$27&""
G21: 주 소 | I21: : | J21: ='입력'!$C$30&""
G22: 대 표 자 | I22: : | J22: ='입력'!$C$28&" (인)"
B25: =IF('입력'!$C$18=""," 귀하",'입력'!$C$18&" 귀하")

Sheet 24 계약금액 조정 신청서
B2: 계 약 금 액 조 정 신 청 서 | O2: ← 처음(목록)으로
O3: ✎ 입력 고치기
B4: 공 사 명 | E4: ='입력'!$C$6&""
B5: 계약 번호 | E5: ='입력'!$C$9&"" | O5: 칸은 「입력」 시트에서 저절로 채워집니다. 여기서 직접 고쳐 써도 됩니다 (그 칸만 수식이 바뀜).
B6: 계 약 일 | E6: =IF('입력'!$C$11="","",YEAR('입력'!$C$11)&". "&MONTH('입력'!$C$11)&". "&DAY('입력'!$C$11)&".")
B7: 조정 구분 | E7: =IF('입력'!$C$115="","[ ] 설계변경 [ ] 물가변동",'입력'!$C$115)
B8: 조정 기준일 | E8: =IF('입력'!$C$117="","",YEAR('입력'!$C$117)&". "&MONTH('입력'!$C$117)&". "&DAY('입력'!$C$117)&".")
B9: 조정 전 계약금액 | E9: =IF('입력'!$C$14="","",'계산'!$J$3&"원정 (₩"&FIXED('입력'!$C$14,0)&")")
B10: 조정 신청 금액 | E10: =IF('입력'!$C$119="","",IF('입력'!$C$118="감액","감액 ","증액 ")&FIXED('입력'!$C$119,0)&"원")
B11: 조정 후 계약금액 | E11: =IF('입력'!$C$145="","",'계산'!$J$13&"원정 (₩"&FIXED('입력'!$C$145,0)&")")
B12: 조정 사유 | E12: ='입력'!$C$120&""
B14: 구 분 | D14: 당초 금액 (원) | F14: 조정 금액 (원) | I14: 증 감 (원) | K14: 산출 근거
B21: 합 계 | D21: =IF(SUM(D15:D20)=0,"",SUM(D15:D20)) | F21: =IF(SUM(F15:F20)=0,"",SUM(F15:F20)) | I21: =IF(SUM(I15:I20)=0,"",SUM(I15:I20))
B23: 위와 같이 계약금액의 조정을 신청합니다.
B24: 붙임 서류 | I24: 부수 | K24: 비고
B25: 조정금액 산출서 | I25: 1부
B26: 근거 자료 | I26: 1부
B28: ※ «조정 전 계약금액» 은 «1. 공사» 의 계약 금액입니다. 산출은 🔁 설계변경 도구(k-conmap.com/change)로 할 수 있습니다.
B30: =IF('입력'!$C$116=""," 년 월 일",YEAR('입력'!$C$116)&"년 "&MONTH('입력'!$C$116)&"월 "&DAY('입력'!$C$116)&"일")
B32: 계약상대자 | G32: 상 호 | I32: : | J32: ='입력'!$C$27&""
G33: 주 소 | I33: : | J33: ='입력'!$C$30&""
G34: 대 표 자 | I34: : | J34: ='입력'!$C$28&" (인)"
B37: =IF('입력'!$C$18=""," 귀하",'입력'!$C$18&" 귀하")

Sheet 25 준공신고서
B2: 준 공 신 고 서 | O2: ← 처음(목록)으로
O3: ✎ 입력 고치기
B4: 공 사 명 | E4: ='입력'!$C$6&""
B5: 계약 번호 | E5: ='입력'!$C$9&"" | O5: 칸은 「입력」 시트에서 저절로 채워집니다. 여기서 직접 고쳐 써도 됩니다 (그 칸만 수식이 바뀜).
B6: 계약 금액 | E6: =IF('입력'!$C$125="","",'계산'!$J$4&"원정 (₩"&FIXED('입력'!$C$125,0)&")")
B7: 공사 기간 | E7: =IF(OR('입력'!$C$12="",'입력'!$C$130=""),"",IF('입력'!$C$12="","",YEAR('입력'!$C$12)&". "&MONTH('입력'!$C$12)&". "&DAY('입력'!$C$12)&".")&" ~ "&IF('입력'!$C$130="","",YEAR('입력'!$C$130)&". "&MONTH('입력'!$C$130)&". "&DAY('입력'!$C$130)&".")&" ("&('입력'!$C$130-'입력'!$C$12+1)&"일)")
B8: 착 공 일 | E8: =IF('입력'!$C$12="","",YEAR('입력'!$C$12)&". "&MONTH('입력'!$C$12)&". "&DAY('입력'!$C$12)&".")
B9: 준 공 일 | E9: =IF('입력'!$C$68="","",YEAR('입력'!$C$68)&". "&MONTH('입력'!$C$68)&". "&DAY('입력'!$C$68)&".")
B10: 현장 위치 | E10: ='입력'!$C$7&""
B11: 현장대리인 | E11: ='입력'!$C$38&""
B13: 위 공사를 계약 조건에 따라 준공하였기에 관계 서류를 붙여 신고합니다.
B14: 붙임 서류 | I14: 부수 | K14: 비고
B15: 준공 사진 | I15: 1부
B16: 준공 내역서 | I16: 1부
B17: 준공 도면 (해당 시) | I17: 1부
B18: 품질시험 성과 (해당 시) | I18: 1부
B19: 하도급대금 지급 확인서 (해당 시) | I19: 1부
B22: =IF('입력'!$C$68=""," 년 월 일",YEAR('입력'!$C$68)&"년 "&MONTH('입력'!$C$68)&"월 "&DAY('입력'!$C$68)&"일")
B24: 계약상대자 | G24: 상 호 | I24: : | J24: ='입력'!$C$27&""
G25: 주 소 | I25: : | J25: ='입력'!$C$30&""
G26: 대 표 자 | I26: : | J26: ='입력'!$C$28&" (인)"
B29: =IF('입력'!$C$18=""," 귀하",'입력'!$C$18&" 귀하")

Sheet 26 준공검사 요청서
B2: 준 공 검 사 요 청 서 | O2: ← 처음(목록)으로
O3: ✎ 입력 고치기
B4: 공 사 명 | E4: ='입력'!$C$6&""
B5: 계약 번호 | E5: ='입력'!$C$9&"" | O5: 칸은 「입력」 시트에서 저절로 채워집니다. 여기서 직접 고쳐 써도 됩니다 (그 칸만 수식이 바뀜).
B6: 계약 금액 | E6: =IF('입력'!$C$125="","",'계산'!$J$4&"원정 (₩"&FIXED('입력'!$C$125,0)&")")
B7: 착 공 일 | E7: =IF('입력'!$C$12="","",YEAR('입력'!$C$12)&". "&MONTH('입력'!$C$12)&". "&DAY('입력'!$C$12)&".")
B8: 준 공 일 | E8: =IF('입력'!$C$68="","",YEAR('입력'!$C$68)&". "&MONTH('입력'!$C$68)&". "&DAY('입력'!$C$68)&".")
B9: 현장 위치 | E9: ='입력'!$C$7&""
B11: 위 공사를 준공하였으므로 준공검사를 하여 주시기 바랍니다.
B13: =IF('입력'!$C$127=""," 년 월 일",YEAR('입력'!$C$127)&"년 "&MONTH('입력'!$C$127)&"월 "&DAY('입력'!$C$127)&"일")
B15: 계약상대자 | G15: 상 호 | I15: : | J15: ='입력'!$C$27&""
G16: 주 소 | I16: : | J16: ='입력'!$C$30&""
G17: 대 표 자 | I17: : | J17: ='입력'!$C$28&" (인)"
B20: =IF('입력'!$C$18=""," 귀하",'입력'!$C$18&" 귀하")

Sheet 27 준공대가 청구서
B2: 준 공 대 가 청 구 서 | O2: ← 처음(목록)으로
O3: ✎ 입력 고치기
B4: 공 사 명 | E4: ='입력'!$C$6&""
B5: 계약 번호 | E5: ='입력'!$C$9&"" | O5: 칸은 「입력」 시트에서 저절로 채워집니다. 여기서 직접 고쳐 써도 됩니다 (그 칸만 수식이 바뀜).
B6: 준 공 일 | E6: =IF('입력'!$C$68="","",YEAR('입력'!$C$68)&". "&MONTH('입력'!$C$68)&". "&DAY('입력'!$C$68)&".")
B7: 준공검사일 | E7: =IF('입력'!$C$70="","",YEAR('입력'!$C$70)&". "&MONTH('입력'!$C$70)&". "&DAY('입력'!$C$70)&".")
B9: 최종 계약금액 | E9: =IF('입력'!$C$125="","",FIXED('입력'!$C$125,0)&"원")
B10: 기성 지급 누계 (공제) | E10: =IF('입력'!$C$74="","",FIXED('입력'!$C$74,0)&"원")
B11: 선금 잔액 정산 (공제) | E11: =IF('입력'!$C$75="","",FIXED('입력'!$C$75,0)&"원")
B12: 지체상금 (공제) | E12: =IF(N('입력'!$C$133)=0,"없음",FIXED('입력'!$C$133,0)&"원 (지체 "&'입력'!$C$131&"일)")
B13: 청구 금액 | E13: =IF('입력'!$C$138="","",'계산'!$J$8&"원정 (₩"&FIXED('입력'!$C$138,0)&")")
B15: 은 행 명 | E15: ='입력'!$C$33&""
B16: 예 금 주 | E16: ='입력'!$C$34&""
B17: 계좌 번호 | E17: ='입력'!$C$35&""
B19: 위 공사의 준공 대가를 위와 같이 청구합니다.
B21: =IF('입력'!$C$139=""," 년 월 일",YEAR('입력'!$C$139)&"년 "&MONTH('입력'!$C$139)&"월 "&DAY('입력'!$C$139)&"일")
B23: 계약상대자 | G23: 상 호 | I23: : | J23: ='입력'!$C$27&""
G24: 주 소 | I24: : | J24: ='입력'!$C$30&""
G25: 대 표 자 | I25: : | J25: ='입력'!$C$28&" (인)"
B28: =IF('입력'!$C$18=""," 귀하",'입력'!$C$18&" 귀하")

Sheet 28 준공정산 동의서
B2: 준 공 정 산 동 의 서 | O2: ← 처음(목록)으로
O3: ✎ 입력 고치기
B4: 공 사 명 | E4: ='입력'!$C$6&""
B5: 계약 번호 | E5: ='입력'!$C$9&"" | O5: 칸은 「입력」 시트에서 저절로 채워집니다. 여기서 직접 고쳐 써도 됩니다 (그 칸만 수식이 바뀜).
B6: 당초 계약금액 | E6: =IF('입력'!$C$14="","",'계산'!$J$3&"원정 (₩"&FIXED('입력'!$C$14,0)&")")
B7: 정산 계약금액 | E7: =IF('입력'!$C$125="","",'계산'!$J$4&"원정 (₩"&FIXED('입력'!$C$125,0)&")")
B8: 증 감 액 | E8: =IF('입력'!$C$141="","",IF('입력'!$C$141<0,"감액 ","증액 ")&FIXED(ABS('입력'!$C$141),0)&"원")
B10: 우리 회사는 위 공사의 준공 정산 결과 최종 계약금액을 위와 같이 확정하는 데 동의하며, 이 금액에 대하여 앞으로 이의를 제기하지 않겠습니다.
B12: =IF('입력'!$C$70=""," 년 월 일",YEAR('입력'!$C$70)&"년 "&MONTH('입력'!$C$70)&"월 "&DAY('입력'!$C$70)&"일")
B14: 계약상대자 | G14: 상 호 | I14: : | J14: ='입력'!$C$27&""
G15: 주 소 | I15: : | J15: ='입력'!$C$30&""
G16: 대 표 자 | I16: : | J16: ='입력'!$C$28&" (인)"
B19: =IF('입력'!$C$18=""," 귀하",'입력'!$C$18&" 귀하")

Sheet 29 하자보수보증금 납부서
B2: 하 자 보 수 보 증 금 납 부 서 | O2: ← 처음(목록)으로
O3: ✎ 입력 고치기
B4: 공 사 명 | E4: ='입력'!$C$6&""
B5: 계약 번호 | E5: ='입력'!$C$9&"" | O5: 칸은 「입력」 시트에서 저절로 채워집니다. 여기서 직접 고쳐 써도 됩니다 (그 칸만 수식이 바뀜).
B6: 최종 계약금액 | E6: =IF('입력'!$C$125="","",'계산'!$J$4&"원정 (₩"&FIXED('입력'!$C$125,0)&")")
B7: 보증금률 | E7: =IF('입력'!$C$47="","",'입력'!$C$47&"%")
B8: 하자보수보증금 | E8: =IF('입력'!$C$126="","",'계산'!$J$6&"원정 (₩"&FIXED('입력'!$C$126,0)&")")
B9: 납부 방법 | E9: ='입력'!$C$49&""
B10: 하자담보책임기간 | E10: =IF('입력'!$C$129="","",'입력'!$C$48&"년 ("&IF('입력'!$C$128="","",YEAR('입력'!$C$128)&". "&MONTH('입력'!$C$128)&". "&DAY('입력'!$C$128)&".")&" ~ "&IF('입력'!$C$129="","",YEAR('입력'!$C$129)&". "&MONTH('입력'!$C$129)&". "&DAY('입력'!$C$129)&".")&")")
B12: 위 공사의 하자보수보증금을 위와 같이 납부합니다.
B13: 붙임 서류 | I13: 부수 | K13: 비고
B14: 하자보수보증서(보증증권) — 현금이면 납부 영수증 | I14: 1부
B17: =IF('입력'!$C$70=""," 년 월 일",YEAR('입력'!$C$70)&"년 "&MONTH('입력'!$C$70)&"월 "&DAY('입력'!$C$70)&"일")
B19: 계약상대자 | G19: 상 호 | I19: : | J19: ='입력'!$C$27&""
G20: 주 소 | I20: : | J20: ='입력'!$C$30&""
G21: 대 표 자 | I21: : | J21: ='입력'!$C$28&" (인)"
B24: =IF('입력'!$C$18=""," 귀하",'입력'!$C$18&" 귀하")

Sheet 30 하자보수보증금 지급각서
B2: 하 자 보 수 보 증 금 지 급 각 서 | O2: ← 처음(목록)으로
O3: ✎ 입력 고치기
B4: 공 사 명 | E4: ='입력'!$C$6&""
B5: 계약 번호 | E5: ='입력'!$C$9&"" | O5: 칸은 「입력」 시트에서 저절로 채워집니다. 여기서 직접 고쳐 써도 됩니다 (그 칸만 수식이 바뀜).
B6: 하자보수보증금 | E6: =IF('입력'!$C$126="","",'계산'!$J$6&"원정 (₩"&FIXED('입력'!$C$126,0)&")")
B7: 하자담보책임기간 | E7: =IF('입력'!$C$129="","",IF('입력'!$C$128="","",YEAR('입력'!$C$128)&". "&MONTH('입력'!$C$128)&". "&DAY('입력'!$C$128)&".")&" ~ "&IF('입력'!$C$129="","",YEAR('입력'!$C$129)&". "&MONTH('입력'!$C$129)&". "&DAY('입력'!$C$129)&"."))
B9: 우리 회사는 위 공사의 하자보수보증금 납부를 면제받는 대신, 하자담보책임기간 안에 하자보수 의무를 이행하지 아니하여 하자보수보증금이 발주기관에 귀속되는 사유가 생긴 때에는 위 금액을 발주기관의 청구에 따라 즉시 현금으로 납부할 것을 각서합니다.
B11: =IF('입력'!$C$70=""," 년 월 일",YEAR('입력'!$C$70)&"년 "&MONTH('입력'!$C$70)&"월 "&DAY('입력'!$C$70)&"일")
B13: 계약상대자 | G13: 상 호 | I13: : | J13: ='입력'!$C$27&""
G14: 주 소 | I14: : | J14: ='입력'!$C$30&""
G15: 대 표 자 | I15: : | J15: ='입력'!$C$28&" (인)"
B18: =IF('입력'!$C$18=""," 귀하",'입력'!$C$18&" 귀하")

Sheet 31 공사감독조서
B2: 공 사 감 독 조 서 | O2: ← 처음(목록)으로
O3: ✎ 입력 고치기
B4: 공 사 명 | E4: ='입력'!$C$6&""
B5: 계약 번호 | E5: ='입력'!$C$9&"" | O5: 칸은 「입력」 시트에서 저절로 채워집니다. 여기서 직접 고쳐 써도 됩니다 (그 칸만 수식이 바뀜).
B6: 계약상대자 | E6: ='입력'!$C$27&IF('입력'!$C$28="",""," (대표 "&'입력'!$C$28&")")
B7: 계약 금액 | E7: =IF('입력'!$C$125="","",'계산'!$J$4&"원정 (₩"&FIXED('입력'!$C$125,0)&")")
B8: 계 약 일 | E8: =IF('입력'!$C$11="","",YEAR('입력'!$C$11)&". "&MONTH('입력'!$C$11)&". "&DAY('입력'!$C$11)&".")
B9: 착 공 일 | E9: =IF('입력'!$C$12="","",YEAR('입력'!$C$12)&". "&MONTH('입력'!$C$12)&". "&DAY('입력'!$C$12)&".")
B10: 준공 기한 | E10: =IF('입력'!$C$130="","",YEAR('입력'!$C$130)&". "&MONTH('입력'!$C$130)&". "&DAY('입력'!$C$130)&".")
B11: 준 공 일 | E11: =IF('입력'!$C$68="","",YEAR('입력'!$C$68)&". "&MONTH('입력'!$C$68)&". "&DAY('입력'!$C$68)&".")
B12: 지체 일수 | E12: =IF('입력'!$C$131="","",IF('입력'!$C$131=0,"없음",'입력'!$C$131&"일"))
B14: 위 공사를 설계서와 계약 조건에 따라 감독한 결과 위와 같이 시공되었음을 확인합니다.
B16: =IF('입력'!$C$127=""," 년 월 일",YEAR('입력'!$C$127)&"년 "&MONTH('입력'!$C$127)&"월 "&DAY('입력'!$C$127)&"일")
B18: 공사 감독자 | G18: 직·성명 | I18: : | J18: ='입력'!$C$20&" (인)"
B21: =IF('입력'!$C$18=""," 귀하",'입력'!$C$18&" 귀하")

Sheet 32 준공검사조서
B2: 준 공 검 사 조 서 | O2: ← 처음(목록)으로
O3: ✎ 입력 고치기
B4: 공 사 명 | E4: ='입력'!$C$6&""
B5: 계약 번호 | E5: ='입력'!$C$9&"" | O5: 칸은 「입력」 시트에서 저절로 채워집니다. 여기서 직접 고쳐 써도 됩니다 (그 칸만 수식이 바뀜).
B6: 계약상대자 | E6: ='입력'!$C$27&IF('입력'!$C$28="",""," (대표 "&'입력'!$C$28&")")
B7: 계약 금액 | E7: =IF('입력'!$C$125="","",'계산'!$J$4&"원정 (₩"&FIXED('입력'!$C$125,0)&")")
B8: 착 공 일 | E8: =IF('입력'!$C$12="","",YEAR('입력'!$C$12)&". "&MONTH('입력'!$C$12)&". "&DAY('입력'!$C$12)&".")
B9: 준 공 일 | E9: =IF('입력'!$C$68="","",YEAR('입력'!$C$68)&". "&MONTH('입력'!$C$68)&". "&DAY('입력'!$C$68)&".")
B10: 검사 요청일 | E10: =IF('입력'!$C$127="","",YEAR('입력'!$C$127)&". "&MONTH('입력'!$C$127)&". "&DAY('입력'!$C$127)&".")
B11: 준공검사일 | E11: =IF('입력'!$C$70="","",YEAR('입력'!$C$70)&". "&MONTH('입력'!$C$70)&". "&DAY('입력'!$C$70)&".")
B12: 검사 결과 | E12: =IF('입력'!$C$71="","합격 / 보완 요구",'입력'!$C$71)
B14: 위 공사에 대하여 설계서·계약서와 관계 서류에 따라 준공검사를 한 결과 위와 같음을 확인합니다.
B16: =IF('입력'!$C$70=""," 년 월 일",YEAR('입력'!$C$70)&"년 "&MONTH('입력'!$C$70)&"월 "&DAY('입력'!$C$70)&"일")
B18: 검 사 자 | G18: 직·성명 | I18: : | J18: ='입력'!$C$21&" (인)"
B20: 입 회 자 | G20: 직·성명 | I20: : | J20: ='입력'!$C$22&" (인)"
B23: =IF('입력'!$C$18=""," 귀하",'입력'!$C$18&" 귀하")

Sheet 33 공사대장
B2: 공 사 대 장 | O2: ← 처음(목록)으로
O3: ✎ 입력 고치기
B4: 공 사 명 | E4: ='입력'!$C$6&""
B5: 현장 위치 | E5: ='입력'!$C$7&"" | O5: 칸은 「입력」 시트에서 저절로 채워집니다. 여기서 직접 고쳐 써도 됩니다 (그 칸만 수식이 바뀜).
B6: 공사 개요 | E6: ='입력'!$C$8&""
B7: 계약 방법 | E7: ='입력'!$C$10&""
B8: 계약 번호 | E8: ='입력'!$C$9&""
B9: 계 약 일 | E9: =IF('입력'!$C$11="","",YEAR('입력'!$C$11)&". "&MONTH('입력'!$C$11)&". "&DAY('입력'!$C$11)&".")
B10: 당초 계약금액 | E10: =IF('입력'!$C$14="","",FIXED('입력'!$C$14,0)&"원")
B11: 최종 계약금액 | E11: =IF('입력'!$C$125="","",FIXED('입력'!$C$125,0)&"원")
B12: 공사 기간 | E12: =IF(OR('입력'!$C$12="",'입력'!$C$130=""),"",IF('입력'!$C$12="","",YEAR('입력'!$C$12)&". "&MONTH('입력'!$C$12)&". "&DAY('입력'!$C$12)&".")&" ~ "&IF('입력'!$C$130="","",YEAR('입력'!$C$130)&". "&MONTH('입력'!$C$130)&". "&DAY('입력'!$C$130)&".")&" ("&('입력'!$C$130-'입력'!$C$12+1)&"일)")
B13: 공기 연장 | E13: =IF('입력'!$C$72="","없음","당초 "&IF('입력'!$C$13="","",YEAR('입력'!$C$13)&". "&MONTH('입력'!$C$13)&". "&DAY('입력'!$C$13)&".")&" → 변경 "&IF('입력'!$C$72="","",YEAR('입력'!$C$72)&". "&MONTH('입력'!$C$72)&". "&DAY('입력'!$C$72)&".")&" ("&('입력'!$C$72-'입력'!$C$13)&"일)")
B14: 준 공 일 | E14: =IF('입력'!$C$68="","",YEAR('입력'!$C$68)&". "&MONTH('입력'!$C$68)&". "&DAY('입력'!$C$68)&".")
B15: 준공검사일 | E15: =IF('입력'!$C$70="","",YEAR('입력'!$C$70)&". "&MONTH('입력'!$C$70)&". "&DAY('입력'!$C$70)&".")
B16: 계약상대자 | E16: ='입력'!$C$27&IF('입력'!$C$28="",""," / 대표 "&'입력'!$C$28)&IF('입력'!$C$31="",""," / "&'입력'!$C$31)
B17: 현장대리인 | E17: ='입력'!$C$38&IF('입력'!$C$42="",""," / "&'입력'!$C$42)
B18: 설 계 자 | E18: ='입력'!$C$23&""
B19: 감 리 자 | E19: ='입력'!$C$24&""
B20: 공사 감독자 | E20: ='입력'!$C$20&""
B21: 계약보증 | E21: =IF('입력'!$C$124="",'입력'!$C$46&"",FIXED('입력'!$C$124,0)&"원 / "&'입력'!$C$46)
B22: 하자보수보증 | E22: =IF('입력'!$C$126="",'입력'!$C$49&"",FIXED('입력'!$C$126,0)&"원 / "&'입력'!$C$49)
B23: 하자담보책임기간 | E23: =IF('입력'!$C$129="","",IF('입력'!$C$128="","",YEAR('입력'!$C$128)&". "&MONTH('입력'!$C$128)&". "&DAY('입력'!$C$128)&".")&" ~ "&IF('입력'!$C$129="","",YEAR('입력'!$C$129)&". "&MONTH('입력'!$C$129)&". "&DAY('입력'!$C$129)&"."))
B24: 지체 일수·상금 | E24: =IF('입력'!$C$131="","",IF('입력'!$C$131=0,"없음",'입력'!$C$131&"일 / "&FIXED(N('입력'!$C$133),0)&"원"))
B26: ※ 공사 하나에 한 장 — 계약부터 하자까지 한눈에 보는 관리 카드입니다.

Sheet 34 하자검사조서
B2: 하 자 검 사 조 서 | O2: ← 처음(목록)으로
O3: ✎ 입력 고치기
B4: 공 사 명 | E4: ='입력'!$C$6&""
B5: 계약상대자 | E5: ='입력'!$C$27&IF('입력'!$C$28="",""," (대표 "&'입력'!$C$28&")") | O5: 칸은 「입력」 시트에서 저절로 채워집니다. 여기서 직접 고쳐 써도 됩니다 (그 칸만 수식이 바뀜).
B6: 준 공 일 | E6: =IF('입력'!$C$68="","",YEAR('입력'!$C$68)&". "&MONTH('입력'!$C$68)&". "&DAY('입력'!$C$68)&".")
B7: 하자담보책임기간 | E7: =IF('입력'!$C$129="","",IF('입력'!$C$128="","",YEAR('입력'!$C$128)&". "&MONTH('입력'!$C$128)&". "&DAY('입력'!$C$128)&".")&" ~ "&IF('입력'!$C$129="","",YEAR('입력'!$C$129)&". "&MONTH('입력'!$C$129)&". "&DAY('입력'!$C$129)&"."))
B8: 검 사 일 | E8: =IF('입력'!$C$81="","",YEAR('입력'!$C$81)&". "&MONTH('입력'!$C$81)&". "&DAY('입력'!$C$81)&".")
B9: 검사 결과 | E9: =IF('입력'!$C$82="","하자 없음 / 하자 있음 (보수 요구)",'입력'!$C$82)
B11: 위 치 | D11: 하자 내용 | H11: 보수 요구 사항 | L11: 비 고
B19: 위 공사의 하자담보책임기간 중 하자 검사를 한 결과 위와 같음을 확인합니다.
B21: =IF('입력'!$C$81=""," 년 월 일",YEAR('입력'!$C$81)&"년 "&MONTH('입력'!$C$81)&"월 "&DAY('입력'!$C$81)&"일")
B23: 검 사 자 | G23: 직·성명 | I23: : | J23: ='입력'!$C$21&" (인)"
B25: 입 회 자 | G25: 계약상대자 | I25: : | J25: ='입력'!$C$27&" (인)"
B28: =IF('입력'!$C$18=""," 귀하",'입력'!$C$18&" 귀하")

Sheet 35 하자대장
B2: 하 자 대 장 | O2: ← 처음(목록)으로
O3: ✎ 입력 고치기
B4: 공 사 명 | E4: ='입력'!$C$6&""
B5: 계약상대자 | E5: ='입력'!$C$27&IF('입력'!$C$31="",""," / "&'입력'!$C$31) | O5: 칸은 「입력」 시트에서 저절로 채워집니다. 여기서 직접 고쳐 써도 됩니다 (그 칸만 수식이 바뀜).
B6: 하자담보책임기간 | E6: =IF('입력'!$C$129="","",IF('입력'!$C$128="","",YEAR('입력'!$C$128)&". "&MONTH('입력'!$C$128)&". "&DAY('입력'!$C$128)&".")&" ~ "&IF('입력'!$C$129="","",YEAR('입력'!$C$129)&". "&MONTH('입력'!$C$129)&". "&DAY('입력'!$C$129)&"."))
B7: 하자보수보증 | E7: =IF('입력'!$C$126="",'입력'!$C$49&"",FIXED('입력'!$C$126,0)&"원 / "&'입력'!$C$49)
B9: 번호 | C9: 접 수 일 | E9: 위치 · 하자 내용 | I9: 보수 요구일 | K9: 보수 완료일 | M9: 확 인
B10: 1
B11: 2
B12: 3
B13: 4
B14: 5
B15: 6
B16: 7
B17: 8
B18: 9
B19: 10
B20: 11
B21: 12
... B23: 14

Sheet 계산
A1: 금액을 한글로 바꾸는 칸 (서류가 씁니다 — 지우지 마세요)
A3: 계약금액 | B3: =IF('입력'!$C$14="","",ROUND(ABS('입력'!$C$14),0)) | C3: =IF(B3="",0,INT(B3/100000000)) | D3: =IF(B3="",0,MOD(INT(B3/10000),10000)) | E3: =IF(B3="",0,MOD(B3,10000)) | F3: =CHOOSE(INT(C3/1000)+1,"","일","이","삼","사","오","육","칠","팔","구")&IF(INT(C3/1000)>0,"천","")&CHOOSE(MOD(INT(C3/100),10)+1,"","일","이","삼","사","오","육","칠","팔","구")&IF(MOD(INT(C3/100),10)>0,"백","")&CHOOSE(MOD(INT(C3/10),10)+1,"","일","이","삼","사","오","육","칠","팔","구")&IF(MOD(INT(C3/10),10)>0,"십","")&CHOOSE(MOD(C3,10)+1,"","일","이","삼","사","오","육","칠","팔","구") | G3: =CHOOSE(INT(D3/1000)+1,"","일","이","삼","사","오","육","칠","팔","구")&IF(INT(D3/1000)>0,"천","")&CHOOSE(MOD(INT(D3/100),10)+1,"","일","이","삼","사","오","육","칠","팔","구")&IF(MOD(INT(D3/100),10)>0,"백","")&CHOOSE(MOD(INT(D3/10),10)+1,"","일","이","삼","사","오","육","칠","팔","구")&IF(MOD(INT(D3/10),10)>0,"십","")&CHOOSE(MOD(D3,10)+1,"","일","이","삼","사","오","육","칠","팔","구") | H3: =CHOOSE(INT(E3/1000)+1,"","일","이","삼","사","오","육","칠","팔","구")&IF(INT(E3/1000)>0,"천","")&CHOOSE(MOD(INT(E3/100),10)+1,"","일","이","삼","사","오","육","칠","팔","구")&IF(MOD(INT(E3/100),10)>0,"백","")&CHOOSE(MOD(INT(E3/10),10)+1,"","일","이","삼","사","오","육","칠","팔","구")&IF(MOD(INT(E3/10),10)>0,"십","")&CHOOSE(MOD(E3,10)+1,"","일","이","삼","사","오","육","칠","팔","구") | I3: =IF(B3="","",IF(B3=0,"영",IF(C3>0,F3&"억","")&IF(D3>0,G3&"만","")&H3)) | J3: =IF(B3="","","일금 "&I3)
A4: 정산액 | B4: =IF('입력'!$C$125="","",ROUND(ABS('입력'!$C$125),0)) | C4: =IF(B4="",0,INT(B4/100000000)) | D4: =IF(B4="",0,MOD(INT(B4/10000),10000)) | E4: =IF(B4="",0,MOD(B4,10000)) | F4: =CHOOSE(INT(C4/1000)+1,"","일","이","삼","사","오","육","칠","팔","구")&IF(INT(C4/1000)>0,"천","")&CHOOSE(MOD(INT(C4/100),10)+1,"","일","이","삼","사","오","육","칠","팔","구")&IF(MOD(INT(C4/100),10)>0,"백","")&CHOOSE(MOD(INT(C4/10),10)+1,"","일","이","삼","사","오","육","칠","팔","구")&IF(MOD(INT(C4/10),10)>0,"십","")&CHOOSE(MOD(C4,10)+1,"","일","이","삼","사","오","육","칠","팔","구") | G4: =CHOOSE(INT(D4/1000)+1,"","일","이","삼","사","오","육","칠","팔","구")&IF(INT(D4/1000)>0,"천","")&CHOOSE(MOD(INT(D4/100),10)+1,"","일","이","삼","사","오","육","칠","팔","구")&IF(MOD(INT(D4/100),10)>0,"백","")&CHOOSE(MOD(INT(D4/10),10)+1,"","일","이","삼","사","오","육","칠","팔","구")&IF(MOD(INT(D4/10),10)>0,"십","")&CHOOSE(MOD(D4,10)+1,"","일","이","삼","사","오","육","칠","팔","구") | H4: =CHOOSE(INT(E4/1000)+1,"","일","이","삼","사","오","육","칠","팔","구")&IF(INT(E4/1000)>0,"천","")&CHOOSE(MOD(INT(E4/100),10)+1,"","일","이","삼","사","오","육","칠","팔","구")&IF(MOD(INT(E4/100),10)>0,"백","")&CHOOSE(MOD(INT(E4/10),10)+1,"","일","이","삼","사","오","육","칠","팔","구")&IF(MOD(INT(E4/10),10)>0,"십","")&CHOOSE(MOD(E4,10)+1,"","일","이","삼","사","오","육","칠","팔","구") | I4: =IF(B4="","",IF(B4=0,"영",IF(C4>0,F4&"억","")&IF(D4>0,G4&"만","")&H4)) | J4: =IF(B4="","","일금 "&I4)
A5: 계약보증금 | B5: =IF('입력'!$C$124="","",ROUND(ABS('입력'!$C$124),0)) | C5: =IF(B5="",0,INT(B5/100000000)) | D5: =IF(B5="",0,MOD(INT(B5/10000),10000)) | E5: =IF(B5="",0,MOD(B5,10000)) | F5: =CHOOSE(INT(C5/1000)+1,"","일","이","삼","사","오","육","칠","팔","구")&IF(INT(C5/1000)>0,"천","")&CHOOSE(MOD(INT(C5/100),10)+1,"","일","이","삼","사","오","육","칠","팔","구")&IF(MOD(INT(C5/100),10)>0,"백","")&CHOOSE(MOD(INT(C5/10),10)+1,"","일","이","삼","사","오","육","칠","팔","구")&IF(MOD(INT(C5/10),10)>0,"십","")&CHOOSE(MOD(C5,10)+1,"","일","이","삼","사","오","육","칠","팔","구") | G5: =CHOOSE(INT(D5/1000)+1,"","일","이","삼","사","오","육","칠","팔","구")&IF(INT(D5/1000)>0,"천","")&CHOOSE(MOD(INT(D5/100),10)+1,"","일","이","삼","사","오","육","칠","팔","구")&IF(MOD(INT(D5/100),10)>0,"백","")&CHOOSE(MOD(INT(D5/10),10)+1,"","일","이","삼","사","오","육","칠","팔","구")&IF(MOD(INT(D5/10),10)>0,"십","")&CHOOSE(MOD(D5,10)+1,"","일","이","삼","사","오","육","칠","팔","구") | H5: =CHOOSE(INT(E5/1000)+1,"","일","이","삼","사","오","육","칠","팔","구")&IF(INT(E5/1000)>0,"천","")&CHOOSE(MOD(INT(E5/100),10)+1,"","일","이","삼","사","오","육","칠","팔","구")&IF(MOD(INT(E5/100),10)>0,"백","")&CHOOSE(MOD(INT(E5/10),10)+1,"","일","이","삼","사","오","육","칠","팔","구")&IF(MOD(INT(E5/10),10)>0,"십","")&CHOOSE(MOD(E5,10)+1,"","일","이","삼","사","오","육","칠","팔","구") | I5: =IF(B5="","",IF(B5=0,"영",IF(C5>0,F5&"억","")&IF(D5>0,G5&"만","")&H5)) | J5: =IF(B5="","","일금 "&I5)
A6: 하자보증금 | B6: =IF('입력'!$C$126="","",ROUND(ABS('입력'!$C$126),0)) | C6: =IF(B6="",0,INT(B6/100000000)) | D6: =IF(B6="",0,MOD(INT(B6/10000),10000)) | E6: =IF(B6="",0,MOD(B6,10000)) | F6: =CHOOSE(INT(C6/1000)+1,"","일","이","삼","사","오","육","칠","팔","구")&IF(INT(C6/1000)>0,"천","")&CHOOSE(MOD(INT(C6/100),10)+1,"","일","이","삼","사","오","육","칠","팔","구")&IF(MOD(INT(C6/100),10)>0,"백","")&CHOOSE(MOD(INT(C6/10),10)+1,"","일","이","삼","사","오","육","칠","팔","구")&IF(MOD(INT(C6/10),10)>0,"십","")&CHOOSE(MOD(C6,10)+1,"","일","이","삼","사","오","육","칠","팔","구") | G6: =CHOOSE(INT(D6/1000)+1,"","일","이","삼","사","오","육","칠","팔","구")&IF(INT(D6/1000)>0,"천","")&CHOOSE(MOD(INT(D6/100),10)+1,"","일","이","삼","사","오","육","칠","팔","구")&IF(MOD(INT(D6/100),10)>0,"백","")&CHOOSE(MOD(INT(D6/10),10)+1,"","일","이","삼","사","오","육","칠","팔","구")&IF(MOD(INT(D6/10),10)>0,"십","")&CHOOSE(MOD(D6,10)+1,"","일","이","삼","사","오","육","칠","팔","구") | H6: =CHOOSE(INT(E6/1000)+1,"","일","이","삼","사","오","육","칠","팔","구")&IF(INT(E6/1000)>0,"천","")&CHOOSE(MOD(INT(E6/100),10)+1,"","일","이","삼","사","오","육","칠","팔","구")&IF(MOD(INT(E6/100),10)>0,"백","")&CHOOSE(MOD(INT(E6/10),10)+1,"","일","이","삼","사","오","육","칠","팔","구")&IF(MOD(INT(E6/10),10)>0,"십","")&CHOOSE(MOD(E6,10)+1,"","일","이","삼","사","오","육","칠","팔","구") | I6: =IF(B6="","",IF(B6=0,"영",IF(C6>0,F6&"억","")&IF(D6>0,G6&"만","")&H6)) | J6: =IF(B6="","","일금 "&I6)
A7: 기성청구액 | B7: =IF('입력'!$C$136="","",ROUND(ABS('입력'!$C$136),0)) | C7: =IF(B7="",0,INT(B7/100000000)) | D7: =IF(B7="",0,MOD(INT(B7/10000),10000)) | E7: =IF(B7="",0,MOD(B7,10000)) | F7: =CHOOSE(INT(C7/1000)+1,"","일","이","삼","사","오","육","칠","팔","구")&IF(INT(C7/1000)>0,"천","")&CHOOSE(MOD(INT(C7/100),10)+1,"","일","이","삼","사","오","육","칠","팔","구")&IF(MOD(INT(C7/100),10)>0,"백","")&CHOOSE(MOD(INT(C7/10),10)+1,"","일","이","삼","사","오","육","칠","팔","구")&IF(MOD(INT(C7/10),10)>0,"십","")&CHOOSE(MOD(C7,10)+1,"","일","이","삼","사","오","육","칠","팔","구") | G7: =CHOOSE(INT(D7/1000)+1,"","일","이","삼","사","오","육","칠","팔","구")&IF(INT(D7/1000)>0,"천","")&CHOOSE(MOD(INT(D7/100),10)+1,"","일","이","삼","사","오","육","칠","팔","구")&IF(MOD(INT(D7/100),10)>0,"백","")&CHOOSE(MOD(INT(D7/10),10)+1,"","일","이","삼","사","오","육","칠","팔","구")&IF(MOD(INT(D7/10),10)>0,"십","")&CHOOSE(MOD(D7,10)+1,"","일","이","삼","사","오","육","칠","팔","구") | H7: =CHOOSE(INT(E7/1000)+1,"","일","이","삼","사","오","육","칠","팔","구")&IF(INT(E7/1000)>0,"천","")&CHOOSE(MOD(INT(E7/100),10)+1,"","일","이","삼","사","오","육","칠","팔","구")&IF(MOD(INT(E7/100),10)>0,"백","")&CHOOSE(MOD(INT(E7/10),10)+1,"","일","이","삼","사","오","육","칠","팔","구")&IF(MOD(INT(E7/10),10)>0,"십","")&CHOOSE(MOD(E7,10)+1,"","일","이","삼","사","오","육","칠","팔","구") | I7: =IF(B7="","",IF(B7=0,"영",IF(C7>0,F7&"억","")&IF(D7>0,G7&"만","")&H7)) | J7: =IF(B7="","","일금 "&I7)
A8: 준공청구액 | B8: =IF('입력'!$C$138="","",ROUND(ABS('입력'!$C$138),0)) | C8: =IF(B8="",0,INT(B8/100000000)) | D8: =IF(B8="",0,MOD(INT(B8/10000),10000)) | E8: =IF(B8="",0,MOD(B8,10000)) | F8: =CHOOSE(INT(C8/1000)+1,"","일","이","삼","사","오","육","칠","팔","구")&IF(INT(C8/1000)>0,"천","")&CHOOSE(MOD(INT(C8/100),10)+1,"","일","이","삼","사","오","육","칠","팔","구")&IF(MOD(INT(C8/100),10)>0,"백","")&CHOOSE(MOD(INT(C8/10),10)+1,"","일","이","삼","사","오","육","칠","팔","구")&IF(MOD(INT(C8/10),10)>0,"십","")&CHOOSE(MOD(C8,10)+1,"","일","이","삼","사","오","육","칠","팔","구") | G8: =CHOOSE(INT(D8/1000)+1,"","일","이","삼","사","오","육","칠","팔","구")&IF(INT(D8/1000)>0,"천","")&CHOOSE(MOD(INT(D8/100),10)+1,"","일","이","삼","사","오","육","칠","팔","구")&IF(MOD(INT(D8/100),10)>0,"백","")&CHOOSE(MOD(INT(D8/10),10)+1,"","일","이","삼","사","오","육","칠","팔","구")&IF(MOD(INT(D8/10),10)>0,"십","")&CHOOSE(MOD(D8,10)+1,"","일","이","삼","사","오","육","칠","팔","구") | H8: =CHOOSE(INT(E8/1000)+1,"","일","이","삼","사","오","육","칠","팔","구")&IF(INT(E8/1000)>0,"천","")&CHOOSE(MOD(INT(E8/100),10)+1,"","일","이","삼","사","오","육","칠","팔","구")&IF(MOD(INT(E8/100),10)>0,"백","")&CHOOSE(MOD(INT(E8/10),10)+1,"","일","이","삼","사","오","육","칠","팔","구")&IF(MOD(INT(E8/10),10)>0,"십","")&CHOOSE(MOD(E8,10)+1,"","일","이","삼","사","오","육","칠","팔","구") | I8: =IF(B8="","",IF(B8=0,"영",IF(C8>0,F8&"억","")&IF(D8>0,G8&"만","")&H8)) | J8: =IF(B8="","","일금 "&I8)
A9: 금회기성 | B9: =IF('입력'!$C$59="","",ROUND(ABS('입력'!$C$59),0)) | C9: =IF(B9="",0,INT(B9/100000000)) | D9: =IF(B9="",0,MOD(INT(B9/10000),10000)) | E9: =IF(B9="",0,MOD(B9,10000)) | F9: =CHOOSE(INT(C9/1000)+1,"","일","이","삼","사","오","육","칠","팔","구")&IF(INT(C9/1000)>0,"천","")&CHOOSE(MOD(INT(C9/100),10)+1,"","일","이","삼","사","오","육","칠","팔","구")&IF(MOD(INT(C9/100),10)>0,"백","")&CHOOSE(MOD(INT(C9/10),10)+1,"","일","이","삼","사","오","육","칠","팔","구")&IF(MOD(INT(C9/10),10)>0,"십","")&CHOOSE(MOD(C9,10)+1,"","일","이","삼","사","오","육","칠","팔","구") | G9: =CHOOSE(INT(D9/1000)+1,"","일","이","삼","사","오","육","칠","팔","구")&IF(INT(D9/1000)>0,"천","")&CHOOSE(MOD(INT(D9/100),10)+1,"","일","이","삼","사","오","육","칠","팔","구")&IF(MOD(INT(D9/100),10)>0,"백","")&CHOOSE(MOD(INT(D9/10),10)+1,"","일","이","삼","사","오","육","칠","팔","구")&IF(MOD(INT(D9/10),10)>0,"십","")&CHOOSE(MOD(D9,10)+1,"","일","이","삼","사","오","육","칠","팔","구") | H9: =CHOOSE(INT(E9/1000)+1,"","일","이","삼","사","오","육","칠","팔","구")&IF(INT(E9/1000)>0,"천","")&CHOOSE(MOD(INT(E9/100),10)+1,"","일","이","삼","사","오","육","칠","팔","구")&IF(MOD(INT(E9/100),10)>0,"백","")&CHOOSE(MOD(INT(E9/10),10)+1,"","일","이","삼","사","오","육","칠","팔","구")&IF(MOD(INT(E9/10),10)>0,"십","")&CHOOSE(MOD(E9,10)+1,"","일","이","삼","사","오","육","칠","팔","구") | I9: =IF(B9="","",IF(B9=0,"영",IF(C9>0,F9&"억","")&IF(D9>0,G9&"만","")&H9)) | J9: =IF(B9="","","일금 "&I9)
A10: 기성누계 | B10: =IF('입력'!$C$134="","",ROUND(ABS('입력'!$C$134),0)) | C10: =IF(B10="",0,INT(B10/100000000)) | D10: =IF(B10="",0,MOD(INT(B10/10000),10000)) | E10: =IF(B10="",0,MOD(B10,10000)) | F10: =CHOOSE(INT(C10/1000)+1,"","일","이","삼","사","오","육","칠","팔","구")&IF(INT(C10/1000)>0,"천","")&CHOOSE(MOD(INT(C10/100),10)+1,"","일","이","삼","사","오","육","칠","팔","구")&IF(MOD(INT(C10/100),10)>0,"백","")&CHOOSE(MOD(INT(C10/10),10)+1,"","일","이","삼","사","오","육","칠","팔","구")&IF(MOD(INT(C10/10),10)>0,"십","")&CHOOSE(MOD(C10,10)+1,"","일","이","삼","사","오","육","칠","팔","구") | G10: =CHOOSE(INT(D10/1000)+1,"","일","이","삼","사","오","육","칠","팔","구")&IF(INT(D10/1000)>0,"천","")&CHOOSE(MOD(INT(D10/100),10)+1,"","일","이","삼","사","오","육","칠","팔","구")&IF(MOD(INT(D10/100),10)>0,"백","")&CHOOSE(MOD(INT(D10/10),10)+1,"","일","이","삼","사","오","육","칠","팔","구")&IF(MOD(INT(D10/10),10)>0,"십","")&CHOOSE(MOD(D10,10)+1,"","일","이","삼","사","오","육","칠","팔","구") | H10: =CHOOSE(INT(E10/1000)+1,"","일","이","삼","사","오","육","칠","팔","구")&IF(INT(E10/1000)>0,"천","")&CHOOSE(MOD(INT(E10/100),10)+1,"","일","이","삼","사","오","육","칠","팔","구")&IF(MOD(INT(E10/100),10)>0,"백","")&CHOOSE(MOD(INT(E10/10),10)+1,"","일","이","삼","사","오","육","칠","팔","구")&IF(MOD(INT(E10/10),10)>0,"십","")&CHOOSE(MOD(E10,10)+1,"","일","이","삼","사","오","육","칠","팔","구") | I10: =IF(B10="","",IF(B10=0,"영",IF(C10>0,F10&"억","")&IF(D10>0,G10&"만","")&H10)) | J10: =IF(B10="","","일금 "&I10)
A11: 증감액abs | B11: =IF(ABS(N('입력'!$C$141))="","",ROUND(ABS(ABS(N('입력'!$C$141))),0)) | C11: =IF(B11="",0,INT(B11/100000000)) | D11: =IF(B11="",0,MOD(INT(B11/10000),10000)) | E11: =IF(B11="",0,MOD(B11,10000)) | F11: =CHOOSE(INT(C11/1000)+1,"","일","이","삼","사","오","육","칠","팔","구")&IF(INT(C11/1000)>0,"천","")&CHOOSE(MOD(INT(C11/100),10)+1,"","일","이","삼","사","오","육","칠","팔","구")&IF(MOD(INT(C11/100),10)>0,"백","")&CHOOSE(MOD(INT(C11/10),10)+1,"","일","이","삼","사","오","육","칠","팔","구")&IF(MOD(INT(C11/10),10)>0,"십","")&CHOOSE(MOD(C11,10)+1,"","일","이","삼","사","오","육","칠","팔","구") | G11: =CHOOSE(INT(D11/1000)+1,"","일","이","삼","사","오","육","칠","팔","구")&IF(INT(D11/1000)>0,"천","")&CHOOSE(MOD(INT(D11/100),10)+1,"","일","이","삼","사","오","육","칠","팔","구")&IF(MOD(INT(D11/100),10)>0,"백","")&CHOOSE(MOD(INT(D11/10),10)+1,"","일","이","삼","사","오","육","칠","팔","구")&IF(MOD(INT(D11/10),10)>0,"십","")&CHOOSE(MOD(D11,10)+1,"","일","이","삼","사","오","육","칠","팔","구") | H11: =CHOOSE(INT(E11/1000)+1,"","일","이","삼","사","오","육","칠","팔","구")&IF(INT(E11/1000)>0,"천","")&CHOOSE(MOD(INT(E11/100),10)+1,"","일","이","삼","사","오","육","칠","팔","구")&IF(MOD(INT(E11/100),10)>0,"백","")&CHOOSE(MOD(INT(E11/10),10)+1,"","일","이","삼","사","오","육","칠","팔","구")&IF(MOD(INT(E11/10),10)>0,"십","")&CHOOSE(MOD(E11,10)+1,"","일","이","삼","사","오","육","칠","팔","구") | I11: =IF(B11="","",IF(B11=0,"영",IF(C11>0,F11&"억","")&IF(D11>0,G11&"만","")&H11)) | J11: =IF(B11="","","일금 "&I11)
