Workbook

Sheet 표지
A1: K-건설맵 | k-conmap.com 건설 서식 | G1: ← 이 1행을 지우고 쓰셔도 됩니다
A3: (공 사 명)
A5: 시 공 계 획 서
A6: [ 방수공사 ]
A8: 20 . .
A10: (회 사 명)
A12: 공사명 · 작성 연월(2026-03 처럼) · 회사명을 여기 한 번만 적으면 뒤 장에 저절로 들어갑니다.

Sheet 개요
A1: K-건설맵 | k-conmap.com 건설 서식 | G1: ← 이 1행을 지우고 쓰셔도 됩니다
A3: 목 차
C5: 1. 공 사 명
C6: 2. 공 사 개 요
C7: 3. 공 사 위 치
C8: 4. 주요 공사 물량
C9: 5. 현 장 조 직 도
C10: 6. 시 공 관 리
C11: 7. 예 정 공 정 표
C12: 8. 품 질 관 리 계 획
C13: 9. 환 경 관 리 계 획
C14: 10. 안 전 관 리 계 획
A16: 1.0 공 사 명
B18: =IF(OR('표지'!A3="",'표지'!A3="(공 사 명)"),"","◦ "&'표지'!A3)
A20: 2.0 공 사 개 요
A22: 공 사 명 | D22: =IF(OR('표지'!A3="",'표지'!A3="(공 사 명)"),"",'표지'!A3)
A23: 공 사 위 치
A24: 발 주 처
A25: 공 사 기 간 | F25: ~ | I25: =IF(OR(N(D25)=0,N(G25)=0),"",IF(G25<D25,"⚠ 준공일이 착공일보다 빠름",G25-D25+1))
A26: 공 사 금 액 | G26: =IF(N(D26)=0,"",D26)
A27: 공 사 규 모
A28: 시 공 사 | D28: =IF(OR('표지'!A10="",'표지'!A10="(회 사 명)"),"",'표지'!A10)
A30: 3.0 공 사 위 치
A32: (위치도를 붙이는 곳 — 현장 위치와 방수 공사 구간을 표시)
A45: 4.0 주요 공사 물량
A47: 구 분 | C47: 명 칭 | F47: 규 격 | H47: 수 량 | J47: 단위 | K47: 비 고
A60: 합 계 (단위가 ㎡ 인 줄) | H60: =IF(SUMIF(J48:J59,"㎡",H48:H59)+SUMIF(J48:J59,"m2",H48:H59)=0,"",SUMIF(J48:J59,"㎡",H48:H59)+SUMIF(J48:J59,"m2",H48:H59)) | J60: ㎡
A62: 5.0 현 장 조 직 도
E64: 현 장 대 리 인
A66: │
B67: 품 질 관 리 자 | F67: ─┼─ | H67: 안 전 관 리 자
F68: │
A69: │
E70: 시 공 업 체
A72: │
E73: 작 업 반 장
A75: ┌──────────┼──────────┐
A76: 장비기사 | C76: 방수공 | E76: 특별인부 | G76: 보통인부 | I76: 합 계
A77: 1 | C77: 3 | E77: 3 | G77: 5 | I77: =IF(SUM(A77,C77,E77,G77)=0,"",SUM(A77,C77,E77,G77))
A79: 하늘색 칸 = 자동(공사명 · 시공사 · 공사기간 일수 · 금액 한글 · ㎡ 합계 · 인원 합계). 인원은 원본 계획서 인원을 넣어 두었습니다.

Sheet 시공관리
A1: K-건설맵 | k-conmap.com 건설 서식 | G1: ← 이 1행을 지우고 쓰셔도 됩니다
A3: 6.0 시 공 관 리
A6: 6-1 시멘트 액체방수
A7: 1) 일반사항
A8: (1) | B8: 시멘트 모르타르계 방수공사의 일반사항은 건축공사 표준시방서(KCS 41 40 방수공사)와 공사시방서를 따른다.
A9: (2) | B9: 재료는 눈 · 비 · 직사광선이 닿지 않는 곳에 밀봉 상태로 보관하고, 운반 · 취급 때 포장이 터지거나 찢어지지 않게 한다. 손상된 자재나 유효기간이 지난 것은 즉시 현장 밖으로 반출한다.
A10: 2) 자재
A11: (1) | B11: 시멘트 — KS L 5201 에 합격하는 1종 보통 포틀랜드 시멘트를 쓴다.
A12: (2) | B12: 모래 — 유해량의 철분 · 염분 · 진흙 · 먼지 및 유기불순물이 없는 양질의 것으로, 바름 두께에 지장이 없는 범위에서 입도가 큰 것을 쓴다.
A13: (3) | B13: 물 — 유해량의 염분 · 철분 · 이온 및 유기물이 없는 깨끗한 물을 쓴다.
A14: (4) | B14: 방수제 — 주성분에 따라 무기질계 · 유기질계 · 폴리머계로 나누며, KS F 4925 의 품질기준에 맞고 품질이 변하지 않게 저장하여 유효기간 안에 쓴다.
A15: [ 시멘트 액체 방수제의 화학조성 분류 ]
A16: 종 류 | D16: 주 성 분
A17: 무기질계 | D17: 염화칼슘계, 규산소다계, 실리케이트계
A18: 유기질계 | D18: 지방산계, 파라핀계
A19: 폴리머계 | D19: 합성고무 라텍스계, 에틸렌비닐아세테이트 에멀션계, 아크릴 에멀션계
A20: 3) 시공
B21: (1) 바탕처리
A22: 가. | C22: 바탕면에 붙은 흙 · 먼지 · 모래 · 자갈 및 레이턴스 등은 정 · 와이어브러시 등으로 제거하고, 지푸라기 · 못 · 철선 등이 모체에 깊이 박힌 부분은 충분한 깊이까지 파낸다.
A23: 나. | C23: 모르타르 · 콘크리트의 불량 부분, 균열이 생긴 부분 및 그 밖의 부실한 부분은 제거 · 보수하여 충분한 강도가 있는 건실한 모체로 만든 다음 방수층을 시공한다.
A24: 다. | C24: 모체에 건조 균열이 진행 중이라고 인정되는 곳이나 방수층에 결함이 생길 우려가 있는 부분은 담당자와 협의하여 대책을 세운다.
A25: 라. | C25: 바탕처리 후에는 물 씻기 등으로 완전히 청소하고 건조한 다음 방수공사를 한다.
B26: (2) 방수제의 배합 및 비빔
A27: 가. | C27: 방수제는 제조자가 지정하는 비율로 넣고 모르타르 믹서로 충분히 비빈다. 방수 시멘트 페이스트는 시멘트를 먼저 2분 이상 건비빔한 뒤, 정해진 물로 희석한 방수제를 넣어 균질해질 때까지 5분 이상 비빈다.
A28: 나. | C28: 방수 모르타르는 모래 · 시멘트 순으로 믹서에 넣어 2분 이상 건비빔한 뒤, 희석한 방수제를 넣어 균질해질 때까지 5분 이상 비빈다.
A29: 다. | C29: 믹서를 멈춘 뒤 모르타르의 수분이나 모래가 분리되지 않아야 하며 불순물이 섞이지 않아야 한다.
B30: (3) 방수층 바름
A31: 가. | C31: 방수액 침투 : 방수액 40%, 물 60% 로 섞어 솔이나 롤러로 바탕면에 침투시킨다.
A32: 나. | C32: 페이스트 1차 도포 : 시멘트 40%, 침투식 액체방수제 20%, 물 40%(용량비)로 섞어 바탕면에 고르게 바른다.
A33: 다. | C33: 모르타르 바름 : 페이스트 도포가 끝나면 시멘트와 모래를 1 : 1 로 섞은 모르타르를 손으로 얇게 문질러 바탕면과 잘 붙게 한다.
A34: 라. | C34: 페이스트 2차 도포 : 시멘트 70%, 침투식 액체방수제 20%, 물 10%(용량비)로 섞어 바탕면에 고르게 바른다.
A35: 마. | C35: 보호 모르타르 : 시멘트와 모래를 1 : 3 으로 섞어 벽은 6 ~ 9mm, 바닥은 10 ~ 12mm 정도로 나무흙손이나 쇠흙손으로 고르게 바른다.
A36: 4) 검측 흐름(FLOW CHART)
D37: 현장 시공 완료
A38: ▼
D39: 시공자 · 담당기술자 점검 | J39: ◀ 첨부 : 시공자 점검표
A40: ▼
D41: 검측요청서 제출 | J41: ◀ 첨부 : 공사참여자 명부 · 관련 도면 · 사진
A42: ▼
D43: 감 리 원(공사감독자) 현장 검측
...

Sheet 공정표
A1: K-건설맵 | k-conmap.com 건설 서식 | N1: ← 이 1행을 지우고 쓰셔도 됩니다
A2: 7.0 예 정 공 정 표
A3: 착 공 일 | B3: =IF(N('개요'!D25)=0,"",'개요'!D25) | D3: ※ 착공일은 공사개요에서 따라옵니다. 공종마다 착수 · 완료일을 적으면 반달 칸에 막대가 그려집니다.
A4: 공 종 | B4: 착 수 | C4: 완 료 | D4: 일 수 | E4: =IF(N(B3)=0,"",EDATE(DATE(YEAR(B3),MONTH(B3),1),0)) | G4: =IF(N(B3)=0,"",EDATE(DATE(YEAR(B3),MONTH(B3),1),1)) | I4: =IF(N(B3)=0,"",EDATE(DATE(YEAR(B3),MONTH(B3),1),2)) | K4: =IF(N(B3)=0,"",EDATE(DATE(YEAR(B3),MONTH(B3),1),3)) | M4: =IF(N(B3)=0,"",EDATE(DATE(YEAR(B3),MONTH(B3),1),4)) | O4: =IF(N(B3)=0,"",EDATE(DATE(YEAR(B3),MONTH(B3),1),5)) | Q4: =IF(N(B3)=0,"",EDATE(DATE(YEAR(B3),MONTH(B3),1),6)) | S4: =IF(N(B3)=0,"",EDATE(DATE(YEAR(B3),MONTH(B3),1),7)) | U4: =IF(N(B3)=0,"",EDATE(DATE(YEAR(B3),MONTH(B3),1),8)) | W4: =IF(N(B3)=0,"",EDATE(DATE(YEAR(B3),MONTH(B3),1),9)) | Y4: =IF(N(B3)=0,"",EDATE(DATE(YEAR(B3),MONTH(B3),1),10)) | AA4: =IF(N(B3)=0,"",EDATE(DATE(YEAR(B3),MONTH(B3),1),11)) | AC4: =IF(N(B3)=0,"",EDATE(DATE(YEAR(B3),MONTH(B3),1),12)) | AE4: =IF(N(B3)=0,"",EDATE(DATE(YEAR(B3),MONTH(B3),1),13)) | AG4: =IF(N(B3)=0,"",EDATE(DATE(YEAR(B3),MONTH(B3),1),14)) | AI4: =IF(N(B3)=0,"",EDATE(DATE(YEAR(B3),MONTH(B3),1),15)) | AK4: =IF(N(B3)=0,"",EDATE(DATE(YEAR(B3),MONTH(B3),1),16)) | AM4: =IF(N(B3)=0,"",EDATE(DATE(YEAR(B3),MONTH(B3),1),17)) | AO4: 비 고
E5: 상 | F5: 하 | G5: 상 | H5: 하 | I5: 상 | J5: 하 | K5: 상 | L5: 하 | M5: 상 | N5: 하 | O5: 상 | P5: 하 | Q5: 상 | R5: 하 | S5: 상 | T5: 하 | U5: 상 | V5: 하 | W5: 상 | X5: 하 | Y5: 상 | Z5: 하 | AA5: 상 | AB5: 하 | AC5: 상 | AD5: 하 | AE5: 상 | AF5: 하 | AG5: 상 | AH5: 하 | AI5: 상 | AJ5: 하 | AK5: 상 | AL5: 하 | AM5: 상 | AN5: 하
E6: =IF(N(B3)=0,"",EDATE(DATE(YEAR(B3),MONTH(B3),1),0)) | F6: =IF(N(B3)=0,"",EDATE(DATE(YEAR(B3),MONTH(B3),1),0)+15) | G6: =IF(N(B3)=0,"",EDATE(DATE(YEAR(B3),MONTH(B3),1),1)) | H6: =IF(N(B3)=0,"",EDATE(DATE(YEAR(B3),MONTH(B3),1),1)+15) | I6: =IF(N(B3)=0,"",EDATE(DATE(YEAR(B3),MONTH(B3),1),2)) | J6: =IF(N(B3)=0,"",EDATE(DATE(YEAR(B3),MONTH(B3),1),2)+15) | K6: =IF(N(B3)=0,"",EDATE(DATE(YEAR(B3),MONTH(B3),1),3)) | L6: =IF(N(B3)=0,"",EDATE(DATE(YEAR(B3),MONTH(B3),1),3)+15) | M6: =IF(N(B3)=0,"",EDATE(DATE(YEAR(B3),MONTH(B3),1),4)) | N6: =IF(N(B3)=0,"",EDATE(DATE(YEAR(B3),MONTH(B3),1),4)+15) | O6: =IF(N(B3)=0,"",EDATE(DATE(YEAR(B3),MONTH(B3),1),5)) | P6: =IF(N(B3)=0,"",EDATE(DATE(YEAR(B3),MONTH(B3),1),5)+15) | Q6: =IF(N(B3)=0,"",EDATE(DATE(YEAR(B3),MONTH(B3),1),6)) | R6: =IF(N(B3)=0,"",EDATE(DATE(YEAR(B3),MONTH(B3),1),6)+15) | S6: =IF(N(B3)=0,"",EDATE(DATE(YEAR(B3),MONTH(B3),1),7)) | T6: =IF(N(B3)=0,"",EDATE(DATE(YEAR(B3),MONTH(B3),1),7)+15) | U6: =IF(N(B3)=0,"",EDATE(DATE(YEAR(B3),MONTH(B3),1),8)) | V6: =IF(N(B3)=0,"",EDATE(DATE(YEAR(B3),MONTH(B3),1),8)+15) | W6: =IF(N(B3)=0,"",EDATE(DATE(YEAR(B3),MONTH(B3),1),9)) | X6: =IF(N(B3)=0,"",EDATE(DATE(YEAR(B3),MONTH(B3),1),9)+15) | Y6: =IF(N(B3)=0,"",EDATE(DATE(YEAR(B3),MONTH(B3),1),10)) | Z6: =IF(N(B3)=0,"",EDATE(DATE(YEAR(B3),MONTH(B3),1),10)+15) | AA6: =IF(N(B3)=0,"",EDATE(DATE(YEAR(B3),MONTH(B3),1),11)) | AB6: =IF(N(B3)=0,"",EDATE(DATE(YEAR(B3),MONTH(B3),1),11)+15) | AC6: =IF(N(B3)=0,"",EDATE(DATE(YEAR(B3),MONTH(B3),1),12)) | AD6: =IF(N(B3)=0,"",EDATE(DATE(YEAR(B3),MONTH(B3),1),12)+15) | AE6: =IF(N(B3)=0,"",EDATE(DATE(YEAR(B3),MONTH(B3),1),13)) | AF6: =IF(N(B3)=0,"",EDATE(DATE(YEAR(B3),MONTH(B3),1),13)+15) | AG6: =IF(N(B3)=0,"",EDATE(DATE(YEAR(B3),MONTH(B3),1),14)) | AH6: =IF(N(B3)=0,"",EDATE(DATE(YEAR(B3),MONTH(B3),1),14)+15) | AI6: =IF(N(B3)=0,"",EDATE(DATE(YEAR(B3),MONTH(B3),1),15)) | AJ6: =IF(N(B3)=0,"",EDATE(DATE(YEAR(B3),MONTH(B3),1),15)+15) | AK6: =IF(N(B3)=0,"",EDATE(DATE(YEAR(B3),MONTH(B3),1),16)) | AL6: =IF(N(B3)=0,"",EDATE(DATE(YEAR(B3),MONTH(B3),1),16)+15) | AM6: =IF(N(B3)=0,"",EDATE(DATE(YEAR(B3),MONTH(B3),1),17)) | AN6: =IF(N(B3)=0,"",EDATE(DATE(YEAR(B3),MONTH(B3),1),17)+15)
E7: =IF(N(B3)=0,"",EDATE(DATE(YEAR(B3),MONTH(B3),1),0)+14) | F7: =IF(N(B3)=0,"",EDATE(DATE(YEAR(B3),MONTH(B3),1),1)-1) | G7: =IF(N(B3)=0,"",EDATE(DATE(YEAR(B3),MONTH(B3),1),1)+14) | H7: =IF(N(B3)=0,"",EDATE(DATE(YEAR(B3),MONTH(B3),1),2)-1) | I7: =IF(N(B3)=0,"",EDATE(DATE(YEAR(B3),MONTH(B3),1),2)+14) | J7: =IF(N(B3)=0,"",EDATE(DATE(YEAR(B3),MONTH(B3),1),3)-1) | K7: =IF(N(B3)=0,"",EDATE(DATE(YEAR(B3),MONTH(B3),1),3)+14) | L7: =IF(N(B3)=0,"",EDATE(DATE(YEAR(B3),MONTH(B3),1),4)-1) | M7: =IF(N(B3)=0,"",EDATE(DATE(YEAR(B3),MONTH(B3),1),4)+14) | N7: =IF(N(B3)=0,"",EDATE(DATE(YEAR(B3),MONTH(B3),1),5)-1) | O7: =IF(N(B3)=0,"",EDATE(DATE(YEAR(B3),MONTH(B3),1),5)+14) | P7: =IF(N(B3)=0,"",EDATE(DATE(YEAR(B3),MONTH(B3),1),6)-1) | Q7: =IF(N(B3)=0,"",EDATE(DATE(YEAR(B3),MONTH(B3),1),6)+14) | R7: =IF(N(B3)=0,"",EDATE(DATE(YEAR(B3),MONTH(B3),1),7)-1) | S7: =IF(N(B3)=0,"",EDATE(DATE(YEAR(B3),MONTH(B3),1),7)+14) | T7: =IF(N(B3)=0,"",EDATE(DATE(YEAR(B3),MONTH(B3),1),8)-1) | U7: =IF(N(B3)=0,"",EDATE(DATE(YEAR(B3),MONTH(B3),1),8)+14) | V7: =IF(N(B3)=0,"",EDATE(DATE(YEAR(B3),MONTH(B3),1),9)-1) | W7: =IF(N(B3)=0,"",EDATE(DATE(YEAR(B3),MONTH(B3),1),9)+14) | X7: =IF(N(B3)=0,"",EDATE(DATE(YEAR(B3),MONTH(B3),1),10)-1) | Y7: =IF(N(B3)=0,"",EDATE(DATE(YEAR(B3),MONTH(B3),1),10)+14) | Z7: =IF(N(B3)=0,"",EDATE(DATE(YEAR(B3),MONTH(B3),1),11)-1) | AA7: =IF(N(B3)=0,"",EDATE(DATE(YEAR(B3),MONTH(B3),1),11)+14) | AB7: =IF(N(B3)=0,"",EDATE(DATE(YEAR(B3),MONTH(B3),1),12)-1) | AC7: =IF(N(B3)=0,"",EDATE(DATE(YEAR(B3),MONTH(B3),1),12)+14) | AD7: =IF(N(B3)=0,"",EDATE(DATE(YEAR(B3),MONTH(B3),1),13)-1) | AE7: =IF(N(B3)=0,"",EDATE(DATE(YEAR(B3),MONTH(B3),1),13)+14) | AF7: =IF(N(B3)=0,"",EDATE(DATE(YEAR(B3),MONTH(B3),1),14)-1) | AG7: =IF(N(B3)=0,"",EDATE(DATE(YEAR(B3),MONTH(B3),1),14)+14) | AH7: =IF(N(B3)=0,"",EDATE(DATE(YEAR(B3),MONTH(B3),1),15)-1) | AI7: =IF(N(B3)=0,"",EDATE(DATE(YEAR(B3),MONTH(B3),1),15)+14) | AJ7: =IF(N(B3)=0,"",EDATE(DATE(YEAR(B3),MONTH(B3),1),16)-1) | AK7: =IF(N(B3)=0,"",EDATE(DATE(YEAR(B3),MONTH(B3),1),16)+14) | AL7: =IF(N(B3)=0,"",EDATE(DATE(YEAR(B3),MONTH(B3),1),17)-1) | AM7: =IF(N(B3)=0,"",EDATE(DATE(YEAR(B3),MONTH(B3),1),17)+14) | AN7: =IF(N(B3)=0,"",EDATE(DATE(YEAR(B3),MONTH(B3),1),18)-1)
A8: 바탕처리 · 청소 | D8: =IF(OR(N(B8)=0,N(C8)=0),"",IF(C8<B8,"⚠",C8-B8+1))
A9: 시멘트 액체방수(바닥) | D9: =IF(OR(N(B9)=0,N(C9)=0),"",IF(C9<B9,"⚠",C9-B9+1))
A10: 시멘트 액체방수(벽) | D10: =IF(OR(N(B10)=0,N(C10)=0),"",IF(C10<B10,"⚠",C10-B10+1))
A11: 규산질계 침투성방수 | D11: =IF(OR(N(B11)=0,N(C11)=0),"",IF(C11<B11,"⚠",C11-B11+1))
A12: 아스팔트 프라이머 · 보호재 | D12: =IF(OR(N(B12)=0,N(C12)=0),"",IF(C12<B12,"⚠",C12-B12+1))
A13: 담수시험 | D13: =IF(OR(N(B13)=0,N(C13)=0),"",IF(C13<B13,"⚠",C13-B13+1))
A14: 보호몰탈 · 마무리 | D14: =IF(OR(N(B14)=0,N(C14)=0),"",IF(C14<B14,"⚠",C14-B14+1))
A15: 검측 · 정리 | D15: =IF(OR(N(B15)=0,N(C15)=0),"",IF(C15<B15,"⚠",C15-B15+1))
D16: =IF(OR(N(B16)=0,N(C16)=0),"",IF(C16<B16,"⚠",C16-B16+1))
D17: =IF(OR(N(B17)=0,N(C17)=0),"",IF(C17<B17,"⚠",C17-B17+1))
D18: =IF(OR(N(B18)=0,N(C18)=0),"",IF(C18<B18,"⚠",C18-B18+1))
D19: =IF(OR(N(B19)=0,N(C19)=0),"",IF(C19<B19,"⚠",C19-B19+1))
D20: =IF(OR(N(B20)=0,N(C20)=0),"",IF(C20<B20,"⚠",C20-B20+1))
D21: =IF(OR(N(B21)=0,N(C21)=0),"",IF(C21<B21,"⚠",C21-B21+1))
A22: ※ 일수 = 완료 − 착수 + 1. 막대는 반달(1~15일 · 16일~말일) 단위입니다. 공정은 현장 여건 · 날씨에 따라 바뀔 수 있습니다.
A24: 하늘색 칸 = 자동(착공일 · 달 머리 · 일수). 공종 이름은 원본 차례를 미리 넣어 두었습니다 — 현장에 맞게 고쳐 쓰세요.

Sheet 관리계획
A1: K-건설맵 | k-conmap.com 건설 서식 | G1: ← 이 1행을 지우고 쓰셔도 됩니다
A3: 8.0 품 질 관 리 계 획
A6: 8-1 품질관리 일반 및 적용범위
A7: (1) | B7: 공사 진행 중 필요에 따라 각종 승인도면 · 제작도면 · 제작요령서 등을 작성하여 공사감독자(감리원)의 승인을 받는다.
A8: (2) | B8: 공사용 재료는 도면 · 공사시방서 및 공사감독자의 지시에 따라, 쓰기 전에 견본 또는 자료를 제출하여 승인을 받은 뒤 쓴다.
A9: (3) | B9: 품질시험은 「건설기술 진흥법」 및 같은 법 시행령 · 시행규칙과 공사시방서에서 정한 바에 따른다.
A11: 8-2 공사용 재료의 품질
A12: (1) | B12: 설계도면 · 공사시방서 및 공사감독자의 따로 지시가 없으면 시방서에서 정한 품질과 규격에 맞는 재료를 쓴다.
A13: (2) | B13: 시방서에 품질 규격이 없으면 한국산업표준(KS) 표시품 또는 이에 준하는 품질과 규격의 재료를 쓴다.
A14: (3) | B14: 기성품을 포함한 공사용 재료는 현장 반입 전에 자재승인 서류(견본 · 카탈로그 · 시험성적서 등)를 제출하여 승인을 받고, 공사감독자의 지시에 따라 품질을 확인할 수 있는 증빙서류를 낸다.
A15: (4) | B15: 재료가 현장에 들어오면 공사감독자의 인수검사를 받고, 합격한 재료는 작업 · 통행에 지장이 없는 곳에 보관하여 수시 점검이 쉽게 한다.
A16: (5) | B16: 「건설기술 진흥법」에 규정된 품질시험을 하고, 시험실 규모 · 시험장비 · 시험요원 배치기준에 따라 시험실을 운영한다.
A17: (6) | B17: 검사 또는 시험에 불합격한 재료는 지체 없이 현장 밖으로 반출한다.
A19: 8-3 시공 확인 및 검사
A20: (1) | B20: 주요 공사단계가 끝났을 때나 공사감독자가 지시할 때는 시공의 정확성과 품질을 확인받는다.
A21: (2) | B21: 검사에 필요한 자료 작성 · 측량 등은 검사자의 지시에 따른다.
A23: 8-4 자재관리
A24: (1) | B24: 들어온 자재는 자재수불대장으로 입 · 출고를 관리한다.
A25: (2) | B25: 자재는 재질별 · 규격별로 나누어 보관한다.
A26: (3) | B26: 운반 · 야적 때 변형되지 않도록 전용 운반 가설대 또는 전용 야적대를 쓴다.
A27: (4) | B27: 반입 자재는 받침목 · 지지목 등으로 지면에서 200mm 이상 띄우고 손상 · 변형 · 침수되지 않게 한다.
A28: (5) | B28: 변형을 막기 위해 받침목 높이를 맞추고 1단 적재를 기본으로 한다.
A30: 9.0 환 경 관 리 계 획
A33: 9-1 개 요
A34: 현장의 폐기물 · 유류 · 쓰레기 및 소음 · 진동 · 비산먼지 등에 의한 오염을 방지한다.
A36: 9-2 중점관리 방침
A37: (1) | B37: 자율적인 환경관리
A38: (2) | B38: 쾌적한 작업환경 관리
A39: (3) | B39: 민원 발생 방지
A41: 9-3 실시계획
A42: (1) | B42: 작업 전후 정리정돈 : 작업 전후 정리정돈을 철저히 하여 쾌적한 작업환경을 유지한다.
A43: (2) | B43: 분리수거 : 분리수거를 철저히 하고, 방수 작업에서 나온 폐기물(빈 용기 · 잔재 등)은 시공업체 부담으로 적법하게 처리하여 쓰레기를 줄인다.
A44: (3) | B44: 민원 발생 억제 : 소음 · 진동 · 비산먼지 · 냄새를 최대한 억제하여 인근 주민의 생활에 피해가 없도록 하고, 적극적으로 환경관리 활동을 한다.
B45: (4) 환경관리 대책
A46: ① | C46: 쓰레기 처리 : 현장 안은 금연하고 쓰레기 수거함을 둔다.
A47: ② | C47: 잔재물 · 빈 용기 : 방수재 잔재와 빈 용기(프라이머 · 용제 용기 포함)는 지정된 장소에 모아 두고 지정 업체가 수거하게 한다.
A48: ③ | C48: 비산먼지 : 현장 안 주요 도로와 작업장 주변은 하루 2회 이상 살수차로 살수하고, 장비 이동 때 먼지가 나지 않도록 서행한다.
A50: 10.0 안 전 관 리 계 획
A53: 10-1 안전관리 목적
A54: 공종의 특수성을 고려하여 현장의 위험요소를 미리 없애 사고를 막음으로써 귀중한 인명을 보호하고 재산 손실을 최소화하며, 작업 능률을 높여 계획 공정을 원만히 달성하는 데 목적이 있다.
...

Sheet 예시-표지
A1: K-건설맵 | k-conmap.com 건설 서식 | G1: 작성 예시 (가상의 현장)
A3: 가나학교 교사 증축공사
A5: 시 공 계 획 서
A6: [ 방수공사 ]
A8: 46082
A10: 예시건설(주)
A12: 이 시트는 작성 예시입니다(가상의 공사 · 회사 · 사람).

Sheet 예시-개요
A1: K-건설맵 | k-conmap.com 건설 서식 | G1: 작성 예시 (가상의 현장)
A3: 목 차
C5: 1. 공 사 명
C6: 2. 공 사 개 요
C7: 3. 공 사 위 치
C8: 4. 주요 공사 물량
C9: 5. 현 장 조 직 도
C10: 6. 시 공 관 리
C11: 7. 예 정 공 정 표
C12: 8. 품 질 관 리 계 획
C13: 9. 환 경 관 리 계 획
C14: 10. 안 전 관 리 계 획
A16: 1.0 공 사 명
B18: =IF(OR('예시-표지'!A3="",'예시-표지'!A3="(공 사 명)"),"","◦ "&'예시-표지'!A3)
A20: 2.0 공 사 개 요
A22: 공 사 명 | D22: =IF(OR('예시-표지'!A3="",'예시-표지'!A3="(공 사 명)"),"",'예시-표지'!A3)
A23: 공 사 위 치 | D23: 가나시 가나동 일원
A24: 발 주 처 | D24: 가나시교육청
A25: 공 사 기 간 | D25: 46083 | F25: ~ | G25: 46387 | I25: =IF(OR(N(D25)=0,N(G25)=0),"",IF(G25<D25,"⚠ 준공일이 착공일보다 빠름",G25-D25+1))
A26: 공 사 금 액 | D26: 8450000000 | G26: =IF(N(D26)=0,"",D26)
A27: 공 사 규 모 | D27: 교사동 증축(지상 4층) · 실습동 리모델링
A28: 시 공 사 | D28: =IF(OR('예시-표지'!A10="",'예시-표지'!A10="(회 사 명)"),"",'예시-표지'!A10)
A30: 3.0 공 사 위 치
A32: (위치도를 붙이는 곳 — 현장 위치와 방수 공사 구간을 표시)
A45: 4.0 주요 공사 물량
A47: 구 분 | C47: 명 칭 | F47: 규 격 | H47: 수 량 | J47: 단위 | K47: 비 고
A48: 교사동 | C48: 시멘트 액체방수 | F48: 내부 바닥 | H48: 210 | J48: ㎡
A49: 교사동 | C49: 시멘트 액체방수 | F49: 내부 벽 | H49: 150 | J49: ㎡
A50: 교사동 | C50: 규산질계 침투성방수 | F50: 바닥 · 비노출 | H50: 360 | J50: ㎡
A51: 교사동 | C51: 규산질계 침투성방수 | F51: 벽 · 비노출 | H51: 720 | J51: ㎡
A52: 교사동 | C52: 아스팔트 프라이머 바름 | F52: 지하 외벽 | H52: 480 | J52: ㎡
A53: 실습동 | C53: 시멘트 액체방수 | F53: 내부 바닥 | H53: 460 | J53: ㎡
A54: 실습동 | C54: 시멘트 액체방수 | F54: 내부 벽 | H54: 120 | J54: ㎡
A55: 실습동 | C55: 규산질계 침투성방수 | F55: 바닥 · 비노출 | H55: 170 | J55: ㎡
A56: 실습동 | C56: 규산질계 침투성방수 | F56: 벽 · 비노출 | H56: 390 | J56: ㎡
A57: 실습동 | C57: 아스팔트 프라이머 바름 | F57: 지하 외벽 | H57: 250 | J57: ㎡
A60: 합 계 (단위가 ㎡ 인 줄) | H60: =IF(SUMIF(J48:J59,"㎡",H48:H59)+SUMIF(J48:J59,"m2",H48:H59)=0,"",SUMIF(J48:J59,"㎡",H48:H59)+SUMIF(J48:J59,"m2",H48:H59)) | J60: ㎡
A62: 5.0 현 장 조 직 도
E64: 현 장 대 리 인
E65: 홍길동
...

Sheet 예시-시공관리
A1: K-건설맵 | k-conmap.com 건설 서식 | G1: 작성 예시 (가상의 현장)
A3: 6.0 시 공 관 리
A6: 6-1 시멘트 액체방수
A7: 1) 일반사항
A8: (1) | B8: 시멘트 모르타르계 방수공사의 일반사항은 건축공사 표준시방서(KCS 41 40 방수공사)와 공사시방서를 따른다.
A9: (2) | B9: 재료는 눈 · 비 · 직사광선이 닿지 않는 곳에 밀봉 상태로 보관하고, 운반 · 취급 때 포장이 터지거나 찢어지지 않게 한다. 손상된 자재나 유효기간이 지난 것은 즉시 현장 밖으로 반출한다.
A10: 2) 자재
A11: (1) | B11: 시멘트 — KS L 5201 에 합격하는 1종 보통 포틀랜드 시멘트를 쓴다.
A12: (2) | B12: 모래 — 유해량의 철분 · 염분 · 진흙 · 먼지 및 유기불순물이 없는 양질의 것으로, 바름 두께에 지장이 없는 범위에서 입도가 큰 것을 쓴다.
A13: (3) | B13: 물 — 유해량의 염분 · 철분 · 이온 및 유기물이 없는 깨끗한 물을 쓴다.
A14: (4) | B14: 방수제 — 주성분에 따라 무기질계 · 유기질계 · 폴리머계로 나누며, KS F 4925 의 품질기준에 맞고 품질이 변하지 않게 저장하여 유효기간 안에 쓴다.
A15: [ 시멘트 액체 방수제의 화학조성 분류 ]
A16: 종 류 | D16: 주 성 분
A17: 무기질계 | D17: 염화칼슘계, 규산소다계, 실리케이트계
A18: 유기질계 | D18: 지방산계, 파라핀계
A19: 폴리머계 | D19: 합성고무 라텍스계, 에틸렌비닐아세테이트 에멀션계, 아크릴 에멀션계
A20: 3) 시공
B21: (1) 바탕처리
A22: 가. | C22: 바탕면에 붙은 흙 · 먼지 · 모래 · 자갈 및 레이턴스 등은 정 · 와이어브러시 등으로 제거하고, 지푸라기 · 못 · 철선 등이 모체에 깊이 박힌 부분은 충분한 깊이까지 파낸다.
A23: 나. | C23: 모르타르 · 콘크리트의 불량 부분, 균열이 생긴 부분 및 그 밖의 부실한 부분은 제거 · 보수하여 충분한 강도가 있는 건실한 모체로 만든 다음 방수층을 시공한다.
A24: 다. | C24: 모체에 건조 균열이 진행 중이라고 인정되는 곳이나 방수층에 결함이 생길 우려가 있는 부분은 담당자와 협의하여 대책을 세운다.
A25: 라. | C25: 바탕처리 후에는 물 씻기 등으로 완전히 청소하고 건조한 다음 방수공사를 한다.
B26: (2) 방수제의 배합 및 비빔
A27: 가. | C27: 방수제는 제조자가 지정하는 비율로 넣고 모르타르 믹서로 충분히 비빈다. 방수 시멘트 페이스트는 시멘트를 먼저 2분 이상 건비빔한 뒤, 정해진 물로 희석한 방수제를 넣어 균질해질 때까지 5분 이상 비빈다.
A28: 나. | C28: 방수 모르타르는 모래 · 시멘트 순으로 믹서에 넣어 2분 이상 건비빔한 뒤, 희석한 방수제를 넣어 균질해질 때까지 5분 이상 비빈다.
A29: 다. | C29: 믹서를 멈춘 뒤 모르타르의 수분이나 모래가 분리되지 않아야 하며 불순물이 섞이지 않아야 한다.
B30: (3) 방수층 바름
A31: 가. | C31: 방수액 침투 : 방수액 40%, 물 60% 로 섞어 솔이나 롤러로 바탕면에 침투시킨다.
A32: 나. | C32: 페이스트 1차 도포 : 시멘트 40%, 침투식 액체방수제 20%, 물 40%(용량비)로 섞어 바탕면에 고르게 바른다.
A33: 다. | C33: 모르타르 바름 : 페이스트 도포가 끝나면 시멘트와 모래를 1 : 1 로 섞은 모르타르를 손으로 얇게 문질러 바탕면과 잘 붙게 한다.
A34: 라. | C34: 페이스트 2차 도포 : 시멘트 70%, 침투식 액체방수제 20%, 물 10%(용량비)로 섞어 바탕면에 고르게 바른다.
A35: 마. | C35: 보호 모르타르 : 시멘트와 모래를 1 : 3 으로 섞어 벽은 6 ~ 9mm, 바닥은 10 ~ 12mm 정도로 나무흙손이나 쇠흙손으로 고르게 바른다.
A36: 4) 검측 흐름(FLOW CHART)
D37: 현장 시공 완료
A38: ▼
D39: 시공자 · 담당기술자 점검 | J39: ◀ 첨부 : 시공자 점검표
A40: ▼
D41: 검측요청서 제출 | J41: ◀ 첨부 : 공사참여자 명부 · 관련 도면 · 사진
A42: ▼
D43: 감 리 원(공사감독자) 현장 검측
...

Sheet 예시-공정표
A1: K-건설맵 | k-conmap.com 건설 서식 | N1: 작성 예시 (가상의 현장)
A2: 7.0 예 정 공 정 표
A3: 착 공 일 | B3: =IF(N('예시-개요'!D25)=0,"",'예시-개요'!D25) | D3: ※ 착공일은 공사개요에서 따라옵니다. 공종마다 착수 · 완료일을 적으면 반달 칸에 막대가 그려집니다.
A4: 공 종 | B4: 착 수 | C4: 완 료 | D4: 일 수 | E4: =IF(N(B3)=0,"",EDATE(DATE(YEAR(B3),MONTH(B3),1),0)) | G4: =IF(N(B3)=0,"",EDATE(DATE(YEAR(B3),MONTH(B3),1),1)) | I4: =IF(N(B3)=0,"",EDATE(DATE(YEAR(B3),MONTH(B3),1),2)) | K4: =IF(N(B3)=0,"",EDATE(DATE(YEAR(B3),MONTH(B3),1),3)) | M4: =IF(N(B3)=0,"",EDATE(DATE(YEAR(B3),MONTH(B3),1),4)) | O4: =IF(N(B3)=0,"",EDATE(DATE(YEAR(B3),MONTH(B3),1),5)) | Q4: =IF(N(B3)=0,"",EDATE(DATE(YEAR(B3),MONTH(B3),1),6)) | S4: =IF(N(B3)=0,"",EDATE(DATE(YEAR(B3),MONTH(B3),1),7)) | U4: =IF(N(B3)=0,"",EDATE(DATE(YEAR(B3),MONTH(B3),1),8)) | W4: =IF(N(B3)=0,"",EDATE(DATE(YEAR(B3),MONTH(B3),1),9)) | Y4: =IF(N(B3)=0,"",EDATE(DATE(YEAR(B3),MONTH(B3),1),10)) | AA4: =IF(N(B3)=0,"",EDATE(DATE(YEAR(B3),MONTH(B3),1),11)) | AC4: =IF(N(B3)=0,"",EDATE(DATE(YEAR(B3),MONTH(B3),1),12)) | AE4: =IF(N(B3)=0,"",EDATE(DATE(YEAR(B3),MONTH(B3),1),13)) | AG4: =IF(N(B3)=0,"",EDATE(DATE(YEAR(B3),MONTH(B3),1),14)) | AI4: =IF(N(B3)=0,"",EDATE(DATE(YEAR(B3),MONTH(B3),1),15)) | AK4: =IF(N(B3)=0,"",EDATE(DATE(YEAR(B3),MONTH(B3),1),16)) | AM4: =IF(N(B3)=0,"",EDATE(DATE(YEAR(B3),MONTH(B3),1),17)) | AO4: 비 고
E5: 상 | F5: 하 | G5: 상 | H5: 하 | I5: 상 | J5: 하 | K5: 상 | L5: 하 | M5: 상 | N5: 하 | O5: 상 | P5: 하 | Q5: 상 | R5: 하 | S5: 상 | T5: 하 | U5: 상 | V5: 하 | W5: 상 | X5: 하 | Y5: 상 | Z5: 하 | AA5: 상 | AB5: 하 | AC5: 상 | AD5: 하 | AE5: 상 | AF5: 하 | AG5: 상 | AH5: 하 | AI5: 상 | AJ5: 하 | AK5: 상 | AL5: 하 | AM5: 상 | AN5: 하
E6: =IF(N(B3)=0,"",EDATE(DATE(YEAR(B3),MONTH(B3),1),0)) | F6: =IF(N(B3)=0,"",EDATE(DATE(YEAR(B3),MONTH(B3),1),0)+15) | G6: =IF(N(B3)=0,"",EDATE(DATE(YEAR(B3),MONTH(B3),1),1)) | H6: =IF(N(B3)=0,"",EDATE(DATE(YEAR(B3),MONTH(B3),1),1)+15) | I6: =IF(N(B3)=0,"",EDATE(DATE(YEAR(B3),MONTH(B3),1),2)) | J6: =IF(N(B3)=0,"",EDATE(DATE(YEAR(B3),MONTH(B3),1),2)+15) | K6: =IF(N(B3)=0,"",EDATE(DATE(YEAR(B3),MONTH(B3),1),3)) | L6: =IF(N(B3)=0,"",EDATE(DATE(YEAR(B3),MONTH(B3),1),3)+15) | M6: =IF(N(B3)=0,"",EDATE(DATE(YEAR(B3),MONTH(B3),1),4)) | N6: =IF(N(B3)=0,"",EDATE(DATE(YEAR(B3),MONTH(B3),1),4)+15) | O6: =IF(N(B3)=0,"",EDATE(DATE(YEAR(B3),MONTH(B3),1),5)) | P6: =IF(N(B3)=0,"",EDATE(DATE(YEAR(B3),MONTH(B3),1),5)+15) | Q6: =IF(N(B3)=0,"",EDATE(DATE(YEAR(B3),MONTH(B3),1),6)) | R6: =IF(N(B3)=0,"",EDATE(DATE(YEAR(B3),MONTH(B3),1),6)+15) | S6: =IF(N(B3)=0,"",EDATE(DATE(YEAR(B3),MONTH(B3),1),7)) | T6: =IF(N(B3)=0,"",EDATE(DATE(YEAR(B3),MONTH(B3),1),7)+15) | U6: =IF(N(B3)=0,"",EDATE(DATE(YEAR(B3),MONTH(B3),1),8)) | V6: =IF(N(B3)=0,"",EDATE(DATE(YEAR(B3),MONTH(B3),1),8)+15) | W6: =IF(N(B3)=0,"",EDATE(DATE(YEAR(B3),MONTH(B3),1),9)) | X6: =IF(N(B3)=0,"",EDATE(DATE(YEAR(B3),MONTH(B3),1),9)+15) | Y6: =IF(N(B3)=0,"",EDATE(DATE(YEAR(B3),MONTH(B3),1),10)) | Z6: =IF(N(B3)=0,"",EDATE(DATE(YEAR(B3),MONTH(B3),1),10)+15) | AA6: =IF(N(B3)=0,"",EDATE(DATE(YEAR(B3),MONTH(B3),1),11)) | AB6: =IF(N(B3)=0,"",EDATE(DATE(YEAR(B3),MONTH(B3),1),11)+15) | AC6: =IF(N(B3)=0,"",EDATE(DATE(YEAR(B3),MONTH(B3),1),12)) | AD6: =IF(N(B3)=0,"",EDATE(DATE(YEAR(B3),MONTH(B3),1),12)+15) | AE6: =IF(N(B3)=0,"",EDATE(DATE(YEAR(B3),MONTH(B3),1),13)) | AF6: =IF(N(B3)=0,"",EDATE(DATE(YEAR(B3),MONTH(B3),1),13)+15) | AG6: =IF(N(B3)=0,"",EDATE(DATE(YEAR(B3),MONTH(B3),1),14)) | AH6: =IF(N(B3)=0,"",EDATE(DATE(YEAR(B3),MONTH(B3),1),14)+15) | AI6: =IF(N(B3)=0,"",EDATE(DATE(YEAR(B3),MONTH(B3),1),15)) | AJ6: =IF(N(B3)=0,"",EDATE(DATE(YEAR(B3),MONTH(B3),1),15)+15) | AK6: =IF(N(B3)=0,"",EDATE(DATE(YEAR(B3),MONTH(B3),1),16)) | AL6: =IF(N(B3)=0,"",EDATE(DATE(YEAR(B3),MONTH(B3),1),16)+15) | AM6: =IF(N(B3)=0,"",EDATE(DATE(YEAR(B3),MONTH(B3),1),17)) | AN6: =IF(N(B3)=0,"",EDATE(DATE(YEAR(B3),MONTH(B3),1),17)+15)
E7: =IF(N(B3)=0,"",EDATE(DATE(YEAR(B3),MONTH(B3),1),0)+14) | F7: =IF(N(B3)=0,"",EDATE(DATE(YEAR(B3),MONTH(B3),1),1)-1) | G7: =IF(N(B3)=0,"",EDATE(DATE(YEAR(B3),MONTH(B3),1),1)+14) | H7: =IF(N(B3)=0,"",EDATE(DATE(YEAR(B3),MONTH(B3),1),2)-1) | I7: =IF(N(B3)=0,"",EDATE(DATE(YEAR(B3),MONTH(B3),1),2)+14) | J7: =IF(N(B3)=0,"",EDATE(DATE(YEAR(B3),MONTH(B3),1),3)-1) | K7: =IF(N(B3)=0,"",EDATE(DATE(YEAR(B3),MONTH(B3),1),3)+14) | L7: =IF(N(B3)=0,"",EDATE(DATE(YEAR(B3),MONTH(B3),1),4)-1) | M7: =IF(N(B3)=0,"",EDATE(DATE(YEAR(B3),MONTH(B3),1),4)+14) | N7: =IF(N(B3)=0,"",EDATE(DATE(YEAR(B3),MONTH(B3),1),5)-1) | O7: =IF(N(B3)=0,"",EDATE(DATE(YEAR(B3),MONTH(B3),1),5)+14) | P7: =IF(N(B3)=0,"",EDATE(DATE(YEAR(B3),MONTH(B3),1),6)-1) | Q7: =IF(N(B3)=0,"",EDATE(DATE(YEAR(B3),MONTH(B3),1),6)+14) | R7: =IF(N(B3)=0,"",EDATE(DATE(YEAR(B3),MONTH(B3),1),7)-1) | S7: =IF(N(B3)=0,"",EDATE(DATE(YEAR(B3),MONTH(B3),1),7)+14) | T7: =IF(N(B3)=0,"",EDATE(DATE(YEAR(B3),MONTH(B3),1),8)-1) | U7: =IF(N(B3)=0,"",EDATE(DATE(YEAR(B3),MONTH(B3),1),8)+14) | V7: =IF(N(B3)=0,"",EDATE(DATE(YEAR(B3),MONTH(B3),1),9)-1) | W7: =IF(N(B3)=0,"",EDATE(DATE(YEAR(B3),MONTH(B3),1),9)+14) | X7: =IF(N(B3)=0,"",EDATE(DATE(YEAR(B3),MONTH(B3),1),10)-1) | Y7: =IF(N(B3)=0,"",EDATE(DATE(YEAR(B3),MONTH(B3),1),10)+14) | Z7: =IF(N(B3)=0,"",EDATE(DATE(YEAR(B3),MONTH(B3),1),11)-1) | AA7: =IF(N(B3)=0,"",EDATE(DATE(YEAR(B3),MONTH(B3),1),11)+14) | AB7: =IF(N(B3)=0,"",EDATE(DATE(YEAR(B3),MONTH(B3),1),12)-1) | AC7: =IF(N(B3)=0,"",EDATE(DATE(YEAR(B3),MONTH(B3),1),12)+14) | AD7: =IF(N(B3)=0,"",EDATE(DATE(YEAR(B3),MONTH(B3),1),13)-1) | AE7: =IF(N(B3)=0,"",EDATE(DATE(YEAR(B3),MONTH(B3),1),13)+14) | AF7: =IF(N(B3)=0,"",EDATE(DATE(YEAR(B3),MONTH(B3),1),14)-1) | AG7: =IF(N(B3)=0,"",EDATE(DATE(YEAR(B3),MONTH(B3),1),14)+14) | AH7: =IF(N(B3)=0,"",EDATE(DATE(YEAR(B3),MONTH(B3),1),15)-1) | AI7: =IF(N(B3)=0,"",EDATE(DATE(YEAR(B3),MONTH(B3),1),15)+14) | AJ7: =IF(N(B3)=0,"",EDATE(DATE(YEAR(B3),MONTH(B3),1),16)-1) | AK7: =IF(N(B3)=0,"",EDATE(DATE(YEAR(B3),MONTH(B3),1),16)+14) | AL7: =IF(N(B3)=0,"",EDATE(DATE(YEAR(B3),MONTH(B3),1),17)-1) | AM7: =IF(N(B3)=0,"",EDATE(DATE(YEAR(B3),MONTH(B3),1),17)+14) | AN7: =IF(N(B3)=0,"",EDATE(DATE(YEAR(B3),MONTH(B3),1),18)-1)
A8: 바탕처리 · 청소 | B8: 46113 | C8: 46132 | D8: =IF(OR(N(B8)=0,N(C8)=0),"",IF(C8<B8,"⚠",C8-B8+1))
A9: 시멘트 액체방수(바닥) | B9: 46128 | C9: 46162 | D9: =IF(OR(N(B9)=0,N(C9)=0),"",IF(C9<B9,"⚠",C9-B9+1))
A10: 시멘트 액체방수(벽) | B10: 46143 | C10: 46173 | D10: =IF(OR(N(B10)=0,N(C10)=0),"",IF(C10<B10,"⚠",C10-B10+1))
A11: 규산질계 침투성방수 | B11: 46158 | C11: 46203 | D11: =IF(OR(N(B11)=0,N(C11)=0),"",IF(C11<B11,"⚠",C11-B11+1))
A12: 아스팔트 프라이머 · 보호재 | B12: 46174 | C12: 46203 | D12: =IF(OR(N(B12)=0,N(C12)=0),"",IF(C12<B12,"⚠",C12-B12+1))
A13: 담수시험 | B13: 46189 | C13: 46218 | D13: =IF(OR(N(B13)=0,N(C13)=0),"",IF(C13<B13,"⚠",C13-B13+1))
A14: 보호몰탈 · 마무리 | B14: 46204 | C14: 46234 | D14: =IF(OR(N(B14)=0,N(C14)=0),"",IF(C14<B14,"⚠",C14-B14+1))
A15: 검측 · 정리 | B15: 46219 | C15: 46248 | D15: =IF(OR(N(B15)=0,N(C15)=0),"",IF(C15<B15,"⚠",C15-B15+1))
D16: =IF(OR(N(B16)=0,N(C16)=0),"",IF(C16<B16,"⚠",C16-B16+1))
D17: =IF(OR(N(B17)=0,N(C17)=0),"",IF(C17<B17,"⚠",C17-B17+1))
D18: =IF(OR(N(B18)=0,N(C18)=0),"",IF(C18<B18,"⚠",C18-B18+1))
D19: =IF(OR(N(B19)=0,N(C19)=0),"",IF(C19<B19,"⚠",C19-B19+1))
D20: =IF(OR(N(B20)=0,N(C20)=0),"",IF(C20<B20,"⚠",C20-B20+1))
D21: =IF(OR(N(B21)=0,N(C21)=0),"",IF(C21<B21,"⚠",C21-B21+1))
A22: ※ 일수 = 완료 − 착수 + 1. 막대는 반달(1~15일 · 16일~말일) 단위입니다. 공정은 현장 여건 · 날씨에 따라 바뀔 수 있습니다.
A24: 이 시트는 작성 예시입니다(가상의 일정).

Sheet 예시-관리계획
A1: K-건설맵 | k-conmap.com 건설 서식 | G1: 작성 예시 (가상의 현장)
A3: 8.0 품 질 관 리 계 획
A6: 8-1 품질관리 일반 및 적용범위
A7: (1) | B7: 공사 진행 중 필요에 따라 각종 승인도면 · 제작도면 · 제작요령서 등을 작성하여 공사감독자(감리원)의 승인을 받는다.
A8: (2) | B8: 공사용 재료는 도면 · 공사시방서 및 공사감독자의 지시에 따라, 쓰기 전에 견본 또는 자료를 제출하여 승인을 받은 뒤 쓴다.
A9: (3) | B9: 품질시험은 「건설기술 진흥법」 및 같은 법 시행령 · 시행규칙과 공사시방서에서 정한 바에 따른다.
A11: 8-2 공사용 재료의 품질
A12: (1) | B12: 설계도면 · 공사시방서 및 공사감독자의 따로 지시가 없으면 시방서에서 정한 품질과 규격에 맞는 재료를 쓴다.
A13: (2) | B13: 시방서에 품질 규격이 없으면 한국산업표준(KS) 표시품 또는 이에 준하는 품질과 규격의 재료를 쓴다.
A14: (3) | B14: 기성품을 포함한 공사용 재료는 현장 반입 전에 자재승인 서류(견본 · 카탈로그 · 시험성적서 등)를 제출하여 승인을 받고, 공사감독자의 지시에 따라 품질을 확인할 수 있는 증빙서류를 낸다.
A15: (4) | B15: 재료가 현장에 들어오면 공사감독자의 인수검사를 받고, 합격한 재료는 작업 · 통행에 지장이 없는 곳에 보관하여 수시 점검이 쉽게 한다.
A16: (5) | B16: 「건설기술 진흥법」에 규정된 품질시험을 하고, 시험실 규모 · 시험장비 · 시험요원 배치기준에 따라 시험실을 운영한다.
A17: (6) | B17: 검사 또는 시험에 불합격한 재료는 지체 없이 현장 밖으로 반출한다.
A19: 8-3 시공 확인 및 검사
A20: (1) | B20: 주요 공사단계가 끝났을 때나 공사감독자가 지시할 때는 시공의 정확성과 품질을 확인받는다.
A21: (2) | B21: 검사에 필요한 자료 작성 · 측량 등은 검사자의 지시에 따른다.
A23: 8-4 자재관리
A24: (1) | B24: 들어온 자재는 자재수불대장으로 입 · 출고를 관리한다.
A25: (2) | B25: 자재는 재질별 · 규격별로 나누어 보관한다.
A26: (3) | B26: 운반 · 야적 때 변형되지 않도록 전용 운반 가설대 또는 전용 야적대를 쓴다.
A27: (4) | B27: 반입 자재는 받침목 · 지지목 등으로 지면에서 200mm 이상 띄우고 손상 · 변형 · 침수되지 않게 한다.
A28: (5) | B28: 변형을 막기 위해 받침목 높이를 맞추고 1단 적재를 기본으로 한다.
A30: 9.0 환 경 관 리 계 획
A33: 9-1 개 요
A34: 현장의 폐기물 · 유류 · 쓰레기 및 소음 · 진동 · 비산먼지 등에 의한 오염을 방지한다.
A36: 9-2 중점관리 방침
A37: (1) | B37: 자율적인 환경관리
A38: (2) | B38: 쾌적한 작업환경 관리
A39: (3) | B39: 민원 발생 방지
A41: 9-3 실시계획
A42: (1) | B42: 작업 전후 정리정돈 : 작업 전후 정리정돈을 철저히 하여 쾌적한 작업환경을 유지한다.
A43: (2) | B43: 분리수거 : 분리수거를 철저히 하고, 방수 작업에서 나온 폐기물(빈 용기 · 잔재 등)은 시공업체 부담으로 적법하게 처리하여 쓰레기를 줄인다.
A44: (3) | B44: 민원 발생 억제 : 소음 · 진동 · 비산먼지 · 냄새를 최대한 억제하여 인근 주민의 생활에 피해가 없도록 하고, 적극적으로 환경관리 활동을 한다.
B45: (4) 환경관리 대책
A46: ① | C46: 쓰레기 처리 : 현장 안은 금연하고 쓰레기 수거함을 둔다.
A47: ② | C47: 잔재물 · 빈 용기 : 방수재 잔재와 빈 용기(프라이머 · 용제 용기 포함)는 지정된 장소에 모아 두고 지정 업체가 수거하게 한다.
A48: ③ | C48: 비산먼지 : 현장 안 주요 도로와 작업장 주변은 하루 2회 이상 살수차로 살수하고, 장비 이동 때 먼지가 나지 않도록 서행한다.
A50: 10.0 안 전 관 리 계 획
A53: 10-1 안전관리 목적
A54: 공종의 특수성을 고려하여 현장의 위험요소를 미리 없애 사고를 막음으로써 귀중한 인명을 보호하고 재산 손실을 최소화하며, 작업 능률을 높여 계획 공정을 원만히 달성하는 데 목적이 있다.
...
