Workbook

Sheet 표지
A1: K-건설맵 | k-conmap.com 건설 서식 | G1: ← 이 1행을 지우고 쓰셔도 됩니다
A3: (공 사 명)
A5: 시 공 계 획 서
A6: [ 도장공사 ]
A8: 20 . .
A10: (회 사 명)
A12: 공사명 · 작성 연월(2026-03 처럼) · 회사명을 여기 한 번만 적으면 뒤 장에 저절로 들어갑니다.

Sheet 개요
A1: K-건설맵 | k-conmap.com 건설 서식 | G1: ← 이 1행을 지우고 쓰셔도 됩니다
A3: 목 차
C5: 1. 공 사 개 요
C6: 2. 예 정 공 정 표
C7: 3. 현 장 조 직 도
C8: 4. 기능인력 투입계획 및 주자재 조달계획
C9: 5. 시 공 관 리
C10: 6. 검측 FLOW CHART · 검측 체크리스트
C11: 7. 품 질 관 리 계 획
C12: 8. 환 경 관 리 계 획
C13: 9. 안 전 관 리 계 획
A15: 1.0 공 사 개 요
A17: 공 사 명 | D17: =IF(OR('표지'!A3="",'표지'!A3="(공 사 명)"),"",'표지'!A3)
A18: 1) 공사목적
A19: =" 이 공사의 목적은 "&IF(D17="","본 공사",D17)&"의 도장공사를 하기 전에 공사계획을 철저히 세워 예상되는 문제를 최소화하고, 공정표에 따라 인원과 자재를 원활히 수급하며, 품질기준과 안전기준을 마련하여 도장공사를 성공적으로 수행하는 데 있다."
A20: 2) 공사기간
A21: 공 사 기 간 | F21: ~ | I21: =IF(OR(N(D21)=0,N(G21)=0),"",IF(G21<D21,"⚠ 준공일이 착공일보다 빠름",G21-D21+1))
A22: 시 공 사 | D22: =IF(OR('표지'!A10="",'표지'!A10="(회 사 명)"),"",'표지'!A10)
A23: 3) 공사내역
A24: 구 분 | C24: 공 종 | F24: 규 격 | H24: 단위 | I24: 수 량 | K24: 비 고
A37: 합 계 (단위가 ㎡ 인 줄) | H37: ㎡ | I37: =IF(SUMIF(H25:H36,"㎡",I25:I36)+SUMIF(H25:H36,"m2",I25:I36)=0,"",SUMIF(H25:H36,"㎡",I25:I36)+SUMIF(H25:H36,"m2",I25:I36))
A39: 하늘색 칸 = 자동(공사명 · 공사목적 글 · 공사기간 일수 · ㎡ 합계).

Sheet 공정표
A1: K-건설맵 | k-conmap.com 건설 서식 | N1: ← 이 1행을 지우고 쓰셔도 됩니다
A2: 2.0 예 정 공 정 표
A3: 착 공 일 | B3: =IF(N('개요'!D21)=0,"",'개요'!D21) | D3: ※ 착공일은 공사개요에서 따라옵니다. 공종마다 착수 · 완료일을 적으면 반달 칸에 막대가 그려집니다.
A4: 공 종 | B4: 착 수 | C4: 완 료 | D4: 일 수 | E4: =IF(N(B3)=0,"",EDATE(DATE(YEAR(B3),MONTH(B3),1),0)) | G4: =IF(N(B3)=0,"",EDATE(DATE(YEAR(B3),MONTH(B3),1),1)) | I4: =IF(N(B3)=0,"",EDATE(DATE(YEAR(B3),MONTH(B3),1),2)) | K4: =IF(N(B3)=0,"",EDATE(DATE(YEAR(B3),MONTH(B3),1),3)) | M4: =IF(N(B3)=0,"",EDATE(DATE(YEAR(B3),MONTH(B3),1),4)) | O4: =IF(N(B3)=0,"",EDATE(DATE(YEAR(B3),MONTH(B3),1),5)) | Q4: =IF(N(B3)=0,"",EDATE(DATE(YEAR(B3),MONTH(B3),1),6)) | S4: =IF(N(B3)=0,"",EDATE(DATE(YEAR(B3),MONTH(B3),1),7)) | U4: =IF(N(B3)=0,"",EDATE(DATE(YEAR(B3),MONTH(B3),1),8)) | W4: =IF(N(B3)=0,"",EDATE(DATE(YEAR(B3),MONTH(B3),1),9)) | Y4: =IF(N(B3)=0,"",EDATE(DATE(YEAR(B3),MONTH(B3),1),10)) | AA4: =IF(N(B3)=0,"",EDATE(DATE(YEAR(B3),MONTH(B3),1),11)) | AC4: =IF(N(B3)=0,"",EDATE(DATE(YEAR(B3),MONTH(B3),1),12)) | AE4: =IF(N(B3)=0,"",EDATE(DATE(YEAR(B3),MONTH(B3),1),13)) | AG4: =IF(N(B3)=0,"",EDATE(DATE(YEAR(B3),MONTH(B3),1),14)) | AI4: =IF(N(B3)=0,"",EDATE(DATE(YEAR(B3),MONTH(B3),1),15)) | AK4: =IF(N(B3)=0,"",EDATE(DATE(YEAR(B3),MONTH(B3),1),16)) | AM4: =IF(N(B3)=0,"",EDATE(DATE(YEAR(B3),MONTH(B3),1),17)) | AO4: 비 고
E5: 상 | F5: 하 | G5: 상 | H5: 하 | I5: 상 | J5: 하 | K5: 상 | L5: 하 | M5: 상 | N5: 하 | O5: 상 | P5: 하 | Q5: 상 | R5: 하 | S5: 상 | T5: 하 | U5: 상 | V5: 하 | W5: 상 | X5: 하 | Y5: 상 | Z5: 하 | AA5: 상 | AB5: 하 | AC5: 상 | AD5: 하 | AE5: 상 | AF5: 하 | AG5: 상 | AH5: 하 | AI5: 상 | AJ5: 하 | AK5: 상 | AL5: 하 | AM5: 상 | AN5: 하
E6: =IF(N(B3)=0,"",EDATE(DATE(YEAR(B3),MONTH(B3),1),0)) | F6: =IF(N(B3)=0,"",EDATE(DATE(YEAR(B3),MONTH(B3),1),0)+15) | G6: =IF(N(B3)=0,"",EDATE(DATE(YEAR(B3),MONTH(B3),1),1)) | H6: =IF(N(B3)=0,"",EDATE(DATE(YEAR(B3),MONTH(B3),1),1)+15) | I6: =IF(N(B3)=0,"",EDATE(DATE(YEAR(B3),MONTH(B3),1),2)) | J6: =IF(N(B3)=0,"",EDATE(DATE(YEAR(B3),MONTH(B3),1),2)+15) | K6: =IF(N(B3)=0,"",EDATE(DATE(YEAR(B3),MONTH(B3),1),3)) | L6: =IF(N(B3)=0,"",EDATE(DATE(YEAR(B3),MONTH(B3),1),3)+15) | M6: =IF(N(B3)=0,"",EDATE(DATE(YEAR(B3),MONTH(B3),1),4)) | N6: =IF(N(B3)=0,"",EDATE(DATE(YEAR(B3),MONTH(B3),1),4)+15) | O6: =IF(N(B3)=0,"",EDATE(DATE(YEAR(B3),MONTH(B3),1),5)) | P6: =IF(N(B3)=0,"",EDATE(DATE(YEAR(B3),MONTH(B3),1),5)+15) | Q6: =IF(N(B3)=0,"",EDATE(DATE(YEAR(B3),MONTH(B3),1),6)) | R6: =IF(N(B3)=0,"",EDATE(DATE(YEAR(B3),MONTH(B3),1),6)+15) | S6: =IF(N(B3)=0,"",EDATE(DATE(YEAR(B3),MONTH(B3),1),7)) | T6: =IF(N(B3)=0,"",EDATE(DATE(YEAR(B3),MONTH(B3),1),7)+15) | U6: =IF(N(B3)=0,"",EDATE(DATE(YEAR(B3),MONTH(B3),1),8)) | V6: =IF(N(B3)=0,"",EDATE(DATE(YEAR(B3),MONTH(B3),1),8)+15) | W6: =IF(N(B3)=0,"",EDATE(DATE(YEAR(B3),MONTH(B3),1),9)) | X6: =IF(N(B3)=0,"",EDATE(DATE(YEAR(B3),MONTH(B3),1),9)+15) | Y6: =IF(N(B3)=0,"",EDATE(DATE(YEAR(B3),MONTH(B3),1),10)) | Z6: =IF(N(B3)=0,"",EDATE(DATE(YEAR(B3),MONTH(B3),1),10)+15) | AA6: =IF(N(B3)=0,"",EDATE(DATE(YEAR(B3),MONTH(B3),1),11)) | AB6: =IF(N(B3)=0,"",EDATE(DATE(YEAR(B3),MONTH(B3),1),11)+15) | AC6: =IF(N(B3)=0,"",EDATE(DATE(YEAR(B3),MONTH(B3),1),12)) | AD6: =IF(N(B3)=0,"",EDATE(DATE(YEAR(B3),MONTH(B3),1),12)+15) | AE6: =IF(N(B3)=0,"",EDATE(DATE(YEAR(B3),MONTH(B3),1),13)) | AF6: =IF(N(B3)=0,"",EDATE(DATE(YEAR(B3),MONTH(B3),1),13)+15) | AG6: =IF(N(B3)=0,"",EDATE(DATE(YEAR(B3),MONTH(B3),1),14)) | AH6: =IF(N(B3)=0,"",EDATE(DATE(YEAR(B3),MONTH(B3),1),14)+15) | AI6: =IF(N(B3)=0,"",EDATE(DATE(YEAR(B3),MONTH(B3),1),15)) | AJ6: =IF(N(B3)=0,"",EDATE(DATE(YEAR(B3),MONTH(B3),1),15)+15) | AK6: =IF(N(B3)=0,"",EDATE(DATE(YEAR(B3),MONTH(B3),1),16)) | AL6: =IF(N(B3)=0,"",EDATE(DATE(YEAR(B3),MONTH(B3),1),16)+15) | AM6: =IF(N(B3)=0,"",EDATE(DATE(YEAR(B3),MONTH(B3),1),17)) | AN6: =IF(N(B3)=0,"",EDATE(DATE(YEAR(B3),MONTH(B3),1),17)+15)
E7: =IF(N(B3)=0,"",EDATE(DATE(YEAR(B3),MONTH(B3),1),0)+14) | F7: =IF(N(B3)=0,"",EDATE(DATE(YEAR(B3),MONTH(B3),1),1)-1) | G7: =IF(N(B3)=0,"",EDATE(DATE(YEAR(B3),MONTH(B3),1),1)+14) | H7: =IF(N(B3)=0,"",EDATE(DATE(YEAR(B3),MONTH(B3),1),2)-1) | I7: =IF(N(B3)=0,"",EDATE(DATE(YEAR(B3),MONTH(B3),1),2)+14) | J7: =IF(N(B3)=0,"",EDATE(DATE(YEAR(B3),MONTH(B3),1),3)-1) | K7: =IF(N(B3)=0,"",EDATE(DATE(YEAR(B3),MONTH(B3),1),3)+14) | L7: =IF(N(B3)=0,"",EDATE(DATE(YEAR(B3),MONTH(B3),1),4)-1) | M7: =IF(N(B3)=0,"",EDATE(DATE(YEAR(B3),MONTH(B3),1),4)+14) | N7: =IF(N(B3)=0,"",EDATE(DATE(YEAR(B3),MONTH(B3),1),5)-1) | O7: =IF(N(B3)=0,"",EDATE(DATE(YEAR(B3),MONTH(B3),1),5)+14) | P7: =IF(N(B3)=0,"",EDATE(DATE(YEAR(B3),MONTH(B3),1),6)-1) | Q7: =IF(N(B3)=0,"",EDATE(DATE(YEAR(B3),MONTH(B3),1),6)+14) | R7: =IF(N(B3)=0,"",EDATE(DATE(YEAR(B3),MONTH(B3),1),7)-1) | S7: =IF(N(B3)=0,"",EDATE(DATE(YEAR(B3),MONTH(B3),1),7)+14) | T7: =IF(N(B3)=0,"",EDATE(DATE(YEAR(B3),MONTH(B3),1),8)-1) | U7: =IF(N(B3)=0,"",EDATE(DATE(YEAR(B3),MONTH(B3),1),8)+14) | V7: =IF(N(B3)=0,"",EDATE(DATE(YEAR(B3),MONTH(B3),1),9)-1) | W7: =IF(N(B3)=0,"",EDATE(DATE(YEAR(B3),MONTH(B3),1),9)+14) | X7: =IF(N(B3)=0,"",EDATE(DATE(YEAR(B3),MONTH(B3),1),10)-1) | Y7: =IF(N(B3)=0,"",EDATE(DATE(YEAR(B3),MONTH(B3),1),10)+14) | Z7: =IF(N(B3)=0,"",EDATE(DATE(YEAR(B3),MONTH(B3),1),11)-1) | AA7: =IF(N(B3)=0,"",EDATE(DATE(YEAR(B3),MONTH(B3),1),11)+14) | AB7: =IF(N(B3)=0,"",EDATE(DATE(YEAR(B3),MONTH(B3),1),12)-1) | AC7: =IF(N(B3)=0,"",EDATE(DATE(YEAR(B3),MONTH(B3),1),12)+14) | AD7: =IF(N(B3)=0,"",EDATE(DATE(YEAR(B3),MONTH(B3),1),13)-1) | AE7: =IF(N(B3)=0,"",EDATE(DATE(YEAR(B3),MONTH(B3),1),13)+14) | AF7: =IF(N(B3)=0,"",EDATE(DATE(YEAR(B3),MONTH(B3),1),14)-1) | AG7: =IF(N(B3)=0,"",EDATE(DATE(YEAR(B3),MONTH(B3),1),14)+14) | AH7: =IF(N(B3)=0,"",EDATE(DATE(YEAR(B3),MONTH(B3),1),15)-1) | AI7: =IF(N(B3)=0,"",EDATE(DATE(YEAR(B3),MONTH(B3),1),15)+14) | AJ7: =IF(N(B3)=0,"",EDATE(DATE(YEAR(B3),MONTH(B3),1),16)-1) | AK7: =IF(N(B3)=0,"",EDATE(DATE(YEAR(B3),MONTH(B3),1),16)+14) | AL7: =IF(N(B3)=0,"",EDATE(DATE(YEAR(B3),MONTH(B3),1),17)-1) | AM7: =IF(N(B3)=0,"",EDATE(DATE(YEAR(B3),MONTH(B3),1),17)+14) | AN7: =IF(N(B3)=0,"",EDATE(DATE(YEAR(B3),MONTH(B3),1),18)-1)
A8: 바탕 만들기 · 퍼티 | D8: =IF(OR(N(B8)=0,N(C8)=0),"",IF(C8<B8,"⚠",C8-B8+1))
A9: 내부 수성페인트 초벌 | D9: =IF(OR(N(B9)=0,N(C9)=0),"",IF(C9<B9,"⚠",C9-B9+1))
A10: 내부 수성페인트 재벌 · 정벌 | D10: =IF(OR(N(B10)=0,N(C10)=0),"",IF(C10<B10,"⚠",C10-B10+1))
A11: 외부 수성페인트 | D11: =IF(OR(N(B11)=0,N(C11)=0),"",IF(C11<B11,"⚠",C11-B11+1))
A12: 걸레받이 세라믹 페인트 | D12: =IF(OR(N(B12)=0,N(C12)=0),"",IF(C12<B12,"⚠",C12-B12+1))
A13: 에폭시 코팅 · 라이닝(바닥) | D13: =IF(OR(N(B13)=0,N(C13)=0),"",IF(C13<B13,"⚠",C13-B13+1))
A14: 보수 · 보양 · 청소 | D14: =IF(OR(N(B14)=0,N(C14)=0),"",IF(C14<B14,"⚠",C14-B14+1))
A15: 검측 · 정리 | D15: =IF(OR(N(B15)=0,N(C15)=0),"",IF(C15<B15,"⚠",C15-B15+1))
D16: =IF(OR(N(B16)=0,N(C16)=0),"",IF(C16<B16,"⚠",C16-B16+1))
D17: =IF(OR(N(B17)=0,N(C17)=0),"",IF(C17<B17,"⚠",C17-B17+1))
D18: =IF(OR(N(B18)=0,N(C18)=0),"",IF(C18<B18,"⚠",C18-B18+1))
D19: =IF(OR(N(B19)=0,N(C19)=0),"",IF(C19<B19,"⚠",C19-B19+1))
D20: =IF(OR(N(B20)=0,N(C20)=0),"",IF(C20<B20,"⚠",C20-B20+1))
D21: =IF(OR(N(B21)=0,N(C21)=0),"",IF(C21<B21,"⚠",C21-B21+1))
A22: ※ 일수 = 완료 − 착수 + 1. 막대는 반달(1~15일 · 16일~말일) 단위입니다. 공정은 현장 여건 · 날씨에 따라 바뀔 수 있습니다.
A24: 하늘색 칸 = 자동(착공일 · 달 머리 · 일수). 공종 이름은 원본 차례를 미리 넣어 두었습니다 — 현장에 맞게 고쳐 쓰세요.

Sheet 조직
A1: K-건설맵 | k-conmap.com 건설 서식 | G1: ← 이 1행을 지우고 쓰셔도 됩니다
A3: 3.0 현 장 조 직 도
E5: 현 장 대 리 인
A7: │
B8: 품 질 관 리 자 | F8: ─┼─ | H8: 안 전 관 리 자
F9: │
A10: │
E11: 시 공 업 체
A13: │
E14: 작 업 팀 장
A16: ┌──────────┼──────────┐
A17: 도장공 | D17: 특별인부 | G17: 보통인부 | J17: 합 계
A18: 3 | D18: 1 | G18: 1 | J18: =IF(SUM(A18,D18,G18)=0,"",SUM(A18,D18,G18))
A20: 4.0 기능인력 투입계획 및 주자재 조달계획
A22: 1) 기능 인력(현장 여건에 따라 작업 인원 변동) — 1일 투입인원(2개조)
A23: 구 분 | E23: 단 위 | G23: 수 량 | I23: 비 고
A24: 공사관리자 | E24: 인 | G24: 1
A25: 도장공 | E25: 인 | G25: 3
A26: 특별인부 및 조공 | E26: 인 | G26: 2
A27: 계 | E27: 인 | G27: =IF(SUM(G24,G25,G26)=0,"",SUM(G24,G25,G26))
A28: ※ 작업 수량에 따라 변동됩니다.
A29: 2) 주자재 조달계획
A30: 자 재 명 | E30: 수 량 | G30: 단위 | H30: 현장반입 예정일자 | J30: 비 고
J31: =IF(OR(N(H31)=0,N('개요'!D21)=0),"",IF(H31<'개요'!D21,"⚠ 착공 전 반입","착공 후 "&(H31-'개요'!D21)&"일"))
J32: =IF(OR(N(H32)=0,N('개요'!D21)=0),"",IF(H32<'개요'!D21,"⚠ 착공 전 반입","착공 후 "&(H32-'개요'!D21)&"일"))
J33: =IF(OR(N(H33)=0,N('개요'!D21)=0),"",IF(H33<'개요'!D21,"⚠ 착공 전 반입","착공 후 "&(H33-'개요'!D21)&"일"))
J34: =IF(OR(N(H34)=0,N('개요'!D21)=0),"",IF(H34<'개요'!D21,"⚠ 착공 전 반입","착공 후 "&(H34-'개요'!D21)&"일"))
J35: =IF(OR(N(H35)=0,N('개요'!D21)=0),"",IF(H35<'개요'!D21,"⚠ 착공 전 반입","착공 후 "&(H35-'개요'!D21)&"일"))
J36: =IF(OR(N(H36)=0,N('개요'!D21)=0),"",IF(H36<'개요'!D21,"⚠ 착공 전 반입","착공 후 "&(H36-'개요'!D21)&"일"))
J37: =IF(OR(N(H37)=0,N('개요'!D21)=0),"",IF(H37<'개요'!D21,"⚠ 착공 전 반입","착공 후 "&(H37-'개요'!D21)&"일"))
J38: =IF(OR(N(H38)=0,N('개요'!D21)=0),"",IF(H38<'개요'!D21,"⚠ 착공 전 반입","착공 후 "&(H38-'개요'!D21)&"일"))
J39: =IF(OR(N(H39)=0,N('개요'!D21)=0),"",IF(H39<'개요'!D21,"⚠ 착공 전 반입","착공 후 "&(H39-'개요'!D21)&"일"))
J40: =IF(OR(N(H40)=0,N('개요'!D21)=0),"",IF(H40<'개요'!D21,"⚠ 착공 전 반입","착공 후 "&(H40-'개요'!D21)&"일"))
A42: 하늘색 칸 = 자동(인원 합계 · 기능인력 계 · 반입 시점 — 착공일 기준). 인원은 원본 계획서 인원을 넣어 두었습니다.

Sheet 시공관리
A1: K-건설맵 | k-conmap.com 건설 서식 | G1: ← 이 1행을 지우고 쓰셔도 됩니다
A3: 5.0 시 공 관 리
A6: 5-1 일반사항
A7: 1) 운반 · 보관 및 취급
A8: (1) | B8: 도장재는 밀봉된 용기에 넣어 개봉하지 않은 상태로 반입하고, 용기에는 도장재의 종류 · 색상 · 수량 · 제조일자 · 제조일련번호 · 상표 · 사용상 주의사항 · 바탕 준비사항 · 건조시간 · 배합에 관한 제조업자의 지침이 적혀 있어야 한다.
A9: (2) | B9: 도장재의 반입 시기는 공사기간 외에 품질시험에 걸리는 기간을 고려하여 정한다.
A10: (3) | B10: 가연성 도료는 전용 창고에 보관하는 것을 원칙으로 하며, 반입한 도료와 사용 중인 도료는 공사감독자가 승인한 창고에 보관하고 도료창고에 «화기 엄금» 표시를 한다.
A11: (4) | B11: 도료창고는 특히 화재에 주의하고, 창고 안과 주변에서 화기 사용을 엄금한다.
A12: (5) | B12: 도료는 될 수 있는 대로 밀봉하여 새거나 엎지르지 않게 다루고, 샌 것이나 엎지른 것은 발화 위험이 없도록 닦아 낸다.
A13: 2) 환경 요구사항
A14: (1) | B14: 도장 작업 중이나 도료 건조기간 중, 도장 장소의 환경 · 기상 조건이 아래와 같아 좋은 결과를 기대할 수 없으면 공사감독자가 승인할 때까지 도장하지 않는다.
A15: (2) | B15: 기온이 낮거나 습도가 높고 환기가 충분하지 않아 건조가 부적당할 때, 주위 기온이 5℃ 미만이거나 상대습도가 85% 를 넘을 때, 눈 · 비가 올 때 및 안개가 끼었을 때. 다만 재료 제조업자의 시방서에 따로 표시한 경우는 예외로 한다.
A17: 5-2 재료
A18: 1) 도장재의 일반 조건
A19: (1) | B19: 도장재료는 한국산업표준(KS)에서 정한 규격에 합격한 것을 쓴다.
A20: (2) | B20: 도료는 상표가 완전하고 개봉하지 않은 채로 현장에 반입하여 KS 표시 여부 · 규격번호 · 품명 · 종별 · 제조연월일 · 포장 번호 및 수량 · 구성성분(안료 · 용제) · 희석방법 · 색명 및 번호 등을 확인받는다.
A21: (3) | B21: 현장에서 쓰는 도장재는 종류별로 한 제조업자의 제품을 쓴다.
A22: (4) | B22: 공장에서 배합이 끝난 제품을 쓰며, 현장 희석은 제조업자가 인정하는 범위에서 한다.
A23: (5) | B23: 상도 · 중도 · 하도의 도막 색상은 서로 다르게 하며, 상도 후 마감 상태가 요구 기준에 맞아야 한다.
A24: 2) 합성수지 에멀션 페인트
A25: (1) | B25: 외부 수성페인트 — KS M 5310 의 1급에 맞는 합성수지 에멀션 페인트(외부용)로 한다. 도면 · 공사시방에 발수용 외부 수성페인트를 쓰도록 명시한 경우에는 KS M 5310 1급 제품으로서 KS M 7057 발수도 시험 결과 R7 이상인 제품으로 하며, 시험편은 KS M 5310 에 따라 만든 시편 5매로 한다.
A26: (2) | B26: 내부 수성페인트 — KS M 5320 의 1급에 맞는 합성수지 에멀션 페인트(내부용)로 한다.
A27: (3) | B27: 광택 합성수지 에멀션 페인트 — 광택 합성수지 에멀션 페인트 규정에 합격한 재료로 한다.
A28: 3) 바닥재 도료칠
A29: (1) | B29: 코팅형 에폭시 바닥재 — 품질은 승인된 제조업자의 품질자료에 따른다.
A30: (2) | B30: 아크릴 수지 에나멜 바닥재 — 품질은 승인된 제조업자의 품질자료에 따른다.
A32: 5-3 시공
A33: 1) 바탕 만들기(면처리)
A34: 각종 도료를 칠하기 전에 바탕 만들기(면처리 · 바탕조정 · 바탕처리 등)를 한다.
A35: 2) 일반 조건
A36: (1) | B36: 칠 바탕면은 칠이나 표면처리를 하기 전에 녹 · 해로운 부착물(먼지 · 기름 · 타르분 · 회반죽 · 플라스터 · 시멘트 · 모르타르)과 노화가 심한 구도막을 완전히 없애고 깨끗이 청소한다.
A37: (2) | B37: 못머리 등 금속이 바탕면에 드러난 곳은 상부 칠 종류에 맞는 녹 방지 조치를 따로 한다.
A38: (3) | B38: 칠할 부위에 붙은 비도장 부위는 바탕정리나 칠하기 전에 보양재를 덮어 도료가 묻지 않게 한다. 특히 실내에서는 벽 · 바닥 · 인접 시설에 묻지 않도록 비닐 · 신문지 등으로 보양한다.
A39: (4) | B39: 면의 결점(홈 · 구멍 · 갈라짐 · 변형 · 옹이 · 흡수성이 고르지 않은 곳 등)을 보수하여 칠하기 좋은 상태로 한다.
A40: (5) | B40: 배어 나오기 · 녹아 나오기 등에 의한 해로운 물질(수분 · 기름 · 수지 · 산 · 알칼리 등)의 작용을 막는 처리를 한다.
A41: (6) | B41: 색상 · 재질이 다른 칠이 만나는 경계는 경계선이 곧도록 테이핑 작업을 한다.
A42: (7) | B42: 도장재와 바탕 종류에 따라 따로 표면처리가 필요하면 도료 제조업자의 지침에 따라 바탕처리를 한다.
A43: 3) 바탕 만들기 공법
A44: 바탕 만들기 공정의 종별(바탕 종류 · 공법)은 아래에 따르며, 종별 지시가 없으면 철재면 3종, 아연도금면 2종 또는 3종, 경금속 및 동합금면 2종으로 한다. 다만 비닐계 에나멜 도장일 때는 철재면 2종, 아연도금면 1종으로 하고, 100℃ 이상에서 건조시키는 공업용 도장은 1종(인산염 처리)으로 한다.
A45: [ 바탕 만들기의 도장 종별 ]
...

Sheet 검측체크
A1: K-건설맵 | k-conmap.com 건설 서식 | G1: ← 이 1행을 지우고 쓰셔도 됩니다
A2: 검 측 체 크 리 스 트
A3: 공종 CODE NO. | E3: 도 장 공 사 | G3: 위치 및 부위
A4: 공종(세부공종) | C4: 공통사항 | G4: 검 측 일 자
A5: 검 사 항 목 | F5: 검 사 기 준 (시방서 · 도면 등) | H5: 검 사 결 과 | L5: 조치 사항
H6: 1 차 | J6: 2 차
H7: 합격 | I7: 불합격 | J7: 합격 | K7: 불합격
A8: 1. 자재공급원 승인은 되었는가 | F8: 승인 여부
A9: 2. 바탕처리는 적정한가(레이턴스 · 먼지 · 오염 제거 등) | F9: 적 · 부
A10: 3. 구조체 곰보 · 이음 조인트 · 균열 · 재료분리 등의 조치는 적정한가 | F10: 적 · 부
A11: 4. 재료의 종류 · 규격 · 품질보증서 등은 확인하였는가 | F11: 적 · 부
A12: 5. 바탕면이 충분히 건조(함수율 5% 이하)되었는가 | F12: 적 · 부
A13: 6. 다른 부위가 오염되지 않게 조치하였는가 | F13: 적 · 부
A14: 7. 재료의 보관 장소 및 보관 방법은 적정한가 | F14: 적 · 부
A15: 8. 시공 때 기온 5℃ 이하 · 습도 80% 이상이면 작업을 중단하고 있는가 | F15: 적 · 부
A16: 판 정 | D16: =IF(COUNTA(H8:H15)+COUNTA(I8:I15)=0,"","1차 합격 "&COUNTA(H8:H15)&" · 불합격 "&COUNTA(I8:I15)&IF(COUNTA(I8:I15)>0," / 2차 합격 "&COUNTA(J8:J15)&" · 불합격 "&COUNTA(K8:K15),"")&IF(COUNTA(H8:H15)+COUNTA(I8:I15)<8," · 빈칸 "&(8-COUNTA(H8:H15)-COUNTA(I8:I15)),"")&" → "&IF(COUNTA(I8:I15)=0,IF(COUNTA(H8:H15)+COUNTA(I8:I15)<8,"점검 중","합격"),IF(AND(COUNTA(K8:K15)=0,COUNTA(J8:J15)>=COUNTA(I8:I15)),"합격(재검측)","보완 후 재검측")))
A17: 시 공 자 점 검 | G17: 건 설 사 업 관 리 자 검 측
A18: 점 검 | D18: 재 점 검 | G18: 검 측 | J18: 재 검 측
A19: (인) | D19: (인) | G19: (인) | J19: (인)
A20: 검 측 체 크 리 스 트
A21: 공종 CODE NO. | E21: 도 장 공 사 | G21: 위치 및 부위
A22: 공종(세부공종) | C22: 수성페인트 | G22: 검 측 일 자
A23: 검 사 항 목 | F23: 검 사 기 준 (시방서 · 도면 등) | H23: 검 사 결 과 | L23: 조치 사항
H24: 1 차 | J24: 2 차
H25: 합격 | I25: 불합격 | J25: 합격 | K25: 불합격
A26: 1. 시공 때 온도는 적정한가 | F26: 적 · 부
A27: 2. 바탕처리는 적정한가(레이턴스 · 먼지 · 오염 제거 등) | F27: 적 · 부
A28: 3. 구조체 곰보 · 이음 조인트 · 균열 · 재료분리 등의 조치는 적정한가 | F28: 적 · 부
A29: 4. 재료의 종류 · 규격 · 품질보증서 등은 확인하였는가 | F29: 적 · 부
A30: 5. 환기 및 조명 설치는 충분한가 | F30: 적 · 부
A31: 6. 재료 배합은 적절한가 | F31: 적 · 부
A32: 7. 시공 절차를 지키는가 | F32: 적 · 부
A33: 8. 칠 두께는 고른가 | F33: 적 · 부
A34: 9. 시공 후 보양 대책은 세웠는가 | F34: 적 · 부
A35: 10. 정해진 색상을 쓰는가 | F35: 적 · 부
F36: 적 · 부
F37: 적 · 부
F38: 적 · 부
A39: 판 정 | D39: =IF(COUNTA(H26:H38)+COUNTA(I26:I38)=0,"","1차 합격 "&COUNTA(H26:H38)&" · 불합격 "&COUNTA(I26:I38)&IF(COUNTA(I26:I38)>0," / 2차 합격 "&COUNTA(J26:J38)&" · 불합격 "&COUNTA(K26:K38),"")&IF(COUNTA(H26:H38)+COUNTA(I26:I38)<13," · 빈칸 "&(13-COUNTA(H26:H38)-COUNTA(I26:I38)),"")&" → "&IF(COUNTA(I26:I38)=0,IF(COUNTA(H26:H38)+COUNTA(I26:I38)<13,"점검 중","합격"),IF(AND(COUNTA(K26:K38)=0,COUNTA(J26:J38)>=COUNTA(I26:I38)),"합격(재검측)","보완 후 재검측")))
A40: 시 공 자 점 검 | G40: 건 설 사 업 관 리 자 검 측
...

Sheet 관리계획
A1: K-건설맵 | k-conmap.com 건설 서식 | G1: ← 이 1행을 지우고 쓰셔도 됩니다
A3: 7.0 품 질 관 리 계 획
A6: 7-1 자재 관리
A7: 1) 적용범위
A8: 입고 자재가 취급 · 보관 등으로 품질이 손상되지 않도록 관리하는 업무에 적용한다.
A9: 2) 창고 구비 조건
A10: (1) | B10: 보관품은 알맞은 기준에 따라 품질에 변형을 주지 않는 장소에 둔다.
A11: (2) | B11: 야적장은 배수가 잘되고 주위에 위험요소가 없는 평탄한 곳으로 자재 운반이 쉬워야 하며, 밖에 두어도 품질 변화가 적은 자재만 보관한다.
A12: 3) 관리 방법
A13: (1) | B13: 보관품은 종류별 · 규격별로 반입 · 반출이 쉬운 상태로 보관하고, 포대 · 상자 또는 완전 포장된 것은 품명 · 수량 등을 적는다.
A14: (2) | B14: 롤(ROLL) 단위 시트류 — 습기 · 물기가 없는 지정 장소에 보관하고, 무게로 휘지 않게 야적량을 알맞게 하며, 세워서 규격별로 정리한다.
A15: (3) | B15: 캔류 — 파손 · 손상을 막기 위해 따로 구분 · 식별하여 관리하고, 다른 공정 작업자 등으로부터 피해를 받지 않게 하며, 찌그러지거나 터지지 않게 보관 · 운반하고, 포장재가 녹슬거나 라벨이 손상되지 않게 한다.
A16: (4) | B16: 그 밖의 자재 — 보관용 선반 · 전용 케이스 등을 이용하여 보관한다.
A18: 7-2 공정별 품질시험 계획
B19: (1) 시공 전 품질관리 — 자재 반입 검사(소요량 참조) · 바탕 상태 검사(바탕처리 후)
A20: [ 바탕 상태 검사 체크리스트 ]
A21: 공 정 | C21: 상 태 | G21: 확인 방법 | I21: 판 정 기 준
A22: 바탕처리 | C22: 거푸집 단차 및 돌기물 | G22: 육안검사 | I22: 높이 3mm 이하
C23: 거푸집 박리제 | G23: 육안검사 | I23: 없음
C24: 레이턴스 · 기름 · 먼지 등 | G24: 육안검사 | I24: 없음
C25: 균열 및 누수 부위 | G25: 육안 · 확대경 | I25: 없음 또는 보수 · 보강 처리되어 있을 것
C26: 나무조각 · 철사 · 종이류 | G26: 육안검사 | I26: 없음
C27: 취약 부위(골재분리 등) 충전 | G27: 육안검사 | I27: 취약 부위가 보강되어 있을 것
B28: (2) 시공 중 품질관리 — 공정별 도장 횟수 확인 · 재료 사용량 준수 여부 · 도장 부위의 하자 발생 여부
B29: (3) 시공 후 품질관리 — 도장 부위의 들뜸 · 손상 · 균열 · 얼룩 발생 여부 · 표면 상태 확인
A31: 8.0 환 경 관 리 계 획
A34: 8-1 개 요
A35: 현장의 폐기물 · 유류 · 쓰레기 및 소음 · 진동 · 비산먼지 등에 의한 오염을 방지한다.
A37: 8-2 중점관리 방침
A38: (1) | B38: 자율적인 환경관리
A39: (2) | B39: 쾌적한 작업환경 관리
A40: (3) | B40: 민원 발생 방지
A42: 8-3 실시계획
A43: (1) | B43: 작업 전후 정리정돈 : 작업 전후 정리정돈을 철저히 하여 쾌적한 작업환경을 유지한다.
A44: (2) | B44: 분리수거 : 분리수거를 철저히 하고, 도장 작업에서 나온 폐기물(빈 도료 용기 · 폐신너 · 걸레 등)은 시공업체 부담으로 적법하게 처리하여 쓰레기를 줄인다.
A45: (3) | B45: 민원 발생 억제 : 소음 · 진동 · 비산먼지 · 냄새를 최대한 억제하여 인근 주민의 생활에 피해가 없도록 하고, 적극적으로 환경관리 활동을 한다.
B46: (4) 환경관리 대책
A47: ① | C47: 쓰레기 처리 : 현장 안은 금연하고 쓰레기 수거함을 둔다.
A48: ② | C48: 잔재물 · 빈 용기 : 빈 도료 용기 · 폐신너 · 도료 묻은 걸레는 인화 위험이 없도록 뚜껑 있는 용기에 모아 지정 장소에 두고, 지정폐기물은 허가 업체에 위탁 처리한다.
A49: ③ | C49: 비산먼지 : 현장 안 주요 도로와 작업장 주변은 하루 2회 이상 살수차로 살수하고, 장비 이동 때 먼지가 나지 않도록 서행한다.
...

Sheet 예시-표지
A1: K-건설맵 | k-conmap.com 건설 서식 | G1: 작성 예시 (가상의 현장)
A3: 가나학교 교사 증축공사
A5: 시 공 계 획 서
A6: [ 도장공사 ]
A8: 46174
A10: 예시건설(주)
A12: 이 시트는 작성 예시입니다(가상의 공사 · 회사 · 사람).

Sheet 예시-개요
A1: K-건설맵 | k-conmap.com 건설 서식 | G1: 작성 예시 (가상의 현장)
A3: 목 차
C5: 1. 공 사 개 요
C6: 2. 예 정 공 정 표
C7: 3. 현 장 조 직 도
C8: 4. 기능인력 투입계획 및 주자재 조달계획
C9: 5. 시 공 관 리
C10: 6. 검측 FLOW CHART · 검측 체크리스트
C11: 7. 품 질 관 리 계 획
C12: 8. 환 경 관 리 계 획
C13: 9. 안 전 관 리 계 획
A15: 1.0 공 사 개 요
A17: 공 사 명 | D17: =IF(OR('예시-표지'!A3="",'예시-표지'!A3="(공 사 명)"),"",'예시-표지'!A3)
A18: 1) 공사목적
A19: =" 이 공사의 목적은 "&IF(D17="","본 공사",D17)&"의 도장공사를 하기 전에 공사계획을 철저히 세워 예상되는 문제를 최소화하고, 공정표에 따라 인원과 자재를 원활히 수급하며, 품질기준과 안전기준을 마련하여 도장공사를 성공적으로 수행하는 데 있다."
A20: 2) 공사기간
A21: 공 사 기 간 | D21: 46083 | F21: ~ | G21: 46387 | I21: =IF(OR(N(D21)=0,N(G21)=0),"",IF(G21<D21,"⚠ 준공일이 착공일보다 빠름",G21-D21+1))
A22: 시 공 사 | D22: =IF(OR('예시-표지'!A10="",'예시-표지'!A10="(회 사 명)"),"",'예시-표지'!A10)
A23: 3) 공사내역
A24: 구 분 | C24: 공 종 | F24: 규 격 | H24: 단위 | I24: 수 량 | K24: 비 고
A25: 교사동 | C25: 수성페인트(롤러칠) | F25: 내부 · 2회 · 친환경 | H25: ㎡ | I25: 2690
A26: 교사동 | C26: 수성페인트(롤러칠) | F26: 내부 석고보드면 · 2회 | H26: ㎡ | I26: 840
A27: 교사동 | C27: 수성페인트(롤러칠) | F27: 외부 · 2회 · 친환경 | H27: ㎡ | I27: 170
A28: 교사동 | C28: 세라믹 페인트(롤러칠) | F28: 걸레받이 | H28: ㎡ | I28: 75
A29: 교사동 | C29: 에폭시 코팅 | F29: 바닥 0.3mm | H29: ㎡ | I29: 185
A30: 실습동 | C30: 수성페인트(롤러칠) | F30: 내부 · 2회 · 친환경 | H30: ㎡ | I30: 2080
A31: 실습동 | C31: 비닐 페인트 | F31: 모르타르면 2회 | H31: ㎡ | I31: 95
A32: 실습동 | C32: 에폭시 코팅 | F32: 바닥 0.3mm | H32: ㎡ | I32: 200
A33: 실습동 | C33: 에폭시 라이닝 | F33: 바닥 3mm | H33: ㎡ | I33: 240
A37: 합 계 (단위가 ㎡ 인 줄) | H37: ㎡ | I37: =IF(SUMIF(H25:H36,"㎡",I25:I36)+SUMIF(H25:H36,"m2",I25:I36)=0,"",SUMIF(H25:H36,"㎡",I25:I36)+SUMIF(H25:H36,"m2",I25:I36))
A39: 이 시트는 작성 예시입니다(가상의 공사 · 회사 · 수량).

Sheet 예시-공정표
A1: K-건설맵 | k-conmap.com 건설 서식 | N1: 작성 예시 (가상의 현장)
A2: 2.0 예 정 공 정 표
A3: 착 공 일 | B3: =IF(N('예시-개요'!D21)=0,"",'예시-개요'!D21) | D3: ※ 착공일은 공사개요에서 따라옵니다. 공종마다 착수 · 완료일을 적으면 반달 칸에 막대가 그려집니다.
A4: 공 종 | B4: 착 수 | C4: 완 료 | D4: 일 수 | E4: =IF(N(B3)=0,"",EDATE(DATE(YEAR(B3),MONTH(B3),1),0)) | G4: =IF(N(B3)=0,"",EDATE(DATE(YEAR(B3),MONTH(B3),1),1)) | I4: =IF(N(B3)=0,"",EDATE(DATE(YEAR(B3),MONTH(B3),1),2)) | K4: =IF(N(B3)=0,"",EDATE(DATE(YEAR(B3),MONTH(B3),1),3)) | M4: =IF(N(B3)=0,"",EDATE(DATE(YEAR(B3),MONTH(B3),1),4)) | O4: =IF(N(B3)=0,"",EDATE(DATE(YEAR(B3),MONTH(B3),1),5)) | Q4: =IF(N(B3)=0,"",EDATE(DATE(YEAR(B3),MONTH(B3),1),6)) | S4: =IF(N(B3)=0,"",EDATE(DATE(YEAR(B3),MONTH(B3),1),7)) | U4: =IF(N(B3)=0,"",EDATE(DATE(YEAR(B3),MONTH(B3),1),8)) | W4: =IF(N(B3)=0,"",EDATE(DATE(YEAR(B3),MONTH(B3),1),9)) | Y4: =IF(N(B3)=0,"",EDATE(DATE(YEAR(B3),MONTH(B3),1),10)) | AA4: =IF(N(B3)=0,"",EDATE(DATE(YEAR(B3),MONTH(B3),1),11)) | AC4: =IF(N(B3)=0,"",EDATE(DATE(YEAR(B3),MONTH(B3),1),12)) | AE4: =IF(N(B3)=0,"",EDATE(DATE(YEAR(B3),MONTH(B3),1),13)) | AG4: =IF(N(B3)=0,"",EDATE(DATE(YEAR(B3),MONTH(B3),1),14)) | AI4: =IF(N(B3)=0,"",EDATE(DATE(YEAR(B3),MONTH(B3),1),15)) | AK4: =IF(N(B3)=0,"",EDATE(DATE(YEAR(B3),MONTH(B3),1),16)) | AM4: =IF(N(B3)=0,"",EDATE(DATE(YEAR(B3),MONTH(B3),1),17)) | AO4: 비 고
E5: 상 | F5: 하 | G5: 상 | H5: 하 | I5: 상 | J5: 하 | K5: 상 | L5: 하 | M5: 상 | N5: 하 | O5: 상 | P5: 하 | Q5: 상 | R5: 하 | S5: 상 | T5: 하 | U5: 상 | V5: 하 | W5: 상 | X5: 하 | Y5: 상 | Z5: 하 | AA5: 상 | AB5: 하 | AC5: 상 | AD5: 하 | AE5: 상 | AF5: 하 | AG5: 상 | AH5: 하 | AI5: 상 | AJ5: 하 | AK5: 상 | AL5: 하 | AM5: 상 | AN5: 하
E6: =IF(N(B3)=0,"",EDATE(DATE(YEAR(B3),MONTH(B3),1),0)) | F6: =IF(N(B3)=0,"",EDATE(DATE(YEAR(B3),MONTH(B3),1),0)+15) | G6: =IF(N(B3)=0,"",EDATE(DATE(YEAR(B3),MONTH(B3),1),1)) | H6: =IF(N(B3)=0,"",EDATE(DATE(YEAR(B3),MONTH(B3),1),1)+15) | I6: =IF(N(B3)=0,"",EDATE(DATE(YEAR(B3),MONTH(B3),1),2)) | J6: =IF(N(B3)=0,"",EDATE(DATE(YEAR(B3),MONTH(B3),1),2)+15) | K6: =IF(N(B3)=0,"",EDATE(DATE(YEAR(B3),MONTH(B3),1),3)) | L6: =IF(N(B3)=0,"",EDATE(DATE(YEAR(B3),MONTH(B3),1),3)+15) | M6: =IF(N(B3)=0,"",EDATE(DATE(YEAR(B3),MONTH(B3),1),4)) | N6: =IF(N(B3)=0,"",EDATE(DATE(YEAR(B3),MONTH(B3),1),4)+15) | O6: =IF(N(B3)=0,"",EDATE(DATE(YEAR(B3),MONTH(B3),1),5)) | P6: =IF(N(B3)=0,"",EDATE(DATE(YEAR(B3),MONTH(B3),1),5)+15) | Q6: =IF(N(B3)=0,"",EDATE(DATE(YEAR(B3),MONTH(B3),1),6)) | R6: =IF(N(B3)=0,"",EDATE(DATE(YEAR(B3),MONTH(B3),1),6)+15) | S6: =IF(N(B3)=0,"",EDATE(DATE(YEAR(B3),MONTH(B3),1),7)) | T6: =IF(N(B3)=0,"",EDATE(DATE(YEAR(B3),MONTH(B3),1),7)+15) | U6: =IF(N(B3)=0,"",EDATE(DATE(YEAR(B3),MONTH(B3),1),8)) | V6: =IF(N(B3)=0,"",EDATE(DATE(YEAR(B3),MONTH(B3),1),8)+15) | W6: =IF(N(B3)=0,"",EDATE(DATE(YEAR(B3),MONTH(B3),1),9)) | X6: =IF(N(B3)=0,"",EDATE(DATE(YEAR(B3),MONTH(B3),1),9)+15) | Y6: =IF(N(B3)=0,"",EDATE(DATE(YEAR(B3),MONTH(B3),1),10)) | Z6: =IF(N(B3)=0,"",EDATE(DATE(YEAR(B3),MONTH(B3),1),10)+15) | AA6: =IF(N(B3)=0,"",EDATE(DATE(YEAR(B3),MONTH(B3),1),11)) | AB6: =IF(N(B3)=0,"",EDATE(DATE(YEAR(B3),MONTH(B3),1),11)+15) | AC6: =IF(N(B3)=0,"",EDATE(DATE(YEAR(B3),MONTH(B3),1),12)) | AD6: =IF(N(B3)=0,"",EDATE(DATE(YEAR(B3),MONTH(B3),1),12)+15) | AE6: =IF(N(B3)=0,"",EDATE(DATE(YEAR(B3),MONTH(B3),1),13)) | AF6: =IF(N(B3)=0,"",EDATE(DATE(YEAR(B3),MONTH(B3),1),13)+15) | AG6: =IF(N(B3)=0,"",EDATE(DATE(YEAR(B3),MONTH(B3),1),14)) | AH6: =IF(N(B3)=0,"",EDATE(DATE(YEAR(B3),MONTH(B3),1),14)+15) | AI6: =IF(N(B3)=0,"",EDATE(DATE(YEAR(B3),MONTH(B3),1),15)) | AJ6: =IF(N(B3)=0,"",EDATE(DATE(YEAR(B3),MONTH(B3),1),15)+15) | AK6: =IF(N(B3)=0,"",EDATE(DATE(YEAR(B3),MONTH(B3),1),16)) | AL6: =IF(N(B3)=0,"",EDATE(DATE(YEAR(B3),MONTH(B3),1),16)+15) | AM6: =IF(N(B3)=0,"",EDATE(DATE(YEAR(B3),MONTH(B3),1),17)) | AN6: =IF(N(B3)=0,"",EDATE(DATE(YEAR(B3),MONTH(B3),1),17)+15)
E7: =IF(N(B3)=0,"",EDATE(DATE(YEAR(B3),MONTH(B3),1),0)+14) | F7: =IF(N(B3)=0,"",EDATE(DATE(YEAR(B3),MONTH(B3),1),1)-1) | G7: =IF(N(B3)=0,"",EDATE(DATE(YEAR(B3),MONTH(B3),1),1)+14) | H7: =IF(N(B3)=0,"",EDATE(DATE(YEAR(B3),MONTH(B3),1),2)-1) | I7: =IF(N(B3)=0,"",EDATE(DATE(YEAR(B3),MONTH(B3),1),2)+14) | J7: =IF(N(B3)=0,"",EDATE(DATE(YEAR(B3),MONTH(B3),1),3)-1) | K7: =IF(N(B3)=0,"",EDATE(DATE(YEAR(B3),MONTH(B3),1),3)+14) | L7: =IF(N(B3)=0,"",EDATE(DATE(YEAR(B3),MONTH(B3),1),4)-1) | M7: =IF(N(B3)=0,"",EDATE(DATE(YEAR(B3),MONTH(B3),1),4)+14) | N7: =IF(N(B3)=0,"",EDATE(DATE(YEAR(B3),MONTH(B3),1),5)-1) | O7: =IF(N(B3)=0,"",EDATE(DATE(YEAR(B3),MONTH(B3),1),5)+14) | P7: =IF(N(B3)=0,"",EDATE(DATE(YEAR(B3),MONTH(B3),1),6)-1) | Q7: =IF(N(B3)=0,"",EDATE(DATE(YEAR(B3),MONTH(B3),1),6)+14) | R7: =IF(N(B3)=0,"",EDATE(DATE(YEAR(B3),MONTH(B3),1),7)-1) | S7: =IF(N(B3)=0,"",EDATE(DATE(YEAR(B3),MONTH(B3),1),7)+14) | T7: =IF(N(B3)=0,"",EDATE(DATE(YEAR(B3),MONTH(B3),1),8)-1) | U7: =IF(N(B3)=0,"",EDATE(DATE(YEAR(B3),MONTH(B3),1),8)+14) | V7: =IF(N(B3)=0,"",EDATE(DATE(YEAR(B3),MONTH(B3),1),9)-1) | W7: =IF(N(B3)=0,"",EDATE(DATE(YEAR(B3),MONTH(B3),1),9)+14) | X7: =IF(N(B3)=0,"",EDATE(DATE(YEAR(B3),MONTH(B3),1),10)-1) | Y7: =IF(N(B3)=0,"",EDATE(DATE(YEAR(B3),MONTH(B3),1),10)+14) | Z7: =IF(N(B3)=0,"",EDATE(DATE(YEAR(B3),MONTH(B3),1),11)-1) | AA7: =IF(N(B3)=0,"",EDATE(DATE(YEAR(B3),MONTH(B3),1),11)+14) | AB7: =IF(N(B3)=0,"",EDATE(DATE(YEAR(B3),MONTH(B3),1),12)-1) | AC7: =IF(N(B3)=0,"",EDATE(DATE(YEAR(B3),MONTH(B3),1),12)+14) | AD7: =IF(N(B3)=0,"",EDATE(DATE(YEAR(B3),MONTH(B3),1),13)-1) | AE7: =IF(N(B3)=0,"",EDATE(DATE(YEAR(B3),MONTH(B3),1),13)+14) | AF7: =IF(N(B3)=0,"",EDATE(DATE(YEAR(B3),MONTH(B3),1),14)-1) | AG7: =IF(N(B3)=0,"",EDATE(DATE(YEAR(B3),MONTH(B3),1),14)+14) | AH7: =IF(N(B3)=0,"",EDATE(DATE(YEAR(B3),MONTH(B3),1),15)-1) | AI7: =IF(N(B3)=0,"",EDATE(DATE(YEAR(B3),MONTH(B3),1),15)+14) | AJ7: =IF(N(B3)=0,"",EDATE(DATE(YEAR(B3),MONTH(B3),1),16)-1) | AK7: =IF(N(B3)=0,"",EDATE(DATE(YEAR(B3),MONTH(B3),1),16)+14) | AL7: =IF(N(B3)=0,"",EDATE(DATE(YEAR(B3),MONTH(B3),1),17)-1) | AM7: =IF(N(B3)=0,"",EDATE(DATE(YEAR(B3),MONTH(B3),1),17)+14) | AN7: =IF(N(B3)=0,"",EDATE(DATE(YEAR(B3),MONTH(B3),1),18)-1)
A8: 바탕 만들기 · 퍼티 | B8: 46204 | C8: 46234 | D8: =IF(OR(N(B8)=0,N(C8)=0),"",IF(C8<B8,"⚠",C8-B8+1))
A9: 내부 수성페인트 초벌 | B9: 46219 | C9: 46265 | D9: =IF(OR(N(B9)=0,N(C9)=0),"",IF(C9<B9,"⚠",C9-B9+1))
A10: 내부 수성페인트 재벌 · 정벌 | B10: 46250 | C10: 46295 | D10: =IF(OR(N(B10)=0,N(C10)=0),"",IF(C10<B10,"⚠",C10-B10+1))
A11: 외부 수성페인트 | B11: 46266 | C11: 46295 | D11: =IF(OR(N(B11)=0,N(C11)=0),"",IF(C11<B11,"⚠",C11-B11+1))
A12: 걸레받이 세라믹 페인트 | B12: 46281 | C12: 46310 | D12: =IF(OR(N(B12)=0,N(C12)=0),"",IF(C12<B12,"⚠",C12-B12+1))
A13: 에폭시 코팅 · 라이닝(바닥) | B13: 46296 | C13: 46326 | D13: =IF(OR(N(B13)=0,N(C13)=0),"",IF(C13<B13,"⚠",C13-B13+1))
A14: 보수 · 보양 · 청소 | B14: 46327 | C14: 46341 | D14: =IF(OR(N(B14)=0,N(C14)=0),"",IF(C14<B14,"⚠",C14-B14+1))
A15: 검측 · 정리 | B15: 46342 | C15: 46356 | D15: =IF(OR(N(B15)=0,N(C15)=0),"",IF(C15<B15,"⚠",C15-B15+1))
D16: =IF(OR(N(B16)=0,N(C16)=0),"",IF(C16<B16,"⚠",C16-B16+1))
D17: =IF(OR(N(B17)=0,N(C17)=0),"",IF(C17<B17,"⚠",C17-B17+1))
D18: =IF(OR(N(B18)=0,N(C18)=0),"",IF(C18<B18,"⚠",C18-B18+1))
D19: =IF(OR(N(B19)=0,N(C19)=0),"",IF(C19<B19,"⚠",C19-B19+1))
D20: =IF(OR(N(B20)=0,N(C20)=0),"",IF(C20<B20,"⚠",C20-B20+1))
D21: =IF(OR(N(B21)=0,N(C21)=0),"",IF(C21<B21,"⚠",C21-B21+1))
A22: ※ 일수 = 완료 − 착수 + 1. 막대는 반달(1~15일 · 16일~말일) 단위입니다. 공정은 현장 여건 · 날씨에 따라 바뀔 수 있습니다.
A24: 이 시트는 작성 예시입니다(가상의 일정).

Sheet 예시-조직
A1: K-건설맵 | k-conmap.com 건설 서식 | G1: 작성 예시 (가상의 현장)
A3: 3.0 현 장 조 직 도
E5: 현 장 대 리 인
E6: 홍길동
A7: │
B8: 품 질 관 리 자 | F8: ─┼─ | H8: 안 전 관 리 자
B9: 김철수 | F9: │ | H9: 박안전
A10: │
E11: 시 공 업 체
E12: 예시도장(주)
A13: │
E14: 작 업 팀 장
E15: 최팀장
A16: ┌──────────┼──────────┐
A17: 도장공 | D17: 특별인부 | G17: 보통인부 | J17: 합 계
A18: 3 | D18: 1 | G18: 1 | J18: =IF(SUM(A18,D18,G18)=0,"",SUM(A18,D18,G18))
A20: 4.0 기능인력 투입계획 및 주자재 조달계획
A22: 1) 기능 인력(현장 여건에 따라 작업 인원 변동) — 1일 투입인원(2개조)
A23: 구 분 | E23: 단 위 | G23: 수 량 | I23: 비 고
A24: 공사관리자 | E24: 인 | G24: 1
A25: 도장공 | E25: 인 | G25: 3
A26: 특별인부 및 조공 | E26: 인 | G26: 2
A27: 계 | E27: 인 | G27: =IF(SUM(G24,G25,G26)=0,"",SUM(G24,G25,G26))
A28: ※ 작업 수량에 따라 변동됩니다.
A29: 2) 주자재 조달계획
A30: 자 재 명 | E30: 수 량 | G30: 단위 | H30: 현장반입 예정일자 | J30: 비 고
A31: 수성페인트(내부) | E31: 950 | G31: L | H31: 46216 | J31: =IF(OR(N(H31)=0,N('예시-개요'!D21)=0),"",IF(H31<'예시-개요'!D21,"⚠ 착공 전 반입","착공 후 "&(H31-'예시-개요'!D21)&"일"))
A32: 수성페인트(외부) | E32: 60 | G32: L | H32: 46258 | J32: =IF(OR(N(H32)=0,N('예시-개요'!D21)=0),"",IF(H32<'예시-개요'!D21,"⚠ 착공 전 반입","착공 후 "&(H32-'예시-개요'!D21)&"일"))
A33: 에폭시 라이닝(하도) | E33: 35 | G33: kg | H33: 46286 | J33: =IF(OR(N(H33)=0,N('예시-개요'!D21)=0),"",IF(H33<'예시-개요'!D21,"⚠ 착공 전 반입","착공 후 "&(H33-'예시-개요'!D21)&"일"))
A34: 에폭시 라이닝(중도) | E34: 1080 | G34: kg | H34: 46286 | J34: =IF(OR(N(H34)=0,N('예시-개요'!D21)=0),"",IF(H34<'예시-개요'!D21,"⚠ 착공 전 반입","착공 후 "&(H34-'예시-개요'!D21)&"일"))
A35: 에폭시 라이닝(상도) | E35: 35 | G35: L | H35: 46286 | J35: =IF(OR(N(H35)=0,N('예시-개요'!D21)=0),"",IF(H35<'예시-개요'!D21,"⚠ 착공 전 반입","착공 후 "&(H35-'예시-개요'!D21)&"일"))
A36: 에폭시 코팅(하도) | E36: 40 | G36: kg | H36: 46286 | J36: =IF(OR(N(H36)=0,N('예시-개요'!D21)=0),"",IF(H36<'예시-개요'!D21,"⚠ 착공 전 반입","착공 후 "&(H36-'예시-개요'!D21)&"일"))
A37: 에폭시 코팅(상도) | E37: 80 | G37: kg | H37: 46286 | J37: =IF(OR(N(H37)=0,N('예시-개요'!D21)=0),"",IF(H37<'예시-개요'!D21,"⚠ 착공 전 반입","착공 후 "&(H37-'예시-개요'!D21)&"일"))
A38: 세라믹 페인트 | E38: 33 | G38: L | H38: 46272 | J38: =IF(OR(N(H38)=0,N('예시-개요'!D21)=0),"",IF(H38<'예시-개요'!D21,"⚠ 착공 전 반입","착공 후 "&(H38-'예시-개요'!D21)&"일"))
J39: =IF(OR(N(H39)=0,N('예시-개요'!D21)=0),"",IF(H39<'예시-개요'!D21,"⚠ 착공 전 반입","착공 후 "&(H39-'예시-개요'!D21)&"일"))
J40: =IF(OR(N(H40)=0,N('예시-개요'!D21)=0),"",IF(H40<'예시-개요'!D21,"⚠ 착공 전 반입","착공 후 "&(H40-'예시-개요'!D21)&"일"))
A42: 이 시트는 작성 예시입니다(가상의 사람 · 수량 · 날짜).

Sheet 예시-시공관리
A1: K-건설맵 | k-conmap.com 건설 서식 | G1: 작성 예시 (가상의 현장)
A3: 5.0 시 공 관 리
A6: 5-1 일반사항
A7: 1) 운반 · 보관 및 취급
A8: (1) | B8: 도장재는 밀봉된 용기에 넣어 개봉하지 않은 상태로 반입하고, 용기에는 도장재의 종류 · 색상 · 수량 · 제조일자 · 제조일련번호 · 상표 · 사용상 주의사항 · 바탕 준비사항 · 건조시간 · 배합에 관한 제조업자의 지침이 적혀 있어야 한다.
A9: (2) | B9: 도장재의 반입 시기는 공사기간 외에 품질시험에 걸리는 기간을 고려하여 정한다.
A10: (3) | B10: 가연성 도료는 전용 창고에 보관하는 것을 원칙으로 하며, 반입한 도료와 사용 중인 도료는 공사감독자가 승인한 창고에 보관하고 도료창고에 «화기 엄금» 표시를 한다.
A11: (4) | B11: 도료창고는 특히 화재에 주의하고, 창고 안과 주변에서 화기 사용을 엄금한다.
A12: (5) | B12: 도료는 될 수 있는 대로 밀봉하여 새거나 엎지르지 않게 다루고, 샌 것이나 엎지른 것은 발화 위험이 없도록 닦아 낸다.
A13: 2) 환경 요구사항
A14: (1) | B14: 도장 작업 중이나 도료 건조기간 중, 도장 장소의 환경 · 기상 조건이 아래와 같아 좋은 결과를 기대할 수 없으면 공사감독자가 승인할 때까지 도장하지 않는다.
A15: (2) | B15: 기온이 낮거나 습도가 높고 환기가 충분하지 않아 건조가 부적당할 때, 주위 기온이 5℃ 미만이거나 상대습도가 85% 를 넘을 때, 눈 · 비가 올 때 및 안개가 끼었을 때. 다만 재료 제조업자의 시방서에 따로 표시한 경우는 예외로 한다.
A17: 5-2 재료
A18: 1) 도장재의 일반 조건
A19: (1) | B19: 도장재료는 한국산업표준(KS)에서 정한 규격에 합격한 것을 쓴다.
A20: (2) | B20: 도료는 상표가 완전하고 개봉하지 않은 채로 현장에 반입하여 KS 표시 여부 · 규격번호 · 품명 · 종별 · 제조연월일 · 포장 번호 및 수량 · 구성성분(안료 · 용제) · 희석방법 · 색명 및 번호 등을 확인받는다.
A21: (3) | B21: 현장에서 쓰는 도장재는 종류별로 한 제조업자의 제품을 쓴다.
A22: (4) | B22: 공장에서 배합이 끝난 제품을 쓰며, 현장 희석은 제조업자가 인정하는 범위에서 한다.
A23: (5) | B23: 상도 · 중도 · 하도의 도막 색상은 서로 다르게 하며, 상도 후 마감 상태가 요구 기준에 맞아야 한다.
A24: 2) 합성수지 에멀션 페인트
A25: (1) | B25: 외부 수성페인트 — KS M 5310 의 1급에 맞는 합성수지 에멀션 페인트(외부용)로 한다. 도면 · 공사시방에 발수용 외부 수성페인트를 쓰도록 명시한 경우에는 KS M 5310 1급 제품으로서 KS M 7057 발수도 시험 결과 R7 이상인 제품으로 하며, 시험편은 KS M 5310 에 따라 만든 시편 5매로 한다.
A26: (2) | B26: 내부 수성페인트 — KS M 5320 의 1급에 맞는 합성수지 에멀션 페인트(내부용)로 한다.
A27: (3) | B27: 광택 합성수지 에멀션 페인트 — 광택 합성수지 에멀션 페인트 규정에 합격한 재료로 한다.
A28: 3) 바닥재 도료칠
A29: (1) | B29: 코팅형 에폭시 바닥재 — 품질은 승인된 제조업자의 품질자료에 따른다.
A30: (2) | B30: 아크릴 수지 에나멜 바닥재 — 품질은 승인된 제조업자의 품질자료에 따른다.
A32: 5-3 시공
A33: 1) 바탕 만들기(면처리)
A34: 각종 도료를 칠하기 전에 바탕 만들기(면처리 · 바탕조정 · 바탕처리 등)를 한다.
A35: 2) 일반 조건
A36: (1) | B36: 칠 바탕면은 칠이나 표면처리를 하기 전에 녹 · 해로운 부착물(먼지 · 기름 · 타르분 · 회반죽 · 플라스터 · 시멘트 · 모르타르)과 노화가 심한 구도막을 완전히 없애고 깨끗이 청소한다.
A37: (2) | B37: 못머리 등 금속이 바탕면에 드러난 곳은 상부 칠 종류에 맞는 녹 방지 조치를 따로 한다.
A38: (3) | B38: 칠할 부위에 붙은 비도장 부위는 바탕정리나 칠하기 전에 보양재를 덮어 도료가 묻지 않게 한다. 특히 실내에서는 벽 · 바닥 · 인접 시설에 묻지 않도록 비닐 · 신문지 등으로 보양한다.
A39: (4) | B39: 면의 결점(홈 · 구멍 · 갈라짐 · 변형 · 옹이 · 흡수성이 고르지 않은 곳 등)을 보수하여 칠하기 좋은 상태로 한다.
A40: (5) | B40: 배어 나오기 · 녹아 나오기 등에 의한 해로운 물질(수분 · 기름 · 수지 · 산 · 알칼리 등)의 작용을 막는 처리를 한다.
A41: (6) | B41: 색상 · 재질이 다른 칠이 만나는 경계는 경계선이 곧도록 테이핑 작업을 한다.
A42: (7) | B42: 도장재와 바탕 종류에 따라 따로 표면처리가 필요하면 도료 제조업자의 지침에 따라 바탕처리를 한다.
A43: 3) 바탕 만들기 공법
A44: 바탕 만들기 공정의 종별(바탕 종류 · 공법)은 아래에 따르며, 종별 지시가 없으면 철재면 3종, 아연도금면 2종 또는 3종, 경금속 및 동합금면 2종으로 한다. 다만 비닐계 에나멜 도장일 때는 철재면 2종, 아연도금면 1종으로 하고, 100℃ 이상에서 건조시키는 공업용 도장은 1종(인산염 처리)으로 한다.
A45: [ 바탕 만들기의 도장 종별 ]
...

Sheet 예시-검측체크
A1: K-건설맵 | k-conmap.com 건설 서식 | G1: 작성 예시 (가상의 현장)
A2: 검 측 체 크 리 스 트
A3: 공종 CODE NO. | E3: 도 장 공 사 | G3: 위치 및 부위 | I3: 교사동 2층 교실 벽 · 천장
A4: 공종(세부공종) | C4: 공통사항 | G4: 검 측 일 자 | I4: 46218
A5: 검 사 항 목 | F5: 검 사 기 준 (시방서 · 도면 등) | H5: 검 사 결 과 | L5: 조치 사항
H6: 1 차 | J6: 2 차
H7: 합격 | I7: 불합격 | J7: 합격 | K7: 불합격
A8: 1. 자재공급원 승인은 되었는가 | F8: 승인 여부 | H8: ○
A9: 2. 바탕처리는 적정한가(레이턴스 · 먼지 · 오염 제거 등) | F9: 적 · 부 | H9: ○
A10: 3. 구조체 곰보 · 이음 조인트 · 균열 · 재료분리 등의 조치는 적정한가 | F10: 적 · 부 | H10: ○
A11: 4. 재료의 종류 · 규격 · 품질보증서 등은 확인하였는가 | F11: 적 · 부 | H11: ○
A12: 5. 바탕면이 충분히 건조(함수율 5% 이하)되었는가 | F12: 적 · 부 | H12: ○
A13: 6. 다른 부위가 오염되지 않게 조치하였는가 | F13: 적 · 부 | H13: ○
A14: 7. 재료의 보관 장소 및 보관 방법은 적정한가 | F14: 적 · 부 | H14: ○
A15: 8. 시공 때 기온 5℃ 이하 · 습도 80% 이상이면 작업을 중단하고 있는가 | F15: 적 · 부 | H15: ○
A16: 판 정 | D16: =IF(COUNTA(H8:H15)+COUNTA(I8:I15)=0,"","1차 합격 "&COUNTA(H8:H15)&" · 불합격 "&COUNTA(I8:I15)&IF(COUNTA(I8:I15)>0," / 2차 합격 "&COUNTA(J8:J15)&" · 불합격 "&COUNTA(K8:K15),"")&IF(COUNTA(H8:H15)+COUNTA(I8:I15)<8," · 빈칸 "&(8-COUNTA(H8:H15)-COUNTA(I8:I15)),"")&" → "&IF(COUNTA(I8:I15)=0,IF(COUNTA(H8:H15)+COUNTA(I8:I15)<8,"점검 중","합격"),IF(AND(COUNTA(K8:K15)=0,COUNTA(J8:J15)>=COUNTA(I8:I15)),"합격(재검측)","보완 후 재검측")))
A17: 시 공 자 점 검 | G17: 건 설 사 업 관 리 자 검 측
A18: 점 검 | D18: 재 점 검 | G18: 검 측 | J18: 재 검 측
A19: (인) | D19: (인) | G19: (인) | J19: (인)
A20: 검 측 체 크 리 스 트
A21: 공종 CODE NO. | E21: 도 장 공 사 | G21: 위치 및 부위 | I21: 교사동 2층 교실 벽 · 천장
A22: 공종(세부공종) | C22: 수성페인트 | G22: 검 측 일 자 | I22: 46275
A23: 검 사 항 목 | F23: 검 사 기 준 (시방서 · 도면 등) | H23: 검 사 결 과 | L23: 조치 사항
H24: 1 차 | J24: 2 차
H25: 합격 | I25: 불합격 | J25: 합격 | K25: 불합격
A26: 1. 시공 때 온도는 적정한가 | F26: 적 · 부 | H26: ○
A27: 2. 바탕처리는 적정한가(레이턴스 · 먼지 · 오염 제거 등) | F27: 적 · 부 | H27: ○
A28: 3. 구조체 곰보 · 이음 조인트 · 균열 · 재료분리 등의 조치는 적정한가 | F28: 적 · 부 | H28: ○
A29: 4. 재료의 종류 · 규격 · 품질보증서 등은 확인하였는가 | F29: 적 · 부 | H29: ○
A30: 5. 환기 및 조명 설치는 충분한가 | F30: 적 · 부 | H30: ○
A31: 6. 재료 배합은 적절한가 | F31: 적 · 부 | H31: ○
A32: 7. 시공 절차를 지키는가 | F32: 적 · 부 | H32: ○
A33: 8. 칠 두께는 고른가 | F33: 적 · 부 | I33: ○ | J33: ○ | L33: 얼룩 부위 덧칠 후 재검측
A34: 9. 시공 후 보양 대책은 세웠는가 | F34: 적 · 부 | H34: ○
A35: 10. 정해진 색상을 쓰는가 | F35: 적 · 부 | H35: ○
F36: 적 · 부
F37: 적 · 부
F38: 적 · 부
A39: 판 정 | D39: =IF(COUNTA(H26:H38)+COUNTA(I26:I38)=0,"","1차 합격 "&COUNTA(H26:H38)&" · 불합격 "&COUNTA(I26:I38)&IF(COUNTA(I26:I38)>0," / 2차 합격 "&COUNTA(J26:J38)&" · 불합격 "&COUNTA(K26:K38),"")&IF(COUNTA(H26:H38)+COUNTA(I26:I38)<13," · 빈칸 "&(13-COUNTA(H26:H38)-COUNTA(I26:I38)),"")&" → "&IF(COUNTA(I26:I38)=0,IF(COUNTA(H26:H38)+COUNTA(I26:I38)<13,"점검 중","합격"),IF(AND(COUNTA(K26:K38)=0,COUNTA(J26:J38)>=COUNTA(I26:I38)),"합격(재검측)","보완 후 재검측")))
A40: 시 공 자 점 검 | G40: 건 설 사 업 관 리 자 검 측
...

Sheet 예시-관리계획
A1: K-건설맵 | k-conmap.com 건설 서식 | G1: 작성 예시 (가상의 현장)
A3: 7.0 품 질 관 리 계 획
A6: 7-1 자재 관리
A7: 1) 적용범위
A8: 입고 자재가 취급 · 보관 등으로 품질이 손상되지 않도록 관리하는 업무에 적용한다.
A9: 2) 창고 구비 조건
A10: (1) | B10: 보관품은 알맞은 기준에 따라 품질에 변형을 주지 않는 장소에 둔다.
A11: (2) | B11: 야적장은 배수가 잘되고 주위에 위험요소가 없는 평탄한 곳으로 자재 운반이 쉬워야 하며, 밖에 두어도 품질 변화가 적은 자재만 보관한다.
A12: 3) 관리 방법
A13: (1) | B13: 보관품은 종류별 · 규격별로 반입 · 반출이 쉬운 상태로 보관하고, 포대 · 상자 또는 완전 포장된 것은 품명 · 수량 등을 적는다.
A14: (2) | B14: 롤(ROLL) 단위 시트류 — 습기 · 물기가 없는 지정 장소에 보관하고, 무게로 휘지 않게 야적량을 알맞게 하며, 세워서 규격별로 정리한다.
A15: (3) | B15: 캔류 — 파손 · 손상을 막기 위해 따로 구분 · 식별하여 관리하고, 다른 공정 작업자 등으로부터 피해를 받지 않게 하며, 찌그러지거나 터지지 않게 보관 · 운반하고, 포장재가 녹슬거나 라벨이 손상되지 않게 한다.
A16: (4) | B16: 그 밖의 자재 — 보관용 선반 · 전용 케이스 등을 이용하여 보관한다.
A18: 7-2 공정별 품질시험 계획
B19: (1) 시공 전 품질관리 — 자재 반입 검사(소요량 참조) · 바탕 상태 검사(바탕처리 후)
A20: [ 바탕 상태 검사 체크리스트 ]
A21: 공 정 | C21: 상 태 | G21: 확인 방법 | I21: 판 정 기 준
A22: 바탕처리 | C22: 거푸집 단차 및 돌기물 | G22: 육안검사 | I22: 높이 3mm 이하
C23: 거푸집 박리제 | G23: 육안검사 | I23: 없음
C24: 레이턴스 · 기름 · 먼지 등 | G24: 육안검사 | I24: 없음
C25: 균열 및 누수 부위 | G25: 육안 · 확대경 | I25: 없음 또는 보수 · 보강 처리되어 있을 것
C26: 나무조각 · 철사 · 종이류 | G26: 육안검사 | I26: 없음
C27: 취약 부위(골재분리 등) 충전 | G27: 육안검사 | I27: 취약 부위가 보강되어 있을 것
B28: (2) 시공 중 품질관리 — 공정별 도장 횟수 확인 · 재료 사용량 준수 여부 · 도장 부위의 하자 발생 여부
B29: (3) 시공 후 품질관리 — 도장 부위의 들뜸 · 손상 · 균열 · 얼룩 발생 여부 · 표면 상태 확인
A31: 8.0 환 경 관 리 계 획
A34: 8-1 개 요
A35: 현장의 폐기물 · 유류 · 쓰레기 및 소음 · 진동 · 비산먼지 등에 의한 오염을 방지한다.
A37: 8-2 중점관리 방침
A38: (1) | B38: 자율적인 환경관리
A39: (2) | B39: 쾌적한 작업환경 관리
A40: (3) | B40: 민원 발생 방지
A42: 8-3 실시계획
A43: (1) | B43: 작업 전후 정리정돈 : 작업 전후 정리정돈을 철저히 하여 쾌적한 작업환경을 유지한다.
A44: (2) | B44: 분리수거 : 분리수거를 철저히 하고, 도장 작업에서 나온 폐기물(빈 도료 용기 · 폐신너 · 걸레 등)은 시공업체 부담으로 적법하게 처리하여 쓰레기를 줄인다.
A45: (3) | B45: 민원 발생 억제 : 소음 · 진동 · 비산먼지 · 냄새를 최대한 억제하여 인근 주민의 생활에 피해가 없도록 하고, 적극적으로 환경관리 활동을 한다.
B46: (4) 환경관리 대책
A47: ① | C47: 쓰레기 처리 : 현장 안은 금연하고 쓰레기 수거함을 둔다.
A48: ② | C48: 잔재물 · 빈 용기 : 빈 도료 용기 · 폐신너 · 도료 묻은 걸레는 인화 위험이 없도록 뚜껑 있는 용기에 모아 지정 장소에 두고, 지정폐기물은 허가 업체에 위탁 처리한다.
A49: ③ | C49: 비산먼지 : 현장 안 주요 도로와 작업장 주변은 하루 2회 이상 살수차로 살수하고, 장비 이동 때 먼지가 나지 않도록 서행한다.
...
