Workbook

Sheet 표지
A1: K-건설맵 | k-conmap.com 건설 서식 | G1: ← 이 1행을 지우고 쓰셔도 됩니다
A3: (공 사 명)
A5: 시 공 계 획 서
A6: [ 미장공사 ]
A8: 20 . .
A10: (회 사 명)
A12: 공사명 · 작성 연월(2026-03 처럼) · 회사명을 여기 한 번만 적으면 뒤 장에 저절로 들어갑니다.

Sheet 개요
A1: K-건설맵 | k-conmap.com 건설 서식 | G1: ← 이 1행을 지우고 쓰셔도 됩니다
A3: 목 차
C5: 1. 공 사 명
C6: 2. 공 사 개 요
C7: 3. 공 사 위 치
C8: 4. 주요 공사 물량
C9: 5. 현 장 조 직 도
C10: 6. 시 공 관 리
C11: 7. 예 정 공 정 표
C12: 8. 품 질 관 리 계 획
C13: 9. 환 경 관 리 계 획
C14: 10. 안 전 관 리 계 획
A16: 1.0 공 사 명
B18: =IF(OR('표지'!A3="",'표지'!A3="(공 사 명)"),"","◦ "&'표지'!A3)
A20: 2.0 공 사 개 요
A22: 공 사 명 | D22: =IF(OR('표지'!A3="",'표지'!A3="(공 사 명)"),"",'표지'!A3)
A23: 공 사 위 치
A24: 발 주 처
A25: 공 사 기 간 | F25: ~ | I25: =IF(OR(N(D25)=0,N(G25)=0),"",IF(G25<D25,"⚠ 준공일이 착공일보다 빠름",G25-D25+1))
A26: 공 사 금 액 | G26: =IF(N(D26)=0,"",D26)
A27: 공 사 규 모
A28: 시 공 사 | D28: =IF(OR('표지'!A10="",'표지'!A10="(회 사 명)"),"",'표지'!A10)
A30: 3.0 공 사 위 치
A32: (위치도를 붙이는 곳 — 현장 위치와 미장 공사 구간을 표시)
A45: 4.0 주요 공사 물량
A47: 구 분 | C47: 명 칭 | F47: 규 격 | H47: 수 량 | J47: 단위 | K47: 비 고
A60: 합 계 (단위가 ㎡ 인 줄) | H60: =IF(SUMIF(J48:J59,"㎡",H48:H59)+SUMIF(J48:J59,"m2",H48:H59)=0,"",SUMIF(J48:J59,"㎡",H48:H59)+SUMIF(J48:J59,"m2",H48:H59)) | J60: ㎡
A62: 5.0 현 장 조 직 도
E64: 현 장 대 리 인
A66: │
B67: 품 질 관 리 자 | F67: ─┼─ | H67: 안 전 관 리 자
F68: │
A69: │
E70: 시 공 업 체
A72: │
E73: 작 업 팀 장
A75: ┌──────────┼──────────┐
A76: 장비기사 | C76: 미장공 | E76: 특별인부 | G76: 보통인부 | I76: 합 계
A77: 1 | C77: 4 | E77: 5 | G77: 2 | I77: =IF(SUM(A77,C77,E77,G77)=0,"",SUM(A77,C77,E77,G77))
A79: 하늘색 칸 = 자동(공사명 · 시공사 · 공사기간 일수 · 금액 한글 · ㎡ 합계 · 인원 합계). 인원은 원본 계획서 인원을 넣어 두었습니다.

Sheet 시공관리
A1: K-건설맵 | k-conmap.com 건설 서식 | G1: ← 이 1행을 지우고 쓰셔도 됩니다
A3: 6.0 시 공 관 리
A6: 6-1 시멘트 모르타르 바름
A7: 1) 적용 범위
A8: 이 절은 시멘트 · 골재 등을 주재료로 한 시멘트 모르타르를 벽 · 바닥 · 천장 등에 바르는 경우에 적용한다.
A9: 2) 한국산업표준(KS)
A10: (1) | B10: KS A 5101 — 표준체
A11: (2) | B11: KS F 4552 — 메탈라스
A12: (3) | B12: KS L 5201 — 포틀랜드 시멘트
A13: (4) | B13: KS L 5204 — 백색 포틀랜드 시멘트
A14: (5) | B14: KS L 9007 — 미장용 생석회 및 소석회
A15: (6) | B15: KS L 5220 — 건조 시멘트 모르타르
A16: 3) 운반 · 보관 · 취급
A17: (1) | B17: 미장용 재료는 섞이거나 훼손되지 않도록 보관한다.
A18: (2) | B18: 공장 제조품은 공장에서 나올 때의 포장이 파손되지 않은 상태로 반입하며, 포장에서 품명 · 자재명 · 수량 · 종류 · 형태를 확인할 수 있어야 한다.
A19: (3) | B19: 시멘트 · 석회 및 부속 재료는 비를 맞지 않게 덮고, 지면보다 30cm 이상 높게 만든 바닥이 있는 창고 등에 건조 상태로 보관하며 겹쳐 쌓기는 13포 이하로 한다.
A20: 4) 환경 요구사항
A21: (1) | B21: 시멘트 모르타르를 바르기 전과 바른 후 최소 1주일 이상 온도를 4℃ 이상으로 유지한다.
A22: (2) | B22: 시멘트 모르타르를 바른 후 최소 1주일 이상 환기를 원활하게 유지한다.
A23: (3) | B23: 동절기 공사는 원칙적으로 하지 않되, 부득이하게 시공할 때는 감리원의 승인을 받은 뒤 보양 · 보온하고 시공한다. 바름면이 들뜨거나 동해를 입었으면 쪼아 내고 다시 바른다.
A24: 5) 다른 공정과의 협력 작업
A25: 매입용 철물(insert) · 고정철물 · 전선배관 등 특별 사항은 미장공사와 관련된 다른 공사 부서에 설명하고, 알맞게 설치되도록 정확한 설치 위치와 설치물에 대해 협조한다.
A26: 6) 재료
B27: (1) 시멘트 — 포틀랜드 시멘트는 KS L 5201 의 1종(보통 포틀랜드 시멘트)에 맞는 제품을 쓴다.
B28: (2) 모래 — 단단하고 깨끗하며 먼지 · 흙 · 유기물 등 유해물이 섞이지 않은 것. 품질기준 :
A29: ▸ | C29: 절건비중 2.4 이상
A30: ▸ | C30: 흡수율 4.0% 이하
A31: ▸ | C31: 점토량 2.0% 이하
A32: ▸ | C32: 유기불순물 — 표준색보다 진하지 않은 것
A33: ▸ | C33: 씻기 시험으로 손실되는 양 3% 이하
A34: ▸ | C34: 염화물 함유량 0.1% 이하
B35: (3) 물 — 유해한 기름 · 산 · 알칼리 · 유기물 등이 기준량 이상 들어 있지 않은, 식수로 쓸 수 있는 깨끗한 물을 쓴다.
B36: (4) 접착재 — 보수성 · 작업성 · 부착성 등을 높이는 것으로, 수축이 적은 합성수지계 무기질 재료를 쓴다.
B37: (5) 부속 재료
A38: ① | C38: 메탈라스 : KS F 4552 에 맞는 메탈라스를 쓴다.
A39: ② | C39: 코너비드 : 두께 0.45mm 아연도금 철재로, 비드 지름 4mm 이고 양쪽에 폭 50mm 의 메시형 날개가 붙은 것을 쓴다.
A40: ③ | C40: 신축줄눈 : 두께 0.45mm 아연도금 철재로, 비드 깊이 13mm 이고 양쪽에 폭 50mm 의 메시형 날개가 붙은 것을 쓴다.
A41: 7) 모르타르 배합
A42: (1) | B42: 미장용 모르타르는 포틀랜드 시멘트 1 : 모래 3 의 비율로 배합한다.
A43: (2) | B43: 시멘트 풀은 포틀랜드 시멘트 1 : 모래 0 의 비율로 배합한다.
...

Sheet 검측체크
A1: K-건설맵 | k-conmap.com 건설 서식 | G1: ← 이 1행을 지우고 쓰셔도 됩니다
A2: 검 측 체 크 리 스 트
A3: 공종 CODE NO. | E3: 미 장 공 사 | G3: 위치 및 부위
A4: 공종(세부공종) | C4: 벽체 시멘트 모르타르 바르기 — 바탕면 처리 및 준비 상태 | G4: 검 측 일 자
A5: 검 사 항 목 | F5: 검 사 기 준 (시방서 · 도면 등) | H5: 검 사 결 과 | L5: 조치 사항
H6: 1 차 | J6: 2 차
H7: 합격 | I7: 불합격 | J7: 합격 | K7: 불합격
A8: 1. 시멘트 · 모래 자재공급원 승인은 되었는가 | F8: 승인 여부
A9: 2. 각종 라스 및 메탈라스의 자재공급원 승인은 되었는가 | F9: 승인 여부
A10: 3. 바탕처리는 적정한가(물축임 · 오염 제거 등) | F10: 적 · 부
A11: 4. 구조체 곰보 · 이음 조인트 · 균열 · 재료분리 등의 조치는 적정한가 | F11: 적 · 부
A12: 5. 창틀 주변 모르타르 사춤은 완료하였는가 | F12: 적 · 부
A13: 6. 전기 및 설비 배관 부위 모르타르 사춤은 완료하였는가 | F13: 적 · 부
A14: 7. 이질재 접합부 라스 설치 및 코너비드 설치 상태는 적정한가 | F14: 적 · 부
A15: 8. 균열 방지용 메탈라스의 설치 방법 및 보강 위치는 적정한가 | F15: 시공상세도
A16: 9. 시멘트벽돌 쌓기 완료 후 일정 기간 보양을 하였는가 | F16: 적 · 부
A17: 10. 콘크리트 균열 부위는 적정하게 보수하였는가(에폭시 그라우팅) | F17: 적 · 부
A18: 판 정 | D18: =IF(COUNTA(H8:H17)+COUNTA(I8:I17)=0,"","1차 합격 "&COUNTA(H8:H17)&" · 불합격 "&COUNTA(I8:I17)&IF(COUNTA(I8:I17)>0," / 2차 합격 "&COUNTA(J8:J17)&" · 불합격 "&COUNTA(K8:K17),"")&IF(COUNTA(H8:H17)+COUNTA(I8:I17)<10," · 빈칸 "&(10-COUNTA(H8:H17)-COUNTA(I8:I17)),"")&" → "&IF(COUNTA(I8:I17)=0,IF(COUNTA(H8:H17)+COUNTA(I8:I17)<10,"점검 중","합격"),IF(AND(COUNTA(K8:K17)=0,COUNTA(J8:J17)>=COUNTA(I8:I17)),"합격(재검측)","보완 후 재검측")))
A19: 시 공 자 점 검 | G19: 감 리 원 검 측
A20: 점 검 | D20: 재 점 검 | G20: 검 측 | J20: 재 검 측
A21: (인) | D21: (인) | G21: (인) | J21: (인)
A22: 검 측 체 크 리 스 트
A23: 공종 CODE NO. | E23: 미 장 공 사 | G23: 위치 및 부위
A24: 공종(세부공종) | C24: 벽체 시멘트 모르타르 바르기 — 초벌 바름 완료 상태 | G24: 검 측 일 자
A25: 검 사 항 목 | F25: 검 사 기 준 (시방서 · 도면 등) | H25: 검 사 결 과 | L25: 조치 사항
H26: 1 차 | J26: 2 차
H27: 합격 | I27: 불합격 | J27: 합격 | K27: 불합격
A28: 1. 시멘트 보관 및 관리는 적정한가(반입일자 · 야적상태 · 습기 등) | F28: 적 · 부
A29: 2. 모래 입도는 적정하며 진흙 · 먼지 · 철분 함유는 없는가 | F29: 적 · 부
A30: 3. 물은 깨끗하고 유해물이 포함되지 않았는가 | F30: 적 · 부
A31: 4. 초벌 바름 두께는 적정한가 | F31: 7mm
A32: 5. 면 긁어 주기는 적정한가 | F32: 가늘고 고르게
A33: 6. 구획별 양생 기간은 적정한가 | F33: 초벌 바름 후 7일 경과
A34: 7. 덧먹임 부분 및 바름 벽은 평활하며 들뜬 곳은 없는가 | F34: 적 · 부
A35: 8. 창호틀 등에 모르타르 오염은 없으며 보양 상태는 양호한가 | F35: 적 · 부
A36: 9. 시공 전 1일 이상, 시공 중 및 시공 후 3일 이상 영상 온도를 유지하였는가 | F36: 적 · 부
A37: 판 정 | D37: =IF(COUNTA(H28:H36)+COUNTA(I28:I36)=0,"","1차 합격 "&COUNTA(H28:H36)&" · 불합격 "&COUNTA(I28:I36)&IF(COUNTA(I28:I36)>0," / 2차 합격 "&COUNTA(J28:J36)&" · 불합격 "&COUNTA(K28:K36),"")&IF(COUNTA(H28:H36)+COUNTA(I28:I36)<9," · 빈칸 "&(9-COUNTA(H28:H36)-COUNTA(I28:I36)),"")&" → "&IF(COUNTA(I28:I36)=0,IF(COUNTA(H28:H36)+COUNTA(I28:I36)<9,"점검 중","합격"),IF(AND(COUNTA(K28:K36)=0,COUNTA(J28:J36)>=COUNTA(I28:I36)),"합격(재검측)","보완 후 재검측")))
A38: 시 공 자 점 검 | G38: 감 리 원 검 측
A39: 점 검 | D39: 재 점 검 | G39: 검 측 | J39: 재 검 측
A40: (인) | D40: (인) | G40: (인) | J40: (인)
...

Sheet 공정표
A1: K-건설맵 | k-conmap.com 건설 서식 | N1: ← 이 1행을 지우고 쓰셔도 됩니다
A2: 7.0 예 정 공 정 표
A3: 착 공 일 | B3: =IF(N('개요'!D25)=0,"",'개요'!D25) | D3: ※ 착공일은 공사개요에서 따라옵니다. 공종마다 착수 · 완료일을 적으면 반달 칸에 막대가 그려집니다.
A4: 공 종 | B4: 착 수 | C4: 완 료 | D4: 일 수 | E4: =IF(N(B3)=0,"",EDATE(DATE(YEAR(B3),MONTH(B3),1),0)) | G4: =IF(N(B3)=0,"",EDATE(DATE(YEAR(B3),MONTH(B3),1),1)) | I4: =IF(N(B3)=0,"",EDATE(DATE(YEAR(B3),MONTH(B3),1),2)) | K4: =IF(N(B3)=0,"",EDATE(DATE(YEAR(B3),MONTH(B3),1),3)) | M4: =IF(N(B3)=0,"",EDATE(DATE(YEAR(B3),MONTH(B3),1),4)) | O4: =IF(N(B3)=0,"",EDATE(DATE(YEAR(B3),MONTH(B3),1),5)) | Q4: =IF(N(B3)=0,"",EDATE(DATE(YEAR(B3),MONTH(B3),1),6)) | S4: =IF(N(B3)=0,"",EDATE(DATE(YEAR(B3),MONTH(B3),1),7)) | U4: =IF(N(B3)=0,"",EDATE(DATE(YEAR(B3),MONTH(B3),1),8)) | W4: =IF(N(B3)=0,"",EDATE(DATE(YEAR(B3),MONTH(B3),1),9)) | Y4: =IF(N(B3)=0,"",EDATE(DATE(YEAR(B3),MONTH(B3),1),10)) | AA4: =IF(N(B3)=0,"",EDATE(DATE(YEAR(B3),MONTH(B3),1),11)) | AC4: =IF(N(B3)=0,"",EDATE(DATE(YEAR(B3),MONTH(B3),1),12)) | AE4: =IF(N(B3)=0,"",EDATE(DATE(YEAR(B3),MONTH(B3),1),13)) | AG4: =IF(N(B3)=0,"",EDATE(DATE(YEAR(B3),MONTH(B3),1),14)) | AI4: =IF(N(B3)=0,"",EDATE(DATE(YEAR(B3),MONTH(B3),1),15)) | AK4: =IF(N(B3)=0,"",EDATE(DATE(YEAR(B3),MONTH(B3),1),16)) | AM4: =IF(N(B3)=0,"",EDATE(DATE(YEAR(B3),MONTH(B3),1),17)) | AO4: 비 고
E5: 상 | F5: 하 | G5: 상 | H5: 하 | I5: 상 | J5: 하 | K5: 상 | L5: 하 | M5: 상 | N5: 하 | O5: 상 | P5: 하 | Q5: 상 | R5: 하 | S5: 상 | T5: 하 | U5: 상 | V5: 하 | W5: 상 | X5: 하 | Y5: 상 | Z5: 하 | AA5: 상 | AB5: 하 | AC5: 상 | AD5: 하 | AE5: 상 | AF5: 하 | AG5: 상 | AH5: 하 | AI5: 상 | AJ5: 하 | AK5: 상 | AL5: 하 | AM5: 상 | AN5: 하
E6: =IF(N(B3)=0,"",EDATE(DATE(YEAR(B3),MONTH(B3),1),0)) | F6: =IF(N(B3)=0,"",EDATE(DATE(YEAR(B3),MONTH(B3),1),0)+15) | G6: =IF(N(B3)=0,"",EDATE(DATE(YEAR(B3),MONTH(B3),1),1)) | H6: =IF(N(B3)=0,"",EDATE(DATE(YEAR(B3),MONTH(B3),1),1)+15) | I6: =IF(N(B3)=0,"",EDATE(DATE(YEAR(B3),MONTH(B3),1),2)) | J6: =IF(N(B3)=0,"",EDATE(DATE(YEAR(B3),MONTH(B3),1),2)+15) | K6: =IF(N(B3)=0,"",EDATE(DATE(YEAR(B3),MONTH(B3),1),3)) | L6: =IF(N(B3)=0,"",EDATE(DATE(YEAR(B3),MONTH(B3),1),3)+15) | M6: =IF(N(B3)=0,"",EDATE(DATE(YEAR(B3),MONTH(B3),1),4)) | N6: =IF(N(B3)=0,"",EDATE(DATE(YEAR(B3),MONTH(B3),1),4)+15) | O6: =IF(N(B3)=0,"",EDATE(DATE(YEAR(B3),MONTH(B3),1),5)) | P6: =IF(N(B3)=0,"",EDATE(DATE(YEAR(B3),MONTH(B3),1),5)+15) | Q6: =IF(N(B3)=0,"",EDATE(DATE(YEAR(B3),MONTH(B3),1),6)) | R6: =IF(N(B3)=0,"",EDATE(DATE(YEAR(B3),MONTH(B3),1),6)+15) | S6: =IF(N(B3)=0,"",EDATE(DATE(YEAR(B3),MONTH(B3),1),7)) | T6: =IF(N(B3)=0,"",EDATE(DATE(YEAR(B3),MONTH(B3),1),7)+15) | U6: =IF(N(B3)=0,"",EDATE(DATE(YEAR(B3),MONTH(B3),1),8)) | V6: =IF(N(B3)=0,"",EDATE(DATE(YEAR(B3),MONTH(B3),1),8)+15) | W6: =IF(N(B3)=0,"",EDATE(DATE(YEAR(B3),MONTH(B3),1),9)) | X6: =IF(N(B3)=0,"",EDATE(DATE(YEAR(B3),MONTH(B3),1),9)+15) | Y6: =IF(N(B3)=0,"",EDATE(DATE(YEAR(B3),MONTH(B3),1),10)) | Z6: =IF(N(B3)=0,"",EDATE(DATE(YEAR(B3),MONTH(B3),1),10)+15) | AA6: =IF(N(B3)=0,"",EDATE(DATE(YEAR(B3),MONTH(B3),1),11)) | AB6: =IF(N(B3)=0,"",EDATE(DATE(YEAR(B3),MONTH(B3),1),11)+15) | AC6: =IF(N(B3)=0,"",EDATE(DATE(YEAR(B3),MONTH(B3),1),12)) | AD6: =IF(N(B3)=0,"",EDATE(DATE(YEAR(B3),MONTH(B3),1),12)+15) | AE6: =IF(N(B3)=0,"",EDATE(DATE(YEAR(B3),MONTH(B3),1),13)) | AF6: =IF(N(B3)=0,"",EDATE(DATE(YEAR(B3),MONTH(B3),1),13)+15) | AG6: =IF(N(B3)=0,"",EDATE(DATE(YEAR(B3),MONTH(B3),1),14)) | AH6: =IF(N(B3)=0,"",EDATE(DATE(YEAR(B3),MONTH(B3),1),14)+15) | AI6: =IF(N(B3)=0,"",EDATE(DATE(YEAR(B3),MONTH(B3),1),15)) | AJ6: =IF(N(B3)=0,"",EDATE(DATE(YEAR(B3),MONTH(B3),1),15)+15) | AK6: =IF(N(B3)=0,"",EDATE(DATE(YEAR(B3),MONTH(B3),1),16)) | AL6: =IF(N(B3)=0,"",EDATE(DATE(YEAR(B3),MONTH(B3),1),16)+15) | AM6: =IF(N(B3)=0,"",EDATE(DATE(YEAR(B3),MONTH(B3),1),17)) | AN6: =IF(N(B3)=0,"",EDATE(DATE(YEAR(B3),MONTH(B3),1),17)+15)
E7: =IF(N(B3)=0,"",EDATE(DATE(YEAR(B3),MONTH(B3),1),0)+14) | F7: =IF(N(B3)=0,"",EDATE(DATE(YEAR(B3),MONTH(B3),1),1)-1) | G7: =IF(N(B3)=0,"",EDATE(DATE(YEAR(B3),MONTH(B3),1),1)+14) | H7: =IF(N(B3)=0,"",EDATE(DATE(YEAR(B3),MONTH(B3),1),2)-1) | I7: =IF(N(B3)=0,"",EDATE(DATE(YEAR(B3),MONTH(B3),1),2)+14) | J7: =IF(N(B3)=0,"",EDATE(DATE(YEAR(B3),MONTH(B3),1),3)-1) | K7: =IF(N(B3)=0,"",EDATE(DATE(YEAR(B3),MONTH(B3),1),3)+14) | L7: =IF(N(B3)=0,"",EDATE(DATE(YEAR(B3),MONTH(B3),1),4)-1) | M7: =IF(N(B3)=0,"",EDATE(DATE(YEAR(B3),MONTH(B3),1),4)+14) | N7: =IF(N(B3)=0,"",EDATE(DATE(YEAR(B3),MONTH(B3),1),5)-1) | O7: =IF(N(B3)=0,"",EDATE(DATE(YEAR(B3),MONTH(B3),1),5)+14) | P7: =IF(N(B3)=0,"",EDATE(DATE(YEAR(B3),MONTH(B3),1),6)-1) | Q7: =IF(N(B3)=0,"",EDATE(DATE(YEAR(B3),MONTH(B3),1),6)+14) | R7: =IF(N(B3)=0,"",EDATE(DATE(YEAR(B3),MONTH(B3),1),7)-1) | S7: =IF(N(B3)=0,"",EDATE(DATE(YEAR(B3),MONTH(B3),1),7)+14) | T7: =IF(N(B3)=0,"",EDATE(DATE(YEAR(B3),MONTH(B3),1),8)-1) | U7: =IF(N(B3)=0,"",EDATE(DATE(YEAR(B3),MONTH(B3),1),8)+14) | V7: =IF(N(B3)=0,"",EDATE(DATE(YEAR(B3),MONTH(B3),1),9)-1) | W7: =IF(N(B3)=0,"",EDATE(DATE(YEAR(B3),MONTH(B3),1),9)+14) | X7: =IF(N(B3)=0,"",EDATE(DATE(YEAR(B3),MONTH(B3),1),10)-1) | Y7: =IF(N(B3)=0,"",EDATE(DATE(YEAR(B3),MONTH(B3),1),10)+14) | Z7: =IF(N(B3)=0,"",EDATE(DATE(YEAR(B3),MONTH(B3),1),11)-1) | AA7: =IF(N(B3)=0,"",EDATE(DATE(YEAR(B3),MONTH(B3),1),11)+14) | AB7: =IF(N(B3)=0,"",EDATE(DATE(YEAR(B3),MONTH(B3),1),12)-1) | AC7: =IF(N(B3)=0,"",EDATE(DATE(YEAR(B3),MONTH(B3),1),12)+14) | AD7: =IF(N(B3)=0,"",EDATE(DATE(YEAR(B3),MONTH(B3),1),13)-1) | AE7: =IF(N(B3)=0,"",EDATE(DATE(YEAR(B3),MONTH(B3),1),13)+14) | AF7: =IF(N(B3)=0,"",EDATE(DATE(YEAR(B3),MONTH(B3),1),14)-1) | AG7: =IF(N(B3)=0,"",EDATE(DATE(YEAR(B3),MONTH(B3),1),14)+14) | AH7: =IF(N(B3)=0,"",EDATE(DATE(YEAR(B3),MONTH(B3),1),15)-1) | AI7: =IF(N(B3)=0,"",EDATE(DATE(YEAR(B3),MONTH(B3),1),15)+14) | AJ7: =IF(N(B3)=0,"",EDATE(DATE(YEAR(B3),MONTH(B3),1),16)-1) | AK7: =IF(N(B3)=0,"",EDATE(DATE(YEAR(B3),MONTH(B3),1),16)+14) | AL7: =IF(N(B3)=0,"",EDATE(DATE(YEAR(B3),MONTH(B3),1),17)-1) | AM7: =IF(N(B3)=0,"",EDATE(DATE(YEAR(B3),MONTH(B3),1),17)+14) | AN7: =IF(N(B3)=0,"",EDATE(DATE(YEAR(B3),MONTH(B3),1),18)-1)
A8: 바탕처리 · 부속철물 설치 | D8: =IF(OR(N(B8)=0,N(C8)=0),"",IF(C8<B8,"⚠",C8-B8+1))
A9: 벽 초벌 바름 | D9: =IF(OR(N(B9)=0,N(C9)=0),"",IF(C9<B9,"⚠",C9-B9+1))
A10: 벽 재벌 · 정벌 바름 | D10: =IF(OR(N(B10)=0,N(C10)=0),"",IF(C10<B10,"⚠",C10-B10+1))
A11: 바닥 모르타르 바름 | D11: =IF(OR(N(B11)=0,N(C11)=0),"",IF(C11<B11,"⚠",C11-B11+1))
A12: 콘크리트 면마무리(견출) | D12: =IF(OR(N(B12)=0,N(C12)=0),"",IF(C12<B12,"⚠",C12-B12+1))
A13: 기계 피니셔 마감 | D13: =IF(OR(N(B13)=0,N(C13)=0),"",IF(C13<B13,"⚠",C13-B13+1))
A14: 보수 · 보양 · 청소 | D14: =IF(OR(N(B14)=0,N(C14)=0),"",IF(C14<B14,"⚠",C14-B14+1))
A15: 검측 · 정리 | D15: =IF(OR(N(B15)=0,N(C15)=0),"",IF(C15<B15,"⚠",C15-B15+1))
D16: =IF(OR(N(B16)=0,N(C16)=0),"",IF(C16<B16,"⚠",C16-B16+1))
D17: =IF(OR(N(B17)=0,N(C17)=0),"",IF(C17<B17,"⚠",C17-B17+1))
D18: =IF(OR(N(B18)=0,N(C18)=0),"",IF(C18<B18,"⚠",C18-B18+1))
D19: =IF(OR(N(B19)=0,N(C19)=0),"",IF(C19<B19,"⚠",C19-B19+1))
D20: =IF(OR(N(B20)=0,N(C20)=0),"",IF(C20<B20,"⚠",C20-B20+1))
D21: =IF(OR(N(B21)=0,N(C21)=0),"",IF(C21<B21,"⚠",C21-B21+1))
A22: ※ 일수 = 완료 − 착수 + 1. 막대는 반달(1~15일 · 16일~말일) 단위입니다. 공정은 현장 여건 · 날씨에 따라 바뀔 수 있습니다.
A24: 하늘색 칸 = 자동(착공일 · 달 머리 · 일수). 공종 이름은 원본 차례를 미리 넣어 두었습니다 — 현장에 맞게 고쳐 쓰세요.

Sheet 관리계획
A1: K-건설맵 | k-conmap.com 건설 서식 | G1: ← 이 1행을 지우고 쓰셔도 됩니다
A3: 8.0 품 질 관 리 계 획
A6: 8-1 품질관리 일반 및 적용범위
A7: (1) | B7: 공사 진행 중 필요에 따라 각종 승인도면 · 제작도면 · 제작요령서 등을 작성하여 공사감독자(감리원)의 승인을 받는다.
A8: (2) | B8: 공사용 재료는 도면 · 공사시방서 및 공사감독자의 지시에 따라, 쓰기 전에 견본 또는 자료를 제출하여 승인을 받은 뒤 쓴다.
A9: (3) | B9: 품질시험은 「건설기술 진흥법」 및 같은 법 시행령 · 시행규칙과 공사시방서에서 정한 바에 따른다.
A11: 8-2 공사용 재료의 품질
A12: (1) | B12: 설계도면 · 공사시방서 및 공사감독자의 따로 지시가 없으면 시방서에서 정한 품질과 규격에 맞는 재료를 쓴다.
A13: (2) | B13: 시방서에 품질 규격이 없으면 한국산업표준(KS) 표시품 또는 이에 준하는 품질과 규격의 재료를 쓴다.
A14: (3) | B14: 기성품을 포함한 공사용 재료는 현장 반입 전에 자재승인 서류(견본 · 카탈로그 · 시험성적서 등)를 제출하여 승인을 받고, 공사감독자의 지시에 따라 품질을 확인할 수 있는 증빙서류를 낸다.
A15: (4) | B15: 재료가 현장에 들어오면 공사감독자의 인수검사를 받고, 합격한 재료는 작업 · 통행에 지장이 없는 곳에 보관하여 수시 점검이 쉽게 한다.
A16: (5) | B16: 「건설기술 진흥법」에 규정된 품질시험을 하고, 시험실 규모 · 시험장비 · 시험요원 배치기준에 따라 시험실을 운영한다.
A17: (6) | B17: 검사 또는 시험에 불합격한 재료는 지체 없이 현장 밖으로 반출한다.
A19: 8-3 시공 확인 및 검사
A20: (1) | B20: 주요 공사단계가 끝났을 때나 공사감독자가 지시할 때는 시공의 정확성과 품질을 확인받는다.
A21: (2) | B21: 검사에 필요한 자료 작성 · 측량 등은 검사자의 지시에 따른다.
A23: 8-4 자재관리
A24: (1) | B24: 들어온 자재는 자재수불대장으로 입 · 출고를 관리한다.
A25: (2) | B25: 자재는 재질별 · 규격별로 나누어 보관한다.
A26: (3) | B26: 운반 · 야적 때 변형되지 않도록 전용 운반 가설대 또는 전용 야적대를 쓴다.
A27: (4) | B27: 반입 자재는 받침목 · 지지목 등으로 지면에서 200mm 이상 띄우고 손상 · 변형 · 침수되지 않게 한다.
A28: (5) | B28: 변형을 막기 위해 받침목 높이를 맞추고 1단 적재를 기본으로 한다.
A30: 9.0 환 경 관 리 계 획
A33: 9-1 개 요
A34: 현장의 폐기물 · 유류 · 쓰레기 및 소음 · 진동 · 비산먼지 등에 의한 오염을 방지한다.
A36: 9-2 중점관리 방침
A37: (1) | B37: 자율적인 환경관리
A38: (2) | B38: 쾌적한 작업환경 관리
A39: (3) | B39: 민원 발생 방지
A41: 9-3 실시계획
A42: (1) | B42: 작업 전후 정리정돈 : 작업 전후 정리정돈을 철저히 하여 쾌적한 작업환경을 유지한다.
A43: (2) | B43: 분리수거 : 분리수거를 철저히 하고, 미장 작업에서 나온 폐기물(모르타르 찌꺼기 · 포대 등)은 시공업체 부담으로 적법하게 처리하여 쓰레기를 줄인다.
A44: (3) | B44: 민원 발생 억제 : 소음 · 진동 · 비산먼지 · 냄새를 최대한 억제하여 인근 주민의 생활에 피해가 없도록 하고, 적극적으로 환경관리 활동을 한다.
B45: (4) 환경관리 대책
A46: ① | C46: 쓰레기 처리 : 현장 안은 금연하고 쓰레기 수거함을 둔다.
A47: ② | C47: 잔재물 : 모르타르 찌꺼기 · 시멘트 포대 등은 지정된 장소에 모아 두고 지정 업체가 수거하게 한다.
A48: ③ | C48: 비산먼지 : 현장 안 주요 도로와 작업장 주변은 하루 2회 이상 살수차로 살수하고, 장비 이동 때 먼지가 나지 않도록 서행한다.
A50: 10.0 안 전 관 리 계 획
A53: 10-1 안전관리 목적
A54: 공종의 특수성을 고려하여 현장의 위험요소를 미리 없애 사고를 막음으로써 귀중한 인명을 보호하고 재산 손실을 최소화하며, 작업 능률을 높여 계획 공정을 원만히 달성하는 데 목적이 있다.
...

Sheet 예시-표지
A1: K-건설맵 | k-conmap.com 건설 서식 | G1: 작성 예시 (가상의 현장)
A3: 가나학교 교사 증축공사
A5: 시 공 계 획 서
A6: [ 미장공사 ]
A8: 46082
A10: 예시건설(주)
A12: 이 시트는 작성 예시입니다(가상의 공사 · 회사 · 사람).

Sheet 예시-개요
A1: K-건설맵 | k-conmap.com 건설 서식 | G1: 작성 예시 (가상의 현장)
A3: 목 차
C5: 1. 공 사 명
C6: 2. 공 사 개 요
C7: 3. 공 사 위 치
C8: 4. 주요 공사 물량
C9: 5. 현 장 조 직 도
C10: 6. 시 공 관 리
C11: 7. 예 정 공 정 표
C12: 8. 품 질 관 리 계 획
C13: 9. 환 경 관 리 계 획
C14: 10. 안 전 관 리 계 획
A16: 1.0 공 사 명
B18: =IF(OR('예시-표지'!A3="",'예시-표지'!A3="(공 사 명)"),"","◦ "&'예시-표지'!A3)
A20: 2.0 공 사 개 요
A22: 공 사 명 | D22: =IF(OR('예시-표지'!A3="",'예시-표지'!A3="(공 사 명)"),"",'예시-표지'!A3)
A23: 공 사 위 치 | D23: 가나시 가나동 일원
A24: 발 주 처 | D24: 가나시교육청
A25: 공 사 기 간 | D25: 46083 | F25: ~ | G25: 46387 | I25: =IF(OR(N(D25)=0,N(G25)=0),"",IF(G25<D25,"⚠ 준공일이 착공일보다 빠름",G25-D25+1))
A26: 공 사 금 액 | D26: 8450000000 | G26: =IF(N(D26)=0,"",D26)
A27: 공 사 규 모 | D27: 교사동 증축(지상 4층) · 실습동 리모델링
A28: 시 공 사 | D28: =IF(OR('예시-표지'!A10="",'예시-표지'!A10="(회 사 명)"),"",'예시-표지'!A10)
A30: 3.0 공 사 위 치
A32: (위치도를 붙이는 곳 — 현장 위치와 미장 공사 구간을 표시)
A45: 4.0 주요 공사 물량
A47: 구 분 | C47: 명 칭 | F47: 규 격 | H47: 수 량 | J47: 단위 | K47: 비 고
A48: 교사동 | C48: 모르타르 기계바름 | F48: 모르타르 1 : 3 | H48: 2380 | J48: ㎡
A49: 교사동 | C49: 모르타르 바름 | F49: 내벽 11mm | H49: 1090 | J49: ㎡
A50: 교사동 | C50: 모르타르 바름 | F50: 외벽 11mm | H50: 170 | J50: ㎡
A51: 교사동 | C51: 모르타르 바름 | F51: 내벽 9mm(초벌) | H51: 130 | J51: ㎡
A52: 교사동 | C52: 콘크리트면 마무리 | F52: 콘크리트면 정리 | H52: 1240 | J52: ㎡
A53: 교사동 | C53: 기계 피니셔 마감 | F53: 기계마감 + 면정리 | H53: 1950 | J53: ㎡
A54: 실습동 | C54: 모르타르 기계바름 | F54: 모르타르 1 : 3 | H54: 1020 | J54: ㎡
A55: 실습동 | C55: 모르타르 바름 | F55: 내벽 11mm | H55: 1060 | J55: ㎡
A56: 실습동 | C56: 콘크리트면 마무리 | F56: 콘크리트면 정리 | H56: 1190 | J56: ㎡
A57: 실습동 | C57: 에폭시 레진 모르타르 | F57: 바닥 3mm | H57: 125 | J57: ㎡
A60: 합 계 (단위가 ㎡ 인 줄) | H60: =IF(SUMIF(J48:J59,"㎡",H48:H59)+SUMIF(J48:J59,"m2",H48:H59)=0,"",SUMIF(J48:J59,"㎡",H48:H59)+SUMIF(J48:J59,"m2",H48:H59)) | J60: ㎡
A62: 5.0 현 장 조 직 도
E64: 현 장 대 리 인
E65: 홍길동
...

Sheet 예시-시공관리
A1: K-건설맵 | k-conmap.com 건설 서식 | G1: 작성 예시 (가상의 현장)
A3: 6.0 시 공 관 리
A6: 6-1 시멘트 모르타르 바름
A7: 1) 적용 범위
A8: 이 절은 시멘트 · 골재 등을 주재료로 한 시멘트 모르타르를 벽 · 바닥 · 천장 등에 바르는 경우에 적용한다.
A9: 2) 한국산업표준(KS)
A10: (1) | B10: KS A 5101 — 표준체
A11: (2) | B11: KS F 4552 — 메탈라스
A12: (3) | B12: KS L 5201 — 포틀랜드 시멘트
A13: (4) | B13: KS L 5204 — 백색 포틀랜드 시멘트
A14: (5) | B14: KS L 9007 — 미장용 생석회 및 소석회
A15: (6) | B15: KS L 5220 — 건조 시멘트 모르타르
A16: 3) 운반 · 보관 · 취급
A17: (1) | B17: 미장용 재료는 섞이거나 훼손되지 않도록 보관한다.
A18: (2) | B18: 공장 제조품은 공장에서 나올 때의 포장이 파손되지 않은 상태로 반입하며, 포장에서 품명 · 자재명 · 수량 · 종류 · 형태를 확인할 수 있어야 한다.
A19: (3) | B19: 시멘트 · 석회 및 부속 재료는 비를 맞지 않게 덮고, 지면보다 30cm 이상 높게 만든 바닥이 있는 창고 등에 건조 상태로 보관하며 겹쳐 쌓기는 13포 이하로 한다.
A20: 4) 환경 요구사항
A21: (1) | B21: 시멘트 모르타르를 바르기 전과 바른 후 최소 1주일 이상 온도를 4℃ 이상으로 유지한다.
A22: (2) | B22: 시멘트 모르타르를 바른 후 최소 1주일 이상 환기를 원활하게 유지한다.
A23: (3) | B23: 동절기 공사는 원칙적으로 하지 않되, 부득이하게 시공할 때는 감리원의 승인을 받은 뒤 보양 · 보온하고 시공한다. 바름면이 들뜨거나 동해를 입었으면 쪼아 내고 다시 바른다.
A24: 5) 다른 공정과의 협력 작업
A25: 매입용 철물(insert) · 고정철물 · 전선배관 등 특별 사항은 미장공사와 관련된 다른 공사 부서에 설명하고, 알맞게 설치되도록 정확한 설치 위치와 설치물에 대해 협조한다.
A26: 6) 재료
B27: (1) 시멘트 — 포틀랜드 시멘트는 KS L 5201 의 1종(보통 포틀랜드 시멘트)에 맞는 제품을 쓴다.
B28: (2) 모래 — 단단하고 깨끗하며 먼지 · 흙 · 유기물 등 유해물이 섞이지 않은 것. 품질기준 :
A29: ▸ | C29: 절건비중 2.4 이상
A30: ▸ | C30: 흡수율 4.0% 이하
A31: ▸ | C31: 점토량 2.0% 이하
A32: ▸ | C32: 유기불순물 — 표준색보다 진하지 않은 것
A33: ▸ | C33: 씻기 시험으로 손실되는 양 3% 이하
A34: ▸ | C34: 염화물 함유량 0.1% 이하
B35: (3) 물 — 유해한 기름 · 산 · 알칼리 · 유기물 등이 기준량 이상 들어 있지 않은, 식수로 쓸 수 있는 깨끗한 물을 쓴다.
B36: (4) 접착재 — 보수성 · 작업성 · 부착성 등을 높이는 것으로, 수축이 적은 합성수지계 무기질 재료를 쓴다.
B37: (5) 부속 재료
A38: ① | C38: 메탈라스 : KS F 4552 에 맞는 메탈라스를 쓴다.
A39: ② | C39: 코너비드 : 두께 0.45mm 아연도금 철재로, 비드 지름 4mm 이고 양쪽에 폭 50mm 의 메시형 날개가 붙은 것을 쓴다.
A40: ③ | C40: 신축줄눈 : 두께 0.45mm 아연도금 철재로, 비드 깊이 13mm 이고 양쪽에 폭 50mm 의 메시형 날개가 붙은 것을 쓴다.
A41: 7) 모르타르 배합
A42: (1) | B42: 미장용 모르타르는 포틀랜드 시멘트 1 : 모래 3 의 비율로 배합한다.
A43: (2) | B43: 시멘트 풀은 포틀랜드 시멘트 1 : 모래 0 의 비율로 배합한다.
...

Sheet 예시-검측체크
A1: K-건설맵 | k-conmap.com 건설 서식 | G1: 작성 예시 (가상의 현장)
A2: 검 측 체 크 리 스 트
A3: 공종 CODE NO. | E3: 미 장 공 사 | G3: 위치 및 부위 | I3: 교사동 2층 교실 벽체
A4: 공종(세부공종) | C4: 벽체 시멘트 모르타르 바르기 — 바탕면 처리 및 준비 상태 | G4: 검 측 일 자 | I4: 46140
A5: 검 사 항 목 | F5: 검 사 기 준 (시방서 · 도면 등) | H5: 검 사 결 과 | L5: 조치 사항
H6: 1 차 | J6: 2 차
H7: 합격 | I7: 불합격 | J7: 합격 | K7: 불합격
A8: 1. 시멘트 · 모래 자재공급원 승인은 되었는가 | F8: 승인 여부 | H8: ○
A9: 2. 각종 라스 및 메탈라스의 자재공급원 승인은 되었는가 | F9: 승인 여부 | H9: ○
A10: 3. 바탕처리는 적정한가(물축임 · 오염 제거 등) | F10: 적 · 부 | H10: ○
A11: 4. 구조체 곰보 · 이음 조인트 · 균열 · 재료분리 등의 조치는 적정한가 | F11: 적 · 부 | H11: ○
A12: 5. 창틀 주변 모르타르 사춤은 완료하였는가 | F12: 적 · 부 | H12: ○
A13: 6. 전기 및 설비 배관 부위 모르타르 사춤은 완료하였는가 | F13: 적 · 부 | H13: ○
A14: 7. 이질재 접합부 라스 설치 및 코너비드 설치 상태는 적정한가 | F14: 적 · 부 | H14: ○
A15: 8. 균열 방지용 메탈라스의 설치 방법 및 보강 위치는 적정한가 | F15: 시공상세도 | H15: ○
A16: 9. 시멘트벽돌 쌓기 완료 후 일정 기간 보양을 하였는가 | F16: 적 · 부 | H16: ○
A17: 10. 콘크리트 균열 부위는 적정하게 보수하였는가(에폭시 그라우팅) | F17: 적 · 부 | H17: ○
A18: 판 정 | D18: =IF(COUNTA(H8:H17)+COUNTA(I8:I17)=0,"","1차 합격 "&COUNTA(H8:H17)&" · 불합격 "&COUNTA(I8:I17)&IF(COUNTA(I8:I17)>0," / 2차 합격 "&COUNTA(J8:J17)&" · 불합격 "&COUNTA(K8:K17),"")&IF(COUNTA(H8:H17)+COUNTA(I8:I17)<10," · 빈칸 "&(10-COUNTA(H8:H17)-COUNTA(I8:I17)),"")&" → "&IF(COUNTA(I8:I17)=0,IF(COUNTA(H8:H17)+COUNTA(I8:I17)<10,"점검 중","합격"),IF(AND(COUNTA(K8:K17)=0,COUNTA(J8:J17)>=COUNTA(I8:I17)),"합격(재검측)","보완 후 재검측")))
A19: 시 공 자 점 검 | G19: 감 리 원 검 측
A20: 점 검 | D20: 재 점 검 | G20: 검 측 | J20: 재 검 측
A21: (인) | D21: (인) | G21: (인) | J21: (인)
A22: 검 측 체 크 리 스 트
A23: 공종 CODE NO. | E23: 미 장 공 사 | G23: 위치 및 부위 | I23: 교사동 2층 교실 벽체
A24: 공종(세부공종) | C24: 벽체 시멘트 모르타르 바르기 — 초벌 바름 완료 상태 | G24: 검 측 일 자 | I24: 46154
A25: 검 사 항 목 | F25: 검 사 기 준 (시방서 · 도면 등) | H25: 검 사 결 과 | L25: 조치 사항
H26: 1 차 | J26: 2 차
H27: 합격 | I27: 불합격 | J27: 합격 | K27: 불합격
A28: 1. 시멘트 보관 및 관리는 적정한가(반입일자 · 야적상태 · 습기 등) | F28: 적 · 부 | H28: ○
A29: 2. 모래 입도는 적정하며 진흙 · 먼지 · 철분 함유는 없는가 | F29: 적 · 부 | H29: ○
A30: 3. 물은 깨끗하고 유해물이 포함되지 않았는가 | F30: 적 · 부 | H30: ○
A31: 4. 초벌 바름 두께는 적정한가 | F31: 7mm | I31: ○ | J31: ○ | L31: 덧바름 후 재검측
A32: 5. 면 긁어 주기는 적정한가 | F32: 가늘고 고르게 | H32: ○
A33: 6. 구획별 양생 기간은 적정한가 | F33: 초벌 바름 후 7일 경과 | H33: ○
A34: 7. 덧먹임 부분 및 바름 벽은 평활하며 들뜬 곳은 없는가 | F34: 적 · 부 | H34: ○
A35: 8. 창호틀 등에 모르타르 오염은 없으며 보양 상태는 양호한가 | F35: 적 · 부 | H35: ○
A36: 9. 시공 전 1일 이상, 시공 중 및 시공 후 3일 이상 영상 온도를 유지하였는가 | F36: 적 · 부 | H36: ○
A37: 판 정 | D37: =IF(COUNTA(H28:H36)+COUNTA(I28:I36)=0,"","1차 합격 "&COUNTA(H28:H36)&" · 불합격 "&COUNTA(I28:I36)&IF(COUNTA(I28:I36)>0," / 2차 합격 "&COUNTA(J28:J36)&" · 불합격 "&COUNTA(K28:K36),"")&IF(COUNTA(H28:H36)+COUNTA(I28:I36)<9," · 빈칸 "&(9-COUNTA(H28:H36)-COUNTA(I28:I36)),"")&" → "&IF(COUNTA(I28:I36)=0,IF(COUNTA(H28:H36)+COUNTA(I28:I36)<9,"점검 중","합격"),IF(AND(COUNTA(K28:K36)=0,COUNTA(J28:J36)>=COUNTA(I28:I36)),"합격(재검측)","보완 후 재검측")))
A38: 시 공 자 점 검 | G38: 감 리 원 검 측
A39: 점 검 | D39: 재 점 검 | G39: 검 측 | J39: 재 검 측
A40: (인) | D40: (인) | G40: (인) | J40: (인)
...

Sheet 예시-공정표
A1: K-건설맵 | k-conmap.com 건설 서식 | N1: 작성 예시 (가상의 현장)
A2: 7.0 예 정 공 정 표
A3: 착 공 일 | B3: =IF(N('예시-개요'!D25)=0,"",'예시-개요'!D25) | D3: ※ 착공일은 공사개요에서 따라옵니다. 공종마다 착수 · 완료일을 적으면 반달 칸에 막대가 그려집니다.
A4: 공 종 | B4: 착 수 | C4: 완 료 | D4: 일 수 | E4: =IF(N(B3)=0,"",EDATE(DATE(YEAR(B3),MONTH(B3),1),0)) | G4: =IF(N(B3)=0,"",EDATE(DATE(YEAR(B3),MONTH(B3),1),1)) | I4: =IF(N(B3)=0,"",EDATE(DATE(YEAR(B3),MONTH(B3),1),2)) | K4: =IF(N(B3)=0,"",EDATE(DATE(YEAR(B3),MONTH(B3),1),3)) | M4: =IF(N(B3)=0,"",EDATE(DATE(YEAR(B3),MONTH(B3),1),4)) | O4: =IF(N(B3)=0,"",EDATE(DATE(YEAR(B3),MONTH(B3),1),5)) | Q4: =IF(N(B3)=0,"",EDATE(DATE(YEAR(B3),MONTH(B3),1),6)) | S4: =IF(N(B3)=0,"",EDATE(DATE(YEAR(B3),MONTH(B3),1),7)) | U4: =IF(N(B3)=0,"",EDATE(DATE(YEAR(B3),MONTH(B3),1),8)) | W4: =IF(N(B3)=0,"",EDATE(DATE(YEAR(B3),MONTH(B3),1),9)) | Y4: =IF(N(B3)=0,"",EDATE(DATE(YEAR(B3),MONTH(B3),1),10)) | AA4: =IF(N(B3)=0,"",EDATE(DATE(YEAR(B3),MONTH(B3),1),11)) | AC4: =IF(N(B3)=0,"",EDATE(DATE(YEAR(B3),MONTH(B3),1),12)) | AE4: =IF(N(B3)=0,"",EDATE(DATE(YEAR(B3),MONTH(B3),1),13)) | AG4: =IF(N(B3)=0,"",EDATE(DATE(YEAR(B3),MONTH(B3),1),14)) | AI4: =IF(N(B3)=0,"",EDATE(DATE(YEAR(B3),MONTH(B3),1),15)) | AK4: =IF(N(B3)=0,"",EDATE(DATE(YEAR(B3),MONTH(B3),1),16)) | AM4: =IF(N(B3)=0,"",EDATE(DATE(YEAR(B3),MONTH(B3),1),17)) | AO4: 비 고
E5: 상 | F5: 하 | G5: 상 | H5: 하 | I5: 상 | J5: 하 | K5: 상 | L5: 하 | M5: 상 | N5: 하 | O5: 상 | P5: 하 | Q5: 상 | R5: 하 | S5: 상 | T5: 하 | U5: 상 | V5: 하 | W5: 상 | X5: 하 | Y5: 상 | Z5: 하 | AA5: 상 | AB5: 하 | AC5: 상 | AD5: 하 | AE5: 상 | AF5: 하 | AG5: 상 | AH5: 하 | AI5: 상 | AJ5: 하 | AK5: 상 | AL5: 하 | AM5: 상 | AN5: 하
E6: =IF(N(B3)=0,"",EDATE(DATE(YEAR(B3),MONTH(B3),1),0)) | F6: =IF(N(B3)=0,"",EDATE(DATE(YEAR(B3),MONTH(B3),1),0)+15) | G6: =IF(N(B3)=0,"",EDATE(DATE(YEAR(B3),MONTH(B3),1),1)) | H6: =IF(N(B3)=0,"",EDATE(DATE(YEAR(B3),MONTH(B3),1),1)+15) | I6: =IF(N(B3)=0,"",EDATE(DATE(YEAR(B3),MONTH(B3),1),2)) | J6: =IF(N(B3)=0,"",EDATE(DATE(YEAR(B3),MONTH(B3),1),2)+15) | K6: =IF(N(B3)=0,"",EDATE(DATE(YEAR(B3),MONTH(B3),1),3)) | L6: =IF(N(B3)=0,"",EDATE(DATE(YEAR(B3),MONTH(B3),1),3)+15) | M6: =IF(N(B3)=0,"",EDATE(DATE(YEAR(B3),MONTH(B3),1),4)) | N6: =IF(N(B3)=0,"",EDATE(DATE(YEAR(B3),MONTH(B3),1),4)+15) | O6: =IF(N(B3)=0,"",EDATE(DATE(YEAR(B3),MONTH(B3),1),5)) | P6: =IF(N(B3)=0,"",EDATE(DATE(YEAR(B3),MONTH(B3),1),5)+15) | Q6: =IF(N(B3)=0,"",EDATE(DATE(YEAR(B3),MONTH(B3),1),6)) | R6: =IF(N(B3)=0,"",EDATE(DATE(YEAR(B3),MONTH(B3),1),6)+15) | S6: =IF(N(B3)=0,"",EDATE(DATE(YEAR(B3),MONTH(B3),1),7)) | T6: =IF(N(B3)=0,"",EDATE(DATE(YEAR(B3),MONTH(B3),1),7)+15) | U6: =IF(N(B3)=0,"",EDATE(DATE(YEAR(B3),MONTH(B3),1),8)) | V6: =IF(N(B3)=0,"",EDATE(DATE(YEAR(B3),MONTH(B3),1),8)+15) | W6: =IF(N(B3)=0,"",EDATE(DATE(YEAR(B3),MONTH(B3),1),9)) | X6: =IF(N(B3)=0,"",EDATE(DATE(YEAR(B3),MONTH(B3),1),9)+15) | Y6: =IF(N(B3)=0,"",EDATE(DATE(YEAR(B3),MONTH(B3),1),10)) | Z6: =IF(N(B3)=0,"",EDATE(DATE(YEAR(B3),MONTH(B3),1),10)+15) | AA6: =IF(N(B3)=0,"",EDATE(DATE(YEAR(B3),MONTH(B3),1),11)) | AB6: =IF(N(B3)=0,"",EDATE(DATE(YEAR(B3),MONTH(B3),1),11)+15) | AC6: =IF(N(B3)=0,"",EDATE(DATE(YEAR(B3),MONTH(B3),1),12)) | AD6: =IF(N(B3)=0,"",EDATE(DATE(YEAR(B3),MONTH(B3),1),12)+15) | AE6: =IF(N(B3)=0,"",EDATE(DATE(YEAR(B3),MONTH(B3),1),13)) | AF6: =IF(N(B3)=0,"",EDATE(DATE(YEAR(B3),MONTH(B3),1),13)+15) | AG6: =IF(N(B3)=0,"",EDATE(DATE(YEAR(B3),MONTH(B3),1),14)) | AH6: =IF(N(B3)=0,"",EDATE(DATE(YEAR(B3),MONTH(B3),1),14)+15) | AI6: =IF(N(B3)=0,"",EDATE(DATE(YEAR(B3),MONTH(B3),1),15)) | AJ6: =IF(N(B3)=0,"",EDATE(DATE(YEAR(B3),MONTH(B3),1),15)+15) | AK6: =IF(N(B3)=0,"",EDATE(DATE(YEAR(B3),MONTH(B3),1),16)) | AL6: =IF(N(B3)=0,"",EDATE(DATE(YEAR(B3),MONTH(B3),1),16)+15) | AM6: =IF(N(B3)=0,"",EDATE(DATE(YEAR(B3),MONTH(B3),1),17)) | AN6: =IF(N(B3)=0,"",EDATE(DATE(YEAR(B3),MONTH(B3),1),17)+15)
E7: =IF(N(B3)=0,"",EDATE(DATE(YEAR(B3),MONTH(B3),1),0)+14) | F7: =IF(N(B3)=0,"",EDATE(DATE(YEAR(B3),MONTH(B3),1),1)-1) | G7: =IF(N(B3)=0,"",EDATE(DATE(YEAR(B3),MONTH(B3),1),1)+14) | H7: =IF(N(B3)=0,"",EDATE(DATE(YEAR(B3),MONTH(B3),1),2)-1) | I7: =IF(N(B3)=0,"",EDATE(DATE(YEAR(B3),MONTH(B3),1),2)+14) | J7: =IF(N(B3)=0,"",EDATE(DATE(YEAR(B3),MONTH(B3),1),3)-1) | K7: =IF(N(B3)=0,"",EDATE(DATE(YEAR(B3),MONTH(B3),1),3)+14) | L7: =IF(N(B3)=0,"",EDATE(DATE(YEAR(B3),MONTH(B3),1),4)-1) | M7: =IF(N(B3)=0,"",EDATE(DATE(YEAR(B3),MONTH(B3),1),4)+14) | N7: =IF(N(B3)=0,"",EDATE(DATE(YEAR(B3),MONTH(B3),1),5)-1) | O7: =IF(N(B3)=0,"",EDATE(DATE(YEAR(B3),MONTH(B3),1),5)+14) | P7: =IF(N(B3)=0,"",EDATE(DATE(YEAR(B3),MONTH(B3),1),6)-1) | Q7: =IF(N(B3)=0,"",EDATE(DATE(YEAR(B3),MONTH(B3),1),6)+14) | R7: =IF(N(B3)=0,"",EDATE(DATE(YEAR(B3),MONTH(B3),1),7)-1) | S7: =IF(N(B3)=0,"",EDATE(DATE(YEAR(B3),MONTH(B3),1),7)+14) | T7: =IF(N(B3)=0,"",EDATE(DATE(YEAR(B3),MONTH(B3),1),8)-1) | U7: =IF(N(B3)=0,"",EDATE(DATE(YEAR(B3),MONTH(B3),1),8)+14) | V7: =IF(N(B3)=0,"",EDATE(DATE(YEAR(B3),MONTH(B3),1),9)-1) | W7: =IF(N(B3)=0,"",EDATE(DATE(YEAR(B3),MONTH(B3),1),9)+14) | X7: =IF(N(B3)=0,"",EDATE(DATE(YEAR(B3),MONTH(B3),1),10)-1) | Y7: =IF(N(B3)=0,"",EDATE(DATE(YEAR(B3),MONTH(B3),1),10)+14) | Z7: =IF(N(B3)=0,"",EDATE(DATE(YEAR(B3),MONTH(B3),1),11)-1) | AA7: =IF(N(B3)=0,"",EDATE(DATE(YEAR(B3),MONTH(B3),1),11)+14) | AB7: =IF(N(B3)=0,"",EDATE(DATE(YEAR(B3),MONTH(B3),1),12)-1) | AC7: =IF(N(B3)=0,"",EDATE(DATE(YEAR(B3),MONTH(B3),1),12)+14) | AD7: =IF(N(B3)=0,"",EDATE(DATE(YEAR(B3),MONTH(B3),1),13)-1) | AE7: =IF(N(B3)=0,"",EDATE(DATE(YEAR(B3),MONTH(B3),1),13)+14) | AF7: =IF(N(B3)=0,"",EDATE(DATE(YEAR(B3),MONTH(B3),1),14)-1) | AG7: =IF(N(B3)=0,"",EDATE(DATE(YEAR(B3),MONTH(B3),1),14)+14) | AH7: =IF(N(B3)=0,"",EDATE(DATE(YEAR(B3),MONTH(B3),1),15)-1) | AI7: =IF(N(B3)=0,"",EDATE(DATE(YEAR(B3),MONTH(B3),1),15)+14) | AJ7: =IF(N(B3)=0,"",EDATE(DATE(YEAR(B3),MONTH(B3),1),16)-1) | AK7: =IF(N(B3)=0,"",EDATE(DATE(YEAR(B3),MONTH(B3),1),16)+14) | AL7: =IF(N(B3)=0,"",EDATE(DATE(YEAR(B3),MONTH(B3),1),17)-1) | AM7: =IF(N(B3)=0,"",EDATE(DATE(YEAR(B3),MONTH(B3),1),17)+14) | AN7: =IF(N(B3)=0,"",EDATE(DATE(YEAR(B3),MONTH(B3),1),18)-1)
A8: 바탕처리 · 부속철물 설치 | B8: 46113 | C8: 46142 | D8: =IF(OR(N(B8)=0,N(C8)=0),"",IF(C8<B8,"⚠",C8-B8+1))
A9: 벽 초벌 바름 | B9: 46128 | C9: 46173 | D9: =IF(OR(N(B9)=0,N(C9)=0),"",IF(C9<B9,"⚠",C9-B9+1))
A10: 벽 재벌 · 정벌 바름 | B10: 46158 | C10: 46203 | D10: =IF(OR(N(B10)=0,N(C10)=0),"",IF(C10<B10,"⚠",C10-B10+1))
A11: 바닥 모르타르 바름 | B11: 46174 | C11: 46218 | D11: =IF(OR(N(B11)=0,N(C11)=0),"",IF(C11<B11,"⚠",C11-B11+1))
A12: 콘크리트 면마무리(견출) | B12: 46143 | C12: 46203 | D12: =IF(OR(N(B12)=0,N(C12)=0),"",IF(C12<B12,"⚠",C12-B12+1))
A13: 기계 피니셔 마감 | B13: 46189 | C13: 46234 | D13: =IF(OR(N(B13)=0,N(C13)=0),"",IF(C13<B13,"⚠",C13-B13+1))
A14: 보수 · 보양 · 청소 | B14: 46219 | C14: 46249 | D14: =IF(OR(N(B14)=0,N(C14)=0),"",IF(C14<B14,"⚠",C14-B14+1))
A15: 검측 · 정리 | B15: 46235 | C15: 46265 | D15: =IF(OR(N(B15)=0,N(C15)=0),"",IF(C15<B15,"⚠",C15-B15+1))
D16: =IF(OR(N(B16)=0,N(C16)=0),"",IF(C16<B16,"⚠",C16-B16+1))
D17: =IF(OR(N(B17)=0,N(C17)=0),"",IF(C17<B17,"⚠",C17-B17+1))
D18: =IF(OR(N(B18)=0,N(C18)=0),"",IF(C18<B18,"⚠",C18-B18+1))
D19: =IF(OR(N(B19)=0,N(C19)=0),"",IF(C19<B19,"⚠",C19-B19+1))
D20: =IF(OR(N(B20)=0,N(C20)=0),"",IF(C20<B20,"⚠",C20-B20+1))
D21: =IF(OR(N(B21)=0,N(C21)=0),"",IF(C21<B21,"⚠",C21-B21+1))
A22: ※ 일수 = 완료 − 착수 + 1. 막대는 반달(1~15일 · 16일~말일) 단위입니다. 공정은 현장 여건 · 날씨에 따라 바뀔 수 있습니다.
A24: 이 시트는 작성 예시입니다(가상의 일정).

Sheet 예시-관리계획
A1: K-건설맵 | k-conmap.com 건설 서식 | G1: 작성 예시 (가상의 현장)
A3: 8.0 품 질 관 리 계 획
A6: 8-1 품질관리 일반 및 적용범위
A7: (1) | B7: 공사 진행 중 필요에 따라 각종 승인도면 · 제작도면 · 제작요령서 등을 작성하여 공사감독자(감리원)의 승인을 받는다.
A8: (2) | B8: 공사용 재료는 도면 · 공사시방서 및 공사감독자의 지시에 따라, 쓰기 전에 견본 또는 자료를 제출하여 승인을 받은 뒤 쓴다.
A9: (3) | B9: 품질시험은 「건설기술 진흥법」 및 같은 법 시행령 · 시행규칙과 공사시방서에서 정한 바에 따른다.
A11: 8-2 공사용 재료의 품질
A12: (1) | B12: 설계도면 · 공사시방서 및 공사감독자의 따로 지시가 없으면 시방서에서 정한 품질과 규격에 맞는 재료를 쓴다.
A13: (2) | B13: 시방서에 품질 규격이 없으면 한국산업표준(KS) 표시품 또는 이에 준하는 품질과 규격의 재료를 쓴다.
A14: (3) | B14: 기성품을 포함한 공사용 재료는 현장 반입 전에 자재승인 서류(견본 · 카탈로그 · 시험성적서 등)를 제출하여 승인을 받고, 공사감독자의 지시에 따라 품질을 확인할 수 있는 증빙서류를 낸다.
A15: (4) | B15: 재료가 현장에 들어오면 공사감독자의 인수검사를 받고, 합격한 재료는 작업 · 통행에 지장이 없는 곳에 보관하여 수시 점검이 쉽게 한다.
A16: (5) | B16: 「건설기술 진흥법」에 규정된 품질시험을 하고, 시험실 규모 · 시험장비 · 시험요원 배치기준에 따라 시험실을 운영한다.
A17: (6) | B17: 검사 또는 시험에 불합격한 재료는 지체 없이 현장 밖으로 반출한다.
A19: 8-3 시공 확인 및 검사
A20: (1) | B20: 주요 공사단계가 끝났을 때나 공사감독자가 지시할 때는 시공의 정확성과 품질을 확인받는다.
A21: (2) | B21: 검사에 필요한 자료 작성 · 측량 등은 검사자의 지시에 따른다.
A23: 8-4 자재관리
A24: (1) | B24: 들어온 자재는 자재수불대장으로 입 · 출고를 관리한다.
A25: (2) | B25: 자재는 재질별 · 규격별로 나누어 보관한다.
A26: (3) | B26: 운반 · 야적 때 변형되지 않도록 전용 운반 가설대 또는 전용 야적대를 쓴다.
A27: (4) | B27: 반입 자재는 받침목 · 지지목 등으로 지면에서 200mm 이상 띄우고 손상 · 변형 · 침수되지 않게 한다.
A28: (5) | B28: 변형을 막기 위해 받침목 높이를 맞추고 1단 적재를 기본으로 한다.
A30: 9.0 환 경 관 리 계 획
A33: 9-1 개 요
A34: 현장의 폐기물 · 유류 · 쓰레기 및 소음 · 진동 · 비산먼지 등에 의한 오염을 방지한다.
A36: 9-2 중점관리 방침
A37: (1) | B37: 자율적인 환경관리
A38: (2) | B38: 쾌적한 작업환경 관리
A39: (3) | B39: 민원 발생 방지
A41: 9-3 실시계획
A42: (1) | B42: 작업 전후 정리정돈 : 작업 전후 정리정돈을 철저히 하여 쾌적한 작업환경을 유지한다.
A43: (2) | B43: 분리수거 : 분리수거를 철저히 하고, 미장 작업에서 나온 폐기물(모르타르 찌꺼기 · 포대 등)은 시공업체 부담으로 적법하게 처리하여 쓰레기를 줄인다.
A44: (3) | B44: 민원 발생 억제 : 소음 · 진동 · 비산먼지 · 냄새를 최대한 억제하여 인근 주민의 생활에 피해가 없도록 하고, 적극적으로 환경관리 활동을 한다.
B45: (4) 환경관리 대책
A46: ① | C46: 쓰레기 처리 : 현장 안은 금연하고 쓰레기 수거함을 둔다.
A47: ② | C47: 잔재물 : 모르타르 찌꺼기 · 시멘트 포대 등은 지정된 장소에 모아 두고 지정 업체가 수거하게 한다.
A48: ③ | C48: 비산먼지 : 현장 안 주요 도로와 작업장 주변은 하루 2회 이상 살수차로 살수하고, 장비 이동 때 먼지가 나지 않도록 서행한다.
A50: 10.0 안 전 관 리 계 획
A53: 10-1 안전관리 목적
A54: 공종의 특수성을 고려하여 현장의 위험요소를 미리 없애 사고를 막음으로써 귀중한 인명을 보호하고 재산 손실을 최소화하며, 작업 능률을 높여 계획 공정을 원만히 달성하는 데 목적이 있다.
...
