Workbook

Sheet 표지
A1: K-건설맵 | k-conmap.com 건설 서식 | G1: ← 이 1행을 지우고 쓰셔도 됩니다
A3: (공 사 명)
A5: 시 공 계 획 서
A6: [ 팽이기초 ]
A8: 20 . .
A10: (회 사 명)
A12: 공사명 · 작성 연월(2026-03 처럼) · 회사명을 여기 한 번만 적으면 뒤 장에 저절로 들어갑니다.

Sheet 개요
A1: K-건설맵 | k-conmap.com 건설 서식 | G1: ← 이 1행을 지우고 쓰셔도 됩니다
A3: 목 차
C5: 1. 공 사 명
C6: 2. 공 사 개 요
C7: 3. 공 사 위 치
C8: 4. 주요 공사 물량
C9: 5. 현 장 조 직 도
C10: 6. 투입장비 및 자재
C11: 7. 투 입 인 원
C12: 8. 예 정 공 정 표
C13: 9. 팽이기초 작업 순서도
C14: 10. 팽이기초의 특성 및 용도
C15: 11. 팽이기초 시공방법
C16: 12. 품질 관리 계획
... C20: [첨부] 관련 도면
A22: 1.0 공 사 명
B24: =IF(OR('표지'!A3="",'표지'!A3="(공 사 명)"),"","◦ "&'표지'!A3)
A26: 2.0 공 사 개 요
A28: 공 사 명 | D28: =IF(OR('표지'!A3="",'표지'!A3="(공 사 명)"),"",'표지'!A3)
A29: 공 사 위 치
A30: 발 주 처
A31: 공 사 기 간 | F31: ~ | I31: =IF(OR(N(D31)=0,N(G31)=0),"",IF(G31<D31,"⚠ 준공일이 착공일보다 빠름",G31-D31+1))
A32: 공 사 금 액 | G32: =IF(N(D32)=0,"",D32)
A33: 공 사 규 모
A34: 현 장 대 리 인
A35: 시 공 사 | D35: =IF(OR('표지'!A10="",'표지'!A10="(회 사 명)"),"",'표지'!A10)
A37: 3.0 공 사 위 치
A39: (위치도를 붙이는 곳 — 현장 위치와 팽이기초 시공 구간을 표시)
A52: 4.0 주요 공사 물량
A54: 구 분 | E54: 팽이기초 시공면적 (㎡) | I54: 비 고
A60: 합 계 | E60: =IF(SUM(E55:E59)=0,"",SUM(E55:E59))
A61: (팽이기초 부설 평면도를 붙이는 곳 — 동별 시공 범위)
A76: 5.0 현 장 조 직 도
E78: 현 장 대 리 인
A80: │
B81: 품 질 관 리 자 | F81: ─┼─ | H81: 안 전 관 리 자
F82: │
A83: │
E84: 시 공 업 체
A86: │
...

Sheet 공정표
A1: K-건설맵 | k-conmap.com 건설 서식 | L1: ← 이 1행을 지우고 쓰셔도 됩니다
A2: 8.0 예 정 공 정 표 (일 단위)
A3: 착 수 일 | D3: ※ 착수일과 공정마다 시작 일차 · 작업 일수를 적으면 끝나는 날과 일 단위 막대가 그려집니다.
A4: 공 정 | B4: 시작 일차 | C4: 일수 | D4: 종료 일차 | E4: 기 간 | F4: 1 | G4: 2 | H4: 3 | I4: 4 | J4: 5 | K4: 6 | L4: 7 | M4: 8 | N4: 9 | O4: 10 | P4: 11 | Q4: 12 | R4: 13 | S4: 14 | T4: 15 | U4: 16 | V4: 17 | W4: 18 | X4: 19 | Y4: 20 | Z4: 21 | AA4: 22 | AB4: 23 | AC4: 24 | AD4: 25 | AE4: 26 | AF4: 27 | AG4: 28 | AH4: 29 | AI4: 30 | AJ4: 비 고
F5: =IF(N(B3)=0,"",B3+0) | G5: =IF(N(B3)=0,"",B3+1) | H5: =IF(N(B3)=0,"",B3+2) | I5: =IF(N(B3)=0,"",B3+3) | J5: =IF(N(B3)=0,"",B3+4) | K5: =IF(N(B3)=0,"",B3+5) | L5: =IF(N(B3)=0,"",B3+6) | M5: =IF(N(B3)=0,"",B3+7) | N5: =IF(N(B3)=0,"",B3+8) | O5: =IF(N(B3)=0,"",B3+9) | P5: =IF(N(B3)=0,"",B3+10) | Q5: =IF(N(B3)=0,"",B3+11) | R5: =IF(N(B3)=0,"",B3+12) | S5: =IF(N(B3)=0,"",B3+13) | T5: =IF(N(B3)=0,"",B3+14) | U5: =IF(N(B3)=0,"",B3+15) | V5: =IF(N(B3)=0,"",B3+16) | W5: =IF(N(B3)=0,"",B3+17) | X5: =IF(N(B3)=0,"",B3+18) | Y5: =IF(N(B3)=0,"",B3+19) | Z5: =IF(N(B3)=0,"",B3+20) | AA5: =IF(N(B3)=0,"",B3+21) | AB5: =IF(N(B3)=0,"",B3+22) | AC5: =IF(N(B3)=0,"",B3+23) | AD5: =IF(N(B3)=0,"",B3+24) | AE5: =IF(N(B3)=0,"",B3+25) | AF5: =IF(N(B3)=0,"",B3+26) | AG5: =IF(N(B3)=0,"",B3+27) | AH5: =IF(N(B3)=0,"",B3+28) | AI5: =IF(N(B3)=0,"",B3+29)
A6: 자재 반입(팽이용기) | D6: =IF(OR(N(B6)=0,N(C6)=0),"",B6+C6-1) | E6: =IF(OR(D6="",N(B3)=0),"",MONTH(B3+B6-1)&"/"&DAY(B3+B6-1)&" ~ "&MONTH(B3+D6-1)&"/"&DAY(B3+D6-1))
A7: 팽이용기 조립 | D7: =IF(OR(N(B7)=0,N(C7)=0),"",B7+C7-1) | E7: =IF(OR(D7="",N(B3)=0),"",MONTH(B3+B7-1)&"/"&DAY(B3+B7-1)&" ~ "&MONTH(B3+D7-1)&"/"&DAY(B3+D7-1))
A8: 철근 조립 | D8: =IF(OR(N(B8)=0,N(C8)=0),"",B8+C8-1) | E8: =IF(OR(D8="",N(B3)=0),"",MONTH(B3+B8-1)&"/"&DAY(B3+B8-1)&" ~ "&MONTH(B3+D8-1)&"/"&DAY(B3+D8-1))
A9: 콘크리트 타설 | D9: =IF(OR(N(B9)=0,N(C9)=0),"",B9+C9-1) | E9: =IF(OR(D9="",N(B3)=0),"",MONTH(B3+B9-1)&"/"&DAY(B3+B9-1)&" ~ "&MONTH(B3+D9-1)&"/"&DAY(B3+D9-1))
A10: 쇄석 채움 · 다짐 | D10: =IF(OR(N(B10)=0,N(C10)=0),"",B10+C10-1) | E10: =IF(OR(D10="",N(B3)=0),"",MONTH(B3+B10-1)&"/"&DAY(B3+B10-1)&" ~ "&MONTH(B3+D10-1)&"/"&DAY(B3+D10-1))
A11: 평판재하시험 | D11: =IF(OR(N(B11)=0,N(C11)=0),"",B11+C11-1) | E11: =IF(OR(D11="",N(B3)=0),"",MONTH(B3+B11-1)&"/"&DAY(B3+B11-1)&" ~ "&MONTH(B3+D11-1)&"/"&DAY(B3+D11-1))
D12: =IF(OR(N(B12)=0,N(C12)=0),"",B12+C12-1) | E12: =IF(OR(D12="",N(B3)=0),"",MONTH(B3+B12-1)&"/"&DAY(B3+B12-1)&" ~ "&MONTH(B3+D12-1)&"/"&DAY(B3+D12-1))
D13: =IF(OR(N(B13)=0,N(C13)=0),"",B13+C13-1) | E13: =IF(OR(D13="",N(B3)=0),"",MONTH(B3+B13-1)&"/"&DAY(B3+B13-1)&" ~ "&MONTH(B3+D13-1)&"/"&DAY(B3+D13-1))
D14: =IF(OR(N(B14)=0,N(C14)=0),"",B14+C14-1) | E14: =IF(OR(D14="",N(B3)=0),"",MONTH(B3+B14-1)&"/"&DAY(B3+B14-1)&" ~ "&MONTH(B3+D14-1)&"/"&DAY(B3+D14-1))
D15: =IF(OR(N(B15)=0,N(C15)=0),"",B15+C15-1) | E15: =IF(OR(D15="",N(B3)=0),"",MONTH(B3+B15-1)&"/"&DAY(B3+B15-1)&" ~ "&MONTH(B3+D15-1)&"/"&DAY(B3+D15-1))
A16: 총 작업 일수 | E16: =IF(COUNT(D6:D15)=0,"",MAX(D6:D15)) | F16: =IF(OR(E16="",N(B3)=0),"",B3+E16-1)
A18: 하늘색 칸 = 자동(종료 일차 · 기간 · 날짜 · 총 작업 일수). 공정 이름은 원본 차례를 미리 넣어 두었습니다.

Sheet 시공방법
A1: K-건설맵 | k-conmap.com 건설 서식 | G1: ← 이 1행을 지우고 쓰셔도 됩니다
A3: 9.0 팽이기초(현장타설형) 시공 작업 순서도
A5: 단 계 | C5: 작 업 | F5: 내 용
A6: Step 1 | C6: 시공 준비 | F6: 정지작업 · 지반 다짐
A7: Step 2 | C7: 팽이용기 반입 | F7: Φ500 팽이용기 반입 · 반입검사
A8: Step 3 | C8: 팽이용기 조립 | F8: 일반철근 D10 과 결속선으로 조립
A9: Step 4 | C9: 유니트 패널 운반 · 설치 | F9: 팽이말뚝 부설 계획 지반에 운반하여 설치
A10: Step 5 | C10: 상부 연결철근 조립 | F10: 일반철근 D10 과 결속선으로 조립
A11: Step 6 | C11: 레미콘 타설 | F11: 25-18-120 레미콘으로 팽이용기 채움
A12: Step 7 | C12: 쇄석 충진 및 다짐 | F12: #57(25mm) 쇄석으로 채우며 다짐
A13: Step 8 | C13: 시공 완료 | F13: 평판재하시험으로 설계 지내력 확인
A32: [ 시공 순서 — 유니트 패널 조립 · 운반 설치 · 상부 연결철근 조립 · 콘크리트 타설 · 쇄석 충진 및 다짐 · 시공 완료 ]
A34: 10.0 팽이기초(현장타설형)의 특성 및 용도
A36: 1) 팽이기초의 특성
A55: ① | B55: 기초 하중이 팽이말뚝을 통해 채움쇄석을 압축 · 구속 → 팽이말뚝과 채움쇄석이 한 몸이 되어 일종의 강성 지반구조를 이룬다.
A56: ② | B56: 채움쇄석이 응력 집중을 막고 하중을 분산 → 지반 안의 응력 분포를 고르게 한다.
A57: ③ | B57: 채움쇄석과 팽이말뚝부와 지반 사이의 마찰저항 → 말뚝부 지반 주변의 측방 변형을 구속한다.
A58: ④ | B58: 효과 : 기초 강성이 재하에 따라 증가 · 팽이의 군입효과 · 부등침하 억제 · 기초 하중 분포 분산 · 지반의 국부 파괴 억제 · 침하(압축변형) 감소 → 침하량 억제 · 지지력 증대
A59: 2) 팽이기초의 용도
A74: 11.0 팽이기초(현장타설형) 시공방법
A76: 1. 준비작업
A77: 가) | B77: 지반 정리 : 지반을 평탄하게 정리하고 다짐작업을 한다. 스펀지 현상이 생기는 구간은 양질의 치환재로 치환한다.
A78: 나) | B78: 시공 위치 확인 및 자재 반입 : 측량으로 팽이기초를 부설할 위치를 정확히 표시하고 확인을 받는다. 자재 반입 경로를 확인하고, 반입 때 설계도서에 적힌 자재의 형상 · 크기 · 수량을 확인하여 반입검사를 한다.
A79: 2. 팽이기초 시공
A80: 가) | B80: 용기 조립 : PP 매트를 설치한 부지에 팽이용기를 조립한 뒤 하부 연결철근을 설치하고, 시공 위치에 팽이용기를 놓은 뒤 상부 철근을 조립한다.
A81: 나) | B81: 상부 철근 연결 · 콘크리트 타설 : 상부 연결철근(D10)과 하부 연결철근(D10)을 연결 철선(#10)으로 잇고, 용기 안에 콘크리트(25-18-120)를 타설한다.
A82: 다) | B82: 쇄석 채움 및 다짐 : 팽이말뚝 사이의 공극을 25mm 쇄석으로 콘크리트 진동기 등을 이용하여 채운다.
A83: 라) | B83: 평판재하시험으로 지내력을 확인한다.
A85: 설명 그림(시공 순서 사진 · 특성 · 용도)은 원본 계획서 그림 그대로입니다.

Sheet 관리계획
A1: K-건설맵 | k-conmap.com 건설 서식 | G1: ← 이 1행을 지우고 쓰셔도 됩니다
A3: 12.0 품 질 관 리 계 획
A6: 12-1 품질관리 일반 및 적용범위
A7: (1) | B7: 공사 진행 중 필요에 따라 각종 승인도면 · 제작도면 · 제작요령서 등을 작성하여 공사감독자(감리원)의 승인을 받는다.
A8: (2) | B8: 공사용 재료는 도면 · 공사시방서 및 공사감독자의 지시에 따라, 쓰기 전에 견본 또는 자료를 제출하여 승인을 받은 뒤 쓴다.
A9: (3) | B9: 품질시험은 「건설기술 진흥법」 및 같은 법 시행령 · 시행규칙과 공사시방서에서 정한 바에 따른다.
A11: 12-2 공사용 재료의 품질
A12: (1) | B12: 설계도면 · 공사시방서 및 공사감독자의 따로 지시가 없으면 시방서에서 정한 품질과 규격에 맞는 재료를 쓴다.
A13: (2) | B13: 시방서에 품질 규격이 없으면 한국산업표준(KS) 표시품 또는 이에 준하는 품질과 규격의 재료를 쓴다.
A14: (3) | B14: 기성품을 포함한 공사용 재료는 현장 반입 전에 자재승인 서류(견본 · 카탈로그 · 시험성적서 등)를 제출하여 승인을 받고, 공사감독자의 지시에 따라 품질을 확인할 수 있는 증빙서류를 낸다.
A15: (4) | B15: 재료가 현장에 들어오면 공사감독자의 인수검사를 받고, 합격한 재료는 작업 · 통행에 지장이 없는 곳에 보관하여 수시 점검이 쉽게 한다.
A16: (5) | B16: 「건설기술 진흥법」에 규정된 품질시험을 하고, 시험실 규모 · 시험장비 · 시험요원 배치기준에 따라 시험실을 운영한다.
A17: (6) | B17: 검사 또는 시험에 불합격한 재료는 지체 없이 현장 밖으로 반출한다.
A19: 12-3 시공 확인 및 검사
A20: (1) | B20: 주요 공사단계가 끝났을 때나 공사감독자가 지시할 때는 시공의 정확성과 품질을 확인받는다.
A21: (2) | B21: 검사에 필요한 자료 작성 · 측량 등은 검사자의 지시에 따른다.
A23: 12-4 자재관리
A24: (1) | B24: 들어온 자재는 자재수불대장으로 입 · 출고를 관리한다.
A25: (2) | B25: 자재는 재질별 · 규격별로 나누어 보관한다.
A26: (3) | B26: 운반 · 야적 때 변형되지 않도록 전용 운반 가설대 또는 전용 야적대를 쓴다.
A27: (4) | B27: 반입 자재는 받침목 · 지지목 등으로 지면에서 200mm 이상 띄우고 손상 · 변형 · 침수되지 않게 한다.
A28: (5) | B28: 변형을 막기 위해 받침목 높이를 맞추고 1단 적재를 기본으로 한다.
A30: 13.0 환 경 관 리 계 획
A33: 13-1 개 요
A34: 현장의 폐기물 · 유류 · 쓰레기 및 소음 · 진동 · 비산먼지 등에 의한 오염을 방지한다.
A36: 13-2 중점관리 방침
A37: (1) | B37: 자율적인 환경관리
A38: (2) | B38: 쾌적한 작업환경 관리
A39: (3) | B39: 민원 발생 방지
A41: 13-3 실시계획
A42: (1) | B42: 작업 전후 정리정돈 : 작업 전후 정리정돈을 철저히 하여 쾌적한 작업환경을 유지한다.
A43: (2) | B43: 분리수거 : 분리수거를 철저히 하고, 팽이기초 작업에서 나온 폐기물(철근 토막 · 결속선 · 포장재 등)은 시공업체 부담으로 적법하게 처리하여 쓰레기를 줄인다.
A44: (3) | B44: 민원 발생 억제 : 소음 · 진동 · 비산먼지 · 냄새를 최대한 억제하여 인근 주민의 생활에 피해가 없도록 하고, 적극적으로 환경관리 활동을 한다.
B45: (4) 환경관리 대책
A46: ① | C46: 쓰레기 처리 : 현장 안은 금연하고 쓰레기 수거함을 둔다.
A47: ② | C47: 잔재물 : 남은 팽이용기 · 철근 토막 · 레미콘 잔량은 지정된 장소에 모아 두고 지정 업체가 수거하게 한다.
A48: ③ | C48: 비산먼지 : 현장 안 주요 도로와 작업장 주변은 하루 2회 이상 살수차로 살수하고, 장비 이동 때 먼지가 나지 않도록 서행한다.
A50: 14.0 안 전 관 리 계 획
A53: 14-1 안전관리 목적
A54: 공종의 특수성을 고려하여 현장의 위험요소를 미리 없애 사고를 막음으로써 귀중한 인명을 보호하고 재산 손실을 최소화하며, 작업 능률을 높여 계획 공정을 원만히 달성하는 데 목적이 있다.
...

Sheet 예시-표지
A1: K-건설맵 | k-conmap.com 건설 서식 | G1: 작성 예시 (가상의 현장)
A3: 가나학교 교사 증축공사
A5: 시 공 계 획 서
A6: [ 팽이기초 ]
A8: 46082
A10: 예시건설(주)
A12: 이 시트는 작성 예시입니다(가상의 공사 · 회사 · 사람).

Sheet 예시-개요
A1: K-건설맵 | k-conmap.com 건설 서식 | G1: 작성 예시 (가상의 현장)
A3: 목 차
C5: 1. 공 사 명
C6: 2. 공 사 개 요
C7: 3. 공 사 위 치
C8: 4. 주요 공사 물량
C9: 5. 현 장 조 직 도
C10: 6. 투입장비 및 자재
C11: 7. 투 입 인 원
C12: 8. 예 정 공 정 표
C13: 9. 팽이기초 작업 순서도
C14: 10. 팽이기초의 특성 및 용도
C15: 11. 팽이기초 시공방법
C16: 12. 품질 관리 계획
... C20: [첨부] 관련 도면
A22: 1.0 공 사 명
B24: =IF(OR('예시-표지'!A3="",'예시-표지'!A3="(공 사 명)"),"","◦ "&'예시-표지'!A3)
A26: 2.0 공 사 개 요
A28: 공 사 명 | D28: =IF(OR('예시-표지'!A3="",'예시-표지'!A3="(공 사 명)"),"",'예시-표지'!A3)
A29: 공 사 위 치 | D29: 가나시 가나동 일원
A30: 발 주 처 | D30: 가나시교육청
A31: 공 사 기 간 | D31: 46083 | F31: ~ | G31: 46387 | I31: =IF(OR(N(D31)=0,N(G31)=0),"",IF(G31<D31,"⚠ 준공일이 착공일보다 빠름",G31-D31+1))
A32: 공 사 금 액 | D32: 8450000000 | G32: =IF(N(D32)=0,"",D32)
A33: 공 사 규 모 | D33: 교사동 · 실습동 증축(팽이기초)
A34: 현 장 대 리 인 | D34: 홍길동
A35: 시 공 사 | D35: =IF(OR('예시-표지'!A10="",'예시-표지'!A10="(회 사 명)"),"",'예시-표지'!A10)
A37: 3.0 공 사 위 치
A39: (위치도를 붙이는 곳 — 현장 위치와 팽이기초 시공 구간을 표시)
A52: 4.0 주요 공사 물량
A54: 구 분 | E54: 팽이기초 시공면적 (㎡) | I54: 비 고
A55: 교사동 | E55: 1620 | I55: 현장타설형 팽이기초
A56: 실습동 | E56: 870 | I56: 현장타설형 팽이기초
A60: 합 계 | E60: =IF(SUM(E55:E59)=0,"",SUM(E55:E59))
A61: (팽이기초 부설 평면도를 붙이는 곳 — 동별 시공 범위)
A76: 5.0 현 장 조 직 도
E78: 현 장 대 리 인
E79: 홍길동
A80: │
B81: 품 질 관 리 자 | F81: ─┼─ | H81: 안 전 관 리 자
B82: 김철수 | F82: │ | H82: 박안전
...

Sheet 예시-공정표
A1: K-건설맵 | k-conmap.com 건설 서식 | L1: 작성 예시 (가상의 현장)
A2: 8.0 예 정 공 정 표 (일 단위)
A3: 착 수 일 | B3: 46118 | D3: ※ 착수일과 공정마다 시작 일차 · 작업 일수를 적으면 끝나는 날과 일 단위 막대가 그려집니다.
A4: 공 정 | B4: 시작 일차 | C4: 일수 | D4: 종료 일차 | E4: 기 간 | F4: 1 | G4: 2 | H4: 3 | I4: 4 | J4: 5 | K4: 6 | L4: 7 | M4: 8 | N4: 9 | O4: 10 | P4: 11 | Q4: 12 | R4: 13 | S4: 14 | T4: 15 | U4: 16 | V4: 17 | W4: 18 | X4: 19 | Y4: 20 | Z4: 21 | AA4: 22 | AB4: 23 | AC4: 24 | AD4: 25 | AE4: 26 | AF4: 27 | AG4: 28 | AH4: 29 | AI4: 30 | AJ4: 비 고
F5: =IF(N(B3)=0,"",B3+0) | G5: =IF(N(B3)=0,"",B3+1) | H5: =IF(N(B3)=0,"",B3+2) | I5: =IF(N(B3)=0,"",B3+3) | J5: =IF(N(B3)=0,"",B3+4) | K5: =IF(N(B3)=0,"",B3+5) | L5: =IF(N(B3)=0,"",B3+6) | M5: =IF(N(B3)=0,"",B3+7) | N5: =IF(N(B3)=0,"",B3+8) | O5: =IF(N(B3)=0,"",B3+9) | P5: =IF(N(B3)=0,"",B3+10) | Q5: =IF(N(B3)=0,"",B3+11) | R5: =IF(N(B3)=0,"",B3+12) | S5: =IF(N(B3)=0,"",B3+13) | T5: =IF(N(B3)=0,"",B3+14) | U5: =IF(N(B3)=0,"",B3+15) | V5: =IF(N(B3)=0,"",B3+16) | W5: =IF(N(B3)=0,"",B3+17) | X5: =IF(N(B3)=0,"",B3+18) | Y5: =IF(N(B3)=0,"",B3+19) | Z5: =IF(N(B3)=0,"",B3+20) | AA5: =IF(N(B3)=0,"",B3+21) | AB5: =IF(N(B3)=0,"",B3+22) | AC5: =IF(N(B3)=0,"",B3+23) | AD5: =IF(N(B3)=0,"",B3+24) | AE5: =IF(N(B3)=0,"",B3+25) | AF5: =IF(N(B3)=0,"",B3+26) | AG5: =IF(N(B3)=0,"",B3+27) | AH5: =IF(N(B3)=0,"",B3+28) | AI5: =IF(N(B3)=0,"",B3+29)
A6: 자재 반입(팽이용기) | B6: 1 | C6: 2 | D6: =IF(OR(N(B6)=0,N(C6)=0),"",B6+C6-1) | E6: =IF(OR(D6="",N(B3)=0),"",MONTH(B3+B6-1)&"/"&DAY(B3+B6-1)&" ~ "&MONTH(B3+D6-1)&"/"&DAY(B3+D6-1))
A7: 팽이용기 조립 | B7: 2 | C7: 6 | D7: =IF(OR(N(B7)=0,N(C7)=0),"",B7+C7-1) | E7: =IF(OR(D7="",N(B3)=0),"",MONTH(B3+B7-1)&"/"&DAY(B3+B7-1)&" ~ "&MONTH(B3+D7-1)&"/"&DAY(B3+D7-1))
A8: 철근 조립 | B8: 4 | C8: 6 | D8: =IF(OR(N(B8)=0,N(C8)=0),"",B8+C8-1) | E8: =IF(OR(D8="",N(B3)=0),"",MONTH(B3+B8-1)&"/"&DAY(B3+B8-1)&" ~ "&MONTH(B3+D8-1)&"/"&DAY(B3+D8-1))
A9: 콘크리트 타설 | B9: 7 | C9: 5 | D9: =IF(OR(N(B9)=0,N(C9)=0),"",B9+C9-1) | E9: =IF(OR(D9="",N(B3)=0),"",MONTH(B3+B9-1)&"/"&DAY(B3+B9-1)&" ~ "&MONTH(B3+D9-1)&"/"&DAY(B3+D9-1))
A10: 쇄석 채움 · 다짐 | B10: 9 | C10: 5 | D10: =IF(OR(N(B10)=0,N(C10)=0),"",B10+C10-1) | E10: =IF(OR(D10="",N(B3)=0),"",MONTH(B3+B10-1)&"/"&DAY(B3+B10-1)&" ~ "&MONTH(B3+D10-1)&"/"&DAY(B3+D10-1))
A11: 평판재하시험 | B11: 14 | C11: 2 | D11: =IF(OR(N(B11)=0,N(C11)=0),"",B11+C11-1) | E11: =IF(OR(D11="",N(B3)=0),"",MONTH(B3+B11-1)&"/"&DAY(B3+B11-1)&" ~ "&MONTH(B3+D11-1)&"/"&DAY(B3+D11-1))
D12: =IF(OR(N(B12)=0,N(C12)=0),"",B12+C12-1) | E12: =IF(OR(D12="",N(B3)=0),"",MONTH(B3+B12-1)&"/"&DAY(B3+B12-1)&" ~ "&MONTH(B3+D12-1)&"/"&DAY(B3+D12-1))
D13: =IF(OR(N(B13)=0,N(C13)=0),"",B13+C13-1) | E13: =IF(OR(D13="",N(B3)=0),"",MONTH(B3+B13-1)&"/"&DAY(B3+B13-1)&" ~ "&MONTH(B3+D13-1)&"/"&DAY(B3+D13-1))
D14: =IF(OR(N(B14)=0,N(C14)=0),"",B14+C14-1) | E14: =IF(OR(D14="",N(B3)=0),"",MONTH(B3+B14-1)&"/"&DAY(B3+B14-1)&" ~ "&MONTH(B3+D14-1)&"/"&DAY(B3+D14-1))
D15: =IF(OR(N(B15)=0,N(C15)=0),"",B15+C15-1) | E15: =IF(OR(D15="",N(B3)=0),"",MONTH(B3+B15-1)&"/"&DAY(B3+B15-1)&" ~ "&MONTH(B3+D15-1)&"/"&DAY(B3+D15-1))
A16: 총 작업 일수 | E16: =IF(COUNT(D6:D15)=0,"",MAX(D6:D15)) | F16: =IF(OR(E16="",N(B3)=0),"",B3+E16-1)
A18: 이 시트는 작성 예시입니다(가상의 일정).

Sheet 예시-시공방법
A1: K-건설맵 | k-conmap.com 건설 서식 | G1: 작성 예시 (가상의 현장)
A3: 9.0 팽이기초(현장타설형) 시공 작업 순서도
A5: 단 계 | C5: 작 업 | F5: 내 용
A6: Step 1 | C6: 시공 준비 | F6: 정지작업 · 지반 다짐
A7: Step 2 | C7: 팽이용기 반입 | F7: Φ500 팽이용기 반입 · 반입검사
A8: Step 3 | C8: 팽이용기 조립 | F8: 일반철근 D10 과 결속선으로 조립
A9: Step 4 | C9: 유니트 패널 운반 · 설치 | F9: 팽이말뚝 부설 계획 지반에 운반하여 설치
A10: Step 5 | C10: 상부 연결철근 조립 | F10: 일반철근 D10 과 결속선으로 조립
A11: Step 6 | C11: 레미콘 타설 | F11: 25-18-120 레미콘으로 팽이용기 채움
A12: Step 7 | C12: 쇄석 충진 및 다짐 | F12: #57(25mm) 쇄석으로 채우며 다짐
A13: Step 8 | C13: 시공 완료 | F13: 평판재하시험으로 설계 지내력 확인
A32: [ 시공 순서 — 유니트 패널 조립 · 운반 설치 · 상부 연결철근 조립 · 콘크리트 타설 · 쇄석 충진 및 다짐 · 시공 완료 ]
A34: 10.0 팽이기초(현장타설형)의 특성 및 용도
A36: 1) 팽이기초의 특성
A55: ① | B55: 기초 하중이 팽이말뚝을 통해 채움쇄석을 압축 · 구속 → 팽이말뚝과 채움쇄석이 한 몸이 되어 일종의 강성 지반구조를 이룬다.
A56: ② | B56: 채움쇄석이 응력 집중을 막고 하중을 분산 → 지반 안의 응력 분포를 고르게 한다.
A57: ③ | B57: 채움쇄석과 팽이말뚝부와 지반 사이의 마찰저항 → 말뚝부 지반 주변의 측방 변형을 구속한다.
A58: ④ | B58: 효과 : 기초 강성이 재하에 따라 증가 · 팽이의 군입효과 · 부등침하 억제 · 기초 하중 분포 분산 · 지반의 국부 파괴 억제 · 침하(압축변형) 감소 → 침하량 억제 · 지지력 증대
A59: 2) 팽이기초의 용도
A74: 11.0 팽이기초(현장타설형) 시공방법
A76: 1. 준비작업
A77: 가) | B77: 지반 정리 : 지반을 평탄하게 정리하고 다짐작업을 한다. 스펀지 현상이 생기는 구간은 양질의 치환재로 치환한다.
A78: 나) | B78: 시공 위치 확인 및 자재 반입 : 측량으로 팽이기초를 부설할 위치를 정확히 표시하고 확인을 받는다. 자재 반입 경로를 확인하고, 반입 때 설계도서에 적힌 자재의 형상 · 크기 · 수량을 확인하여 반입검사를 한다.
A79: 2. 팽이기초 시공
A80: 가) | B80: 용기 조립 : PP 매트를 설치한 부지에 팽이용기를 조립한 뒤 하부 연결철근을 설치하고, 시공 위치에 팽이용기를 놓은 뒤 상부 철근을 조립한다.
A81: 나) | B81: 상부 철근 연결 · 콘크리트 타설 : 상부 연결철근(D10)과 하부 연결철근(D10)을 연결 철선(#10)으로 잇고, 용기 안에 콘크리트(25-18-120)를 타설한다.
A82: 다) | B82: 쇄석 채움 및 다짐 : 팽이말뚝 사이의 공극을 25mm 쇄석으로 콘크리트 진동기 등을 이용하여 채운다.
A83: 라) | B83: 평판재하시험으로 지내력을 확인한다.
A85: 이 시트는 작성 예시입니다.

Sheet 예시-관리계획
A1: K-건설맵 | k-conmap.com 건설 서식 | G1: 작성 예시 (가상의 현장)
A3: 12.0 품 질 관 리 계 획
A6: 12-1 품질관리 일반 및 적용범위
A7: (1) | B7: 공사 진행 중 필요에 따라 각종 승인도면 · 제작도면 · 제작요령서 등을 작성하여 공사감독자(감리원)의 승인을 받는다.
A8: (2) | B8: 공사용 재료는 도면 · 공사시방서 및 공사감독자의 지시에 따라, 쓰기 전에 견본 또는 자료를 제출하여 승인을 받은 뒤 쓴다.
A9: (3) | B9: 품질시험은 「건설기술 진흥법」 및 같은 법 시행령 · 시행규칙과 공사시방서에서 정한 바에 따른다.
A11: 12-2 공사용 재료의 품질
A12: (1) | B12: 설계도면 · 공사시방서 및 공사감독자의 따로 지시가 없으면 시방서에서 정한 품질과 규격에 맞는 재료를 쓴다.
A13: (2) | B13: 시방서에 품질 규격이 없으면 한국산업표준(KS) 표시품 또는 이에 준하는 품질과 규격의 재료를 쓴다.
A14: (3) | B14: 기성품을 포함한 공사용 재료는 현장 반입 전에 자재승인 서류(견본 · 카탈로그 · 시험성적서 등)를 제출하여 승인을 받고, 공사감독자의 지시에 따라 품질을 확인할 수 있는 증빙서류를 낸다.
A15: (4) | B15: 재료가 현장에 들어오면 공사감독자의 인수검사를 받고, 합격한 재료는 작업 · 통행에 지장이 없는 곳에 보관하여 수시 점검이 쉽게 한다.
A16: (5) | B16: 「건설기술 진흥법」에 규정된 품질시험을 하고, 시험실 규모 · 시험장비 · 시험요원 배치기준에 따라 시험실을 운영한다.
A17: (6) | B17: 검사 또는 시험에 불합격한 재료는 지체 없이 현장 밖으로 반출한다.
A19: 12-3 시공 확인 및 검사
A20: (1) | B20: 주요 공사단계가 끝났을 때나 공사감독자가 지시할 때는 시공의 정확성과 품질을 확인받는다.
A21: (2) | B21: 검사에 필요한 자료 작성 · 측량 등은 검사자의 지시에 따른다.
A23: 12-4 자재관리
A24: (1) | B24: 들어온 자재는 자재수불대장으로 입 · 출고를 관리한다.
A25: (2) | B25: 자재는 재질별 · 규격별로 나누어 보관한다.
A26: (3) | B26: 운반 · 야적 때 변형되지 않도록 전용 운반 가설대 또는 전용 야적대를 쓴다.
A27: (4) | B27: 반입 자재는 받침목 · 지지목 등으로 지면에서 200mm 이상 띄우고 손상 · 변형 · 침수되지 않게 한다.
A28: (5) | B28: 변형을 막기 위해 받침목 높이를 맞추고 1단 적재를 기본으로 한다.
A30: 13.0 환 경 관 리 계 획
A33: 13-1 개 요
A34: 현장의 폐기물 · 유류 · 쓰레기 및 소음 · 진동 · 비산먼지 등에 의한 오염을 방지한다.
A36: 13-2 중점관리 방침
A37: (1) | B37: 자율적인 환경관리
A38: (2) | B38: 쾌적한 작업환경 관리
A39: (3) | B39: 민원 발생 방지
A41: 13-3 실시계획
A42: (1) | B42: 작업 전후 정리정돈 : 작업 전후 정리정돈을 철저히 하여 쾌적한 작업환경을 유지한다.
A43: (2) | B43: 분리수거 : 분리수거를 철저히 하고, 팽이기초 작업에서 나온 폐기물(철근 토막 · 결속선 · 포장재 등)은 시공업체 부담으로 적법하게 처리하여 쓰레기를 줄인다.
A44: (3) | B44: 민원 발생 억제 : 소음 · 진동 · 비산먼지 · 냄새를 최대한 억제하여 인근 주민의 생활에 피해가 없도록 하고, 적극적으로 환경관리 활동을 한다.
B45: (4) 환경관리 대책
A46: ① | C46: 쓰레기 처리 : 현장 안은 금연하고 쓰레기 수거함을 둔다.
A47: ② | C47: 잔재물 : 남은 팽이용기 · 철근 토막 · 레미콘 잔량은 지정된 장소에 모아 두고 지정 업체가 수거하게 한다.
A48: ③ | C48: 비산먼지 : 현장 안 주요 도로와 작업장 주변은 하루 2회 이상 살수차로 살수하고, 장비 이동 때 먼지가 나지 않도록 서행한다.
A50: 14.0 안 전 관 리 계 획
A53: 14-1 안전관리 목적
A54: 공종의 특수성을 고려하여 현장의 위험요소를 미리 없애 사고를 막음으로써 귀중한 인명을 보호하고 재산 손실을 최소화하며, 작업 능률을 높여 계획 공정을 원만히 달성하는 데 목적이 있다.
...
