Workbook

Sheet 원가계산서
A1: K-건설맵 | k-conmap.com ← 이 1행을 지우고 쓰셔도 됩니다
A2: 공 사 원 가 계 산 서
A3: 구분 | B3: 비 목 | C3: 요율(%) | D3: 산 출 근 거 | E3: 당 초 | F3: 변경 후 | G3: 증 감
A4: 1 | B4: 직 접 재 료 비 | D4: 당초 Σ(수량 × 재료비단가) · 변경 = 당초 + 증감대비표(제65조) | E4: =SUMPRODUCT(N(내역서!$F$4:$F$203),N(내역서!$G$4:$G$203)) | F4: =E4+SUM(증감대비표!$U$4:$U$203) | G4: =F4-E4
A5: 2 | B5: 간 접 재 료 비 | D5: 사람이 넣습니다 | E5: 0 | F5: 0 | G5: =F5-E5
A6: 3 | B6: 작업설·부산물 등(△) | D6: 사람이 넣습니다 (빼는 값이면 음수) | E6: 0 | F6: 0 | G6: =F6-E6
A7: A | B7: [ 재 료 비 ] 소 계 | D7: ( 1 + 2 + 3 ) | E7: =E4+E5+E6 | F7: =F4+F5+F6 | G7: =F7-E7
A8: 4 | B8: 직 접 노 무 비 | D8: 당초 Σ(수량 × 노무비단가) · 변경 = 당초 + 증감대비표(제65조) | E8: =SUMPRODUCT(N(내역서!$F$4:$F$203),N(내역서!$H$4:$H$203)) | F8: =E8+SUM(증감대비표!$V$4:$V$203) | G8: =F8-E8
A9: 5 | B9: 간 접 노 무 비 | C9: ='설정'!C19 | D9: 4 × 요율 | E9: =ROUND(E8*'설정'!$C$19/100,0) | F9: =ROUND(F8*'설정'!$C$19/100,0) | G9: =F9-E9
A10: B | B10: [ 노 무 비 ] 소 계 | D10: ( 4 + 5 ) | E10: =E8+E9 | F10: =F8+F9 | G10: =F10-E10
A11: 6 | B11: 산 출 경 비 | D11: 당초 Σ(수량 × 경비단가) · 변경 = 당초 + 증감대비표(제65조) | E11: =SUMPRODUCT(N(내역서!$F$4:$F$203),N(내역서!$I$4:$I$203)) | F11: =E11+SUM(증감대비표!$W$4:$W$203) | G11: =F11-E11
A12: 7 | B12: 산 재 보 험 료 | C12: ='설정'!C20 | D12: B × 요율 | E12: =ROUND(E10*'설정'!$C$20/100,0) | F12: =ROUND(F10*'설정'!$C$20/100,0) | G12: =F12-E12
A13: 8 | B13: 고 용 보 험 료 | C13: ='설정'!C21 | D13: B × 요율 | E13: =ROUND(E10*'설정'!$C$21/100,0) | F13: =ROUND(F10*'설정'!$C$21/100,0) | G13: =F13-E13
A14: 9 | B14: 건 강 보 험 료 | C14: ='설정'!C22 | D14: 4 × 요율 | E14: =ROUND(E8*'설정'!$C$22/100,0) | F14: =ROUND(F8*'설정'!$C$22/100,0) | G14: =F14-E14
A15: 10 | B15: 연 금 보 험 료 | C15: ='설정'!C23 | D15: 4 × 요율 | E15: =ROUND(E8*'설정'!$C$23/100,0) | F15: =ROUND(F8*'설정'!$C$23/100,0) | G15: =F15-E15
A16: 11 | B16: 노인장기요양보험료 | C16: ='설정'!C24 | D16: 9 × 요율 | E16: =ROUND(E14*'설정'!$C$24/100,0) | F16: =ROUND(F14*'설정'!$C$24/100,0) | G16: =F16-E16
A17: 12 | B17: 퇴 직 공 제 부 금 비 | C17: ='설정'!C25 | D17: 4 × 요율 | E17: =ROUND(E8*'설정'!$C$25/100,0) | F17: =ROUND(F8*'설정'!$C$25/100,0) | G17: =F17-E17
A18: 13 | B18: 건설기계대여금지급보증서발급액 | C18: ='설정'!C26 | D18: ( A + 4 + 6 ) × 요율 | E18: =ROUND((E7+E8+E11)*'설정'!$C$26/100,0) | F18: =ROUND((F7+F8+F11)*'설정'!$C$26/100,0) | G18: =F18-E18
A19: 14 | B19: 산 업 안 전 보건관리비 | C19: ='설정'!C27 | D19: ( ( A + 4 ) + K ÷ 1.1 ) × 요율 | E19: =ROUND(((E7+E8)+E34/1.1)*'설정'!$C$27/100,0) | F19: =ROUND(((F7+F8)+F34/1.1)*'설정'!$C$27/100,0) | G19: =F19-E19
A20: 15 | B20: 환 경 보 전 비 | C20: ='설정'!C28 | D20: ( A + 4 + 6 ) × 요율 | E20: =ROUND((E7+E8+E11)*'설정'!$C$28/100,0) | F20: =ROUND((F7+F8+F11)*'설정'!$C$28/100,0) | G20: =F20-E20
A21: 16 | B21: 공 사 이 행 보증수수료 | D21: 사람이 넣습니다 | E21: 0 | F21: 0 | G21: =F21-E21
A22: 17 | B22: 하도급대금지급보증수수료 | C22: ='설정'!C29 | D22: ( A + 4 + 6 ) × 요율 | E22: =ROUND((E7+E8+E11)*'설정'!$C$29/100,0) | F22: =ROUND((F7+F8+F11)*'설정'!$C$29/100,0) | G22: =F22-E22
A23: 18 | B23: 석 면 분 담 금 | C23: ='설정'!C30 | D23: B × 요율 | E23: =ROUND(E10*'설정'!$C$30/100,0) | F23: =ROUND(F10*'설정'!$C$30/100,0) | G23: =F23-E23
A24: 19 | B24: 임 금 채 권 부 담 금 | C24: ='설정'!C31 | D24: B × 요율 | E24: =ROUND(E10*'설정'!$C$31/100,0) | F24: =ROUND(F10*'설정'!$C$31/100,0) | G24: =F24-E24
A25: 20 | B25: 기 타 경 비 | C25: ='설정'!C32 | D25: ( A + B ) × 요율 | E25: =ROUND((E7+E10)*'설정'!$C$32/100,0) | F25: =ROUND((F7+F10)*'설정'!$C$32/100,0) | G25: =F25-E25
A26: C | B26: [ 경 비 ] 소 계 | D26: ( 6 ~ 20 ) | E26: =SUM(E11:E25) | F26: =SUM(F11:F25) | G26: =F26-E26
A27: D | B27: 순 공 사 원 가 | D27: ( A + B + C ) | E27: =E7+E10+E26 | F27: =F7+F10+F26 | G27: =F27-E27
A28: E | B28: 일 반 관 리 비 | C28: ='설정'!C33 | D28: D × 요율 | E28: =ROUND(E27*'설정'!$C$33/100,0) | F28: =ROUND(F27*'설정'!$C$33/100,0) | G28: =F28-E28
A29: F | B29: 이 윤 | C29: ='설정'!C34 | D29: ( B + C + E ) × 요율 — 재료비는 넣지 않습니다 | E29: =ROUND((E10+E26+E28)*'설정'!$C$34/100,0) | F29: =ROUND((F10+F26+F28)*'설정'!$C$34/100,0) | G29: =F29-E29
A30: G | B30: 폐 기 물 처 리 비 | D30: 사람이 넣습니다 | E30: 0 | F30: 0 | G30: =F30-E30
A31: H | B31: 총 원 가 | D31: ( D + E + F + G ) | E31: =E27+E28+E29+E30 | F31: =F27+F28+F29+F30 | G31: =F31-E31
A32: I | B32: 부 가 가 치 세 | C32: ='설정'!C35 | D32: H × 요율 | E32: =ROUND(E31*'설정'!$C$35/100,0) | F32: =ROUND(F31*'설정'!$C$35/100,0) | G32: =F32-E32
A33: J | B33: 도 급 액 | D33: ( H + I ) | E33: =E31+E32 | F33: =F31+F32 | G33: =F33-E33
A34: K | B34: 관 급 자 재 대 | D34: 사람이 넣습니다 | E34: 0 | F34: 0 | G34: =F34-E34
A35: L | B35: 총 공 사 비 | D35: ( J + K ) | E35: =E33+E34 | F35: =F33+F34 | G35: =F35-E35
A37: 조달청 설계내역서 110장을 열어 줄 차례·요율·산출근거를 세어 그대로 맞춘 것입니다. 노랑 칸만 사람이 넣습니다(간접재료비·작업설·공사이행보증·폐기물·관급자재대). ⚠️ 요율은 해마다·공사 규모마다 바뀝니다 — «설정» 시트에 발주처 설계서의 요율을 넣고 쓰십시오. 이윤은 (B+C+E)에만 곱합니다 — 재료비(A)는 넣지 않습니다. 산업안전보건관리비는 관급자재대(K)를 1.1로 나눠 더한 값에 곱합니다. «변경 후» 직접비는 당초 + 증감대비표의 제65조 증감(증가 = 계약단가 · 신규 = 당시단가 × 낙찰률)입니다 — 증감 열의 «도급액» 증감이 곧 계약금액 조정액입니다(제비율 · 부가세 포함).

Sheet 증감대비표
A1: K-건설맵 | k-conmap.com ← 이 1행을 지우고 쓰셔도 됩니다
A2: 증 감 대 비 표
A3: 번호 | B3: 공종코드 | C3: 품 명 | D3: 규 격 | E3: 단위 | F3: 당초수량 | G3: 계약단가 | H3: 당초금액 | I3: 변경수량 | J3: 당시단가 | K3: 증감수량 | L3: 구분 | M3: 협의(Y) | N3: 예정가격단가 | O3: 적용단가 | P3: 증감금액 | Q3: 단가 근거 | R3: 적용 재료비 | S3: 적용 노무비 | T3: 적용 경비 | U3: 증감 재료비 | V3: 증감 노무비 | W3: 증감 경비
A4: =IF($B4="","",ROW()-4+1) | B4: =내역서!$B4 | C4: =IF($B4="","",내역서!$C4) | D4: =IF($B4="","",내역서!$D4) | E4: =IF($B4="","",내역서!$E4) | F4: =IF($B4="","",N(내역서!$F4)) | G4: =IF($B4="","",N(내역서!$J4)) | H4: =IF($B4="","",N(내역서!$K4)) | I4: =IF($B4="","",N(내역서!$N4)) | J4: =IF($B4="","",N(내역서!$R4)) | K4: =IF($B4="","",N($I4)-N($F4)) | L4: =IF($B4="","",IF(N(내역서!$F4)=0,"신규",IF($K4<0,"감소",IF($K4>0,"증가","-")))) | O4: =IF($B4="","",IF($L4="감소",$G4,IF($L4="증가",IF($M4="Y",ROUND(($J4+$J4*('설정'!$C$15/100))/2,0),IF(AND($N4<>"",$G4>$N4),$N4,$G4)),IF($L4="신규",IF($M4="Y",ROUND(($J4+$J4*('설정'!$C$15/100))/2,0),ROUND($J4*('설정'!$C$15/100),0)),0)))) | P4: =IF($B4="","",ROUND(N($K4)*N($O4),0)) | Q4: =IF($B4="","",IF($L4="감소","감소분 → 계약단가",IF(AND($M4="Y",OR($L4="증가",$L4="신규")),"발주기관 요구 → 협의 (불성립 시 (당시단가+당시단가×낙찰률)÷2)",IF($L4="증가",IF(AND($N4<>"",$G4>$N4),"증가분 → 계약단가>예정가격단가 이므로 예정가격단가","증가분 → 계약단가 (낙찰률을 곱하지 않습니다)"),IF($L4="신규","신규비목 → 당시단가 × 낙찰률",""))))) | R4: =IF($B4="","",IF(N($O4)=0,0,IF(OR($L4="감소",AND($L4="증가",$M4<>"Y")),IF(N($G4)=0,0,ROUND(N(내역서!$G4)*$O4/$G4,0)),IF(N($J4)=0,0,ROUND(N(내역서!$O4)*$O4/$J4,0))))) | S4: =IF($B4="","",IF(N($O4)=0,0,IF(OR($L4="감소",AND($L4="증가",$M4<>"Y")),IF(N($G4)=0,0,ROUND(N(내역서!$H4)*$O4/$G4,0)),IF(N($J4)=0,0,ROUND(N(내역서!$P4)*$O4/$J4,0))))) | T4: =IF($B4="","",N($O4)-N($R4)-N($S4)) | U4: =IF($B4="","",ROUND(N($K4)*N($R4),0)) | V4: =IF($B4="","",ROUND(N($K4)*N($S4),0)) | W4: =IF($B4="","",N($P4)-N($U4)-N($V4))
A5: =IF($B5="","",ROW()-4+1) | B5: =내역서!$B5 | C5: =IF($B5="","",내역서!$C5) | D5: =IF($B5="","",내역서!$D5) | E5: =IF($B5="","",내역서!$E5) | F5: =IF($B5="","",N(내역서!$F5)) | G5: =IF($B5="","",N(내역서!$J5)) | H5: =IF($B5="","",N(내역서!$K5)) | I5: =IF($B5="","",N(내역서!$N5)) | J5: =IF($B5="","",N(내역서!$R5)) | K5: =IF($B5="","",N($I5)-N($F5)) | L5: =IF($B5="","",IF(N(내역서!$F5)=0,"신규",IF($K5<0,"감소",IF($K5>0,"증가","-")))) | O5: =IF($B5="","",IF($L5="감소",$G5,IF($L5="증가",IF($M5="Y",ROUND(($J5+$J5*('설정'!$C$15/100))/2,0),IF(AND($N5<>"",$G5>$N5),$N5,$G5)),IF($L5="신규",IF($M5="Y",ROUND(($J5+$J5*('설정'!$C$15/100))/2,0),ROUND($J5*('설정'!$C$15/100),0)),0)))) | P5: =IF($B5="","",ROUND(N($K5)*N($O5),0)) | Q5: =IF($B5="","",IF($L5="감소","감소분 → 계약단가",IF(AND($M5="Y",OR($L5="증가",$L5="신규")),"발주기관 요구 → 협의 (불성립 시 (당시단가+당시단가×낙찰률)÷2)",IF($L5="증가",IF(AND($N5<>"",$G5>$N5),"증가분 → 계약단가>예정가격단가 이므로 예정가격단가","증가분 → 계약단가 (낙찰률을 곱하지 않습니다)"),IF($L5="신규","신규비목 → 당시단가 × 낙찰률",""))))) | R5: =IF($B5="","",IF(N($O5)=0,0,IF(OR($L5="감소",AND($L5="증가",$M5<>"Y")),IF(N($G5)=0,0,ROUND(N(내역서!$G5)*$O5/$G5,0)),IF(N($J5)=0,0,ROUND(N(내역서!$O5)*$O5/$J5,0))))) | S5: =IF($B5="","",IF(N($O5)=0,0,IF(OR($L5="감소",AND($L5="증가",$M5<>"Y")),IF(N($G5)=0,0,ROUND(N(내역서!$H5)*$O5/$G5,0)),IF(N($J5)=0,0,ROUND(N(내역서!$P5)*$O5/$J5,0))))) | T5: =IF($B5="","",N($O5)-N($R5)-N($S5)) | U5: =IF($B5="","",ROUND(N($K5)*N($R5),0)) | V5: =IF($B5="","",ROUND(N($K5)*N($S5),0)) | W5: =IF($B5="","",N($P5)-N($U5)-N($V5))
A6: =IF($B6="","",ROW()-4+1) | B6: =내역서!$B6 | C6: =IF($B6="","",내역서!$C6) | D6: =IF($B6="","",내역서!$D6) | E6: =IF($B6="","",내역서!$E6) | F6: =IF($B6="","",N(내역서!$F6)) | G6: =IF($B6="","",N(내역서!$J6)) | H6: =IF($B6="","",N(내역서!$K6)) | I6: =IF($B6="","",N(내역서!$N6)) | J6: =IF($B6="","",N(내역서!$R6)) | K6: =IF($B6="","",N($I6)-N($F6)) | L6: =IF($B6="","",IF(N(내역서!$F6)=0,"신규",IF($K6<0,"감소",IF($K6>0,"증가","-")))) | O6: =IF($B6="","",IF($L6="감소",$G6,IF($L6="증가",IF($M6="Y",ROUND(($J6+$J6*('설정'!$C$15/100))/2,0),IF(AND($N6<>"",$G6>$N6),$N6,$G6)),IF($L6="신규",IF($M6="Y",ROUND(($J6+$J6*('설정'!$C$15/100))/2,0),ROUND($J6*('설정'!$C$15/100),0)),0)))) | P6: =IF($B6="","",ROUND(N($K6)*N($O6),0)) | Q6: =IF($B6="","",IF($L6="감소","감소분 → 계약단가",IF(AND($M6="Y",OR($L6="증가",$L6="신규")),"발주기관 요구 → 협의 (불성립 시 (당시단가+당시단가×낙찰률)÷2)",IF($L6="증가",IF(AND($N6<>"",$G6>$N6),"증가분 → 계약단가>예정가격단가 이므로 예정가격단가","증가분 → 계약단가 (낙찰률을 곱하지 않습니다)"),IF($L6="신규","신규비목 → 당시단가 × 낙찰률",""))))) | R6: =IF($B6="","",IF(N($O6)=0,0,IF(OR($L6="감소",AND($L6="증가",$M6<>"Y")),IF(N($G6)=0,0,ROUND(N(내역서!$G6)*$O6/$G6,0)),IF(N($J6)=0,0,ROUND(N(내역서!$O6)*$O6/$J6,0))))) | S6: =IF($B6="","",IF(N($O6)=0,0,IF(OR($L6="감소",AND($L6="증가",$M6<>"Y")),IF(N($G6)=0,0,ROUND(N(내역서!$H6)*$O6/$G6,0)),IF(N($J6)=0,0,ROUND(N(내역서!$P6)*$O6/$J6,0))))) | T6: =IF($B6="","",N($O6)-N($R6)-N($S6)) | U6: =IF($B6="","",ROUND(N($K6)*N($R6),0)) | V6: =IF($B6="","",ROUND(N($K6)*N($S6),0)) | W6: =IF($B6="","",N($P6)-N($U6)-N($V6))
A7: =IF($B7="","",ROW()-4+1) | B7: =내역서!$B7 | C7: =IF($B7="","",내역서!$C7) | D7: =IF($B7="","",내역서!$D7) | E7: =IF($B7="","",내역서!$E7) | F7: =IF($B7="","",N(내역서!$F7)) | G7: =IF($B7="","",N(내역서!$J7)) | H7: =IF($B7="","",N(내역서!$K7)) | I7: =IF($B7="","",N(내역서!$N7)) | J7: =IF($B7="","",N(내역서!$R7)) | K7: =IF($B7="","",N($I7)-N($F7)) | L7: =IF($B7="","",IF(N(내역서!$F7)=0,"신규",IF($K7<0,"감소",IF($K7>0,"증가","-")))) | O7: =IF($B7="","",IF($L7="감소",$G7,IF($L7="증가",IF($M7="Y",ROUND(($J7+$J7*('설정'!$C$15/100))/2,0),IF(AND($N7<>"",$G7>$N7),$N7,$G7)),IF($L7="신규",IF($M7="Y",ROUND(($J7+$J7*('설정'!$C$15/100))/2,0),ROUND($J7*('설정'!$C$15/100),0)),0)))) | P7: =IF($B7="","",ROUND(N($K7)*N($O7),0)) | Q7: =IF($B7="","",IF($L7="감소","감소분 → 계약단가",IF(AND($M7="Y",OR($L7="증가",$L7="신규")),"발주기관 요구 → 협의 (불성립 시 (당시단가+당시단가×낙찰률)÷2)",IF($L7="증가",IF(AND($N7<>"",$G7>$N7),"증가분 → 계약단가>예정가격단가 이므로 예정가격단가","증가분 → 계약단가 (낙찰률을 곱하지 않습니다)"),IF($L7="신규","신규비목 → 당시단가 × 낙찰률",""))))) | R7: =IF($B7="","",IF(N($O7)=0,0,IF(OR($L7="감소",AND($L7="증가",$M7<>"Y")),IF(N($G7)=0,0,ROUND(N(내역서!$G7)*$O7/$G7,0)),IF(N($J7)=0,0,ROUND(N(내역서!$O7)*$O7/$J7,0))))) | S7: =IF($B7="","",IF(N($O7)=0,0,IF(OR($L7="감소",AND($L7="증가",$M7<>"Y")),IF(N($G7)=0,0,ROUND(N(내역서!$H7)*$O7/$G7,0)),IF(N($J7)=0,0,ROUND(N(내역서!$P7)*$O7/$J7,0))))) | T7: =IF($B7="","",N($O7)-N($R7)-N($S7)) | U7: =IF($B7="","",ROUND(N($K7)*N($R7),0)) | V7: =IF($B7="","",ROUND(N($K7)*N($S7),0)) | W7: =IF($B7="","",N($P7)-N($U7)-N($V7))
A8: =IF($B8="","",ROW()-4+1) | B8: =내역서!$B8 | C8: =IF($B8="","",내역서!$C8) | D8: =IF($B8="","",내역서!$D8) | E8: =IF($B8="","",내역서!$E8) | F8: =IF($B8="","",N(내역서!$F8)) | G8: =IF($B8="","",N(내역서!$J8)) | H8: =IF($B8="","",N(내역서!$K8)) | I8: =IF($B8="","",N(내역서!$N8)) | J8: =IF($B8="","",N(내역서!$R8)) | K8: =IF($B8="","",N($I8)-N($F8)) | L8: =IF($B8="","",IF(N(내역서!$F8)=0,"신규",IF($K8<0,"감소",IF($K8>0,"증가","-")))) | O8: =IF($B8="","",IF($L8="감소",$G8,IF($L8="증가",IF($M8="Y",ROUND(($J8+$J8*('설정'!$C$15/100))/2,0),IF(AND($N8<>"",$G8>$N8),$N8,$G8)),IF($L8="신규",IF($M8="Y",ROUND(($J8+$J8*('설정'!$C$15/100))/2,0),ROUND($J8*('설정'!$C$15/100),0)),0)))) | P8: =IF($B8="","",ROUND(N($K8)*N($O8),0)) | Q8: =IF($B8="","",IF($L8="감소","감소분 → 계약단가",IF(AND($M8="Y",OR($L8="증가",$L8="신규")),"발주기관 요구 → 협의 (불성립 시 (당시단가+당시단가×낙찰률)÷2)",IF($L8="증가",IF(AND($N8<>"",$G8>$N8),"증가분 → 계약단가>예정가격단가 이므로 예정가격단가","증가분 → 계약단가 (낙찰률을 곱하지 않습니다)"),IF($L8="신규","신규비목 → 당시단가 × 낙찰률",""))))) | R8: =IF($B8="","",IF(N($O8)=0,0,IF(OR($L8="감소",AND($L8="증가",$M8<>"Y")),IF(N($G8)=0,0,ROUND(N(내역서!$G8)*$O8/$G8,0)),IF(N($J8)=0,0,ROUND(N(내역서!$O8)*$O8/$J8,0))))) | S8: =IF($B8="","",IF(N($O8)=0,0,IF(OR($L8="감소",AND($L8="증가",$M8<>"Y")),IF(N($G8)=0,0,ROUND(N(내역서!$H8)*$O8/$G8,0)),IF(N($J8)=0,0,ROUND(N(내역서!$P8)*$O8/$J8,0))))) | T8: =IF($B8="","",N($O8)-N($R8)-N($S8)) | U8: =IF($B8="","",ROUND(N($K8)*N($R8),0)) | V8: =IF($B8="","",ROUND(N($K8)*N($S8),0)) | W8: =IF($B8="","",N($P8)-N($U8)-N($V8))
A9: =IF($B9="","",ROW()-4+1) | B9: =내역서!$B9 | C9: =IF($B9="","",내역서!$C9) | D9: =IF($B9="","",내역서!$D9) | E9: =IF($B9="","",내역서!$E9) | F9: =IF($B9="","",N(내역서!$F9)) | G9: =IF($B9="","",N(내역서!$J9)) | H9: =IF($B9="","",N(내역서!$K9)) | I9: =IF($B9="","",N(내역서!$N9)) | J9: =IF($B9="","",N(내역서!$R9)) | K9: =IF($B9="","",N($I9)-N($F9)) | L9: =IF($B9="","",IF(N(내역서!$F9)=0,"신규",IF($K9<0,"감소",IF($K9>0,"증가","-")))) | O9: =IF($B9="","",IF($L9="감소",$G9,IF($L9="증가",IF($M9="Y",ROUND(($J9+$J9*('설정'!$C$15/100))/2,0),IF(AND($N9<>"",$G9>$N9),$N9,$G9)),IF($L9="신규",IF($M9="Y",ROUND(($J9+$J9*('설정'!$C$15/100))/2,0),ROUND($J9*('설정'!$C$15/100),0)),0)))) | P9: =IF($B9="","",ROUND(N($K9)*N($O9),0)) | Q9: =IF($B9="","",IF($L9="감소","감소분 → 계약단가",IF(AND($M9="Y",OR($L9="증가",$L9="신규")),"발주기관 요구 → 협의 (불성립 시 (당시단가+당시단가×낙찰률)÷2)",IF($L9="증가",IF(AND($N9<>"",$G9>$N9),"증가분 → 계약단가>예정가격단가 이므로 예정가격단가","증가분 → 계약단가 (낙찰률을 곱하지 않습니다)"),IF($L9="신규","신규비목 → 당시단가 × 낙찰률",""))))) | R9: =IF($B9="","",IF(N($O9)=0,0,IF(OR($L9="감소",AND($L9="증가",$M9<>"Y")),IF(N($G9)=0,0,ROUND(N(내역서!$G9)*$O9/$G9,0)),IF(N($J9)=0,0,ROUND(N(내역서!$O9)*$O9/$J9,0))))) | S9: =IF($B9="","",IF(N($O9)=0,0,IF(OR($L9="감소",AND($L9="증가",$M9<>"Y")),IF(N($G9)=0,0,ROUND(N(내역서!$H9)*$O9/$G9,0)),IF(N($J9)=0,0,ROUND(N(내역서!$P9)*$O9/$J9,0))))) | T9: =IF($B9="","",N($O9)-N($R9)-N($S9)) | U9: =IF($B9="","",ROUND(N($K9)*N($R9),0)) | V9: =IF($B9="","",ROUND(N($K9)*N($S9),0)) | W9: =IF($B9="","",N($P9)-N($U9)-N($V9))
A10: =IF($B10="","",ROW()-4+1) | B10: =내역서!$B10 | C10: =IF($B10="","",내역서!$C10) | D10: =IF($B10="","",내역서!$D10) | E10: =IF($B10="","",내역서!$E10) | F10: =IF($B10="","",N(내역서!$F10)) | G10: =IF($B10="","",N(내역서!$J10)) | H10: =IF($B10="","",N(내역서!$K10)) | I10: =IF($B10="","",N(내역서!$N10)) | J10: =IF($B10="","",N(내역서!$R10)) | K10: =IF($B10="","",N($I10)-N($F10)) | L10: =IF($B10="","",IF(N(내역서!$F10)=0,"신규",IF($K10<0,"감소",IF($K10>0,"증가","-")))) | O10: =IF($B10="","",IF($L10="감소",$G10,IF($L10="증가",IF($M10="Y",ROUND(($J10+$J10*('설정'!$C$15/100))/2,0),IF(AND($N10<>"",$G10>$N10),$N10,$G10)),IF($L10="신규",IF($M10="Y",ROUND(($J10+$J10*('설정'!$C$15/100))/2,0),ROUND($J10*('설정'!$C$15/100),0)),0)))) | P10: =IF($B10="","",ROUND(N($K10)*N($O10),0)) | Q10: =IF($B10="","",IF($L10="감소","감소분 → 계약단가",IF(AND($M10="Y",OR($L10="증가",$L10="신규")),"발주기관 요구 → 협의 (불성립 시 (당시단가+당시단가×낙찰률)÷2)",IF($L10="증가",IF(AND($N10<>"",$G10>$N10),"증가분 → 계약단가>예정가격단가 이므로 예정가격단가","증가분 → 계약단가 (낙찰률을 곱하지 않습니다)"),IF($L10="신규","신규비목 → 당시단가 × 낙찰률",""))))) | R10: =IF($B10="","",IF(N($O10)=0,0,IF(OR($L10="감소",AND($L10="증가",$M10<>"Y")),IF(N($G10)=0,0,ROUND(N(내역서!$G10)*$O10/$G10,0)),IF(N($J10)=0,0,ROUND(N(내역서!$O10)*$O10/$J10,0))))) | S10: =IF($B10="","",IF(N($O10)=0,0,IF(OR($L10="감소",AND($L10="증가",$M10<>"Y")),IF(N($G10)=0,0,ROUND(N(내역서!$H10)*$O10/$G10,0)),IF(N($J10)=0,0,ROUND(N(내역서!$P10)*$O10/$J10,0))))) | T10: =IF($B10="","",N($O10)-N($R10)-N($S10)) | U10: =IF($B10="","",ROUND(N($K10)*N($R10),0)) | V10: =IF($B10="","",ROUND(N($K10)*N($S10),0)) | W10: =IF($B10="","",N($P10)-N($U10)-N($V10))
A11: =IF($B11="","",ROW()-4+1) | B11: =내역서!$B11 | C11: =IF($B11="","",내역서!$C11) | D11: =IF($B11="","",내역서!$D11) | E11: =IF($B11="","",내역서!$E11) | F11: =IF($B11="","",N(내역서!$F11)) | G11: =IF($B11="","",N(내역서!$J11)) | H11: =IF($B11="","",N(내역서!$K11)) | I11: =IF($B11="","",N(내역서!$N11)) | J11: =IF($B11="","",N(내역서!$R11)) | K11: =IF($B11="","",N($I11)-N($F11)) | L11: =IF($B11="","",IF(N(내역서!$F11)=0,"신규",IF($K11<0,"감소",IF($K11>0,"증가","-")))) | O11: =IF($B11="","",IF($L11="감소",$G11,IF($L11="증가",IF($M11="Y",ROUND(($J11+$J11*('설정'!$C$15/100))/2,0),IF(AND($N11<>"",$G11>$N11),$N11,$G11)),IF($L11="신규",IF($M11="Y",ROUND(($J11+$J11*('설정'!$C$15/100))/2,0),ROUND($J11*('설정'!$C$15/100),0)),0)))) | P11: =IF($B11="","",ROUND(N($K11)*N($O11),0)) | Q11: =IF($B11="","",IF($L11="감소","감소분 → 계약단가",IF(AND($M11="Y",OR($L11="증가",$L11="신규")),"발주기관 요구 → 협의 (불성립 시 (당시단가+당시단가×낙찰률)÷2)",IF($L11="증가",IF(AND($N11<>"",$G11>$N11),"증가분 → 계약단가>예정가격단가 이므로 예정가격단가","증가분 → 계약단가 (낙찰률을 곱하지 않습니다)"),IF($L11="신규","신규비목 → 당시단가 × 낙찰률",""))))) | R11: =IF($B11="","",IF(N($O11)=0,0,IF(OR($L11="감소",AND($L11="증가",$M11<>"Y")),IF(N($G11)=0,0,ROUND(N(내역서!$G11)*$O11/$G11,0)),IF(N($J11)=0,0,ROUND(N(내역서!$O11)*$O11/$J11,0))))) | S11: =IF($B11="","",IF(N($O11)=0,0,IF(OR($L11="감소",AND($L11="증가",$M11<>"Y")),IF(N($G11)=0,0,ROUND(N(내역서!$H11)*$O11/$G11,0)),IF(N($J11)=0,0,ROUND(N(내역서!$P11)*$O11/$J11,0))))) | T11: =IF($B11="","",N($O11)-N($R11)-N($S11)) | U11: =IF($B11="","",ROUND(N($K11)*N($R11),0)) | V11: =IF($B11="","",ROUND(N($K11)*N($S11),0)) | W11: =IF($B11="","",N($P11)-N($U11)-N($V11))
A12: =IF($B12="","",ROW()-4+1) | B12: =내역서!$B12 | C12: =IF($B12="","",내역서!$C12) | D12: =IF($B12="","",내역서!$D12) | E12: =IF($B12="","",내역서!$E12) | F12: =IF($B12="","",N(내역서!$F12)) | G12: =IF($B12="","",N(내역서!$J12)) | H12: =IF($B12="","",N(내역서!$K12)) | I12: =IF($B12="","",N(내역서!$N12)) | J12: =IF($B12="","",N(내역서!$R12)) | K12: =IF($B12="","",N($I12)-N($F12)) | L12: =IF($B12="","",IF(N(내역서!$F12)=0,"신규",IF($K12<0,"감소",IF($K12>0,"증가","-")))) | O12: =IF($B12="","",IF($L12="감소",$G12,IF($L12="증가",IF($M12="Y",ROUND(($J12+$J12*('설정'!$C$15/100))/2,0),IF(AND($N12<>"",$G12>$N12),$N12,$G12)),IF($L12="신규",IF($M12="Y",ROUND(($J12+$J12*('설정'!$C$15/100))/2,0),ROUND($J12*('설정'!$C$15/100),0)),0)))) | P12: =IF($B12="","",ROUND(N($K12)*N($O12),0)) | Q12: =IF($B12="","",IF($L12="감소","감소분 → 계약단가",IF(AND($M12="Y",OR($L12="증가",$L12="신규")),"발주기관 요구 → 협의 (불성립 시 (당시단가+당시단가×낙찰률)÷2)",IF($L12="증가",IF(AND($N12<>"",$G12>$N12),"증가분 → 계약단가>예정가격단가 이므로 예정가격단가","증가분 → 계약단가 (낙찰률을 곱하지 않습니다)"),IF($L12="신규","신규비목 → 당시단가 × 낙찰률",""))))) | R12: =IF($B12="","",IF(N($O12)=0,0,IF(OR($L12="감소",AND($L12="증가",$M12<>"Y")),IF(N($G12)=0,0,ROUND(N(내역서!$G12)*$O12/$G12,0)),IF(N($J12)=0,0,ROUND(N(내역서!$O12)*$O12/$J12,0))))) | S12: =IF($B12="","",IF(N($O12)=0,0,IF(OR($L12="감소",AND($L12="증가",$M12<>"Y")),IF(N($G12)=0,0,ROUND(N(내역서!$H12)*$O12/$G12,0)),IF(N($J12)=0,0,ROUND(N(내역서!$P12)*$O12/$J12,0))))) | T12: =IF($B12="","",N($O12)-N($R12)-N($S12)) | U12: =IF($B12="","",ROUND(N($K12)*N($R12),0)) | V12: =IF($B12="","",ROUND(N($K12)*N($S12),0)) | W12: =IF($B12="","",N($P12)-N($U12)-N($V12))
A13: =IF($B13="","",ROW()-4+1) | B13: =내역서!$B13 | C13: =IF($B13="","",내역서!$C13) | D13: =IF($B13="","",내역서!$D13) | E13: =IF($B13="","",내역서!$E13) | F13: =IF($B13="","",N(내역서!$F13)) | G13: =IF($B13="","",N(내역서!$J13)) | H13: =IF($B13="","",N(내역서!$K13)) | I13: =IF($B13="","",N(내역서!$N13)) | J13: =IF($B13="","",N(내역서!$R13)) | K13: =IF($B13="","",N($I13)-N($F13)) | L13: =IF($B13="","",IF(N(내역서!$F13)=0,"신규",IF($K13<0,"감소",IF($K13>0,"증가","-")))) | O13: =IF($B13="","",IF($L13="감소",$G13,IF($L13="증가",IF($M13="Y",ROUND(($J13+$J13*('설정'!$C$15/100))/2,0),IF(AND($N13<>"",$G13>$N13),$N13,$G13)),IF($L13="신규",IF($M13="Y",ROUND(($J13+$J13*('설정'!$C$15/100))/2,0),ROUND($J13*('설정'!$C$15/100),0)),0)))) | P13: =IF($B13="","",ROUND(N($K13)*N($O13),0)) | Q13: =IF($B13="","",IF($L13="감소","감소분 → 계약단가",IF(AND($M13="Y",OR($L13="증가",$L13="신규")),"발주기관 요구 → 협의 (불성립 시 (당시단가+당시단가×낙찰률)÷2)",IF($L13="증가",IF(AND($N13<>"",$G13>$N13),"증가분 → 계약단가>예정가격단가 이므로 예정가격단가","증가분 → 계약단가 (낙찰률을 곱하지 않습니다)"),IF($L13="신규","신규비목 → 당시단가 × 낙찰률",""))))) | R13: =IF($B13="","",IF(N($O13)=0,0,IF(OR($L13="감소",AND($L13="증가",$M13<>"Y")),IF(N($G13)=0,0,ROUND(N(내역서!$G13)*$O13/$G13,0)),IF(N($J13)=0,0,ROUND(N(내역서!$O13)*$O13/$J13,0))))) | S13: =IF($B13="","",IF(N($O13)=0,0,IF(OR($L13="감소",AND($L13="증가",$M13<>"Y")),IF(N($G13)=0,0,ROUND(N(내역서!$H13)*$O13/$G13,0)),IF(N($J13)=0,0,ROUND(N(내역서!$P13)*$O13/$J13,0))))) | T13: =IF($B13="","",N($O13)-N($R13)-N($S13)) | U13: =IF($B13="","",ROUND(N($K13)*N($R13),0)) | V13: =IF($B13="","",ROUND(N($K13)*N($S13),0)) | W13: =IF($B13="","",N($P13)-N($U13)-N($V13))
A14: =IF($B14="","",ROW()-4+1) | B14: =내역서!$B14 | C14: =IF($B14="","",내역서!$C14) | D14: =IF($B14="","",내역서!$D14) | E14: =IF($B14="","",내역서!$E14) | F14: =IF($B14="","",N(내역서!$F14)) | G14: =IF($B14="","",N(내역서!$J14)) | H14: =IF($B14="","",N(내역서!$K14)) | I14: =IF($B14="","",N(내역서!$N14)) | J14: =IF($B14="","",N(내역서!$R14)) | K14: =IF($B14="","",N($I14)-N($F14)) | L14: =IF($B14="","",IF(N(내역서!$F14)=0,"신규",IF($K14<0,"감소",IF($K14>0,"증가","-")))) | O14: =IF($B14="","",IF($L14="감소",$G14,IF($L14="증가",IF($M14="Y",ROUND(($J14+$J14*('설정'!$C$15/100))/2,0),IF(AND($N14<>"",$G14>$N14),$N14,$G14)),IF($L14="신규",IF($M14="Y",ROUND(($J14+$J14*('설정'!$C$15/100))/2,0),ROUND($J14*('설정'!$C$15/100),0)),0)))) | P14: =IF($B14="","",ROUND(N($K14)*N($O14),0)) | Q14: =IF($B14="","",IF($L14="감소","감소분 → 계약단가",IF(AND($M14="Y",OR($L14="증가",$L14="신규")),"발주기관 요구 → 협의 (불성립 시 (당시단가+당시단가×낙찰률)÷2)",IF($L14="증가",IF(AND($N14<>"",$G14>$N14),"증가분 → 계약단가>예정가격단가 이므로 예정가격단가","증가분 → 계약단가 (낙찰률을 곱하지 않습니다)"),IF($L14="신규","신규비목 → 당시단가 × 낙찰률",""))))) | R14: =IF($B14="","",IF(N($O14)=0,0,IF(OR($L14="감소",AND($L14="증가",$M14<>"Y")),IF(N($G14)=0,0,ROUND(N(내역서!$G14)*$O14/$G14,0)),IF(N($J14)=0,0,ROUND(N(내역서!$O14)*$O14/$J14,0))))) | S14: =IF($B14="","",IF(N($O14)=0,0,IF(OR($L14="감소",AND($L14="증가",$M14<>"Y")),IF(N($G14)=0,0,ROUND(N(내역서!$H14)*$O14/$G14,0)),IF(N($J14)=0,0,ROUND(N(내역서!$P14)*$O14/$J14,0))))) | T14: =IF($B14="","",N($O14)-N($R14)-N($S14)) | U14: =IF($B14="","",ROUND(N($K14)*N($R14),0)) | V14: =IF($B14="","",ROUND(N($K14)*N($S14),0)) | W14: =IF($B14="","",N($P14)-N($U14)-N($V14))
A15: =IF($B15="","",ROW()-4+1) | B15: =내역서!$B15 | C15: =IF($B15="","",내역서!$C15) | D15: =IF($B15="","",내역서!$D15) | E15: =IF($B15="","",내역서!$E15) | F15: =IF($B15="","",N(내역서!$F15)) | G15: =IF($B15="","",N(내역서!$J15)) | H15: =IF($B15="","",N(내역서!$K15)) | I15: =IF($B15="","",N(내역서!$N15)) | J15: =IF($B15="","",N(내역서!$R15)) | K15: =IF($B15="","",N($I15)-N($F15)) | L15: =IF($B15="","",IF(N(내역서!$F15)=0,"신규",IF($K15<0,"감소",IF($K15>0,"증가","-")))) | O15: =IF($B15="","",IF($L15="감소",$G15,IF($L15="증가",IF($M15="Y",ROUND(($J15+$J15*('설정'!$C$15/100))/2,0),IF(AND($N15<>"",$G15>$N15),$N15,$G15)),IF($L15="신규",IF($M15="Y",ROUND(($J15+$J15*('설정'!$C$15/100))/2,0),ROUND($J15*('설정'!$C$15/100),0)),0)))) | P15: =IF($B15="","",ROUND(N($K15)*N($O15),0)) | Q15: =IF($B15="","",IF($L15="감소","감소분 → 계약단가",IF(AND($M15="Y",OR($L15="증가",$L15="신규")),"발주기관 요구 → 협의 (불성립 시 (당시단가+당시단가×낙찰률)÷2)",IF($L15="증가",IF(AND($N15<>"",$G15>$N15),"증가분 → 계약단가>예정가격단가 이므로 예정가격단가","증가분 → 계약단가 (낙찰률을 곱하지 않습니다)"),IF($L15="신규","신규비목 → 당시단가 × 낙찰률",""))))) | R15: =IF($B15="","",IF(N($O15)=0,0,IF(OR($L15="감소",AND($L15="증가",$M15<>"Y")),IF(N($G15)=0,0,ROUND(N(내역서!$G15)*$O15/$G15,0)),IF(N($J15)=0,0,ROUND(N(내역서!$O15)*$O15/$J15,0))))) | S15: =IF($B15="","",IF(N($O15)=0,0,IF(OR($L15="감소",AND($L15="증가",$M15<>"Y")),IF(N($G15)=0,0,ROUND(N(내역서!$H15)*$O15/$G15,0)),IF(N($J15)=0,0,ROUND(N(내역서!$P15)*$O15/$J15,0))))) | T15: =IF($B15="","",N($O15)-N($R15)-N($S15)) | U15: =IF($B15="","",ROUND(N($K15)*N($R15),0)) | V15: =IF($B15="","",ROUND(N($K15)*N($S15),0)) | W15: =IF($B15="","",N($P15)-N($U15)-N($V15))
... A203: =IF($B203="","",ROW()-4+1) | B203: =내역서!$B203 | C203: =IF($B203="","",내역서!$C203) | D203: =IF($B203="","",내역서!$D203) | E203: =IF($B203="","",내역서!$E203) | F203: =IF($B203="","",N(내역서!$F203)) | G203: =IF($B203="","",N(내역서!$J203)) | H203: =IF($B203="","",N(내역서!$K203)) | I203: =IF($B203="","",N(내역서!$N203)) | J203: =IF($B203="","",N(내역서!$R203)) | K203: =IF($B203="","",N($I203)-N($F203)) | L203: =IF($B203="","",IF(N(내역서!$F203)=0,"신규",IF($K203<0,"감소",IF($K203>0,"증가","-")))) | O203: =IF($B203="","",IF($L203="감소",$G203,IF($L203="증가",IF($M203="Y",ROUND(($J203+$J203*('설정'!$C$15/100))/2,0),IF(AND($N203<>"",$G203>$N203),$N203,$G203)),IF($L203="신규",IF($M203="Y",ROUND(($J203+$J203*('설정'!$C$15/100))/2,0),ROUND($J203*('설정'!$C$15/100),0)),0)))) | P203: =IF($B203="","",ROUND(N($K203)*N($O203),0)) | Q203: =IF($B203="","",IF($L203="감소","감소분 → 계약단가",IF(AND($M203="Y",OR($L203="증가",$L203="신규")),"발주기관 요구 → 협의 (불성립 시 (당시단가+당시단가×낙찰률)÷2)",IF($L203="증가",IF(AND($N203<>"",$G203>$N203),"증가분 → 계약단가>예정가격단가 이므로 예정가격단가","증가분 → 계약단가 (낙찰률을 곱하지 않습니다)"),IF($L203="신규","신규비목 → 당시단가 × 낙찰률",""))))) | R203: =IF($B203="","",IF(N($O203)=0,0,IF(OR($L203="감소",AND($L203="증가",$M203<>"Y")),IF(N($G203)=0,0,ROUND(N(내역서!$G203)*$O203/$G203,0)),IF(N($J203)=0,0,ROUND(N(내역서!$O203)*$O203/$J203,0))))) | S203: =IF($B203="","",IF(N($O203)=0,0,IF(OR($L203="감소",AND($L203="증가",$M203<>"Y")),IF(N($G203)=0,0,ROUND(N(내역서!$H203)*$O203/$G203,0)),IF(N($J203)=0,0,ROUND(N(내역서!$P203)*$O203/$J203,0))))) | T203: =IF($B203="","",N($O203)-N($R203)-N($S203)) | U203: =IF($B203="","",ROUND(N($K203)*N($R203),0)) | V203: =IF($B203="","",ROUND(N($K203)*N($S203),0)) | W203: =IF($B203="","",N($P203)-N($U203)-N($V203))
N204: 증가 소계 | P204: =SUMIF($L$4:$L$203,"증가",$P$4:$P$203)
N205: 감소 소계 | P205: =SUMIF($L$4:$L$203,"감소",$P$4:$P$203)
N206: 신규 소계 | P206: =SUMIF($L$4:$L$203,"신규",$P$4:$P$203)
N207: 직접공사비 증감 합계 | P207: =SUM($P$4:$P$203)
N208: 제비율 · 일반관리비 · 이윤 · 부가세 증감 | P208: =원가계산서!$G$33-P207
N209: 계약금액 증감 (원가계산서 도급액) | P209: =원가계산서!$G$33
N210: 변경 후 계약금액 | P210: ='설정'!$C$13+P209
A212: 이 표는 손으로 채우는 곳이 «협의(Y)» 와 «예정가격단가» 둘뿐입니다. 나머지는 전부 자동입니다. · 발주기관이 요구해서 늘어난 분이면 협의 칸에 Y 를 넣으세요 — 단가가 협의식으로 바뀝니다. · 예정가격단가는 «아는 경우에만» 적으세요. 계약단가가 그보다 높으면 예정가격단가가 적용됩니다. · 증가분에는 낙찰률을 곱하지 않습니다. 낙찰률은 «신규 비목» 에만 곱합니다. · R~W 열은 적용단가를 재료비 · 노무비 · 경비로 가른 것입니다 — 원가계산서 «변경 후» 가 «당초 + 이 증감» 으로 셉니다. · 변경 후 계약금액 = 계약금액 + 원가계산서 «도급액» 증감(간접노무비 · 보험료 · 일반관리비 · 이윤 · 부가세까지 · 시행령 제65조⑥).

Sheet 공종별집계
A1: K-건설맵 | k-conmap.com ← 이 1행을 지우고 쓰셔도 됩니다
A2: 공 종 별 집 계
A3: 대공종 코드 | B3: 대공종 명 | C3: 당초금액 | D3: 증감금액 | E3: 변경 후 금액 | F3: 증감률(%)
C4: =IF($A4="","",SUMPRODUCT((LEFT(내역서!$B$4:$B$203,LEN($A4))=$A4)*N(내역서!$K$4:$K$203))) | D4: =IF($A4="","",SUMPRODUCT((LEFT(증감대비표!$B$4:$B$203,LEN($A4))=$A4)*N(증감대비표!$P$4:$P$203))) | E4: =IF($A4="","",N($C4)+N($D4)) | F4: =IF(OR($A4="",N($C4)=0),"",ROUND($D4/$C4*100,2))
C5: =IF($A5="","",SUMPRODUCT((LEFT(내역서!$B$4:$B$203,LEN($A5))=$A5)*N(내역서!$K$4:$K$203))) | D5: =IF($A5="","",SUMPRODUCT((LEFT(증감대비표!$B$4:$B$203,LEN($A5))=$A5)*N(증감대비표!$P$4:$P$203))) | E5: =IF($A5="","",N($C5)+N($D5)) | F5: =IF(OR($A5="",N($C5)=0),"",ROUND($D5/$C5*100,2))
C6: =IF($A6="","",SUMPRODUCT((LEFT(내역서!$B$4:$B$203,LEN($A6))=$A6)*N(내역서!$K$4:$K$203))) | D6: =IF($A6="","",SUMPRODUCT((LEFT(증감대비표!$B$4:$B$203,LEN($A6))=$A6)*N(증감대비표!$P$4:$P$203))) | E6: =IF($A6="","",N($C6)+N($D6)) | F6: =IF(OR($A6="",N($C6)=0),"",ROUND($D6/$C6*100,2))
C7: =IF($A7="","",SUMPRODUCT((LEFT(내역서!$B$4:$B$203,LEN($A7))=$A7)*N(내역서!$K$4:$K$203))) | D7: =IF($A7="","",SUMPRODUCT((LEFT(증감대비표!$B$4:$B$203,LEN($A7))=$A7)*N(증감대비표!$P$4:$P$203))) | E7: =IF($A7="","",N($C7)+N($D7)) | F7: =IF(OR($A7="",N($C7)=0),"",ROUND($D7/$C7*100,2))
C8: =IF($A8="","",SUMPRODUCT((LEFT(내역서!$B$4:$B$203,LEN($A8))=$A8)*N(내역서!$K$4:$K$203))) | D8: =IF($A8="","",SUMPRODUCT((LEFT(증감대비표!$B$4:$B$203,LEN($A8))=$A8)*N(증감대비표!$P$4:$P$203))) | E8: =IF($A8="","",N($C8)+N($D8)) | F8: =IF(OR($A8="",N($C8)=0),"",ROUND($D8/$C8*100,2))
C9: =IF($A9="","",SUMPRODUCT((LEFT(내역서!$B$4:$B$203,LEN($A9))=$A9)*N(내역서!$K$4:$K$203))) | D9: =IF($A9="","",SUMPRODUCT((LEFT(증감대비표!$B$4:$B$203,LEN($A9))=$A9)*N(증감대비표!$P$4:$P$203))) | E9: =IF($A9="","",N($C9)+N($D9)) | F9: =IF(OR($A9="",N($C9)=0),"",ROUND($D9/$C9*100,2))
C10: =IF($A10="","",SUMPRODUCT((LEFT(내역서!$B$4:$B$203,LEN($A10))=$A10)*N(내역서!$K$4:$K$203))) | D10: =IF($A10="","",SUMPRODUCT((LEFT(증감대비표!$B$4:$B$203,LEN($A10))=$A10)*N(증감대비표!$P$4:$P$203))) | E10: =IF($A10="","",N($C10)+N($D10)) | F10: =IF(OR($A10="",N($C10)=0),"",ROUND($D10/$C10*100,2))
C11: =IF($A11="","",SUMPRODUCT((LEFT(내역서!$B$4:$B$203,LEN($A11))=$A11)*N(내역서!$K$4:$K$203))) | D11: =IF($A11="","",SUMPRODUCT((LEFT(증감대비표!$B$4:$B$203,LEN($A11))=$A11)*N(증감대비표!$P$4:$P$203))) | E11: =IF($A11="","",N($C11)+N($D11)) | F11: =IF(OR($A11="",N($C11)=0),"",ROUND($D11/$C11*100,2))
C12: =IF($A12="","",SUMPRODUCT((LEFT(내역서!$B$4:$B$203,LEN($A12))=$A12)*N(내역서!$K$4:$K$203))) | D12: =IF($A12="","",SUMPRODUCT((LEFT(증감대비표!$B$4:$B$203,LEN($A12))=$A12)*N(증감대비표!$P$4:$P$203))) | E12: =IF($A12="","",N($C12)+N($D12)) | F12: =IF(OR($A12="",N($C12)=0),"",ROUND($D12/$C12*100,2))
C13: =IF($A13="","",SUMPRODUCT((LEFT(내역서!$B$4:$B$203,LEN($A13))=$A13)*N(내역서!$K$4:$K$203))) | D13: =IF($A13="","",SUMPRODUCT((LEFT(증감대비표!$B$4:$B$203,LEN($A13))=$A13)*N(증감대비표!$P$4:$P$203))) | E13: =IF($A13="","",N($C13)+N($D13)) | F13: =IF(OR($A13="",N($C13)=0),"",ROUND($D13/$C13*100,2))
C14: =IF($A14="","",SUMPRODUCT((LEFT(내역서!$B$4:$B$203,LEN($A14))=$A14)*N(내역서!$K$4:$K$203))) | D14: =IF($A14="","",SUMPRODUCT((LEFT(증감대비표!$B$4:$B$203,LEN($A14))=$A14)*N(증감대비표!$P$4:$P$203))) | E14: =IF($A14="","",N($C14)+N($D14)) | F14: =IF(OR($A14="",N($C14)=0),"",ROUND($D14/$C14*100,2))
C15: =IF($A15="","",SUMPRODUCT((LEFT(내역서!$B$4:$B$203,LEN($A15))=$A15)*N(내역서!$K$4:$K$203))) | D15: =IF($A15="","",SUMPRODUCT((LEFT(증감대비표!$B$4:$B$203,LEN($A15))=$A15)*N(증감대비표!$P$4:$P$203))) | E15: =IF($A15="","",N($C15)+N($D15)) | F15: =IF(OR($A15="",N($C15)=0),"",ROUND($D15/$C15*100,2))
... C28: =IF($A28="","",SUMPRODUCT((LEFT(내역서!$B$4:$B$203,LEN($A28))=$A28)*N(내역서!$K$4:$K$203))) | D28: =IF($A28="","",SUMPRODUCT((LEFT(증감대비표!$B$4:$B$203,LEN($A28))=$A28)*N(증감대비표!$P$4:$P$203))) | E28: =IF($A28="","",N($C28)+N($D28)) | F28: =IF(OR($A28="",N($C28)=0),"",ROUND($D28/$C28*100,2))
B29: 합 계 | C29: =SUM(C4:C28) | D29: =SUM(D4:D28) | E29: =SUM(E4:E28)
A31: 대공종 코드에 «토공» 처럼 코드 앞부분을 적으면 그 글자로 시작하는 모든 줄을 묶습니다. 예: 코드가 «토공-001, 토공-002» 이면 «토공» 이라고 적으세요.

Sheet 내역서
A1: K-건설맵 | k-conmap.com ← 이 1행을 지우고 쓰셔도 됩니다
A2: 산 출 내 역 서 (당초 · 변경 · 증감)
A3: 번호 | B3: 공종코드 | C3: 품 명 | D3: 규 격 | E3: 단위 | F3: 당초 수량 | G3: 당초 재료비 | H3: 당초 노무비 | I3: 당초 경비 | J3: 당초 합계단가 | K3: 당초 금액 | L3: 변경 수량(산출서) | M3: 변경 수량(직접) | N3: 변경 적용수량 | O3: 변경 재료비 | P3: 변경 노무비 | Q3: 변경 경비 | R3: 변경 합계단가 | S3: 변경 금액 | T3: 증감 수량 | U3: 증감 금액 | V3: 비고
C4: =IF($B4="","",IFERROR(VLOOKUP($B4,단가마스터!$A$4:$H$303,2,FALSE),IFERROR(VLOOKUP($B4,일위대가!$N$4:$T$63,2,FALSE),"⚠️단가 없음"))) | D4: =IF($B4="","",IFERROR(VLOOKUP($B4,단가마스터!$A$4:$H$303,3,FALSE),"")) | E4: =IF($B4="","",IFERROR(VLOOKUP($B4,단가마스터!$A$4:$H$303,4,FALSE),IFERROR(VLOOKUP($B4,일위대가!$N$4:$T$63,3,FALSE),""))) | J4: =IF($B4="","",N($G4)+N($H4)+N($I4)) | K4: =IF($B4="","",ROUND(N($F4)*N($J4),0)) | L4: =IF($B4="","",SUMIFS(수량산출서!$H$4:$H$253,수량산출서!$A$4:$A$253,"변경",수량산출서!$B$4:$B$253,$B4)) | N4: =IF($B4="","",IF($M4<>"",$M4,N($L4))) | O4: =IF($B4="","",IFERROR(VLOOKUP($B4,단가마스터!$A$4:$H$303,5,FALSE),IFERROR(VLOOKUP($B4,일위대가!$N$4:$T$63,4,FALSE),0))) | P4: =IF($B4="","",IFERROR(VLOOKUP($B4,단가마스터!$A$4:$H$303,6,FALSE),IFERROR(VLOOKUP($B4,일위대가!$N$4:$T$63,5,FALSE),0))) | Q4: =IF($B4="","",IFERROR(VLOOKUP($B4,단가마스터!$A$4:$H$303,7,FALSE),IFERROR(VLOOKUP($B4,일위대가!$N$4:$T$63,6,FALSE),0))) | R4: =IF($B4="","",N($O4)+N($P4)+N($Q4)) | S4: =IF($B4="","",ROUND(N($N4)*N($R4),0)) | T4: =IF($B4="","",N($N4)-N($F4)) | U4: =IF($B4="","",N($S4)-N($K4))
C5: =IF($B5="","",IFERROR(VLOOKUP($B5,단가마스터!$A$4:$H$303,2,FALSE),IFERROR(VLOOKUP($B5,일위대가!$N$4:$T$63,2,FALSE),"⚠️단가 없음"))) | D5: =IF($B5="","",IFERROR(VLOOKUP($B5,단가마스터!$A$4:$H$303,3,FALSE),"")) | E5: =IF($B5="","",IFERROR(VLOOKUP($B5,단가마스터!$A$4:$H$303,4,FALSE),IFERROR(VLOOKUP($B5,일위대가!$N$4:$T$63,3,FALSE),""))) | J5: =IF($B5="","",N($G5)+N($H5)+N($I5)) | K5: =IF($B5="","",ROUND(N($F5)*N($J5),0)) | L5: =IF($B5="","",SUMIFS(수량산출서!$H$4:$H$253,수량산출서!$A$4:$A$253,"변경",수량산출서!$B$4:$B$253,$B5)) | N5: =IF($B5="","",IF($M5<>"",$M5,N($L5))) | O5: =IF($B5="","",IFERROR(VLOOKUP($B5,단가마스터!$A$4:$H$303,5,FALSE),IFERROR(VLOOKUP($B5,일위대가!$N$4:$T$63,4,FALSE),0))) | P5: =IF($B5="","",IFERROR(VLOOKUP($B5,단가마스터!$A$4:$H$303,6,FALSE),IFERROR(VLOOKUP($B5,일위대가!$N$4:$T$63,5,FALSE),0))) | Q5: =IF($B5="","",IFERROR(VLOOKUP($B5,단가마스터!$A$4:$H$303,7,FALSE),IFERROR(VLOOKUP($B5,일위대가!$N$4:$T$63,6,FALSE),0))) | R5: =IF($B5="","",N($O5)+N($P5)+N($Q5)) | S5: =IF($B5="","",ROUND(N($N5)*N($R5),0)) | T5: =IF($B5="","",N($N5)-N($F5)) | U5: =IF($B5="","",N($S5)-N($K5))
C6: =IF($B6="","",IFERROR(VLOOKUP($B6,단가마스터!$A$4:$H$303,2,FALSE),IFERROR(VLOOKUP($B6,일위대가!$N$4:$T$63,2,FALSE),"⚠️단가 없음"))) | D6: =IF($B6="","",IFERROR(VLOOKUP($B6,단가마스터!$A$4:$H$303,3,FALSE),"")) | E6: =IF($B6="","",IFERROR(VLOOKUP($B6,단가마스터!$A$4:$H$303,4,FALSE),IFERROR(VLOOKUP($B6,일위대가!$N$4:$T$63,3,FALSE),""))) | J6: =IF($B6="","",N($G6)+N($H6)+N($I6)) | K6: =IF($B6="","",ROUND(N($F6)*N($J6),0)) | L6: =IF($B6="","",SUMIFS(수량산출서!$H$4:$H$253,수량산출서!$A$4:$A$253,"변경",수량산출서!$B$4:$B$253,$B6)) | N6: =IF($B6="","",IF($M6<>"",$M6,N($L6))) | O6: =IF($B6="","",IFERROR(VLOOKUP($B6,단가마스터!$A$4:$H$303,5,FALSE),IFERROR(VLOOKUP($B6,일위대가!$N$4:$T$63,4,FALSE),0))) | P6: =IF($B6="","",IFERROR(VLOOKUP($B6,단가마스터!$A$4:$H$303,6,FALSE),IFERROR(VLOOKUP($B6,일위대가!$N$4:$T$63,5,FALSE),0))) | Q6: =IF($B6="","",IFERROR(VLOOKUP($B6,단가마스터!$A$4:$H$303,7,FALSE),IFERROR(VLOOKUP($B6,일위대가!$N$4:$T$63,6,FALSE),0))) | R6: =IF($B6="","",N($O6)+N($P6)+N($Q6)) | S6: =IF($B6="","",ROUND(N($N6)*N($R6),0)) | T6: =IF($B6="","",N($N6)-N($F6)) | U6: =IF($B6="","",N($S6)-N($K6))
C7: =IF($B7="","",IFERROR(VLOOKUP($B7,단가마스터!$A$4:$H$303,2,FALSE),IFERROR(VLOOKUP($B7,일위대가!$N$4:$T$63,2,FALSE),"⚠️단가 없음"))) | D7: =IF($B7="","",IFERROR(VLOOKUP($B7,단가마스터!$A$4:$H$303,3,FALSE),"")) | E7: =IF($B7="","",IFERROR(VLOOKUP($B7,단가마스터!$A$4:$H$303,4,FALSE),IFERROR(VLOOKUP($B7,일위대가!$N$4:$T$63,3,FALSE),""))) | J7: =IF($B7="","",N($G7)+N($H7)+N($I7)) | K7: =IF($B7="","",ROUND(N($F7)*N($J7),0)) | L7: =IF($B7="","",SUMIFS(수량산출서!$H$4:$H$253,수량산출서!$A$4:$A$253,"변경",수량산출서!$B$4:$B$253,$B7)) | N7: =IF($B7="","",IF($M7<>"",$M7,N($L7))) | O7: =IF($B7="","",IFERROR(VLOOKUP($B7,단가마스터!$A$4:$H$303,5,FALSE),IFERROR(VLOOKUP($B7,일위대가!$N$4:$T$63,4,FALSE),0))) | P7: =IF($B7="","",IFERROR(VLOOKUP($B7,단가마스터!$A$4:$H$303,6,FALSE),IFERROR(VLOOKUP($B7,일위대가!$N$4:$T$63,5,FALSE),0))) | Q7: =IF($B7="","",IFERROR(VLOOKUP($B7,단가마스터!$A$4:$H$303,7,FALSE),IFERROR(VLOOKUP($B7,일위대가!$N$4:$T$63,6,FALSE),0))) | R7: =IF($B7="","",N($O7)+N($P7)+N($Q7)) | S7: =IF($B7="","",ROUND(N($N7)*N($R7),0)) | T7: =IF($B7="","",N($N7)-N($F7)) | U7: =IF($B7="","",N($S7)-N($K7))
C8: =IF($B8="","",IFERROR(VLOOKUP($B8,단가마스터!$A$4:$H$303,2,FALSE),IFERROR(VLOOKUP($B8,일위대가!$N$4:$T$63,2,FALSE),"⚠️단가 없음"))) | D8: =IF($B8="","",IFERROR(VLOOKUP($B8,단가마스터!$A$4:$H$303,3,FALSE),"")) | E8: =IF($B8="","",IFERROR(VLOOKUP($B8,단가마스터!$A$4:$H$303,4,FALSE),IFERROR(VLOOKUP($B8,일위대가!$N$4:$T$63,3,FALSE),""))) | J8: =IF($B8="","",N($G8)+N($H8)+N($I8)) | K8: =IF($B8="","",ROUND(N($F8)*N($J8),0)) | L8: =IF($B8="","",SUMIFS(수량산출서!$H$4:$H$253,수량산출서!$A$4:$A$253,"변경",수량산출서!$B$4:$B$253,$B8)) | N8: =IF($B8="","",IF($M8<>"",$M8,N($L8))) | O8: =IF($B8="","",IFERROR(VLOOKUP($B8,단가마스터!$A$4:$H$303,5,FALSE),IFERROR(VLOOKUP($B8,일위대가!$N$4:$T$63,4,FALSE),0))) | P8: =IF($B8="","",IFERROR(VLOOKUP($B8,단가마스터!$A$4:$H$303,6,FALSE),IFERROR(VLOOKUP($B8,일위대가!$N$4:$T$63,5,FALSE),0))) | Q8: =IF($B8="","",IFERROR(VLOOKUP($B8,단가마스터!$A$4:$H$303,7,FALSE),IFERROR(VLOOKUP($B8,일위대가!$N$4:$T$63,6,FALSE),0))) | R8: =IF($B8="","",N($O8)+N($P8)+N($Q8)) | S8: =IF($B8="","",ROUND(N($N8)*N($R8),0)) | T8: =IF($B8="","",N($N8)-N($F8)) | U8: =IF($B8="","",N($S8)-N($K8))
C9: =IF($B9="","",IFERROR(VLOOKUP($B9,단가마스터!$A$4:$H$303,2,FALSE),IFERROR(VLOOKUP($B9,일위대가!$N$4:$T$63,2,FALSE),"⚠️단가 없음"))) | D9: =IF($B9="","",IFERROR(VLOOKUP($B9,단가마스터!$A$4:$H$303,3,FALSE),"")) | E9: =IF($B9="","",IFERROR(VLOOKUP($B9,단가마스터!$A$4:$H$303,4,FALSE),IFERROR(VLOOKUP($B9,일위대가!$N$4:$T$63,3,FALSE),""))) | J9: =IF($B9="","",N($G9)+N($H9)+N($I9)) | K9: =IF($B9="","",ROUND(N($F9)*N($J9),0)) | L9: =IF($B9="","",SUMIFS(수량산출서!$H$4:$H$253,수량산출서!$A$4:$A$253,"변경",수량산출서!$B$4:$B$253,$B9)) | N9: =IF($B9="","",IF($M9<>"",$M9,N($L9))) | O9: =IF($B9="","",IFERROR(VLOOKUP($B9,단가마스터!$A$4:$H$303,5,FALSE),IFERROR(VLOOKUP($B9,일위대가!$N$4:$T$63,4,FALSE),0))) | P9: =IF($B9="","",IFERROR(VLOOKUP($B9,단가마스터!$A$4:$H$303,6,FALSE),IFERROR(VLOOKUP($B9,일위대가!$N$4:$T$63,5,FALSE),0))) | Q9: =IF($B9="","",IFERROR(VLOOKUP($B9,단가마스터!$A$4:$H$303,7,FALSE),IFERROR(VLOOKUP($B9,일위대가!$N$4:$T$63,6,FALSE),0))) | R9: =IF($B9="","",N($O9)+N($P9)+N($Q9)) | S9: =IF($B9="","",ROUND(N($N9)*N($R9),0)) | T9: =IF($B9="","",N($N9)-N($F9)) | U9: =IF($B9="","",N($S9)-N($K9))
C10: =IF($B10="","",IFERROR(VLOOKUP($B10,단가마스터!$A$4:$H$303,2,FALSE),IFERROR(VLOOKUP($B10,일위대가!$N$4:$T$63,2,FALSE),"⚠️단가 없음"))) | D10: =IF($B10="","",IFERROR(VLOOKUP($B10,단가마스터!$A$4:$H$303,3,FALSE),"")) | E10: =IF($B10="","",IFERROR(VLOOKUP($B10,단가마스터!$A$4:$H$303,4,FALSE),IFERROR(VLOOKUP($B10,일위대가!$N$4:$T$63,3,FALSE),""))) | J10: =IF($B10="","",N($G10)+N($H10)+N($I10)) | K10: =IF($B10="","",ROUND(N($F10)*N($J10),0)) | L10: =IF($B10="","",SUMIFS(수량산출서!$H$4:$H$253,수량산출서!$A$4:$A$253,"변경",수량산출서!$B$4:$B$253,$B10)) | N10: =IF($B10="","",IF($M10<>"",$M10,N($L10))) | O10: =IF($B10="","",IFERROR(VLOOKUP($B10,단가마스터!$A$4:$H$303,5,FALSE),IFERROR(VLOOKUP($B10,일위대가!$N$4:$T$63,4,FALSE),0))) | P10: =IF($B10="","",IFERROR(VLOOKUP($B10,단가마스터!$A$4:$H$303,6,FALSE),IFERROR(VLOOKUP($B10,일위대가!$N$4:$T$63,5,FALSE),0))) | Q10: =IF($B10="","",IFERROR(VLOOKUP($B10,단가마스터!$A$4:$H$303,7,FALSE),IFERROR(VLOOKUP($B10,일위대가!$N$4:$T$63,6,FALSE),0))) | R10: =IF($B10="","",N($O10)+N($P10)+N($Q10)) | S10: =IF($B10="","",ROUND(N($N10)*N($R10),0)) | T10: =IF($B10="","",N($N10)-N($F10)) | U10: =IF($B10="","",N($S10)-N($K10))
C11: =IF($B11="","",IFERROR(VLOOKUP($B11,단가마스터!$A$4:$H$303,2,FALSE),IFERROR(VLOOKUP($B11,일위대가!$N$4:$T$63,2,FALSE),"⚠️단가 없음"))) | D11: =IF($B11="","",IFERROR(VLOOKUP($B11,단가마스터!$A$4:$H$303,3,FALSE),"")) | E11: =IF($B11="","",IFERROR(VLOOKUP($B11,단가마스터!$A$4:$H$303,4,FALSE),IFERROR(VLOOKUP($B11,일위대가!$N$4:$T$63,3,FALSE),""))) | J11: =IF($B11="","",N($G11)+N($H11)+N($I11)) | K11: =IF($B11="","",ROUND(N($F11)*N($J11),0)) | L11: =IF($B11="","",SUMIFS(수량산출서!$H$4:$H$253,수량산출서!$A$4:$A$253,"변경",수량산출서!$B$4:$B$253,$B11)) | N11: =IF($B11="","",IF($M11<>"",$M11,N($L11))) | O11: =IF($B11="","",IFERROR(VLOOKUP($B11,단가마스터!$A$4:$H$303,5,FALSE),IFERROR(VLOOKUP($B11,일위대가!$N$4:$T$63,4,FALSE),0))) | P11: =IF($B11="","",IFERROR(VLOOKUP($B11,단가마스터!$A$4:$H$303,6,FALSE),IFERROR(VLOOKUP($B11,일위대가!$N$4:$T$63,5,FALSE),0))) | Q11: =IF($B11="","",IFERROR(VLOOKUP($B11,단가마스터!$A$4:$H$303,7,FALSE),IFERROR(VLOOKUP($B11,일위대가!$N$4:$T$63,6,FALSE),0))) | R11: =IF($B11="","",N($O11)+N($P11)+N($Q11)) | S11: =IF($B11="","",ROUND(N($N11)*N($R11),0)) | T11: =IF($B11="","",N($N11)-N($F11)) | U11: =IF($B11="","",N($S11)-N($K11))
C12: =IF($B12="","",IFERROR(VLOOKUP($B12,단가마스터!$A$4:$H$303,2,FALSE),IFERROR(VLOOKUP($B12,일위대가!$N$4:$T$63,2,FALSE),"⚠️단가 없음"))) | D12: =IF($B12="","",IFERROR(VLOOKUP($B12,단가마스터!$A$4:$H$303,3,FALSE),"")) | E12: =IF($B12="","",IFERROR(VLOOKUP($B12,단가마스터!$A$4:$H$303,4,FALSE),IFERROR(VLOOKUP($B12,일위대가!$N$4:$T$63,3,FALSE),""))) | J12: =IF($B12="","",N($G12)+N($H12)+N($I12)) | K12: =IF($B12="","",ROUND(N($F12)*N($J12),0)) | L12: =IF($B12="","",SUMIFS(수량산출서!$H$4:$H$253,수량산출서!$A$4:$A$253,"변경",수량산출서!$B$4:$B$253,$B12)) | N12: =IF($B12="","",IF($M12<>"",$M12,N($L12))) | O12: =IF($B12="","",IFERROR(VLOOKUP($B12,단가마스터!$A$4:$H$303,5,FALSE),IFERROR(VLOOKUP($B12,일위대가!$N$4:$T$63,4,FALSE),0))) | P12: =IF($B12="","",IFERROR(VLOOKUP($B12,단가마스터!$A$4:$H$303,6,FALSE),IFERROR(VLOOKUP($B12,일위대가!$N$4:$T$63,5,FALSE),0))) | Q12: =IF($B12="","",IFERROR(VLOOKUP($B12,단가마스터!$A$4:$H$303,7,FALSE),IFERROR(VLOOKUP($B12,일위대가!$N$4:$T$63,6,FALSE),0))) | R12: =IF($B12="","",N($O12)+N($P12)+N($Q12)) | S12: =IF($B12="","",ROUND(N($N12)*N($R12),0)) | T12: =IF($B12="","",N($N12)-N($F12)) | U12: =IF($B12="","",N($S12)-N($K12))
C13: =IF($B13="","",IFERROR(VLOOKUP($B13,단가마스터!$A$4:$H$303,2,FALSE),IFERROR(VLOOKUP($B13,일위대가!$N$4:$T$63,2,FALSE),"⚠️단가 없음"))) | D13: =IF($B13="","",IFERROR(VLOOKUP($B13,단가마스터!$A$4:$H$303,3,FALSE),"")) | E13: =IF($B13="","",IFERROR(VLOOKUP($B13,단가마스터!$A$4:$H$303,4,FALSE),IFERROR(VLOOKUP($B13,일위대가!$N$4:$T$63,3,FALSE),""))) | J13: =IF($B13="","",N($G13)+N($H13)+N($I13)) | K13: =IF($B13="","",ROUND(N($F13)*N($J13),0)) | L13: =IF($B13="","",SUMIFS(수량산출서!$H$4:$H$253,수량산출서!$A$4:$A$253,"변경",수량산출서!$B$4:$B$253,$B13)) | N13: =IF($B13="","",IF($M13<>"",$M13,N($L13))) | O13: =IF($B13="","",IFERROR(VLOOKUP($B13,단가마스터!$A$4:$H$303,5,FALSE),IFERROR(VLOOKUP($B13,일위대가!$N$4:$T$63,4,FALSE),0))) | P13: =IF($B13="","",IFERROR(VLOOKUP($B13,단가마스터!$A$4:$H$303,6,FALSE),IFERROR(VLOOKUP($B13,일위대가!$N$4:$T$63,5,FALSE),0))) | Q13: =IF($B13="","",IFERROR(VLOOKUP($B13,단가마스터!$A$4:$H$303,7,FALSE),IFERROR(VLOOKUP($B13,일위대가!$N$4:$T$63,6,FALSE),0))) | R13: =IF($B13="","",N($O13)+N($P13)+N($Q13)) | S13: =IF($B13="","",ROUND(N($N13)*N($R13),0)) | T13: =IF($B13="","",N($N13)-N($F13)) | U13: =IF($B13="","",N($S13)-N($K13))
C14: =IF($B14="","",IFERROR(VLOOKUP($B14,단가마스터!$A$4:$H$303,2,FALSE),IFERROR(VLOOKUP($B14,일위대가!$N$4:$T$63,2,FALSE),"⚠️단가 없음"))) | D14: =IF($B14="","",IFERROR(VLOOKUP($B14,단가마스터!$A$4:$H$303,3,FALSE),"")) | E14: =IF($B14="","",IFERROR(VLOOKUP($B14,단가마스터!$A$4:$H$303,4,FALSE),IFERROR(VLOOKUP($B14,일위대가!$N$4:$T$63,3,FALSE),""))) | J14: =IF($B14="","",N($G14)+N($H14)+N($I14)) | K14: =IF($B14="","",ROUND(N($F14)*N($J14),0)) | L14: =IF($B14="","",SUMIFS(수량산출서!$H$4:$H$253,수량산출서!$A$4:$A$253,"변경",수량산출서!$B$4:$B$253,$B14)) | N14: =IF($B14="","",IF($M14<>"",$M14,N($L14))) | O14: =IF($B14="","",IFERROR(VLOOKUP($B14,단가마스터!$A$4:$H$303,5,FALSE),IFERROR(VLOOKUP($B14,일위대가!$N$4:$T$63,4,FALSE),0))) | P14: =IF($B14="","",IFERROR(VLOOKUP($B14,단가마스터!$A$4:$H$303,6,FALSE),IFERROR(VLOOKUP($B14,일위대가!$N$4:$T$63,5,FALSE),0))) | Q14: =IF($B14="","",IFERROR(VLOOKUP($B14,단가마스터!$A$4:$H$303,7,FALSE),IFERROR(VLOOKUP($B14,일위대가!$N$4:$T$63,6,FALSE),0))) | R14: =IF($B14="","",N($O14)+N($P14)+N($Q14)) | S14: =IF($B14="","",ROUND(N($N14)*N($R14),0)) | T14: =IF($B14="","",N($N14)-N($F14)) | U14: =IF($B14="","",N($S14)-N($K14))
C15: =IF($B15="","",IFERROR(VLOOKUP($B15,단가마스터!$A$4:$H$303,2,FALSE),IFERROR(VLOOKUP($B15,일위대가!$N$4:$T$63,2,FALSE),"⚠️단가 없음"))) | D15: =IF($B15="","",IFERROR(VLOOKUP($B15,단가마스터!$A$4:$H$303,3,FALSE),"")) | E15: =IF($B15="","",IFERROR(VLOOKUP($B15,단가마스터!$A$4:$H$303,4,FALSE),IFERROR(VLOOKUP($B15,일위대가!$N$4:$T$63,3,FALSE),""))) | J15: =IF($B15="","",N($G15)+N($H15)+N($I15)) | K15: =IF($B15="","",ROUND(N($F15)*N($J15),0)) | L15: =IF($B15="","",SUMIFS(수량산출서!$H$4:$H$253,수량산출서!$A$4:$A$253,"변경",수량산출서!$B$4:$B$253,$B15)) | N15: =IF($B15="","",IF($M15<>"",$M15,N($L15))) | O15: =IF($B15="","",IFERROR(VLOOKUP($B15,단가마스터!$A$4:$H$303,5,FALSE),IFERROR(VLOOKUP($B15,일위대가!$N$4:$T$63,4,FALSE),0))) | P15: =IF($B15="","",IFERROR(VLOOKUP($B15,단가마스터!$A$4:$H$303,6,FALSE),IFERROR(VLOOKUP($B15,일위대가!$N$4:$T$63,5,FALSE),0))) | Q15: =IF($B15="","",IFERROR(VLOOKUP($B15,단가마스터!$A$4:$H$303,7,FALSE),IFERROR(VLOOKUP($B15,일위대가!$N$4:$T$63,6,FALSE),0))) | R15: =IF($B15="","",N($O15)+N($P15)+N($Q15)) | S15: =IF($B15="","",ROUND(N($N15)*N($R15),0)) | T15: =IF($B15="","",N($N15)-N($F15)) | U15: =IF($B15="","",N($S15)-N($K15))
... C203: =IF($B203="","",IFERROR(VLOOKUP($B203,단가마스터!$A$4:$H$303,2,FALSE),IFERROR(VLOOKUP($B203,일위대가!$N$4:$T$63,2,FALSE),"⚠️단가 없음"))) | D203: =IF($B203="","",IFERROR(VLOOKUP($B203,단가마스터!$A$4:$H$303,3,FALSE),"")) | E203: =IF($B203="","",IFERROR(VLOOKUP($B203,단가마스터!$A$4:$H$303,4,FALSE),IFERROR(VLOOKUP($B203,일위대가!$N$4:$T$63,3,FALSE),""))) | J203: =IF($B203="","",N($G203)+N($H203)+N($I203)) | K203: =IF($B203="","",ROUND(N($F203)*N($J203),0)) | L203: =IF($B203="","",SUMIFS(수량산출서!$H$4:$H$253,수량산출서!$A$4:$A$253,"변경",수량산출서!$B$4:$B$253,$B203)) | N203: =IF($B203="","",IF($M203<>"",$M203,N($L203))) | O203: =IF($B203="","",IFERROR(VLOOKUP($B203,단가마스터!$A$4:$H$303,5,FALSE),IFERROR(VLOOKUP($B203,일위대가!$N$4:$T$63,4,FALSE),0))) | P203: =IF($B203="","",IFERROR(VLOOKUP($B203,단가마스터!$A$4:$H$303,6,FALSE),IFERROR(VLOOKUP($B203,일위대가!$N$4:$T$63,5,FALSE),0))) | Q203: =IF($B203="","",IFERROR(VLOOKUP($B203,단가마스터!$A$4:$H$303,7,FALSE),IFERROR(VLOOKUP($B203,일위대가!$N$4:$T$63,6,FALSE),0))) | R203: =IF($B203="","",N($O203)+N($P203)+N($Q203)) | S203: =IF($B203="","",ROUND(N($N203)*N($R203),0)) | T203: =IF($B203="","",N($N203)-N($F203)) | U203: =IF($B203="","",N($S203)-N($K203))
B204: 합 계 | K204: =SUM(K4:K203) | S204: =SUM(S4:S203) | U204: =SUM(U4:U203)
A206: 공종코드만 넣으면 품명·규격·단위가 단가마스터(없으면 일위대가)에서 따라옵니다. ⚠️ 당초 쪽 수량과 단가는 **계약 내역서에서 그대로 옮겨 적으십시오** — 계약단가는 지금 시세가 아니라 계약 당시 값입니다. 변경 쪽 단가만 단가마스터·일위대가에서 자동으로 옵니다. 변경 수량은 수량산출서에서 «변경» 으로 넣은 것이 합쳐지고, «수량(직접)» 에 적으면 그 값이 이깁니다. 당초 수량이 비어 있고 변경 수량만 있으면 **신규 비목**입니다 — 증감대비표가 그렇게 잡습니다.

Sheet 일위대가
A1: K-건설맵 | k-conmap.com ← 이 1행을 지우고 쓰셔도 됩니다
A2: 일 위 대 가 표 | N2: ▶ 오른쪽 = 일위번호별 단가 (내역서가 여기를 봅니다)
A3: 일위번호 | B3: 구성코드 | C3: 품 명 | D3: 규 격 | E3: 단위 | F3: 수량 | G3: 재료비단가 | H3: 노무비단가 | I3: 경비단가 | J3: 재료비금액 | K3: 노무비금액 | L3: 경비금액 | N3: 일위번호 | O3: 일위 품명 | P3: 단위 | Q3: 재료비계 | R3: 노무비계 | S3: 경비계 | T3: 합계단가
C4: =IF($B4="","",IFERROR(VLOOKUP($B4,단가마스터!$A$4:$H$303,2,FALSE),"⚠️단가마스터에 없음")) | D4: =IF($B4="","",IFERROR(VLOOKUP($B4,단가마스터!$A$4:$H$303,3,FALSE),"")) | E4: =IF($B4="","",IFERROR(VLOOKUP($B4,단가마스터!$A$4:$H$303,4,FALSE),"")) | G4: =IF($B4="","",IFERROR(VLOOKUP($B4,단가마스터!$A$4:$H$303,5,FALSE),0)) | H4: =IF($B4="","",IFERROR(VLOOKUP($B4,단가마스터!$A$4:$H$303,6,FALSE),0)) | I4: =IF($B4="","",IFERROR(VLOOKUP($B4,단가마스터!$A$4:$H$303,7,FALSE),0)) | J4: =IF($B4="","",N($F4)*N($G4)) | K4: =IF($B4="","",N($F4)*N($H4)) | L4: =IF($B4="","",N($F4)*N($I4)) | Q4: =IF($N4="","",SUMIF($A$4:$A$303,$N4,$J$4:$J$303)) | R4: =IF($N4="","",SUMIF($A$4:$A$303,$N4,$K$4:$K$303)) | S4: =IF($N4="","",SUMIF($A$4:$A$303,$N4,$L$4:$L$303)) | T4: =IF($N4="","",N(Q4)+N(R4)+N(S4))
C5: =IF($B5="","",IFERROR(VLOOKUP($B5,단가마스터!$A$4:$H$303,2,FALSE),"⚠️단가마스터에 없음")) | D5: =IF($B5="","",IFERROR(VLOOKUP($B5,단가마스터!$A$4:$H$303,3,FALSE),"")) | E5: =IF($B5="","",IFERROR(VLOOKUP($B5,단가마스터!$A$4:$H$303,4,FALSE),"")) | G5: =IF($B5="","",IFERROR(VLOOKUP($B5,단가마스터!$A$4:$H$303,5,FALSE),0)) | H5: =IF($B5="","",IFERROR(VLOOKUP($B5,단가마스터!$A$4:$H$303,6,FALSE),0)) | I5: =IF($B5="","",IFERROR(VLOOKUP($B5,단가마스터!$A$4:$H$303,7,FALSE),0)) | J5: =IF($B5="","",N($F5)*N($G5)) | K5: =IF($B5="","",N($F5)*N($H5)) | L5: =IF($B5="","",N($F5)*N($I5)) | Q5: =IF($N5="","",SUMIF($A$4:$A$303,$N5,$J$4:$J$303)) | R5: =IF($N5="","",SUMIF($A$4:$A$303,$N5,$K$4:$K$303)) | S5: =IF($N5="","",SUMIF($A$4:$A$303,$N5,$L$4:$L$303)) | T5: =IF($N5="","",N(Q5)+N(R5)+N(S5))
C6: =IF($B6="","",IFERROR(VLOOKUP($B6,단가마스터!$A$4:$H$303,2,FALSE),"⚠️단가마스터에 없음")) | D6: =IF($B6="","",IFERROR(VLOOKUP($B6,단가마스터!$A$4:$H$303,3,FALSE),"")) | E6: =IF($B6="","",IFERROR(VLOOKUP($B6,단가마스터!$A$4:$H$303,4,FALSE),"")) | G6: =IF($B6="","",IFERROR(VLOOKUP($B6,단가마스터!$A$4:$H$303,5,FALSE),0)) | H6: =IF($B6="","",IFERROR(VLOOKUP($B6,단가마스터!$A$4:$H$303,6,FALSE),0)) | I6: =IF($B6="","",IFERROR(VLOOKUP($B6,단가마스터!$A$4:$H$303,7,FALSE),0)) | J6: =IF($B6="","",N($F6)*N($G6)) | K6: =IF($B6="","",N($F6)*N($H6)) | L6: =IF($B6="","",N($F6)*N($I6)) | Q6: =IF($N6="","",SUMIF($A$4:$A$303,$N6,$J$4:$J$303)) | R6: =IF($N6="","",SUMIF($A$4:$A$303,$N6,$K$4:$K$303)) | S6: =IF($N6="","",SUMIF($A$4:$A$303,$N6,$L$4:$L$303)) | T6: =IF($N6="","",N(Q6)+N(R6)+N(S6))
C7: =IF($B7="","",IFERROR(VLOOKUP($B7,단가마스터!$A$4:$H$303,2,FALSE),"⚠️단가마스터에 없음")) | D7: =IF($B7="","",IFERROR(VLOOKUP($B7,단가마스터!$A$4:$H$303,3,FALSE),"")) | E7: =IF($B7="","",IFERROR(VLOOKUP($B7,단가마스터!$A$4:$H$303,4,FALSE),"")) | G7: =IF($B7="","",IFERROR(VLOOKUP($B7,단가마스터!$A$4:$H$303,5,FALSE),0)) | H7: =IF($B7="","",IFERROR(VLOOKUP($B7,단가마스터!$A$4:$H$303,6,FALSE),0)) | I7: =IF($B7="","",IFERROR(VLOOKUP($B7,단가마스터!$A$4:$H$303,7,FALSE),0)) | J7: =IF($B7="","",N($F7)*N($G7)) | K7: =IF($B7="","",N($F7)*N($H7)) | L7: =IF($B7="","",N($F7)*N($I7)) | Q7: =IF($N7="","",SUMIF($A$4:$A$303,$N7,$J$4:$J$303)) | R7: =IF($N7="","",SUMIF($A$4:$A$303,$N7,$K$4:$K$303)) | S7: =IF($N7="","",SUMIF($A$4:$A$303,$N7,$L$4:$L$303)) | T7: =IF($N7="","",N(Q7)+N(R7)+N(S7))
C8: =IF($B8="","",IFERROR(VLOOKUP($B8,단가마스터!$A$4:$H$303,2,FALSE),"⚠️단가마스터에 없음")) | D8: =IF($B8="","",IFERROR(VLOOKUP($B8,단가마스터!$A$4:$H$303,3,FALSE),"")) | E8: =IF($B8="","",IFERROR(VLOOKUP($B8,단가마스터!$A$4:$H$303,4,FALSE),"")) | G8: =IF($B8="","",IFERROR(VLOOKUP($B8,단가마스터!$A$4:$H$303,5,FALSE),0)) | H8: =IF($B8="","",IFERROR(VLOOKUP($B8,단가마스터!$A$4:$H$303,6,FALSE),0)) | I8: =IF($B8="","",IFERROR(VLOOKUP($B8,단가마스터!$A$4:$H$303,7,FALSE),0)) | J8: =IF($B8="","",N($F8)*N($G8)) | K8: =IF($B8="","",N($F8)*N($H8)) | L8: =IF($B8="","",N($F8)*N($I8)) | Q8: =IF($N8="","",SUMIF($A$4:$A$303,$N8,$J$4:$J$303)) | R8: =IF($N8="","",SUMIF($A$4:$A$303,$N8,$K$4:$K$303)) | S8: =IF($N8="","",SUMIF($A$4:$A$303,$N8,$L$4:$L$303)) | T8: =IF($N8="","",N(Q8)+N(R8)+N(S8))
C9: =IF($B9="","",IFERROR(VLOOKUP($B9,단가마스터!$A$4:$H$303,2,FALSE),"⚠️단가마스터에 없음")) | D9: =IF($B9="","",IFERROR(VLOOKUP($B9,단가마스터!$A$4:$H$303,3,FALSE),"")) | E9: =IF($B9="","",IFERROR(VLOOKUP($B9,단가마스터!$A$4:$H$303,4,FALSE),"")) | G9: =IF($B9="","",IFERROR(VLOOKUP($B9,단가마스터!$A$4:$H$303,5,FALSE),0)) | H9: =IF($B9="","",IFERROR(VLOOKUP($B9,단가마스터!$A$4:$H$303,6,FALSE),0)) | I9: =IF($B9="","",IFERROR(VLOOKUP($B9,단가마스터!$A$4:$H$303,7,FALSE),0)) | J9: =IF($B9="","",N($F9)*N($G9)) | K9: =IF($B9="","",N($F9)*N($H9)) | L9: =IF($B9="","",N($F9)*N($I9)) | Q9: =IF($N9="","",SUMIF($A$4:$A$303,$N9,$J$4:$J$303)) | R9: =IF($N9="","",SUMIF($A$4:$A$303,$N9,$K$4:$K$303)) | S9: =IF($N9="","",SUMIF($A$4:$A$303,$N9,$L$4:$L$303)) | T9: =IF($N9="","",N(Q9)+N(R9)+N(S9))
C10: =IF($B10="","",IFERROR(VLOOKUP($B10,단가마스터!$A$4:$H$303,2,FALSE),"⚠️단가마스터에 없음")) | D10: =IF($B10="","",IFERROR(VLOOKUP($B10,단가마스터!$A$4:$H$303,3,FALSE),"")) | E10: =IF($B10="","",IFERROR(VLOOKUP($B10,단가마스터!$A$4:$H$303,4,FALSE),"")) | G10: =IF($B10="","",IFERROR(VLOOKUP($B10,단가마스터!$A$4:$H$303,5,FALSE),0)) | H10: =IF($B10="","",IFERROR(VLOOKUP($B10,단가마스터!$A$4:$H$303,6,FALSE),0)) | I10: =IF($B10="","",IFERROR(VLOOKUP($B10,단가마스터!$A$4:$H$303,7,FALSE),0)) | J10: =IF($B10="","",N($F10)*N($G10)) | K10: =IF($B10="","",N($F10)*N($H10)) | L10: =IF($B10="","",N($F10)*N($I10)) | Q10: =IF($N10="","",SUMIF($A$4:$A$303,$N10,$J$4:$J$303)) | R10: =IF($N10="","",SUMIF($A$4:$A$303,$N10,$K$4:$K$303)) | S10: =IF($N10="","",SUMIF($A$4:$A$303,$N10,$L$4:$L$303)) | T10: =IF($N10="","",N(Q10)+N(R10)+N(S10))
C11: =IF($B11="","",IFERROR(VLOOKUP($B11,단가마스터!$A$4:$H$303,2,FALSE),"⚠️단가마스터에 없음")) | D11: =IF($B11="","",IFERROR(VLOOKUP($B11,단가마스터!$A$4:$H$303,3,FALSE),"")) | E11: =IF($B11="","",IFERROR(VLOOKUP($B11,단가마스터!$A$4:$H$303,4,FALSE),"")) | G11: =IF($B11="","",IFERROR(VLOOKUP($B11,단가마스터!$A$4:$H$303,5,FALSE),0)) | H11: =IF($B11="","",IFERROR(VLOOKUP($B11,단가마스터!$A$4:$H$303,6,FALSE),0)) | I11: =IF($B11="","",IFERROR(VLOOKUP($B11,단가마스터!$A$4:$H$303,7,FALSE),0)) | J11: =IF($B11="","",N($F11)*N($G11)) | K11: =IF($B11="","",N($F11)*N($H11)) | L11: =IF($B11="","",N($F11)*N($I11)) | Q11: =IF($N11="","",SUMIF($A$4:$A$303,$N11,$J$4:$J$303)) | R11: =IF($N11="","",SUMIF($A$4:$A$303,$N11,$K$4:$K$303)) | S11: =IF($N11="","",SUMIF($A$4:$A$303,$N11,$L$4:$L$303)) | T11: =IF($N11="","",N(Q11)+N(R11)+N(S11))
C12: =IF($B12="","",IFERROR(VLOOKUP($B12,단가마스터!$A$4:$H$303,2,FALSE),"⚠️단가마스터에 없음")) | D12: =IF($B12="","",IFERROR(VLOOKUP($B12,단가마스터!$A$4:$H$303,3,FALSE),"")) | E12: =IF($B12="","",IFERROR(VLOOKUP($B12,단가마스터!$A$4:$H$303,4,FALSE),"")) | G12: =IF($B12="","",IFERROR(VLOOKUP($B12,단가마스터!$A$4:$H$303,5,FALSE),0)) | H12: =IF($B12="","",IFERROR(VLOOKUP($B12,단가마스터!$A$4:$H$303,6,FALSE),0)) | I12: =IF($B12="","",IFERROR(VLOOKUP($B12,단가마스터!$A$4:$H$303,7,FALSE),0)) | J12: =IF($B12="","",N($F12)*N($G12)) | K12: =IF($B12="","",N($F12)*N($H12)) | L12: =IF($B12="","",N($F12)*N($I12)) | Q12: =IF($N12="","",SUMIF($A$4:$A$303,$N12,$J$4:$J$303)) | R12: =IF($N12="","",SUMIF($A$4:$A$303,$N12,$K$4:$K$303)) | S12: =IF($N12="","",SUMIF($A$4:$A$303,$N12,$L$4:$L$303)) | T12: =IF($N12="","",N(Q12)+N(R12)+N(S12))
C13: =IF($B13="","",IFERROR(VLOOKUP($B13,단가마스터!$A$4:$H$303,2,FALSE),"⚠️단가마스터에 없음")) | D13: =IF($B13="","",IFERROR(VLOOKUP($B13,단가마스터!$A$4:$H$303,3,FALSE),"")) | E13: =IF($B13="","",IFERROR(VLOOKUP($B13,단가마스터!$A$4:$H$303,4,FALSE),"")) | G13: =IF($B13="","",IFERROR(VLOOKUP($B13,단가마스터!$A$4:$H$303,5,FALSE),0)) | H13: =IF($B13="","",IFERROR(VLOOKUP($B13,단가마스터!$A$4:$H$303,6,FALSE),0)) | I13: =IF($B13="","",IFERROR(VLOOKUP($B13,단가마스터!$A$4:$H$303,7,FALSE),0)) | J13: =IF($B13="","",N($F13)*N($G13)) | K13: =IF($B13="","",N($F13)*N($H13)) | L13: =IF($B13="","",N($F13)*N($I13)) | Q13: =IF($N13="","",SUMIF($A$4:$A$303,$N13,$J$4:$J$303)) | R13: =IF($N13="","",SUMIF($A$4:$A$303,$N13,$K$4:$K$303)) | S13: =IF($N13="","",SUMIF($A$4:$A$303,$N13,$L$4:$L$303)) | T13: =IF($N13="","",N(Q13)+N(R13)+N(S13))
C14: =IF($B14="","",IFERROR(VLOOKUP($B14,단가마스터!$A$4:$H$303,2,FALSE),"⚠️단가마스터에 없음")) | D14: =IF($B14="","",IFERROR(VLOOKUP($B14,단가마스터!$A$4:$H$303,3,FALSE),"")) | E14: =IF($B14="","",IFERROR(VLOOKUP($B14,단가마스터!$A$4:$H$303,4,FALSE),"")) | G14: =IF($B14="","",IFERROR(VLOOKUP($B14,단가마스터!$A$4:$H$303,5,FALSE),0)) | H14: =IF($B14="","",IFERROR(VLOOKUP($B14,단가마스터!$A$4:$H$303,6,FALSE),0)) | I14: =IF($B14="","",IFERROR(VLOOKUP($B14,단가마스터!$A$4:$H$303,7,FALSE),0)) | J14: =IF($B14="","",N($F14)*N($G14)) | K14: =IF($B14="","",N($F14)*N($H14)) | L14: =IF($B14="","",N($F14)*N($I14)) | Q14: =IF($N14="","",SUMIF($A$4:$A$303,$N14,$J$4:$J$303)) | R14: =IF($N14="","",SUMIF($A$4:$A$303,$N14,$K$4:$K$303)) | S14: =IF($N14="","",SUMIF($A$4:$A$303,$N14,$L$4:$L$303)) | T14: =IF($N14="","",N(Q14)+N(R14)+N(S14))
C15: =IF($B15="","",IFERROR(VLOOKUP($B15,단가마스터!$A$4:$H$303,2,FALSE),"⚠️단가마스터에 없음")) | D15: =IF($B15="","",IFERROR(VLOOKUP($B15,단가마스터!$A$4:$H$303,3,FALSE),"")) | E15: =IF($B15="","",IFERROR(VLOOKUP($B15,단가마스터!$A$4:$H$303,4,FALSE),"")) | G15: =IF($B15="","",IFERROR(VLOOKUP($B15,단가마스터!$A$4:$H$303,5,FALSE),0)) | H15: =IF($B15="","",IFERROR(VLOOKUP($B15,단가마스터!$A$4:$H$303,6,FALSE),0)) | I15: =IF($B15="","",IFERROR(VLOOKUP($B15,단가마스터!$A$4:$H$303,7,FALSE),0)) | J15: =IF($B15="","",N($F15)*N($G15)) | K15: =IF($B15="","",N($F15)*N($H15)) | L15: =IF($B15="","",N($F15)*N($I15)) | Q15: =IF($N15="","",SUMIF($A$4:$A$303,$N15,$J$4:$J$303)) | R15: =IF($N15="","",SUMIF($A$4:$A$303,$N15,$K$4:$K$303)) | S15: =IF($N15="","",SUMIF($A$4:$A$303,$N15,$L$4:$L$303)) | T15: =IF($N15="","",N(Q15)+N(R15)+N(S15))
... C63: =IF($B63="","",IFERROR(VLOOKUP($B63,단가마스터!$A$4:$H$303,2,FALSE),"⚠️단가마스터에 없음")) | D63: =IF($B63="","",IFERROR(VLOOKUP($B63,단가마스터!$A$4:$H$303,3,FALSE),"")) | E63: =IF($B63="","",IFERROR(VLOOKUP($B63,단가마스터!$A$4:$H$303,4,FALSE),"")) | G63: =IF($B63="","",IFERROR(VLOOKUP($B63,단가마스터!$A$4:$H$303,5,FALSE),0)) | H63: =IF($B63="","",IFERROR(VLOOKUP($B63,단가마스터!$A$4:$H$303,6,FALSE),0)) | I63: =IF($B63="","",IFERROR(VLOOKUP($B63,단가마스터!$A$4:$H$303,7,FALSE),0)) | J63: =IF($B63="","",N($F63)*N($G63)) | K63: =IF($B63="","",N($F63)*N($H63)) | L63: =IF($B63="","",N($F63)*N($I63)) | Q63: =IF($N63="","",SUMIF($A$4:$A$303,$N63,$J$4:$J$303)) | R63: =IF($N63="","",SUMIF($A$4:$A$303,$N63,$K$4:$K$303)) | S63: =IF($N63="","",SUMIF($A$4:$A$303,$N63,$L$4:$L$303)) | T63: =IF($N63="","",N(Q63)+N(R63)+N(S63))
C64: =IF($B64="","",IFERROR(VLOOKUP($B64,단가마스터!$A$4:$H$303,2,FALSE),"⚠️단가마스터에 없음")) | D64: =IF($B64="","",IFERROR(VLOOKUP($B64,단가마스터!$A$4:$H$303,3,FALSE),"")) | E64: =IF($B64="","",IFERROR(VLOOKUP($B64,단가마스터!$A$4:$H$303,4,FALSE),"")) | G64: =IF($B64="","",IFERROR(VLOOKUP($B64,단가마스터!$A$4:$H$303,5,FALSE),0)) | H64: =IF($B64="","",IFERROR(VLOOKUP($B64,단가마스터!$A$4:$H$303,6,FALSE),0)) | I64: =IF($B64="","",IFERROR(VLOOKUP($B64,단가마스터!$A$4:$H$303,7,FALSE),0)) | J64: =IF($B64="","",N($F64)*N($G64)) | K64: =IF($B64="","",N($F64)*N($H64)) | L64: =IF($B64="","",N($F64)*N($I64))
C65: =IF($B65="","",IFERROR(VLOOKUP($B65,단가마스터!$A$4:$H$303,2,FALSE),"⚠️단가마스터에 없음")) | D65: =IF($B65="","",IFERROR(VLOOKUP($B65,단가마스터!$A$4:$H$303,3,FALSE),"")) | E65: =IF($B65="","",IFERROR(VLOOKUP($B65,단가마스터!$A$4:$H$303,4,FALSE),"")) | G65: =IF($B65="","",IFERROR(VLOOKUP($B65,단가마스터!$A$4:$H$303,5,FALSE),0)) | H65: =IF($B65="","",IFERROR(VLOOKUP($B65,단가마스터!$A$4:$H$303,6,FALSE),0)) | I65: =IF($B65="","",IFERROR(VLOOKUP($B65,단가마스터!$A$4:$H$303,7,FALSE),0)) | J65: =IF($B65="","",N($F65)*N($G65)) | K65: =IF($B65="","",N($F65)*N($H65)) | L65: =IF($B65="","",N($F65)*N($I65))
C66: =IF($B66="","",IFERROR(VLOOKUP($B66,단가마스터!$A$4:$H$303,2,FALSE),"⚠️단가마스터에 없음")) | D66: =IF($B66="","",IFERROR(VLOOKUP($B66,단가마스터!$A$4:$H$303,3,FALSE),"")) | E66: =IF($B66="","",IFERROR(VLOOKUP($B66,단가마스터!$A$4:$H$303,4,FALSE),"")) | G66: =IF($B66="","",IFERROR(VLOOKUP($B66,단가마스터!$A$4:$H$303,5,FALSE),0)) | H66: =IF($B66="","",IFERROR(VLOOKUP($B66,단가마스터!$A$4:$H$303,6,FALSE),0)) | I66: =IF($B66="","",IFERROR(VLOOKUP($B66,단가마스터!$A$4:$H$303,7,FALSE),0)) | J66: =IF($B66="","",N($F66)*N($G66)) | K66: =IF($B66="","",N($F66)*N($H66)) | L66: =IF($B66="","",N($F66)*N($I66))
C67: =IF($B67="","",IFERROR(VLOOKUP($B67,단가마스터!$A$4:$H$303,2,FALSE),"⚠️단가마스터에 없음")) | D67: =IF($B67="","",IFERROR(VLOOKUP($B67,단가마스터!$A$4:$H$303,3,FALSE),"")) | E67: =IF($B67="","",IFERROR(VLOOKUP($B67,단가마스터!$A$4:$H$303,4,FALSE),"")) | G67: =IF($B67="","",IFERROR(VLOOKUP($B67,단가마스터!$A$4:$H$303,5,FALSE),0)) | H67: =IF($B67="","",IFERROR(VLOOKUP($B67,단가마스터!$A$4:$H$303,6,FALSE),0)) | I67: =IF($B67="","",IFERROR(VLOOKUP($B67,단가마스터!$A$4:$H$303,7,FALSE),0)) | J67: =IF($B67="","",N($F67)*N($G67)) | K67: =IF($B67="","",N($F67)*N($H67)) | L67: =IF($B67="","",N($F67)*N($I67))
C68: =IF($B68="","",IFERROR(VLOOKUP($B68,단가마스터!$A$4:$H$303,2,FALSE),"⚠️단가마스터에 없음")) | D68: =IF($B68="","",IFERROR(VLOOKUP($B68,단가마스터!$A$4:$H$303,3,FALSE),"")) | E68: =IF($B68="","",IFERROR(VLOOKUP($B68,단가마스터!$A$4:$H$303,4,FALSE),"")) | G68: =IF($B68="","",IFERROR(VLOOKUP($B68,단가마스터!$A$4:$H$303,5,FALSE),0)) | H68: =IF($B68="","",IFERROR(VLOOKUP($B68,단가마스터!$A$4:$H$303,6,FALSE),0)) | I68: =IF($B68="","",IFERROR(VLOOKUP($B68,단가마스터!$A$4:$H$303,7,FALSE),0)) | J68: =IF($B68="","",N($F68)*N($G68)) | K68: =IF($B68="","",N($F68)*N($H68)) | L68: =IF($B68="","",N($F68)*N($I68))
C69: =IF($B69="","",IFERROR(VLOOKUP($B69,단가마스터!$A$4:$H$303,2,FALSE),"⚠️단가마스터에 없음")) | D69: =IF($B69="","",IFERROR(VLOOKUP($B69,단가마스터!$A$4:$H$303,3,FALSE),"")) | E69: =IF($B69="","",IFERROR(VLOOKUP($B69,단가마스터!$A$4:$H$303,4,FALSE),"")) | G69: =IF($B69="","",IFERROR(VLOOKUP($B69,단가마스터!$A$4:$H$303,5,FALSE),0)) | H69: =IF($B69="","",IFERROR(VLOOKUP($B69,단가마스터!$A$4:$H$303,6,FALSE),0)) | I69: =IF($B69="","",IFERROR(VLOOKUP($B69,단가마스터!$A$4:$H$303,7,FALSE),0)) | J69: =IF($B69="","",N($F69)*N($G69)) | K69: =IF($B69="","",N($F69)*N($H69)) | L69: =IF($B69="","",N($F69)*N($I69))
C70: =IF($B70="","",IFERROR(VLOOKUP($B70,단가마스터!$A$4:$H$303,2,FALSE),"⚠️단가마스터에 없음")) | D70: =IF($B70="","",IFERROR(VLOOKUP($B70,단가마스터!$A$4:$H$303,3,FALSE),"")) | E70: =IF($B70="","",IFERROR(VLOOKUP($B70,단가마스터!$A$4:$H$303,4,FALSE),"")) | G70: =IF($B70="","",IFERROR(VLOOKUP($B70,단가마스터!$A$4:$H$303,5,FALSE),0)) | H70: =IF($B70="","",IFERROR(VLOOKUP($B70,단가마스터!$A$4:$H$303,6,FALSE),0)) | I70: =IF($B70="","",IFERROR(VLOOKUP($B70,단가마스터!$A$4:$H$303,7,FALSE),0)) | J70: =IF($B70="","",N($F70)*N($G70)) | K70: =IF($B70="","",N($F70)*N($H70)) | L70: =IF($B70="","",N($F70)*N($I70))
C71: =IF($B71="","",IFERROR(VLOOKUP($B71,단가마스터!$A$4:$H$303,2,FALSE),"⚠️단가마스터에 없음")) | D71: =IF($B71="","",IFERROR(VLOOKUP($B71,단가마스터!$A$4:$H$303,3,FALSE),"")) | E71: =IF($B71="","",IFERROR(VLOOKUP($B71,단가마스터!$A$4:$H$303,4,FALSE),"")) | G71: =IF($B71="","",IFERROR(VLOOKUP($B71,단가마스터!$A$4:$H$303,5,FALSE),0)) | H71: =IF($B71="","",IFERROR(VLOOKUP($B71,단가마스터!$A$4:$H$303,6,FALSE),0)) | I71: =IF($B71="","",IFERROR(VLOOKUP($B71,단가마스터!$A$4:$H$303,7,FALSE),0)) | J71: =IF($B71="","",N($F71)*N($G71)) | K71: =IF($B71="","",N($F71)*N($H71)) | L71: =IF($B71="","",N($F71)*N($I71))
C72: =IF($B72="","",IFERROR(VLOOKUP($B72,단가마스터!$A$4:$H$303,2,FALSE),"⚠️단가마스터에 없음")) | D72: =IF($B72="","",IFERROR(VLOOKUP($B72,단가마스터!$A$4:$H$303,3,FALSE),"")) | E72: =IF($B72="","",IFERROR(VLOOKUP($B72,단가마스터!$A$4:$H$303,4,FALSE),"")) | G72: =IF($B72="","",IFERROR(VLOOKUP($B72,단가마스터!$A$4:$H$303,5,FALSE),0)) | H72: =IF($B72="","",IFERROR(VLOOKUP($B72,단가마스터!$A$4:$H$303,6,FALSE),0)) | I72: =IF($B72="","",IFERROR(VLOOKUP($B72,단가마스터!$A$4:$H$303,7,FALSE),0)) | J72: =IF($B72="","",N($F72)*N($G72)) | K72: =IF($B72="","",N($F72)*N($H72)) | L72: =IF($B72="","",N($F72)*N($I72))
